Workbook

Sheet Sayfa1
D4: Önceki | E4: 45383 | F4: =+E4+1 -> 45384 | G4: =+F4+1 -> 45385 | H4: =+G4+1 -> 45386 | I4: =+H4+1 -> 45387 | J4: 45390 | K4: =+J4+1 -> 45391 | L4: 45397 | M4: =+L4+1 -> 45398 | N4: =+M4+1 -> 45399 | O4: =+N4+1 -> 45400 | P4: =+O4+1 -> 45401 | Q4: 45404 | R4: =+Q4+1 -> 45405 | S4: =+R4+1 -> 45406 | T4: =+S4+1 -> 45407 | U4: =+T4+1 -> 45408 | V4: =+U4+1 -> 45409 | W4: =+V4+1 -> 45410 | X4: =+W4+1 -> 45411 | Y4: =+X4+1 -> 45412
B5: BORSA | D5: =72856.0034747703-50000/32.5 -> 71317.542 | E5: 70716.193 | F5: 69265.422 | G5: 68946.794 | H5: 69384.162 | I5: 71368.397 | J5: 74001.336 | K5: 74448.943 | L5: 73292.314 | M5: 71016.206 | N5: 70979.347 | O5: 70840.532 | P5: 71510.191 | Q5: 71350.91 | R5: =+İcmal!$U$6 -> 71350.91
B6: MIDAS | D6: 17165.256 | E6: 22516.739 | F6: 22086.174 | G6: 22255.721 | H6: 21716.114 | I6: 21716.114 | J6: 22149.471 | K6: 22095.373 | L6: 21007.858 | M6: 21007.858 | N6: 20559.6 | O6: 20436.243 | P6: 20168.975 | Q6: 20266.001 | R6: =+İcmal!$U$13 -> 20266.001
B8: TOPLAM | D8: =SUM(D5:D6) -> 88482.798 | E8: =SUM(E5:E6) -> 93232.933 | F8: =SUM(F5:F6) -> 91351.596 | G8: =SUM(G5:G6) -> 91202.515 | H8: =SUM(H5:H6) -> 91100.276 | I8: =SUM(I5:I6) -> 93084.511 | J8: =SUM(J5:J6) -> 96150.808 | K8: =SUM(K5:K6) -> 96544.315 | ... Y8: =SUM(Y5:Y6) -> 0
D10: =+D5-350000/32.18 -> 60441.221 | E10: =+E5-350000/32.18 -> 59839.873 | F10: =+F5-350000/32.18 -> 58389.102 | G10: =+G5-350000/32.18 -> 58070.473 | H10: =+H5-350000/32.18 -> 58507.842 | I10: =+I5-350000/32.18 -> 60492.076 | J10: =+J5-350000/32.18 -> 63125.016 | K10: =+K5-350000/32.18 -> 63572.622 | ... U10: =+U5-350000/32.18 -> -10876.321 | V10: =+V5+350000/32.18 -> 10876.321
D13: =+D4 -> Önceki | E13: =+E4 -> 45383 | F13: =+F4 -> 45384 | G13: =+G4 -> 45385 | H13: =+H4 -> 45386 | I13: =+I4 -> 45387 | J13: =+J4 -> 45390 | K13: =+K4 -> 45391 | ... U13: =+U4 -> 45408
B14: BORSA | C14: =SUM(E14:Y14) -> 33.367993 | D14: =+D5 -> 71317.542 | E14: =+IF(E5="",0,E5-D5) -> -601.34846 | F14: =+IF(F5="",0,F5-E5) -> -1450.7712 | G14: =+IF(G5="",0,G5-F5) -> -318.62836 | H14: =+IF(H5="",0,H5-G5) -> 437.36847 | I14: =+IF(I5="",0,I5-H5) -> 1984.2347 | J14: =+IF(J5="",0,J5-I5) -> 2632.9394 | K14: =+IF(K5="",0,K5-J5) -> 447.6061 | L14: =+IF(L5="",0,L5-K5) -> -1156.6285 | ... Y14: =+IF(Y5="",0,Y5-X5) -> 0
B15: MIDAS | C15: =SUM(E15:Y15) -> 3100.745 | D15: =+D6 -> 17165.256 | E15: =+IF(E6="",0,E6-D6) -> 5351.4835 | F15: =+IF(F6="",0,F6-E6) -> -430.5656 | G15: =+IF(G6="",0,G6-F6) -> 169.54711 | H15: =+IF(H6="",0,H6-G6) -> -539.60675 | I15: =+IF(I6="",0,I6-H6) -> 0 | J15: =+IF(J6="",0,J6-I6) -> 433.3575 | K15: =+IF(K6="",0,K6-J6) -> -54.098722 | L15: =+IF(L6="",0,L6-K6) -> -1087.5144 | ... Y15: =+IF(Y6="",0,Y6-X6) -> 0
B17: TOPLAM | C17: =SUM(E17:Y17) -> 3134.113 | D17: =SUM(D14:D15) -> 88482.798 | E17: =SUM(E14:E15) -> 4750.135 | F17: =SUM(F14:F15) -> -1881.3368 | G17: =SUM(G14:G15) -> -149.08125 | H17: =SUM(H14:H15) -> -102.23828 | I17: =SUM(I14:I15) -> 1984.2347 | J17: =SUM(J14:J15) -> 3066.2969 | K17: =SUM(K14:K15) -> 393.50738 | ... Y17: =SUM(Y14:Y15) -> 0
E19: =+E17/D8 -> 0.053684277 | F19: =+F17/E8 -> -0.020178887 | G19: =+G17/F8 -> -0.0016319502 | H19: =+H17/G8 -> -0.0011210029 | I19: =+I17/H8 -> 0.021780776 | J19: =+J17/I8 -> 0.032941 | K19: =+K17/J8 -> 0.0040926061 | L19: =+L17/K8 -> -0.023244693 | ... Y19: =+Y17/X8 -> #DIV/0!
C21: =SUM(D21:Y21) -> 2980298.1 | D21: =D17*İcmal!$P$2 -> 2878345.4 | E21: =E17*İcmal!$P$2 -> 154521.89 | F21: =F17*İcmal!$P$2 -> -61199.886 | G21: =G17*İcmal!$P$2 -> -4849.6132 | H21: =H17*İcmal!$P$2 -> -3325.8113 | I21: =I17*İcmal!$P$2 -> 64547.154 | J21: =J17*İcmal!$P$2 -> 99746.638 | K21: =K17*İcmal!$P$2 -> 12800.795 | ... Y21: =Y17*İcmal!$P$2 -> 0
D22: =+D8*30.65 -> 2711997.7 | E22: =+E8*32.42 -> 3022611.7 | F22: =+F8*30.72 -> 2806321 | G22: =+G8*30.72 -> 2801741.2 | H22: =+H8*30.72 -> 2798600.5 | I22: =+I8*30.72 -> 2859556.2 | J22: =+J8*32.16 -> 3092210 | K22: =+K8*32.2 -> 3108726.9 | L22: =+L8*32.2 -> 3036465.5 | M22: =+M8*32.45 -> 2986180.9 | N22: =+N8*32.5 -> 2975015.8 | O22: =+O8*30.72 -> 2804022.5 | P22: =+P8*30.72 -> 2816384 | Q22: =+Q8*30.72 -> 2814471.5 | R22: =+R8*30.72 -> 2814471.5 | S22: =+S8*30.72 -> 0 | T22: =+T8*30.72 -> 0 | U22: =+U8*30.72 -> 0 | V22: =+V8*32.19 -> 0 | W22: =+W8*32.2 -> 0 | X22: =+X8*32.26 -> 0 | Y22: =+Y8*32.38 -> 0
C26: 88482.798
D27: BORSA | H27: MIDAS | J27: TOPLAM | L27: ARTIŞ
C28: Şubat 2.Hafta | D28: 658.03923 | E28: =+D28 -> 658.03923 | H28: 727.09196 | I28: =+H28 -> 727.09196 | J28: =+H28+D28 -> 1385.1312 | K28: =+J28 -> 1385.1312 | L28: =+J28/$C$26 -> 0.015654243 | M28: =+K28/$C$26 -> 0.015654243 | O28: =40000*M28+40000 -> 40626.17
C29: Şubat 3.Hafta | D29: 463.07491 | E29: =+D29+E28 -> 1121.1141 | H29: 1138.241 | I29: =+H29+I28 -> 1865.333 | J29: =+H29+D29 -> 1601.3159 | K29: =+J29+K28 -> 2986.4471 | L29: =+J29/$C$26 -> 0.018097483 | M29: =+K29/$C$26 -> 0.033751726 | O29: =40000*M29+40000 -> 41350.069
C30: Şubat 4.Hafta | D30: -750.93538 | E30: =+D30+E29 -> 370.17876 | H30: 1581.3974 | I30: =+H30+I29 -> 3446.7303 | J30: =+H30+D30 -> 830.46198 | K30: =+J30+K29 -> 3816.9091 | L30: =+J30/$C$26 -> 0.0093855756 | M30: =+K30/$C$26 -> 0.043137301 | O30: =40000*M30+40000 -> 41725.492
C31: Mart 1.Hafta | D31: -533.6806 | E31: =+D31+E30 -> -163.50184 | H31: 1468.9962 | I31: =+H31+I30 -> 4915.7265 | J31: =+H31+D31 -> 935.31559 | K31: =+J31+K30 -> 4752.2247 | L31: =+J31/$C$26 -> 0.010570592 | M31: =+K31/$C$26 -> 0.053707894 | O31: =40000*M31+40000 -> 42148.316
C32: Mart 2.Hafta | D32: -1588.1563 | E32: =+D32+E31 -> -1751.6581 | H32: -840.63293 | I32: =+H32+I31 -> 4075.0936 | J32: =+H32+D32 -> -2428.7892 | K32: =+J32+K31 -> 2323.4355 | L32: =+J32/$C$26 -> -0.027449282 | M32: =+K32/$C$26 -> 0.026258612 | O32: =40000*M32+40000 -> 41050.344
C33: Mart 3.Hafta | D33: -2588.2267 | E33: =+D33+E32 -> -4339.8848 | H33: 882.31701 | I33: =+H33+I32 -> 4957.4106 | J33: =+H33+D33 -> -1705.9097 | K33: =+J33+K32 -> 617.5258 | L33: =+J33/$C$26 -> -0.019279563 | M33: =+K33/$C$26 -> 0.0069790492 | O33: =40000*M33+40000 -> 40279.162
C34: Mart 4. Hafta | D34: 2022.5289 | E34: =+D34+E33 -> -2317.3559 | H34: 454.73418 | I34: =+H34+I33 -> 5412.1448 | J34: =+H34+D34 -> 2477.2631 | K34: =+J34+K33 -> 3094.7889 | L34: =+J34/$C$26 -> 0.027997116 | M34: =+K34/$C$26 -> 0.034976165 | O34: =40000*M34+40000 -> 41399.047
C35: Nisan 1.Hafta | D35: 3716.6716 | E35: =+D35+E34 -> 1399.3157 | H35: -569.38171 | I35: =+H35+I34 -> 4842.7631 | J35: =+H35+D35 -> 3147.2899 | K35: =+J35+K34 -> 6242.0788 | L35: =+J35/$C$26 -> 0.035569511 | M35: =+K35/$C$26 -> 0.070545676 | O35: =40000*M35+40000 -> 42821.827
C36: Nisan 2.Hafta | D36: 193.62336 | E36: =+D36+E35 -> 1592.9391 | H36: 87.35395 | I36: =+H36+I35 -> 4930.117 | J36: =+H36+D36 -> 280.97731 | K36: =+J36+K35 -> 6523.0561 | L36: =+J36/$C$26 -> 0.0031755021 | M36: =+K36/$C$26 -> 0.073721178 | O36: =40000*M36+40000 -> 42948.847
C37: Nisan 3.Hafta | D37: -1400.2902 | E37: =+D37+E36 -> 192.64889 | H37: -1926.3976 | I37: =+H37+I36 -> 3003.7194 | J37: =+$C$17-K36 -> -3388.9431 | K37: =+J37+K36 -> 3134.113 | L37: =+J37/$C$26 -> -0.038300588 | M37: =+K37/$C$26 -> 0.035420591 | O37: =40000*M37+40000 -> 41416.824
C38: Nisan 4.Hafta | D38: =+$C$14-E37 -> -159.2809 | E38: =+D38+E37 -> 33.367993 | H38: =+$C$15-I37 -> 97.025546 | I38: =+H38+I37 -> 3100.745 | J38: =+$C$17-K37 -> 0 | K38: =+J38+K37 -> 3134.113 | L38: =+J38/$C$26 -> 0 | M38: =+K38/$C$26 -> 0.035420591 | O38: =40000*M38+40000 -> 41416.824
D39: =+$C$14-E38 -> 0 | E39: =+D39+E38 -> 33.367993 | H39: =+$C$15-I38 -> 0 | I39: =+H39+I38 -> 3100.745 | J39: =+$C$17-K38 -> 0 | K39: =+J39+K38 -> 3134.113 | L39: =+J39/$C$26 -> 0 | M39: =+K39/$C$26 -> 0.035420591 | O39: =40000*M39+40000 -> 41416.824
D40: =+$C$14-E39 -> 0 | E40: =+D40+E39 -> 33.367993 | H40: =+$C$15-I39 -> 0 | I40: =+H40+I39 -> 3100.745 | J40: =+$C$17-K39 -> 0 | K40: =+J40+K39 -> 3134.113 | L40: =+J40/$C$26 -> 0 | M40: =+K40/$C$26 -> 0.035420591 | O40: =40000*M40+40000 -> 41416.824
D41: =+$C$14-E40 -> 0 | E41: =+D41+E40 -> 33.367993 | H41: =+$C$15-I40 -> 0 | I41: =+H41+I40 -> 3100.745 | J41: =+$C$17-K40 -> 0 | K41: =+J41+K40 -> 3134.113 | L41: =+J41/$C$26 -> 0 | M41: =+K41/$C$26 -> 0.035420591 | O41: =40000*M41+40000 -> 41416.824
D42: =+$C$14-E41 -> 0 | E42: =+D42+E41 -> 33.367993 | H42: =+$C$15-I41 -> 0 | I42: =+H42+I41 -> 3100.745 | J42: =+$C$17-K41 -> 0 | K42: =+J42+K41 -> 3134.113 | L42: =+J42/$C$26 -> 0 | M42: =+K42/$C$26 -> 0.035420591 | O42: =40000*M42+40000 -> 41416.824
D43: =+$C$14-E42 -> 0 | E43: =+D43+E42 -> 33.367993 | H43: =+$C$15-I42 -> 0 | I43: =+H43+I42 -> 3100.745 | J43: =+$C$17-K42 -> 0 | K43: =+J43+K42 -> 3134.113 | L43: =+J43/$C$26 -> 0 | M43: =+K43/$C$26 -> 0.035420591 | O43: =40000*M43+40000 -> 41416.824
D44: =+$C$14-E43 -> 0 | E44: =+D44+E43 -> 33.367993 | H44: =+$C$15-I43 -> 0 | I44: =+H44+I43 -> 3100.745 | J44: =+$C$17-K43 -> 0 | K44: =+J44+K43 -> 3134.113 | L44: =+J44/$C$26 -> 0 | M44: =+K44/$C$26 -> 0.035420591 | O44: =40000*M44+40000 -> 41416.824
D45: =+$C$14-E44 -> 0 | E45: =+D45+E44 -> 33.367993 | H45: =+$C$15-I44 -> 0 | I45: =+H45+I44 -> 3100.745 | J45: =+$C$17-K44 -> 0 | K45: =+J45+K44 -> 3134.113 | L45: =+J45/$C$26 -> 0 | M45: =+K45/$C$26 -> 0.035420591 | O45: =40000*M45+40000 -> 41416.824
D46: =+$C$14-E45 -> 0 | E46: =+D46+E45 -> 33.367993 | H46: =+$C$15-I45 -> 0 | I46: =+H46+I45 -> 3100.745 | J46: =+$C$17-K45 -> 0 | K46: =+J46+K45 -> 3134.113 | L46: =+J46/$C$26 -> 0 | M46: =+K46/$C$26 -> 0.035420591 | O46: =40000*M46+40000 -> 41416.824
D47: =+$C$14-E46 -> 0 | E47: =+D47+E46 -> 33.367993 | H47: =+$C$15-I46 -> 0 | I47: =+H47+I46 -> 3100.745 | J47: =+$C$17-K46 -> 0 | K47: =+J47+K46 -> 3134.113 | L47: =+J47/$C$26 -> 0 | M47: =+K47/$C$26 -> 0.035420591 | O47: =40000*M47+40000 -> 41416.824
D48: =+$C$14-E47 -> 0 | E48: =+D48+E47 -> 33.367993 | H48: =+$C$15-I47 -> 0 | I48: =+H48+I47 -> 3100.745 | J48: =+$C$17-K47 -> 0 | K48: =+J48+K47 -> 3134.113 | L48: =+J48/$C$26 -> 0 | M48: =+K48/$C$26 -> 0.035420591 | O48: =40000*M48+40000 -> 41416.824
D49: =+$C$14-E48 -> 0 | E49: =+D49+E48 -> 33.367993 | H49: =+$C$15-I48 -> 0 | I49: =+H49+I48 -> 3100.745 | J49: =+$C$17-K48 -> 0 | K49: =+J49+K48 -> 3134.113 | L49: =+J49/$C$26 -> 0 | M49: =+K49/$C$26 -> 0.035420591 | O49: =40000*M49+40000 -> 41416.824 | Q49: =+Q51+T51 -> 11304.1
D50: =+$C$14-E49 -> 0 | E50: =+D50+E49 -> 33.367993 | H50: =+$C$15-I49 -> 0 | I50: =+H50+I49 -> 3100.745 | J50: =+$C$17-K49 -> 0 | K50: =+J50+K49 -> 3134.113 | L50: =+J50/$C$26 -> 0 | M50: =+K50/$C$26 -> 0.035420591 | O50: =40000*M50+40000 -> 41416.824
Q51: =SUM(Q53:Q60) -> 12176.2 | T51: =SUM(T53:T60) -> -872.1
O52: adet | P52: fiyat | Q52: tutar
G53: 1 | I53: AHGAZ | J53: X | O53: 70 | P53: 13.49 | Q53: =+P53*O53 -> 944.3 | S53: 12.8 | T53: =(S53-P53)*O53 -> -48.3
...

Sheet İcmal
B2: HİSSE | C2: ADET | D2: MALİYET | E2: FİYAT | F2: GÜNCEL TUTAT | G2: KAR/ZARAR | H2: ANALIZ | I2: HEDEF | J2: DATA | K2: DURUM | L2: İŞLEM ADET | M2: İŞLEM FİYATI | N2: HEDEF2 | P2: 32.53
B3: ADESE | C3: =+ADESE!C1 -> 4200 | D3: =+ADESE!F1 -> 2.6280952 | E3: 2.33 | F3: =E3*C3 -> 9786 | G3: =+ADESE!G1 -> -1252 | H3: =IFERROR(Tablo2[[#This Row],[FİYAT]]/Tablo2[[#This Row],[MALİYET]]-1,"") -> -0.11342635 | I3: =+ADESE!$K$2/ADESE!$J$2 -> 0.60166001 | J3: =IF(Tablo2[[#This Row],[MALİYET]]<1,6,IF(Tablo2[[#This Row],[HEDEF]]>1,1,LOOKUP(Tablo2[[#This Row],[ANALIZ]],{-1000000,-0.15,-0.1,-0.05,0,0.05,0.1,0.15,0.2;-4,-3,-2,-1,0,1,2,3,4}))) -> -3 | K3: =IF(Tablo2[[#This Row],[MALİYET]]<1,"TUT",IF(Tablo2[[#This Row],[HEDEF]]>2,"SAT",IFERROR(INDEX($AA$6:$AC$14,MATCH(Tablo2[[#This Row],[DATA]],$AC$6:$AC$14,0),1),""))) -> AL-3 | L3: =IF(Tablo2[[#This Row],[DURUM]]="SAT",Tablo2[[#This Row],[ADET]]*0.5,ROUND(-IFERROR(INDEX($AA$6:$AD$14,MATCH(Tablo2[[#This Row],[DATA]],$AC$6:$AC$14,0),4),"")*Tablo2[[#This Row],[ADET]],0)) -> 840 | M3: =IF(Tablo2[[#This Row],[DURUM]]="SAT",IF(Tablo2[[#This Row],[MALİYET]]<Tablo2[[#This Row],[FİYAT]],Tablo2[[#This Row],[FİYAT]],Tablo2[[#This Row],[MALİYET]])*1.1,IF(Tablo2[[#This Row],[DATA]]=0,"",IFERROR((1+INDEX($AA$6:$AD$14,MATCH(Tablo2[[#This Row],[DATA]],$AC$6:$AC$14,0),2))*IF(Tablo2[[#This Row],[DATA]]<0,Tablo2[[#This Row],[MALİYET]],Tablo2[[#This Row],[FİYAT]]),0))) -> 2.233881 | N3: 500
B4: AKBNK | C4: =+AKBNK!C1 -> 0 | D4: =+AKBNK!F1 | E4: 56.05 | F4: =E4*C4 -> 0 | G4: =+AKBNK!G1 -> 3643.7905 | H4: =IFERROR(Tablo2[[#This Row],[FİYAT]]/Tablo2[[#This Row],[MALİYET]]-1,"") | I4: =+AKBNK!$K$2/AKBNK!$J$2 -> 0 | J4: =IF(Tablo2[[#This Row],[MALİYET]]<1,6,IF(Tablo2[[#This Row],[HEDEF]]>1,1,LOOKUP(Tablo2[[#This Row],[ANALIZ]],{-1000000,-0.15,-0.1,-0.05,0,0.05,0.1,0.15,0.2;-4,-3,-2,-1,0,1,2,3,4}))) -> #N/A | K4: =IF(Tablo2[[#This Row],[MALİYET]]<1,"TUT",IF(Tablo2[[#This Row],[HEDEF]]>2,"SAT",IFERROR(INDEX($AA$6:$AC$14,MATCH(Tablo2[[#This Row],[DATA]],$AC$6:$AC$14,0),1),""))) | L4: =IF(Tablo2[[#This Row],[DURUM]]="SAT",Tablo2[[#This Row],[ADET]]*0.5,ROUND(-IFERROR(INDEX($AA$6:$AD$14,MATCH(Tablo2[[#This Row],[DATA]],$AC$6:$AC$14,0),4),"")*Tablo2[[#This Row],[ADET]],0)) -> #VALUE! | M4: =IF(Tablo2[[#This Row],[DURUM]]="SAT",IF(Tablo2[[#This Row],[MALİYET]]<Tablo2[[#This Row],[FİYAT]],Tablo2[[#This Row],[FİYAT]],Tablo2[[#This Row],[MALİYET]])*1.1,IF(Tablo2[[#This Row],[DATA]]=0,"",IFERROR((1+INDEX($AA$6:$AD$14,MATCH(Tablo2[[#This Row],[DATA]],$AC$6:$AC$14,0),2))*IF(Tablo2[[#This Row],[DATA]]<0,Tablo2[[#This Row],[MALİYET]],Tablo2[[#This Row],[FİYAT]]),0))) -> #N/A | N4: 1000 | P4: Toplam Yatırım | R4: =955000+380000+350000+290000+350000-50000 -> 2275000 | U4: =30235.5027786858+380000/32.04 -> 42095.678
B5: ALARK | C5: =ALARK!$C$1 -> 530 | D5: =ALARK!$F$1 -> 137.48113 | E5: 114.7 | F5: =E5*C5 -> 60791 | G5: =ALARK!$G$1 -> -12074 | H5: =IFERROR(Tablo2[[#This Row],[FİYAT]]/Tablo2[[#This Row],[MALİYET]]-1,"") -> -0.1657037 | I5: =+ALARK!$K$2/ALARK!$J$2 -> 1.8687673 | J5: =IF(Tablo2[[#This Row],[MALİYET]]<1,6,IF(Tablo2[[#This Row],[HEDEF]]>1,1,LOOKUP(Tablo2[[#This Row],[ANALIZ]],{-1000000,-0.15,-0.1,-0.05,0,0.05,0.1,0.15,0.2;-4,-3,-2,-1,0,1,2,3,4}))) -> 1 | K5: =IF(Tablo2[[#This Row],[MALİYET]]<1,"TUT",IF(Tablo2[[#This Row],[HEDEF]]>2,"SAT",IFERROR(INDEX($AA$6:$AC$14,MATCH(Tablo2[[#This Row],[DATA]],$AC$6:$AC$14,0),1),""))) -> SAT-1 | L5: =IF(Tablo2[[#This Row],[DURUM]]="SAT",Tablo2[[#This Row],[ADET]]*0.5,ROUND(-IFERROR(INDEX($AA$6:$AD$14,MATCH(Tablo2[[#This Row],[DATA]],$AC$6:$AC$14,0),4),"")*Tablo2[[#This Row],[ADET]],0)) -> -53 | M5: =IF(Tablo2[[#This Row],[DURUM]]="SAT",IF(Tablo2[[#This Row],[MALİYET]]<Tablo2[[#This Row],[FİYAT]],Tablo2[[#This Row],[FİYAT]],Tablo2[[#This Row],[MALİYET]])*1.1,IF(Tablo2[[#This Row],[DATA]]=0,"",IFERROR((1+INDEX($AA$6:$AD$14,MATCH(Tablo2[[#This Row],[DATA]],$AC$6:$AC$14,0),2))*IF(Tablo2[[#This Row],[DATA]]<0,Tablo2[[#This Row],[MALİYET]],Tablo2[[#This Row],[FİYAT]]),0))) -> 120.435 | N5: 1000
B6: ARASE | C6: =+ARASE!C1 -> 1200 | D6: =+ARASE!F1 -> 70.334333 | E6: 69.1 | F6: =E6*C6 -> 82920 | G6: =+ARASE!G1 -> 7182.6014 | H6: =IFERROR(Tablo2[[#This Row],[FİYAT]]/Tablo2[[#This Row],[MALİYET]]-1,"") -> -0.017549505 | I6: =+ARASE!$K$2/ARASE!$J$2 -> 1.2745158 | J6: =IF(Tablo2[[#This Row],[MALİYET]]<1,6,IF(Tablo2[[#This Row],[HEDEF]]>1,1,LOOKUP(Tablo2[[#This Row],[ANALIZ]],{-1000000,-0.15,-0.1,-0.05,0,0.05,0.1,0.15,0.2;-4,-3,-2,-1,0,1,2,3,4}))) -> 1 | K6: =IF(Tablo2[[#This Row],[MALİYET]]<1,"TUT",IF(Tablo2[[#This Row],[HEDEF]]>2,"SAT",IFERROR(INDEX($AA$6:$AC$14,MATCH(Tablo2[[#This Row],[DATA]],$AC$6:$AC$14,0),1),""))) -> SAT-1 | L6: =IF(Tablo2[[#This Row],[DURUM]]="SAT",Tablo2[[#This Row],[ADET]]*0.5,ROUND(-IFERROR(INDEX($AA$6:$AD$14,MATCH(Tablo2[[#This Row],[DATA]],$AC$6:$AC$14,0),4),"")*Tablo2[[#This Row],[ADET]],0)) -> -120 | M6: =IF(Tablo2[[#This Row],[DURUM]]="SAT",IF(Tablo2[[#This Row],[MALİYET]]<Tablo2[[#This Row],[FİYAT]],Tablo2[[#This Row],[FİYAT]],Tablo2[[#This Row],[MALİYET]])*1.1,IF(Tablo2[[#This Row],[DATA]]=0,"",IFERROR((1+INDEX($AA$6:$AD$14,MATCH(Tablo2[[#This Row],[DATA]],$AC$6:$AC$14,0),2))*IF(Tablo2[[#This Row],[DATA]]<0,Tablo2[[#This Row],[MALİYET]],Tablo2[[#This Row],[FİYAT]]),0))) -> 72.555 | N6: 2000 | P6: Anlık Değer | R6: =SUM(Tablo2[GÜNCEL TUTAT]) -> 2002038 | U6: =(R6+R7)/P2 -> 71350.91 | X6: =+U6*$P$2 -> 2321045.1 | AA6: AL-4 | AB6: -0.2 | AC6: =LOOKUP(AB6,{-1000,-0.15,-0.1,-0.05,0,0.05,0.1,0.15,0.2;-4,-3,-2,-1,0,1,2,3,4}) -> -4 | AD6: -0.25
B7: ARCLK | C7: =ARCLK!C1 -> 100 | D7: =ARCLK!F1 -> 122.75687 | E7: 161 | F7: =E7*C7 -> 16100 | G7: =+ARCLK!G1 -> 3824.3132 | H7: =IFERROR(Tablo2[[#This Row],[FİYAT]]/Tablo2[[#This Row],[MALİYET]]-1,"") -> 0.31153558 | I7: =+ARCLK!$K$2/ARCLK!$J$2 -> 0.24746388 | J7: =IF(Tablo2[[#This Row],[MALİYET]]<1,6,IF(Tablo2[[#This Row],[HEDEF]]>1,1,LOOKUP(Tablo2[[#This Row],[ANALIZ]],{-1000000,-0.15,-0.1,-0.05,0,0.05,0.1,0.15,0.2;-4,-3,-2,-1,0,1,2,3,4}))) -> 4 | K7: =IF(Tablo2[[#This Row],[MALİYET]]<1,"TUT",IF(Tablo2[[#This Row],[HEDEF]]>2,"SAT",IFERROR(INDEX($AA$6:$AC$14,MATCH(Tablo2[[#This Row],[DATA]],$AC$6:$AC$14,0),1),""))) -> SAT-4 | L7: =IF(Tablo2[[#This Row],[DURUM]]="SAT",Tablo2[[#This Row],[ADET]]*0.5,ROUND(-IFERROR(INDEX($AA$6:$AD$14,MATCH(Tablo2[[#This Row],[DATA]],$AC$6:$AC$14,0),4),"")*Tablo2[[#This Row],[ADET]],0)) -> -25 | M7: =IF(Tablo2[[#This Row],[DURUM]]="SAT",IF(Tablo2[[#This Row],[MALİYET]]<Tablo2[[#This Row],[FİYAT]],Tablo2[[#This Row],[FİYAT]],Tablo2[[#This Row],[MALİYET]])*1.1,IF(Tablo2[[#This Row],[DATA]]=0,"",IFERROR((1+INDEX($AA$6:$AD$14,MATCH(Tablo2[[#This Row],[DATA]],$AC$6:$AC$14,0),2))*IF(Tablo2[[#This Row],[DATA]]<0,Tablo2[[#This Row],[MALİYET]],Tablo2[[#This Row],[FİYAT]]),0))) -> 193.2 | N7: 2000 | P7: Nakit | R7: =307703+Sayfa1!Q49 -> 319007.1 | AA7: AL-3 | AB7: -0.15 | AC7: =LOOKUP(AB7,{-1000,-0.15,-0.1,-0.05,0,0.05,0.1,0.15,0.2;-4,-3,-2,-1,0,1,2,3,4}) -> -3 | AD7: -0.2
B8: ARENA | C8: =+ARENA!C1 -> 150 | D8: =+ARENA!F1 -> 7.0947851 | E8: 51.2 | F8: =E8*C8 -> 7680 | G8: =+ARENA!G1 -> 6615.7822 | H8: =IFERROR(Tablo2[[#This Row],[FİYAT]]/Tablo2[[#This Row],[MALİYET]]-1,"") -> 6.2165682 | I8: =+ARENA!$K$2/ARENA!$J$2 -> 0.23608976 | J8: =IF(Tablo2[[#This Row],[MALİYET]]<1,6,IF(Tablo2[[#This Row],[HEDEF]]>1,1,LOOKUP(Tablo2[[#This Row],[ANALIZ]],{-1000000,-0.15,-0.1,-0.05,0,0.05,0.1,0.15,0.2;-4,-3,-2,-1,0,1,2,3,4}))) -> 4 | K8: =IF(Tablo2[[#This Row],[MALİYET]]<1,"TUT",IF(Tablo2[[#This Row],[HEDEF]]>2,"SAT",IFERROR(INDEX($AA$6:$AC$14,MATCH(Tablo2[[#This Row],[DATA]],$AC$6:$AC$14,0),1),""))) -> SAT-4 | L8: =IF(Tablo2[[#This Row],[DURUM]]="SAT",Tablo2[[#This Row],[ADET]]*0.5,ROUND(-IFERROR(INDEX($AA$6:$AD$14,MATCH(Tablo2[[#This Row],[DATA]],$AC$6:$AC$14,0),4),"")*Tablo2[[#This Row],[ADET]],0)) -> -38 | M8: =IF(Tablo2[[#This Row],[DURUM]]="SAT",IF(Tablo2[[#This Row],[MALİYET]]<Tablo2[[#This Row],[FİYAT]],Tablo2[[#This Row],[FİYAT]],Tablo2[[#This Row],[MALİYET]])*1.1,IF(Tablo2[[#This Row],[DATA]]=0,"",IFERROR((1+INDEX($AA$6:$AD$14,MATCH(Tablo2[[#This Row],[DATA]],$AC$6:$AC$14,0),2))*IF(Tablo2[[#This Row],[DATA]]<0,Tablo2[[#This Row],[MALİYET]],Tablo2[[#This Row],[FİYAT]]),0))) -> 61.44 | N8: 1000 | P8: Kar | R8: =+R6+R7-R4 -> 46045.1 | S8: =R8/R4 -> 0.020239604 | U8: =+U6-U4 -> 29255.232 | V8: =+U8/U4 -> 0.69496998 | AA8: AL-2 | AB8: -0.1 | AC8: =LOOKUP(AB8,{-1000,-0.15,-0.1,-0.05,0,0.05,0.1,0.15,0.2;-4,-3,-2,-1,0,1,2,3,4}) -> -2 | AD8: -0.15
B9: ARZUM | C9: =+ARZUM!C1 -> 450 | D9: =+ARZUM!F1 -> 36.361529 | E9: 46 | F9: =E9*C9 -> 20700 | G9: =+ARZUM!G1 -> 4337.312 | H9: =IFERROR(Tablo2[[#This Row],[FİYAT]]/Tablo2[[#This Row],[MALİYET]]-1,"") -> 0.26507332 | I9: =+ARZUM!$K$2/ARZUM!$J$2 -> 1.2726714 | J9: =IF(Tablo2[[#This Row],[MALİYET]]<1,6,IF(Tablo2[[#This Row],[HEDEF]]>1,1,LOOKUP(Tablo2[[#This Row],[ANALIZ]],{-1000000,-0.15,-0.1,-0.05,0,0.05,0.1,0.15,0.2;-4,-3,-2,-1,0,1,2,3,4}))) -> 1 | K9: =IF(Tablo2[[#This Row],[MALİYET]]<1,"TUT",IF(Tablo2[[#This Row],[HEDEF]]>2,"SAT",IFERROR(INDEX($AA$6:$AC$14,MATCH(Tablo2[[#This Row],[DATA]],$AC$6:$AC$14,0),1),""))) -> SAT-1 | L9: =IF(Tablo2[[#This Row],[DURUM]]="SAT",Tablo2[[#This Row],[ADET]]*0.5,ROUND(-IFERROR(INDEX($AA$6:$AD$14,MATCH(Tablo2[[#This Row],[DATA]],$AC$6:$AC$14,0),4),"")*Tablo2[[#This Row],[ADET]],0)) -> -45 | M9: =IF(Tablo2[[#This Row],[DURUM]]="SAT",IF(Tablo2[[#This Row],[MALİYET]]<Tablo2[[#This Row],[FİYAT]],Tablo2[[#This Row],[FİYAT]],Tablo2[[#This Row],[MALİYET]])*1.1,IF(Tablo2[[#This Row],[DATA]]=0,"",IFERROR((1+INDEX($AA$6:$AD$14,MATCH(Tablo2[[#This Row],[DATA]],$AC$6:$AC$14,0),2))*IF(Tablo2[[#This Row],[DATA]]<0,Tablo2[[#This Row],[MALİYET]],Tablo2[[#This Row],[FİYAT]]),0))) -> 48.3 | N9: 500 | AA9: AL-1 | AB9: -0.05 | AC9: =LOOKUP(AB9,{-1000,-0.15,-0.1,-0.05,0,0.05,0.1,0.15,0.2;-4,-3,-2,-1,0,1,2,3,4}) -> -1 | AD9: -0.1
B10: ASELS | C10: =+ASELS!C1 -> 200 | D10: 51.25 | E10: 57.8 | F10: =E10*C10 -> 11560 | G10: =+ASELS!G1 -> 1932.659 | H10: =IFERROR(Tablo2[[#This Row],[FİYAT]]/Tablo2[[#This Row],[MALİYET]]-1,"") -> 0.12780488 | I10: =+ASELS!$K$2/ASELS!$J$2 -> 0.17768214 | J10: =IF(Tablo2[[#This Row],[MALİYET]]<1,6,IF(Tablo2[[#This Row],[HEDEF]]>1,1,LOOKUP(Tablo2[[#This Row],[ANALIZ]],{-1000000,-0.15,-0.1,-0.05,0,0.05,0.1,0.15,0.2;-4,-3,-2,-1,0,1,2,3,4}))) -> 2 | K10: =IF(Tablo2[[#This Row],[MALİYET]]<1,"TUT",IF(Tablo2[[#This Row],[HEDEF]]>2,"SAT",IFERROR(INDEX($AA$6:$AC$14,MATCH(Tablo2[[#This Row],[DATA]],$AC$6:$AC$14,0),1),""))) -> SAT-2 | L10: =IF(Tablo2[[#This Row],[DURUM]]="SAT",Tablo2[[#This Row],[ADET]]*0.5,ROUND(-IFERROR(INDEX($AA$6:$AD$14,MATCH(Tablo2[[#This Row],[DATA]],$AC$6:$AC$14,0),4),"")*Tablo2[[#This Row],[ADET]],0)) -> -30 | M10: =IF(Tablo2[[#This Row],[DURUM]]="SAT",IF(Tablo2[[#This Row],[MALİYET]]<Tablo2[[#This Row],[FİYAT]],Tablo2[[#This Row],[FİYAT]],Tablo2[[#This Row],[MALİYET]])*1.1,IF(Tablo2[[#This Row],[DATA]]=0,"",IFERROR((1+INDEX($AA$6:$AD$14,MATCH(Tablo2[[#This Row],[DATA]],$AC$6:$AC$14,0),2))*IF(Tablo2[[#This Row],[DATA]]<0,Tablo2[[#This Row],[MALİYET]],Tablo2[[#This Row],[FİYAT]]),0))) -> 63.58 | N10: 2000 | U10: =+S10/P2 -> 0 | X10: =+U10*$P$2 -> 0 | AA10: TUT | AB10: 0 | AC10: =LOOKUP(AB10,{-1000,-0.15,-0.1,-0.05,0,0.05,0.1,0.15,0.2;-4,-3,-2,-1,0,1,2,3,4}) -> 0 | AD10: 0
B11: ASTOR | C11: =+ASTOR!C1 -> 990 | D11: =+ASTOR!F1 -> 123.21314 | E11: 95.1 | F11: =E11*C11 -> 94149 | G11: =+ASTOR!G1 -> -42638.011 | H11: =IFERROR(Tablo2[[#This Row],[FİYAT]]/Tablo2[[#This Row],[MALİYET]]-1,"") -> -0.22816672 | I11: =+ASTOR!$K$2/ASTOR!$J$2 -> 1.4471104 | J11: =IF(Tablo2[[#This Row],[MALİYET]]<1,6,IF(Tablo2[[#This Row],[HEDEF]]>1,1,LOOKUP(Tablo2[[#This Row],[ANALIZ]],{-1000000,-0.15,-0.1,-0.05,0,0.05,0.1,0.15,0.2;-4,-3,-2,-1,0,1,2,3,4}))) -> 1 | K11: =IF(Tablo2[[#This Row],[MALİYET]]<1,"TUT",IF(Tablo2[[#This Row],[HEDEF]]>2,"SAT",IFERROR(INDEX($AA$6:$AC$14,MATCH(Tablo2[[#This Row],[DATA]],$AC$6:$AC$14,0),1),""))) -> SAT-1 | L11: =IF(Tablo2[[#This Row],[DURUM]]="SAT",Tablo2[[#This Row],[ADET]]*0.5,ROUND(-IFERROR(INDEX($AA$6:$AD$14,MATCH(Tablo2[[#This Row],[DATA]],$AC$6:$AC$14,0),4),"")*Tablo2[[#This Row],[ADET]],0)) -> -99 | M11: =IF(Tablo2[[#This Row],[DURUM]]="SAT",IF(Tablo2[[#This Row],[MALİYET]]<Tablo2[[#This Row],[FİYAT]],Tablo2[[#This Row],[FİYAT]],Tablo2[[#This Row],[MALİYET]])*1.1,IF(Tablo2[[#This Row],[DATA]]=0,"",IFERROR((1+INDEX($AA$6:$AD$14,MATCH(Tablo2[[#This Row],[DATA]],$AC$6:$AC$14,0),2))*IF(Tablo2[[#This Row],[DATA]]<0,Tablo2[[#This Row],[MALİYET]],Tablo2[[#This Row],[FİYAT]]),0))) -> 99.855 | N11: 2000 | P11: USD | X11: =+U11*$P$2 -> 0 | AA11: SAT-1 | AB11: 0.05 | AC11: =LOOKUP(AB11,{-1000,-0.15,-0.1,-0.05,0,0.05,0.1,0.15,0.2;-4,-3,-2,-1,0,1,2,3,4}) -> 1 | AD11: 0.1
B12: BIMAS | C12: =+BIMAS!C1 -> 120 | D12: =+BIMAS!F1 -> 364.42616 | E12: 370 | F12: =E12*C12 -> 44400 | G12: =+BIMAS!G1 -> 668.8608 | H12: =IFERROR(Tablo2[[#This Row],[FİYAT]]/Tablo2[[#This Row],[MALİYET]]-1,"") -> 0.015294841 | I12: =+BIMAS!$K$2/BIMAS!$J$2 -> 0.68244697 | J12: =IF(Tablo2[[#This Row],[MALİYET]]<1,6,IF(Tablo2[[#This Row],[HEDEF]]>1,1,LOOKUP(Tablo2[[#This Row],[ANALIZ]],{-1000000,-0.15,-0.1,-0.05,0,0.05,0.1,0.15,0.2;-4,-3,-2,-1,0,1,2,3,4}))) -> 0 | K12: =IF(Tablo2[[#This Row],[MALİYET]]<1,"TUT",IF(Tablo2[[#This Row],[HEDEF]]>2,"SAT",IFERROR(INDEX($AA$6:$AC$14,MATCH(Tablo2[[#This Row],[DATA]],$AC$6:$AC$14,0),1),""))) -> TUT | L12: =IF(Tablo2[[#This Row],[DURUM]]="SAT",Tablo2[[#This Row],[ADET]]*0.5,ROUND(-IFERROR(INDEX($AA$6:$AD$14,MATCH(Tablo2[[#This Row],[DATA]],$AC$6:$AC$14,0),4),"")*Tablo2[[#This Row],[ADET]],0)) -> 0 | M12: =IF(Tablo2[[#This Row],[DURUM]]="SAT",IF(Tablo2[[#This Row],[MALİYET]]<Tablo2[[#This Row],[FİYAT]],Tablo2[[#This Row],[FİYAT]],Tablo2[[#This Row],[MALİYET]])*1.1,IF(Tablo2[[#This Row],[DATA]]=0,"",IFERROR((1+INDEX($AA$6:$AD$14,MATCH(Tablo2[[#This Row],[DATA]],$AC$6:$AC$14,0),2))*IF(Tablo2[[#This Row],[DATA]]<0,Tablo2[[#This Row],[MALİYET]],Tablo2[[#This Row],[FİYAT]]),0))) | N12: 2000 | P12: TL | S12: 0 | U12: =+S12/P2 -> 0 | X12: =+U12*$P$2 -> 0 | AA12: SAT-2 | AB12: 0.1 | AC12: =LOOKUP(AB12,{-1000,-0.15,-0.1,-0.05,0,0.05,0.1,0.15,0.2;-4,-3,-2,-1,0,1,2,3,4}) -> 2 | AD12: 0.15
B13: BRLSM | C13: =BRLSM!C1 -> 2000 | D13: =BRLSM!F1 -> 23.83211 | E13: 27.8 | F13: =E13*C13 -> 55600 | G13: =+BRLSM!G1 -> 7935.7798 | H13: =IFERROR(Tablo2[[#This Row],[FİYAT]]/Tablo2[[#This Row],[MALİYET]]-1,"") -> 0.16649344 | I13: =+BRLSM!$K$2/BRLSM!$J$2 -> 1.7091915 | J13: =IF(Tablo2[[#This Row],[MALİYET]]<1,6,IF(Tablo2[[#This Row],[HEDEF]]>1,1,LOOKUP(Tablo2[[#This Row],[ANALIZ]],{-1000000,-0.15,-0.1,-0.05,0,0.05,0.1,0.15,0.2;-4,-3,-2,-1,0,1,2,3,4}))) -> 1 | K13: =IF(Tablo2[[#This Row],[MALİYET]]<1,"TUT",IF(Tablo2[[#This Row],[HEDEF]]>2,"SAT",IFERROR(INDEX($AA$6:$AC$14,MATCH(Tablo2[[#This Row],[DATA]],$AC$6:$AC$14,0),1),""))) -> SAT-1 | L13: =IF(Tablo2[[#This Row],[DURUM]]="SAT",Tablo2[[#This Row],[ADET]]*0.5,ROUND(-IFERROR(INDEX($AA$6:$AD$14,MATCH(Tablo2[[#This Row],[DATA]],$AC$6:$AC$14,0),4),"")*Tablo2[[#This Row],[ADET]],0)) -> -200 | M13: =IF(Tablo2[[#This Row],[DURUM]]="SAT",IF(Tablo2[[#This Row],[MALİYET]]<Tablo2[[#This Row],[FİYAT]],Tablo2[[#This Row],[FİYAT]],Tablo2[[#This Row],[MALİYET]])*1.1,IF(Tablo2[[#This Row],[DATA]]=0,"",IFERROR((1+INDEX($AA$6:$AD$14,MATCH(Tablo2[[#This Row],[DATA]],$AC$6:$AC$14,0),2))*IF(Tablo2[[#This Row],[DATA]]<0,Tablo2[[#This Row],[MALİYET]],Tablo2[[#This Row],[FİYAT]]),0))) -> 29.19 | N13: 1000 | P13: MIDAS | S13: 659253 | U13: =S13/P2 -> 20266.001 | X13: =+U13*$P$2 -> 659253 | AA13: SAT-3 | AB13: 0.15 | AC13: =LOOKUP(AB13,{-1000,-0.15,-0.1,-0.05,0,0.05,0.1,0.15,0.2;-4,-3,-2,-1,0,1,2,3,4}) -> 3 | AD13: 0.2
B14: BURVA | C14: =BURVA!C1 -> 100 | D14: =+BURVA!F1 -> 1.351979 | E14: 171.1 | F14: =E14*C14 -> 17110 | G14: =+BURVA!G1 -> 16974.802 | H14: =IFERROR(Tablo2[[#This Row],[FİYAT]]/Tablo2[[#This Row],[MALİYET]]-1,"") -> 125.55522 | I14: =+BURVA!$K$2/BURVA!$J$2 -> 0.52597602 | J14: =IF(Tablo2[[#This Row],[MALİYET]]<1,6,IF(Tablo2[[#This Row],[HEDEF]]>1,1,LOOKUP(Tablo2[[#This Row],[ANALIZ]],{-1000000,-0.15,-0.1,-0.05,0,0.05,0.1,0.15,0.2;-4,-3,-2,-1,0,1,2,3,4}))) -> 4 | K14: =IF(Tablo2[[#This Row],[MALİYET]]<1,"TUT",IF(Tablo2[[#This Row],[HEDEF]]>2,"SAT",IFERROR(INDEX($AA$6:$AC$14,MATCH(Tablo2[[#This Row],[DATA]],$AC$6:$AC$14,0),1),""))) -> SAT-4 | L14: =IF(Tablo2[[#This Row],[DURUM]]="SAT",Tablo2[[#This Row],[ADET]]*0.5,ROUND(-IFERROR(INDEX($AA$6:$AD$14,MATCH(Tablo2[[#This Row],[DATA]],$AC$6:$AC$14,0),4),"")*Tablo2[[#This Row],[ADET]],0)) -> -25 | M14: =IF(Tablo2[[#This Row],[DURUM]]="SAT",IF(Tablo2[[#This Row],[MALİYET]]<Tablo2[[#This Row],[FİYAT]],Tablo2[[#This Row],[FİYAT]],Tablo2[[#This Row],[MALİYET]])*1.1,IF(Tablo2[[#This Row],[DATA]]=0,"",IFERROR((1+INDEX($AA$6:$AD$14,MATCH(Tablo2[[#This Row],[DATA]],$AC$6:$AC$14,0),2))*IF(Tablo2[[#This Row],[DATA]]<0,Tablo2[[#This Row],[MALİYET]],Tablo2[[#This Row],[FİYAT]]),0))) -> 205.32 | N14: 1000 | AA14: SAT-4 | AB14: 0.2 | AC14: =LOOKUP(AB14,{-1000,-0.15,-0.1,-0.05,0,0.05,0.1,0.15,0.2;-4,-3,-2,-1,0,1,2,3,4}) -> 4 | AD14: 0.25
B15: CATES | C15: =+CATES!C1 -> 150 | D15: =+CATES!F1 -> 57.315 | E15: 58 | F15: =E15*C15 -> 8700 | G15: =+CATES!G1 -> 102.75 | H15: =IFERROR(Tablo2[[#This Row],[FİYAT]]/Tablo2[[#This Row],[MALİYET]]-1,"") -> 0.011951496 | I15: =+CATES!$K$2/CATES!$J$2 -> 267.44543 | J15: =IF(Tablo2[[#This Row],[MALİYET]]<1,6,IF(Tablo2[[#This Row],[HEDEF]]>1,1,LOOKUP(Tablo2[[#This Row],[ANALIZ]],{-1000000,-0.15,-0.1,-0.05,0,0.05,0.1,0.15,0.2;-4,-3,-2,-1,0,1,2,3,4}))) -> 1 | K15: =IF(Tablo2[[#This Row],[MALİYET]]<1,"TUT",IF(Tablo2[[#This Row],[HEDEF]]>2,"SAT",IFERROR(INDEX($AA$6:$AC$14,MATCH(Tablo2[[#This Row],[DATA]],$AC$6:$AC$14,0),1),""))) -> SAT | L15: =IF(Tablo2[[#This Row],[DURUM]]="SAT",Tablo2[[#This Row],[ADET]]*0.5,ROUND(-IFERROR(INDEX($AA$6:$AD$14,MATCH(Tablo2[[#This Row],[DATA]],$AC$6:$AC$14,0),4),"")*Tablo2[[#This Row],[ADET]],0)) -> 75 | M15: =IF(Tablo2[[#This Row],[DURUM]]="SAT",IF(Tablo2[[#This Row],[MALİYET]]<Tablo2[[#This Row],[FİYAT]],Tablo2[[#This Row],[FİYAT]],Tablo2[[#This Row],[MALİYET]])*1.1,IF(Tablo2[[#This Row],[DATA]]=0,"",IFERROR((1+INDEX($AA$6:$AD$14,MATCH(Tablo2[[#This Row],[DATA]],$AC$6:$AC$14,0),2))*IF(Tablo2[[#This Row],[DATA]]<0,Tablo2[[#This Row],[MALİYET]],Tablo2[[#This Row],[FİYAT]]),0))) -> 63.8 | N15: 1
B16: CWENE | C16: =+CWENE!C1 -> 85 | D16: =+CWENE!F1 -> 310.01471 | E16: 305 | F16: =E16*C16 -> 25925 | G16: =+CWENE!G1 -> -426.25 | H16: =IFERROR(Tablo2[[#This Row],[FİYAT]]/Tablo2[[#This Row],[MALİYET]]-1,"") -> -0.016175703 | I16: =+CWENE!$K$2/CWENE!$J$2 -> 0.79695666 | J16: =IF(Tablo2[[#This Row],[MALİYET]]<1,6,IF(Tablo2[[#This Row],[HEDEF]]>1,1,LOOKUP(Tablo2[[#This Row],[ANALIZ]],{-1000000,-0.15,-0.1,-0.05,0,0.05,0.1,0.15,0.2;-4,-3,-2,-1,0,1,2,3,4}))) -> -1 | K16: =IF(Tablo2[[#This Row],[MALİYET]]<1,"TUT",IF(Tablo2[[#This Row],[HEDEF]]>2,"SAT",IFERROR(INDEX($AA$6:$AC$14,MATCH(Tablo2[[#This Row],[DATA]],$AC$6:$AC$14,0),1),""))) -> AL-1 | L16: =IF(Tablo2[[#This Row],[DURUM]]="SAT",Tablo2[[#This Row],[ADET]]*0.5,ROUND(-IFERROR(INDEX($AA$6:$AD$14,MATCH(Tablo2[[#This Row],[DATA]],$AC$6:$AC$14,0),4),"")*Tablo2[[#This Row],[ADET]],0)) -> 9 | M16: =IF(Tablo2[[#This Row],[DURUM]]="SAT",IF(Tablo2[[#This Row],[MALİYET]]<Tablo2[[#This Row],[FİYAT]],Tablo2[[#This Row],[FİYAT]],Tablo2[[#This Row],[MALİYET]])*1.1,IF(Tablo2[[#This Row],[DATA]]=0,"",IFERROR((1+INDEX($AA$6:$AD$14,MATCH(Tablo2[[#This Row],[DATA]],$AC$6:$AC$14,0),2))*IF(Tablo2[[#This Row],[DATA]]<0,Tablo2[[#This Row],[MALİYET]],Tablo2[[#This Row],[FİYAT]]),0))) -> 294.51397 | N16: 1000
B17: DEVA | C17: =+DEVA!C1 -> 400 | D17: =+DEVA!F1 -> 79.0125 | E17: 73.9 | F17: =E17*C17 -> 29560 | G17: =+DEVA!G1 -> -646 | H17: =IFERROR(Tablo2[[#This Row],[FİYAT]]/Tablo2[[#This Row],[MALİYET]]-1,"") -> -0.064704952 | I17: =+DEVA!$K$2/DEVA!$J$2 -> 0.90869966 | J17: =IF(Tablo2[[#This Row],[MALİYET]]<1,6,IF(Tablo2[[#This Row],[HEDEF]]>1,1,LOOKUP(Tablo2[[#This Row],[ANALIZ]],{-1000000,-0.15,-0.1,-0.05,0,0.05,0.1,0.15,0.2;-4,-3,-2,-1,0,1,2,3,4}))) -> -2 | K17: =IF(Tablo2[[#This Row],[MALİYET]]<1,"TUT",IF(Tablo2[[#This Row],[HEDEF]]>2,"SAT",IFERROR(INDEX($AA$6:$AC$14,MATCH(Tablo2[[#This Row],[DATA]],$AC$6:$AC$14,0),1),""))) -> AL-2 | L17: =IF(Tablo2[[#This Row],[DURUM]]="SAT",Tablo2[[#This Row],[ADET]]*0.5,ROUND(-IFERROR(INDEX($AA$6:$AD$14,MATCH(Tablo2[[#This Row],[DATA]],$AC$6:$AC$14,0),4),"")*Tablo2[[#This Row],[ADET]],0)) -> 60 | M17: =IF(Tablo2[[#This Row],[DURUM]]="SAT",IF(Tablo2[[#This Row],[MALİYET]]<Tablo2[[#This Row],[FİYAT]],Tablo2[[#This Row],[FİYAT]],Tablo2[[#This Row],[MALİYET]])*1.1,IF(Tablo2[[#This Row],[DATA]]=0,"",IFERROR((1+INDEX($AA$6:$AD$14,MATCH(Tablo2[[#This Row],[DATA]],$AC$6:$AC$14,0),2))*IF(Tablo2[[#This Row],[DATA]]<0,Tablo2[[#This Row],[MALİYET]],Tablo2[[#This Row],[FİYAT]]),0))) -> 71.11125 | N17: 1000
B18: DOAS | C18: =+DOAS!C1 -> 530 | D18: =+DOAS!$F$1 -> 339.49059 | E18: 319 | F18: =E18*C18 -> 169070 | G18: =+DOAS!$G$1 -> -10860.012 | H18: =IFERROR(Tablo2[[#This Row],[FİYAT]]/Tablo2[[#This Row],[MALİYET]]-1,"") -> -0.060356866 | I18: =+DOAS!$K$2/DOAS!$J$2 -> 1.7324521 | J18: =IF(Tablo2[[#This Row],[MALİYET]]<1,6,IF(Tablo2[[#This Row],[HEDEF]]>1,1,LOOKUP(Tablo2[[#This Row],[ANALIZ]],{-1000000,-0.15,-0.1,-0.05,0,0.05,0.1,0.15,0.2;-4,-3,-2,-1,0,1,2,3,4}))) -> 1 | K18: =IF(Tablo2[[#This Row],[MALİYET]]<1,"TUT",IF(Tablo2[[#This Row],[HEDEF]]>2,"SAT",IFERROR(INDEX($AA$6:$AC$14,MATCH(Tablo2[[#This Row],[DATA]],$AC$6:$AC$14,0),1),""))) -> SAT-1 | L18: =IF(Tablo2[[#This Row],[DURUM]]="SAT",Tablo2[[#This Row],[ADET]]*0.5,ROUND(-IFERROR(INDEX($AA$6:$AD$14,MATCH(Tablo2[[#This Row],[DATA]],$AC$6:$AC$14,0),4),"")*Tablo2[[#This Row],[ADET]],0)) -> -53 | M18: =IF(Tablo2[[#This Row],[DURUM]]="SAT",IF(Tablo2[[#This Row],[MALİYET]]<Tablo2[[#This Row],[FİYAT]],Tablo2[[#This Row],[FİYAT]],Tablo2[[#This Row],[MALİYET]])*1.1,IF(Tablo2[[#This Row],[DATA]]=0,"",IFERROR((1+INDEX($AA$6:$AD$14,MATCH(Tablo2[[#This Row],[DATA]],$AC$6:$AC$14,0),2))*IF(Tablo2[[#This Row],[DATA]]<0,Tablo2[[#This Row],[MALİYET]],Tablo2[[#This Row],[FİYAT]]),0))) -> 334.95 | N18: 3000
B19: DOKTA | C19: =+DOKTA!$C$1 -> 4000 | D19: =+DOKTA!$F$1 -> 36.61325 | E19: 36.18 | F19: =E19*C19 -> 144720 | G19: =+DOKTA!$G$1 -> -1733 | H19: =IFERROR(Tablo2[[#This Row],[FİYAT]]/Tablo2[[#This Row],[MALİYET]]-1,"") -> -0.011833148 | I19: =+DOKTA!$K$2/DOKTA!$J$2 -> 4.4488165 | J19: =IF(Tablo2[[#This Row],[MALİYET]]<1,6,IF(Tablo2[[#This Row],[HEDEF]]>1,1,LOOKUP(Tablo2[[#This Row],[ANALIZ]],{-1000000,-0.15,-0.1,-0.05,0,0.05,0.1,0.15,0.2;-4,-3,-2,-1,0,1,2,3,4}))) -> 1 | K19: =IF(Tablo2[[#This Row],[MALİYET]]<1,"TUT",IF(Tablo2[[#This Row],[HEDEF]]>2,"SAT",IFERROR(INDEX($AA$6:$AC$14,MATCH(Tablo2[[#This Row],[DATA]],$AC$6:$AC$14,0),1),""))) -> SAT | L19: =IF(Tablo2[[#This Row],[DURUM]]="SAT",Tablo2[[#This Row],[ADET]]*0.5,ROUND(-IFERROR(INDEX($AA$6:$AD$14,MATCH(Tablo2[[#This Row],[DATA]],$AC$6:$AC$14,0),4),"")*Tablo2[[#This Row],[ADET]],0)) -> 2000 | M19: =IF(Tablo2[[#This Row],[DURUM]]="SAT",IF(Tablo2[[#This Row],[MALİYET]]<Tablo2[[#This Row],[FİYAT]],Tablo2[[#This Row],[FİYAT]],Tablo2[[#This Row],[MALİYET]])*1.1,IF(Tablo2[[#This Row],[DATA]]=0,"",IFERROR((1+INDEX($AA$6:$AD$14,MATCH(Tablo2[[#This Row],[DATA]],$AC$6:$AC$14,0),2))*IF(Tablo2[[#This Row],[DATA]]<0,Tablo2[[#This Row],[MALİYET]],Tablo2[[#This Row],[FİYAT]]),0))) -> 40.274575 | N19: 1000
B20: EDATA | C20: =+EDATA!$C$1 -> 1000 | D20: =EDATA!$F$1 -> 16.857092 | E20: 22.5 | F20: =E20*C20 -> 22500 | G20: =EDATA!$G$1 -> 5642.9075 | H20: =IFERROR(Tablo2[[#This Row],[FİYAT]]/Tablo2[[#This Row],[MALİYET]]-1,"") -> 0.33474975 | I20: =+EDATA!$K$2/EDATA!$J$2 -> 0.69166923 | J20: =IF(Tablo2[[#This Row],[MALİYET]]<1,6,IF(Tablo2[[#This Row],[HEDEF]]>1,1,LOOKUP(Tablo2[[#This Row],[ANALIZ]],{-1000000,-0.15,-0.1,-0.05,0,0.05,0.1,0.15,0.2;-4,-3,-2,-1,0,1,2,3,4}))) -> 4 | K20: =IF(Tablo2[[#This Row],[MALİYET]]<1,"TUT",IF(Tablo2[[#This Row],[HEDEF]]>2,"SAT",IFERROR(INDEX($AA$6:$AC$14,MATCH(Tablo2[[#This Row],[DATA]],$AC$6:$AC$14,0),1),""))) -> SAT-4 | L20: =IF(Tablo2[[#This Row],[DURUM]]="SAT",Tablo2[[#This Row],[ADET]]*0.5,ROUND(-IFERROR(INDEX($AA$6:$AD$14,MATCH(Tablo2[[#This Row],[DATA]],$AC$6:$AC$14,0),4),"")*Tablo2[[#This Row],[ADET]],0)) -> -250 | M20: =IF(Tablo2[[#This Row],[DURUM]]="SAT",IF(Tablo2[[#This Row],[MALİYET]]<Tablo2[[#This Row],[FİYAT]],Tablo2[[#This Row],[FİYAT]],Tablo2[[#This Row],[MALİYET]])*1.1,IF(Tablo2[[#This Row],[DATA]]=0,"",IFERROR((1+INDEX($AA$6:$AD$14,MATCH(Tablo2[[#This Row],[DATA]],$AC$6:$AC$14,0),2))*IF(Tablo2[[#This Row],[DATA]]<0,Tablo2[[#This Row],[MALİYET]],Tablo2[[#This Row],[FİYAT]]),0))) -> 27 | N20: 1000 | S20: =U20*P2 -> 2980298.1 | U20: =U12+U11+U10+U6+U13 -> 91616.911 | X20: =X12+X11+X10+X6+X13 -> 2980298.1
B21: EDIP | C21: =EDIP!$C$1 -> 0 | D21: =EDIP!$F$1 | E21: 19.65 | F21: =E21*C21 -> 0 | G21: =EDIP!$G$1 -> 3195.7885 | H21: =IFERROR(Tablo2[[#This Row],[FİYAT]]/Tablo2[[#This Row],[MALİYET]]-1,"") | I21: =+EDIP!$K$2/EDIP!$J$2 -> 0 | J21: =IF(Tablo2[[#This Row],[MALİYET]]<1,6,IF(Tablo2[[#This Row],[HEDEF]]>1,1,LOOKUP(Tablo2[[#This Row],[ANALIZ]],{-1000000,-0.15,-0.1,-0.05,0,0.05,0.1,0.15,0.2;-4,-3,-2,-1,0,1,2,3,4}))) -> #N/A | K21: =IF(Tablo2[[#This Row],[MALİYET]]<1,"TUT",IF(Tablo2[[#This Row],[HEDEF]]>2,"SAT",IFERROR(INDEX($AA$6:$AC$14,MATCH(Tablo2[[#This Row],[DATA]],$AC$6:$AC$14,0),1),""))) | L21: =IF(Tablo2[[#This Row],[DURUM]]="SAT",Tablo2[[#This Row],[ADET]]*0.5,ROUND(-IFERROR(INDEX($AA$6:$AD$14,MATCH(Tablo2[[#This Row],[DATA]],$AC$6:$AC$14,0),4),"")*Tablo2[[#This Row],[ADET]],0)) -> #VALUE! | M21: =IF(Tablo2[[#This Row],[DURUM]]="SAT",IF(Tablo2[[#This Row],[MALİYET]]<Tablo2[[#This Row],[FİYAT]],Tablo2[[#This Row],[FİYAT]],Tablo2[[#This Row],[MALİYET]])*1.1,IF(Tablo2[[#This Row],[DATA]]=0,"",IFERROR((1+INDEX($AA$6:$AD$14,MATCH(Tablo2[[#This Row],[DATA]],$AC$6:$AC$14,0),2))*IF(Tablo2[[#This Row],[DATA]]<0,Tablo2[[#This Row],[MALİYET]],Tablo2[[#This Row],[FİYAT]]),0))) -> #N/A | N21: 1000
B22: EKOS | C22: =EKOS!$C$1 -> 0 | D22: =EKOS!$F$1 | E22: 48.6 | F22: =E22*C22 -> 0 | G22: =EKOS!$G$1 -> 428 | H22: =IFERROR(Tablo2[[#This Row],[FİYAT]]/Tablo2[[#This Row],[MALİYET]]-1,"") | I22: =+EKOS!$K$2/EKOS!$J$2 -> 0 | J22: =IF(Tablo2[[#This Row],[MALİYET]]<1,6,IF(Tablo2[[#This Row],[HEDEF]]>1,1,LOOKUP(Tablo2[[#This Row],[ANALIZ]],{-1000000,-0.15,-0.1,-0.05,0,0.05,0.1,0.15,0.2;-4,-3,-2,-1,0,1,2,3,4}))) -> #N/A | K22: =IF(Tablo2[[#This Row],[MALİYET]]<1,"TUT",IF(Tablo2[[#This Row],[HEDEF]]>2,"SAT",IFERROR(INDEX($AA$6:$AC$14,MATCH(Tablo2[[#This Row],[DATA]],$AC$6:$AC$14,0),1),""))) | L22: =IF(Tablo2[[#This Row],[DURUM]]="SAT",Tablo2[[#This Row],[ADET]]*0.5,ROUND(-IFERROR(INDEX($AA$6:$AD$14,MATCH(Tablo2[[#This Row],[DATA]],$AC$6:$AC$14,0),4),"")*Tablo2[[#This Row],[ADET]],0)) -> #VALUE! | M22: =IF(Tablo2[[#This Row],[DURUM]]="SAT",IF(Tablo2[[#This Row],[MALİYET]]<Tablo2[[#This Row],[FİYAT]],Tablo2[[#This Row],[FİYAT]],Tablo2[[#This Row],[MALİYET]])*1.1,IF(Tablo2[[#This Row],[DATA]]=0,"",IFERROR((1+INDEX($AA$6:$AD$14,MATCH(Tablo2[[#This Row],[DATA]],$AC$6:$AC$14,0),2))*IF(Tablo2[[#This Row],[DATA]]<0,Tablo2[[#This Row],[MALİYET]],Tablo2[[#This Row],[FİYAT]]),0))) -> #N/A | N22: 1
B23: ENJSA | C23: =ENJSA!$C$1 -> 800 | D23: =ENJSA!$F$1 -> 50.885108 | E23: 63.05 | F23: =E23*C23 -> 50440 | G23: =ENJSA!$G$1 -> 17598.827 | H23: =IFERROR(Tablo2[[#This Row],[FİYAT]]/Tablo2[[#This Row],[MALİYET]]-1,"") -> 0.23906586 | I23: =+ENJSA!$K$2/ENJSA!$J$2 -> 0.77528435 | J23: =IF(Tablo2[[#This Row],[MALİYET]]<1,6,IF(Tablo2[[#This Row],[HEDEF]]>1,1,LOOKUP(Tablo2[[#This Row],[ANALIZ]],{-1000000,-0.15,-0.1,-0.05,0,0.05,0.1,0.15,0.2;-4,-3,-2,-1,0,1,2,3,4}))) -> 4 | K23: =IF(Tablo2[[#This Row],[MALİYET]]<1,"TUT",IF(Tablo2[[#This Row],[HEDEF]]>2,"SAT",IFERROR(INDEX($AA$6:$AC$14,MATCH(Tablo2[[#This Row],[DATA]],$AC$6:$AC$14,0),1),""))) -> SAT-4 | L23: =IF(Tablo2[[#This Row],[DURUM]]="SAT",Tablo2[[#This Row],[ADET]]*0.5,ROUND(-IFERROR(INDEX($AA$6:$AD$14,MATCH(Tablo2[[#This Row],[DATA]],$AC$6:$AC$14,0),4),"")*Tablo2[[#This Row],[ADET]],0)) -> -200 | M23: =IF(Tablo2[[#This Row],[DURUM]]="SAT",IF(Tablo2[[#This Row],[MALİYET]]<Tablo2[[#This Row],[FİYAT]],Tablo2[[#This Row],[FİYAT]],Tablo2[[#This Row],[MALİYET]])*1.1,IF(Tablo2[[#This Row],[DATA]]=0,"",IFERROR((1+INDEX($AA$6:$AD$14,MATCH(Tablo2[[#This Row],[DATA]],$AC$6:$AC$14,0),2))*IF(Tablo2[[#This Row],[DATA]]<0,Tablo2[[#This Row],[MALİYET]],Tablo2[[#This Row],[FİYAT]]),0))) -> 75.66 | N23: 2000
B24: ENKAI | C24: =ENKAI!$C$1 -> 500 | D24: =ENKAI!$F$1 -> 35.59 | E24: 36.14 | F24: =E24*C24 -> 18070 | G24: =ENKAI!$G$1 -> 275 | H24: =IFERROR(Tablo2[[#This Row],[FİYAT]]/Tablo2[[#This Row],[MALİYET]]-1,"") -> 0.015453779 | I24: =+ENKAI!$K$2/ENKAI!$J$2 -> 0.55548724 | J24: =IF(Tablo2[[#This Row],[MALİYET]]<1,6,IF(Tablo2[[#This Row],[HEDEF]]>1,1,LOOKUP(Tablo2[[#This Row],[ANALIZ]],{-1000000,-0.15,-0.1,-0.05,0,0.05,0.1,0.15,0.2;-4,-3,-2,-1,0,1,2,3,4}))) -> 0 | K24: =IF(Tablo2[[#This Row],[MALİYET]]<1,"TUT",IF(Tablo2[[#This Row],[HEDEF]]>2,"SAT",IFERROR(INDEX($AA$6:$AC$14,MATCH(Tablo2[[#This Row],[DATA]],$AC$6:$AC$14,0),1),""))) -> TUT | L24: =IF(Tablo2[[#This Row],[DURUM]]="SAT",Tablo2[[#This Row],[ADET]]*0.5,ROUND(-IFERROR(INDEX($AA$6:$AD$14,MATCH(Tablo2[[#This Row],[DATA]],$AC$6:$AC$14,0),4),"")*Tablo2[[#This Row],[ADET]],0)) -> 0 | M24: =IF(Tablo2[[#This Row],[DURUM]]="SAT",IF(Tablo2[[#This Row],[MALİYET]]<Tablo2[[#This Row],[FİYAT]],Tablo2[[#This Row],[FİYAT]],Tablo2[[#This Row],[MALİYET]])*1.1,IF(Tablo2[[#This Row],[DATA]]=0,"",IFERROR((1+INDEX($AA$6:$AD$14,MATCH(Tablo2[[#This Row],[DATA]],$AC$6:$AC$14,0),2))*IF(Tablo2[[#This Row],[DATA]]<0,Tablo2[[#This Row],[MALİYET]],Tablo2[[#This Row],[FİYAT]]),0))) | N24: 1000
B25: ENSRI | C25: =ENSRI!$C$1 -> 0 | D25: =ENSRI!$F$1 | E25: 37.98 | F25: =E25*C25 -> 0 | G25: =ENSRI!$G$1 -> 680 | H25: =IFERROR(Tablo2[[#This Row],[FİYAT]]/Tablo2[[#This Row],[MALİYET]]-1,"") | I25: =+ADESE!$K$2/ADESE!$J$2 -> 0.60166001 | J25: =IF(Tablo2[[#This Row],[MALİYET]]<1,6,IF(Tablo2[[#This Row],[HEDEF]]>1,1,LOOKUP(Tablo2[[#This Row],[ANALIZ]],{-1000000,-0.15,-0.1,-0.05,0,0.05,0.1,0.15,0.2;-4,-3,-2,-1,0,1,2,3,4}))) -> #N/A | K25: =IF(Tablo2[[#This Row],[MALİYET]]<1,"TUT",IF(Tablo2[[#This Row],[HEDEF]]>2,"SAT",IFERROR(INDEX($AA$6:$AC$14,MATCH(Tablo2[[#This Row],[DATA]],$AC$6:$AC$14,0),1),""))) | L25: =IF(Tablo2[[#This Row],[DURUM]]="SAT",Tablo2[[#This Row],[ADET]]*0.5,ROUND(-IFERROR(INDEX($AA$6:$AD$14,MATCH(Tablo2[[#This Row],[DATA]],$AC$6:$AC$14,0),4),"")*Tablo2[[#This Row],[ADET]],0)) -> #VALUE! | M25: =IF(Tablo2[[#This Row],[DURUM]]="SAT",IF(Tablo2[[#This Row],[MALİYET]]<Tablo2[[#This Row],[FİYAT]],Tablo2[[#This Row],[FİYAT]],Tablo2[[#This Row],[MALİYET]])*1.1,IF(Tablo2[[#This Row],[DATA]]=0,"",IFERROR((1+INDEX($AA$6:$AD$14,MATCH(Tablo2[[#This Row],[DATA]],$AC$6:$AC$14,0),2))*IF(Tablo2[[#This Row],[DATA]]<0,Tablo2[[#This Row],[MALİYET]],Tablo2[[#This Row],[FİYAT]]),0))) -> #N/A
B26: FENER | C26: =FENER!$C$1 -> 0 | D26: =FENER!$F$1 | E26: 103 | F26: =E26*C26 -> 0 | G26: =FENER!$G$1 -> #VALUE! | H26: =IFERROR(Tablo2[[#This Row],[FİYAT]]/Tablo2[[#This Row],[MALİYET]]-1,"") | I26: =+ADESE!$K$2/ADESE!$J$2 -> 0.60166001 | J26: =IF(Tablo2[[#This Row],[MALİYET]]<1,6,IF(Tablo2[[#This Row],[HEDEF]]>1,1,LOOKUP(Tablo2[[#This Row],[ANALIZ]],{-1000000,-0.15,-0.1,-0.05,0,0.05,0.1,0.15,0.2;-4,-3,-2,-1,0,1,2,3,4}))) -> #N/A | K26: =IF(Tablo2[[#This Row],[MALİYET]]<1,"TUT",IF(Tablo2[[#This Row],[HEDEF]]>2,"SAT",IFERROR(INDEX($AA$6:$AC$14,MATCH(Tablo2[[#This Row],[DATA]],$AC$6:$AC$14,0),1),""))) | L26: =IF(Tablo2[[#This Row],[DURUM]]="SAT",Tablo2[[#This Row],[ADET]]*0.5,ROUND(-IFERROR(INDEX($AA$6:$AD$14,MATCH(Tablo2[[#This Row],[DATA]],$AC$6:$AC$14,0),4),"")*Tablo2[[#This Row],[ADET]],0)) -> #VALUE! | M26: =IF(Tablo2[[#This Row],[DURUM]]="SAT",IF(Tablo2[[#This Row],[MALİYET]]<Tablo2[[#This Row],[FİYAT]],Tablo2[[#This Row],[FİYAT]],Tablo2[[#This Row],[MALİYET]])*1.1,IF(Tablo2[[#This Row],[DATA]]=0,"",IFERROR((1+INDEX($AA$6:$AD$14,MATCH(Tablo2[[#This Row],[DATA]],$AC$6:$AC$14,0),2))*IF(Tablo2[[#This Row],[DATA]]<0,Tablo2[[#This Row],[MALİYET]],Tablo2[[#This Row],[FİYAT]]),0))) -> #N/A
B27: FROTO | C27: =FROTO!$C$1 -> 30 | D27: =FROTO!$F$1 -> 979.00931 | E27: 1122 | F27: =E27*C27 -> 33660 | G27: =FROTO!$G$1 -> 4289.7207 | H27: =IFERROR(Tablo2[[#This Row],[FİYAT]]/Tablo2[[#This Row],[MALİYET]]-1,"") -> 0.14605652 | I27: =+FROTO!$K$2/FROTO!$J$2 -> 1.0347372 | J27: =IF(Tablo2[[#This Row],[MALİYET]]<1,6,IF(Tablo2[[#This Row],[HEDEF]]>1,1,LOOKUP(Tablo2[[#This Row],[ANALIZ]],{-1000000,-0.15,-0.1,-0.05,0,0.05,0.1,0.15,0.2;-4,-3,-2,-1,0,1,2,3,4}))) -> 1 | K27: =IF(Tablo2[[#This Row],[MALİYET]]<1,"TUT",IF(Tablo2[[#This Row],[HEDEF]]>2,"SAT",IFERROR(INDEX($AA$6:$AC$14,MATCH(Tablo2[[#This Row],[DATA]],$AC$6:$AC$14,0),1),""))) -> SAT-1 | L27: =IF(Tablo2[[#This Row],[DURUM]]="SAT",Tablo2[[#This Row],[ADET]]*0.5,ROUND(-IFERROR(INDEX($AA$6:$AD$14,MATCH(Tablo2[[#This Row],[DATA]],$AC$6:$AC$14,0),4),"")*Tablo2[[#This Row],[ADET]],0)) -> -3 | M27: =IF(Tablo2[[#This Row],[DURUM]]="SAT",IF(Tablo2[[#This Row],[MALİYET]]<Tablo2[[#This Row],[FİYAT]],Tablo2[[#This Row],[FİYAT]],Tablo2[[#This Row],[MALİYET]])*1.1,IF(Tablo2[[#This Row],[DATA]]=0,"",IFERROR((1+INDEX($AA$6:$AD$14,MATCH(Tablo2[[#This Row],[DATA]],$AC$6:$AC$14,0),2))*IF(Tablo2[[#This Row],[DATA]]<0,Tablo2[[#This Row],[MALİYET]],Tablo2[[#This Row],[FİYAT]]),0))) -> 1178.1 | N27: 1000
B28: GENTS | C28: =GENTS!$C$1 -> 0 | D28: =GENTS!$F$1 | E28: 9.23 | F28: =E28*C28 -> 0 | G28: =GENTS!$G$1 -> 460.44999 | H28: =IFERROR(Tablo2[[#This Row],[FİYAT]]/Tablo2[[#This Row],[MALİYET]]-1,"") | I28: =+ADESE!$K$2/ADESE!$J$2 -> 0.60166001 | J28: =IF(Tablo2[[#This Row],[MALİYET]]<1,6,IF(Tablo2[[#This Row],[HEDEF]]>1,1,LOOKUP(Tablo2[[#This Row],[ANALIZ]],{-1000000,-0.15,-0.1,-0.05,0,0.05,0.1,0.15,0.2;-4,-3,-2,-1,0,1,2,3,4}))) -> #N/A | K28: =IF(Tablo2[[#This Row],[MALİYET]]<1,"TUT",IF(Tablo2[[#This Row],[HEDEF]]>2,"SAT",IFERROR(INDEX($AA$6:$AC$14,MATCH(Tablo2[[#This Row],[DATA]],$AC$6:$AC$14,0),1),""))) | L28: =IF(Tablo2[[#This Row],[DURUM]]="SAT",Tablo2[[#This Row],[ADET]]*0.5,ROUND(-IFERROR(INDEX($AA$6:$AD$14,MATCH(Tablo2[[#This Row],[DATA]],$AC$6:$AC$14,0),4),"")*Tablo2[[#This Row],[ADET]],0)) -> #VALUE! | M28: =IF(Tablo2[[#This Row],[DURUM]]="SAT",IF(Tablo2[[#This Row],[MALİYET]]<Tablo2[[#This Row],[FİYAT]],Tablo2[[#This Row],[FİYAT]],Tablo2[[#This Row],[MALİYET]])*1.1,IF(Tablo2[[#This Row],[DATA]]=0,"",IFERROR((1+INDEX($AA$6:$AD$14,MATCH(Tablo2[[#This Row],[DATA]],$AC$6:$AC$14,0),2))*IF(Tablo2[[#This Row],[DATA]]<0,Tablo2[[#This Row],[MALİYET]],Tablo2[[#This Row],[FİYAT]]),0))) -> #N/A
B29: GEREL | C29: =GEREL!$C$1 -> 0 | D29: =GEREL!$F$1 | E29: 32.42 | F29: =E29*C29 -> 0 | G29: =GEREL!$G$1 -> -2274 | H29: =IFERROR(Tablo2[[#This Row],[FİYAT]]/Tablo2[[#This Row],[MALİYET]]-1,"") | I29: =+GEREL!$K$2/GEREL!$J$2 -> 0 | J29: =IF(Tablo2[[#This Row],[MALİYET]]<1,6,IF(Tablo2[[#This Row],[HEDEF]]>1,1,LOOKUP(Tablo2[[#This Row],[ANALIZ]],{-1000000,-0.15,-0.1,-0.05,0,0.05,0.1,0.15,0.2;-4,-3,-2,-1,0,1,2,3,4}))) -> #N/A | K29: =IF(Tablo2[[#This Row],[MALİYET]]<1,"TUT",IF(Tablo2[[#This Row],[HEDEF]]>2,"SAT",IFERROR(INDEX($AA$6:$AC$14,MATCH(Tablo2[[#This Row],[DATA]],$AC$6:$AC$14,0),1),""))) | L29: =IF(Tablo2[[#This Row],[DURUM]]="SAT",Tablo2[[#This Row],[ADET]]*0.5,ROUND(-IFERROR(INDEX($AA$6:$AD$14,MATCH(Tablo2[[#This Row],[DATA]],$AC$6:$AC$14,0),4),"")*Tablo2[[#This Row],[ADET]],0)) -> #VALUE! | M29: =IF(Tablo2[[#This Row],[DURUM]]="SAT",IF(Tablo2[[#This Row],[MALİYET]]<Tablo2[[#This Row],[FİYAT]],Tablo2[[#This Row],[FİYAT]],Tablo2[[#This Row],[MALİYET]])*1.1,IF(Tablo2[[#This Row],[DATA]]=0,"",IFERROR((1+INDEX($AA$6:$AD$14,MATCH(Tablo2[[#This Row],[DATA]],$AC$6:$AC$14,0),2))*IF(Tablo2[[#This Row],[DATA]]<0,Tablo2[[#This Row],[MALİYET]],Tablo2[[#This Row],[FİYAT]]),0))) -> #N/A | N29: 1000
B30: GRSEL | C30: =GRSEL!$C$1 -> 150 | D30: =GRSEL!$F$1 -> 47.99393 | E30: 90.7 | F30: =E30*C30 -> 13605 | G30: =GRSEL!$G$1 -> 6405.9106 | H30: =IFERROR(Tablo2[[#This Row],[FİYAT]]/Tablo2[[#This Row],[MALİYET]]-1,"") -> 0.88982233 | I30: =+GRSEL!$K$2/GRSEL!$J$2 -> 0.41822933 | J30: =IF(Tablo2[[#This Row],[MALİYET]]<1,6,IF(Tablo2[[#This Row],[HEDEF]]>1,1,LOOKUP(Tablo2[[#This Row],[ANALIZ]],{-1000000,-0.15,-0.1,-0.05,0,0.05,0.1,0.15,0.2;-4,-3,-2,-1,0,1,2,3,4}))) -> 4 | K30: =IF(Tablo2[[#This Row],[MALİYET]]<1,"TUT",IF(Tablo2[[#This Row],[HEDEF]]>2,"SAT",IFERROR(INDEX($AA$6:$AC$14,MATCH(Tablo2[[#This Row],[DATA]],$AC$6:$AC$14,0),1),""))) -> SAT-4 | L30: =IF(Tablo2[[#This Row],[DURUM]]="SAT",Tablo2[[#This Row],[ADET]]*0.5,ROUND(-IFERROR(INDEX($AA$6:$AD$14,MATCH(Tablo2[[#This Row],[DATA]],$AC$6:$AC$14,0),4),"")*Tablo2[[#This Row],[ADET]],0)) -> -38 | M30: =IF(Tablo2[[#This Row],[DURUM]]="SAT",IF(Tablo2[[#This Row],[MALİYET]]<Tablo2[[#This Row],[FİYAT]],Tablo2[[#This Row],[FİYAT]],Tablo2[[#This Row],[MALİYET]])*1.1,IF(Tablo2[[#This Row],[DATA]]=0,"",IFERROR((1+INDEX($AA$6:$AD$14,MATCH(Tablo2[[#This Row],[DATA]],$AC$6:$AC$14,0),2))*IF(Tablo2[[#This Row],[DATA]]<0,Tablo2[[#This Row],[MALİYET]],Tablo2[[#This Row],[FİYAT]]),0))) -> 108.84 | N30: 1000
B31: GWIND | C31: =GWIND!$C$1 -> 300 | D31: =GWIND!$F$1 -> 19.290062 | E31: 27.06 | F31: =E31*C31 -> 8118 | G31: =GWIND!$G$1 -> 4983.9628 | H31: =IFERROR(Tablo2[[#This Row],[FİYAT]]/Tablo2[[#This Row],[MALİYET]]-1,"") -> 0.40279487 | I31: =+GWIND!$K$2/GWIND!$J$2 -> 0.24955426 | J31: =IF(Tablo2[[#This Row],[MALİYET]]<1,6,IF(Tablo2[[#This Row],[HEDEF]]>1,1,LOOKUP(Tablo2[[#This Row],[ANALIZ]],{-1000000,-0.15,-0.1,-0.05,0,0.05,0.1,0.15,0.2;-4,-3,-2,-1,0,1,2,3,4}))) -> 4 | K31: =IF(Tablo2[[#This Row],[MALİYET]]<1,"TUT",IF(Tablo2[[#This Row],[HEDEF]]>2,"SAT",IFERROR(INDEX($AA$6:$AC$14,MATCH(Tablo2[[#This Row],[DATA]],$AC$6:$AC$14,0),1),""))) -> SAT-4 | L31: =IF(Tablo2[[#This Row],[DURUM]]="SAT",Tablo2[[#This Row],[ADET]]*0.5,ROUND(-IFERROR(INDEX($AA$6:$AD$14,MATCH(Tablo2[[#This Row],[DATA]],$AC$6:$AC$14,0),4),"")*Tablo2[[#This Row],[ADET]],0)) -> -75 | M31: =IF(Tablo2[[#This Row],[DURUM]]="SAT",IF(Tablo2[[#This Row],[MALİYET]]<Tablo2[[#This Row],[FİYAT]],Tablo2[[#This Row],[FİYAT]],Tablo2[[#This Row],[MALİYET]])*1.1,IF(Tablo2[[#This Row],[DATA]]=0,"",IFERROR((1+INDEX($AA$6:$AD$14,MATCH(Tablo2[[#This Row],[DATA]],$AC$6:$AC$14,0),2))*IF(Tablo2[[#This Row],[DATA]]<0,Tablo2[[#This Row],[MALİYET]],Tablo2[[#This Row],[FİYAT]]),0))) -> 32.472 | N31: 1000
B32: HTTBT | C32: =HTTBT!$C$1 -> 100 | D32: =HTTBT!$F$1 -> 32.425 | E32: 71.55 | F32: =E32*C32 -> 7155 | G32: =HTTBT!$G$1 -> 3912.5 | H32: =IFERROR(Tablo2[[#This Row],[FİYAT]]/Tablo2[[#This Row],[MALİYET]]-1,"") -> 1.2066307 | I32: =+HTTBT!$K$2/HTTBT!$J$2 -> 0.21995081 | J32: =IF(Tablo2[[#This Row],[MALİYET]]<1,6,IF(Tablo2[[#This Row],[HEDEF]]>1,1,LOOKUP(Tablo2[[#This Row],[ANALIZ]],{-1000000,-0.15,-0.1,-0.05,0,0.05,0.1,0.15,0.2;-4,-3,-2,-1,0,1,2,3,4}))) -> 4 | K32: =IF(Tablo2[[#This Row],[MALİYET]]<1,"TUT",IF(Tablo2[[#This Row],[HEDEF]]>2,"SAT",IFERROR(INDEX($AA$6:$AC$14,MATCH(Tablo2[[#This Row],[DATA]],$AC$6:$AC$14,0),1),""))) -> SAT-4 | L32: =IF(Tablo2[[#This Row],[DURUM]]="SAT",Tablo2[[#This Row],[ADET]]*0.5,ROUND(-IFERROR(INDEX($AA$6:$AD$14,MATCH(Tablo2[[#This Row],[DATA]],$AC$6:$AC$14,0),4),"")*Tablo2[[#This Row],[ADET]],0)) -> -25 | M32: =IF(Tablo2[[#This Row],[DURUM]]="SAT",IF(Tablo2[[#This Row],[MALİYET]]<Tablo2[[#This Row],[FİYAT]],Tablo2[[#This Row],[FİYAT]],Tablo2[[#This Row],[MALİYET]])*1.1,IF(Tablo2[[#This Row],[DATA]]=0,"",IFERROR((1+INDEX($AA$6:$AD$14,MATCH(Tablo2[[#This Row],[DATA]],$AC$6:$AC$14,0),2))*IF(Tablo2[[#This Row],[DATA]]<0,Tablo2[[#This Row],[MALİYET]],Tablo2[[#This Row],[FİYAT]]),0))) -> 85.86 | N32: 1000
B33: INDES | C33: =INDES!$C$1 -> 0 | D33: =INDES!$F$1 | E33: 10.6 | F33: =E33*C33 -> 0 | G33: =INDES!$G$1 -> 898.3981 | H33: =IFERROR(Tablo2[[#This Row],[FİYAT]]/Tablo2[[#This Row],[MALİYET]]-1,"") | I33: =+ADESE!$K$2/ADESE!$J$2 -> 0.60166001 | J33: =IF(Tablo2[[#This Row],[MALİYET]]<1,6,IF(Tablo2[[#This Row],[HEDEF]]>1,1,LOOKUP(Tablo2[[#This Row],[ANALIZ]],{-1000000,-0.15,-0.1,-0.05,0,0.05,0.1,0.15,0.2;-4,-3,-2,-1,0,1,2,3,4}))) -> #N/A | K33: =IF(Tablo2[[#This Row],[MALİYET]]<1,"TUT",IF(Tablo2[[#This Row],[HEDEF]]>2,"SAT",IFERROR(INDEX($AA$6:$AC$14,MATCH(Tablo2[[#This Row],[DATA]],$AC$6:$AC$14,0),1),""))) | L33: =IF(Tablo2[[#This Row],[DURUM]]="SAT",Tablo2[[#This Row],[ADET]]*0.5,ROUND(-IFERROR(INDEX($AA$6:$AD$14,MATCH(Tablo2[[#This Row],[DATA]],$AC$6:$AC$14,0),4),"")*Tablo2[[#This Row],[ADET]],0)) -> #VALUE! | M33: =IF(Tablo2[[#This Row],[DURUM]]="SAT",IF(Tablo2[[#This Row],[MALİYET]]<Tablo2[[#This Row],[FİYAT]],Tablo2[[#This Row],[FİYAT]],Tablo2[[#This Row],[MALİYET]])*1.1,IF(Tablo2[[#This Row],[DATA]]=0,"",IFERROR((1+INDEX($AA$6:$AD$14,MATCH(Tablo2[[#This Row],[DATA]],$AC$6:$AC$14,0),2))*IF(Tablo2[[#This Row],[DATA]]<0,Tablo2[[#This Row],[MALİYET]],Tablo2[[#This Row],[FİYAT]]),0))) -> #N/A
B34: KBORU | C34: =KBORU!$C$1 -> 90 | D34: =KBORU!$F$1 -> 119.55556 | E34: 110.6 | F34: =E34*C34 -> 9954 | G34: =KBORU!$G$1 -> -806 | H34: =IFERROR(Tablo2[[#This Row],[FİYAT]]/Tablo2[[#This Row],[MALİYET]]-1,"") -> -0.074907063 | I34: =+KBORU!$K$2/KBORU!$J$2 -> 305.99447 | J34: =IF(Tablo2[[#This Row],[MALİYET]]<1,6,IF(Tablo2[[#This Row],[HEDEF]]>1,1,LOOKUP(Tablo2[[#This Row],[ANALIZ]],{-1000000,-0.15,-0.1,-0.05,0,0.05,0.1,0.15,0.2;-4,-3,-2,-1,0,1,2,3,4}))) -> 1 | K34: =IF(Tablo2[[#This Row],[MALİYET]]<1,"TUT",IF(Tablo2[[#This Row],[HEDEF]]>2,"SAT",IFERROR(INDEX($AA$6:$AC$14,MATCH(Tablo2[[#This Row],[DATA]],$AC$6:$AC$14,0),1),""))) -> SAT | L34: =IF(Tablo2[[#This Row],[DURUM]]="SAT",Tablo2[[#This Row],[ADET]]*0.5,ROUND(-IFERROR(INDEX($AA$6:$AD$14,MATCH(Tablo2[[#This Row],[DATA]],$AC$6:$AC$14,0),4),"")*Tablo2[[#This Row],[ADET]],0)) -> 45 | M34: =IF(Tablo2[[#This Row],[DURUM]]="SAT",IF(Tablo2[[#This Row],[MALİYET]]<Tablo2[[#This Row],[FİYAT]],Tablo2[[#This Row],[FİYAT]],Tablo2[[#This Row],[MALİYET]])*1.1,IF(Tablo2[[#This Row],[DATA]]=0,"",IFERROR((1+INDEX($AA$6:$AD$14,MATCH(Tablo2[[#This Row],[DATA]],$AC$6:$AC$14,0),2))*IF(Tablo2[[#This Row],[DATA]]<0,Tablo2[[#This Row],[MALİYET]],Tablo2[[#This Row],[FİYAT]]),0))) -> 131.51111 | N34: 1
B35: KCHOL | C35: =KCHOL!$C$1 -> 230 | D35: =KCHOL!$F$1 -> 182.55284 | E35: 216 | F35: =E35*C35 -> 49680 | G35: =KCHOL!$G$1 -> 7692.847 | H35: =IFERROR(Tablo2[[#This Row],[FİYAT]]/Tablo2[[#This Row],[MALİYET]]-1,"") -> 0.18321907 | I35: =+KCHOL!$K$2/KCHOL!$J$2 -> 0.76360283 | J35: =IF(Tablo2[[#This Row],[MALİYET]]<1,6,IF(Tablo2[[#This Row],[HEDEF]]>1,1,LOOKUP(Tablo2[[#This Row],[ANALIZ]],{-1000000,-0.15,-0.1,-0.05,0,0.05,0.1,0.15,0.2;-4,-3,-2,-1,0,1,2,3,4}))) -> 3 | K35: =IF(Tablo2[[#This Row],[MALİYET]]<1,"TUT",IF(Tablo2[[#This Row],[HEDEF]]>2,"SAT",IFERROR(INDEX($AA$6:$AC$14,MATCH(Tablo2[[#This Row],[DATA]],$AC$6:$AC$14,0),1),""))) -> SAT-3 | L35: =IF(Tablo2[[#This Row],[DURUM]]="SAT",Tablo2[[#This Row],[ADET]]*0.5,ROUND(-IFERROR(INDEX($AA$6:$AD$14,MATCH(Tablo2[[#This Row],[DATA]],$AC$6:$AC$14,0),4),"")*Tablo2[[#This Row],[ADET]],0)) -> -46 | M35: =IF(Tablo2[[#This Row],[DURUM]]="SAT",IF(Tablo2[[#This Row],[MALİYET]]<Tablo2[[#This Row],[FİYAT]],Tablo2[[#This Row],[FİYAT]],Tablo2[[#This Row],[MALİYET]])*1.1,IF(Tablo2[[#This Row],[DATA]]=0,"",IFERROR((1+INDEX($AA$6:$AD$14,MATCH(Tablo2[[#This Row],[DATA]],$AC$6:$AC$14,0),2))*IF(Tablo2[[#This Row],[DATA]]<0,Tablo2[[#This Row],[MALİYET]],Tablo2[[#This Row],[FİYAT]]),0))) -> 248.4 | N35: 2000
B36: KIMMR | C36: =KIMMR!$C$1 -> 0 | D36: =KIMMR!$F$1 | E36: 9.97 | F36: =E36*C36 -> 0 | G36: =KIMMR!$G$1 -> 2420.7022 | H36: =IFERROR(Tablo2[[#This Row],[FİYAT]]/Tablo2[[#This Row],[MALİYET]]-1,"") | I36: =+ADESE!$K$2/ADESE!$J$2 -> 0.60166001 | J36: =IF(Tablo2[[#This Row],[MALİYET]]<1,6,IF(Tablo2[[#This Row],[HEDEF]]>1,1,LOOKUP(Tablo2[[#This Row],[ANALIZ]],{-1000000,-0.15,-0.1,-0.05,0,0.05,0.1,0.15,0.2;-4,-3,-2,-1,0,1,2,3,4}))) -> #N/A | K36: =IF(Tablo2[[#This Row],[MALİYET]]<1,"TUT",IF(Tablo2[[#This Row],[HEDEF]]>2,"SAT",IFERROR(INDEX($AA$6:$AC$14,MATCH(Tablo2[[#This Row],[DATA]],$AC$6:$AC$14,0),1),""))) | L36: =IF(Tablo2[[#This Row],[DURUM]]="SAT",Tablo2[[#This Row],[ADET]]*0.5,ROUND(-IFERROR(INDEX($AA$6:$AD$14,MATCH(Tablo2[[#This Row],[DATA]],$AC$6:$AC$14,0),4),"")*Tablo2[[#This Row],[ADET]],0)) -> #VALUE! | M36: =IF(Tablo2[[#This Row],[DURUM]]="SAT",IF(Tablo2[[#This Row],[MALİYET]]<Tablo2[[#This Row],[FİYAT]],Tablo2[[#This Row],[FİYAT]],Tablo2[[#This Row],[MALİYET]])*1.1,IF(Tablo2[[#This Row],[DATA]]=0,"",IFERROR((1+INDEX($AA$6:$AD$14,MATCH(Tablo2[[#This Row],[DATA]],$AC$6:$AC$14,0),2))*IF(Tablo2[[#This Row],[DATA]]<0,Tablo2[[#This Row],[MALİYET]],Tablo2[[#This Row],[FİYAT]]),0))) -> #N/A
B37: KRVGD | C37: =+KRVGD!C1 -> 0 | D37: =KRVGD!$F$1 | E37: 27.2 | F37: =E37*C37 -> 0 | G37: =KRVGD!$G$1 -> 602.5 | H37: =IFERROR(Tablo2[[#This Row],[FİYAT]]/Tablo2[[#This Row],[MALİYET]]-1,"") | I37: =+ADESE!$K$2/ADESE!$J$2 -> 0.60166001 | J37: =IF(Tablo2[[#This Row],[MALİYET]]<1,6,IF(Tablo2[[#This Row],[HEDEF]]>1,1,LOOKUP(Tablo2[[#This Row],[ANALIZ]],{-1000000,-0.15,-0.1,-0.05,0,0.05,0.1,0.15,0.2;-4,-3,-2,-1,0,1,2,3,4}))) -> #N/A | K37: =IF(Tablo2[[#This Row],[MALİYET]]<1,"TUT",IF(Tablo2[[#This Row],[HEDEF]]>2,"SAT",IFERROR(INDEX($AA$6:$AC$14,MATCH(Tablo2[[#This Row],[DATA]],$AC$6:$AC$14,0),1),""))) | L37: =IF(Tablo2[[#This Row],[DURUM]]="SAT",Tablo2[[#This Row],[ADET]]*0.5,ROUND(-IFERROR(INDEX($AA$6:$AD$14,MATCH(Tablo2[[#This Row],[DATA]],$AC$6:$AC$14,0),4),"")*Tablo2[[#This Row],[ADET]],0)) -> #VALUE! | M37: =IF(Tablo2[[#This Row],[DURUM]]="SAT",IF(Tablo2[[#This Row],[MALİYET]]<Tablo2[[#This Row],[FİYAT]],Tablo2[[#This Row],[FİYAT]],Tablo2[[#This Row],[MALİYET]])*1.1,IF(Tablo2[[#This Row],[DATA]]=0,"",IFERROR((1+INDEX($AA$6:$AD$14,MATCH(Tablo2[[#This Row],[DATA]],$AC$6:$AC$14,0),2))*IF(Tablo2[[#This Row],[DATA]]<0,Tablo2[[#This Row],[MALİYET]],Tablo2[[#This Row],[FİYAT]]),0))) -> #N/A
B38: KONTR | C38: =KONTR!$C$1 -> 30 | D38: =KONTR!$F$1 -> 464.45689 | E38: 233.5 | F38: =E38*C38 -> 7005 | G38: =KONTR!$G$1 -> -6928.7068 | H38: =IFERROR(Tablo2[[#This Row],[FİYAT]]/Tablo2[[#This Row],[MALİYET]]-1,"") -> -0.49726228 | I38: =+KONTR!$K$2/KONTR!$J$2 -> 0.21533969 | J38: =IF(Tablo2[[#This Row],[MALİYET]]<1,6,IF(Tablo2[[#This Row],[HEDEF]]>1,1,LOOKUP(Tablo2[[#This Row],[ANALIZ]],{-1000000,-0.15,-0.1,-0.05,0,0.05,0.1,0.15,0.2;-4,-3,-2,-1,0,1,2,3,4}))) -> -4 | K38: =IF(Tablo2[[#This Row],[MALİYET]]<1,"TUT",IF(Tablo2[[#This Row],[HEDEF]]>2,"SAT",IFERROR(INDEX($AA$6:$AC$14,MATCH(Tablo2[[#This Row],[DATA]],$AC$6:$AC$14,0),1),""))) -> AL-4 | L38: =IF(Tablo2[[#This Row],[DURUM]]="SAT",Tablo2[[#This Row],[ADET]]*0.5,ROUND(-IFERROR(INDEX($AA$6:$AD$14,MATCH(Tablo2[[#This Row],[DATA]],$AC$6:$AC$14,0),4),"")*Tablo2[[#This Row],[ADET]],0)) -> 8 | M38: =IF(Tablo2[[#This Row],[DURUM]]="SAT",IF(Tablo2[[#This Row],[MALİYET]]<Tablo2[[#This Row],[FİYAT]],Tablo2[[#This Row],[FİYAT]],Tablo2[[#This Row],[MALİYET]])*1.1,IF(Tablo2[[#This Row],[DATA]]=0,"",IFERROR((1+INDEX($AA$6:$AD$14,MATCH(Tablo2[[#This Row],[DATA]],$AC$6:$AC$14,0),2))*IF(Tablo2[[#This Row],[DATA]]<0,Tablo2[[#This Row],[MALİYET]],Tablo2[[#This Row],[FİYAT]]),0))) -> 371.56551 | N38: 1000
B39: MAVI | C39: =MAVI!$C$1 -> 450 | D39: =MAVI!$F$1 -> 64.178178 | E39: 81.05 | F39: =E39*C39 -> 36472.5 | G39: =MAVI!$G$1 -> 7592.32 | H39: =IFERROR(Tablo2[[#This Row],[FİYAT]]/Tablo2[[#This Row],[MALİYET]]-1,"") -> 0.26289033 | I39: =+ADESE!$K$2/ADESE!$J$2 -> 0.60166001 | J39: =IF(Tablo2[[#This Row],[MALİYET]]<1,6,IF(Tablo2[[#This Row],[HEDEF]]>1,1,LOOKUP(Tablo2[[#This Row],[ANALIZ]],{-1000000,-0.15,-0.1,-0.05,0,0.05,0.1,0.15,0.2;-4,-3,-2,-1,0,1,2,3,4}))) -> 4 | K39: =IF(Tablo2[[#This Row],[MALİYET]]<1,"TUT",IF(Tablo2[[#This Row],[HEDEF]]>2,"SAT",IFERROR(INDEX($AA$6:$AC$14,MATCH(Tablo2[[#This Row],[DATA]],$AC$6:$AC$14,0),1),""))) -> SAT-4 | L39: =IF(Tablo2[[#This Row],[DURUM]]="SAT",Tablo2[[#This Row],[ADET]]*0.5,ROUND(-IFERROR(INDEX($AA$6:$AD$14,MATCH(Tablo2[[#This Row],[DATA]],$AC$6:$AC$14,0),4),"")*Tablo2[[#This Row],[ADET]],0)) -> -113 | M39: =IF(Tablo2[[#This Row],[DURUM]]="SAT",IF(Tablo2[[#This Row],[MALİYET]]<Tablo2[[#This Row],[FİYAT]],Tablo2[[#This Row],[FİYAT]],Tablo2[[#This Row],[MALİYET]])*1.1,IF(Tablo2[[#This Row],[DATA]]=0,"",IFERROR((1+INDEX($AA$6:$AD$14,MATCH(Tablo2[[#This Row],[DATA]],$AC$6:$AC$14,0),2))*IF(Tablo2[[#This Row],[DATA]]<0,Tablo2[[#This Row],[MALİYET]],Tablo2[[#This Row],[FİYAT]]),0))) -> 97.26 | N39: 1000
