Workbook

Sheet İcmal
C3: Toplam Dönen Varlıklar | D3: Toplam Duran Varlıklar | E3: Toplam Kısa Vadeli Yükümlülükler | F3: Toplam Uzun Vadeli Yükümlülükler | H3: Toplam Özkaynaklar | I3: Brüt Kar (Zarar) | J3: Genel Yönetim Giderleri (-) | K3: Pazarlama, Satış ve Dağıtım Giderleri (-) | L3: Araştırma ve Geliştirme Giderleri (-) | M3: Amortisman | N3: Dönem Karı (Zararı) | O3: Satış Gelirleri
B4: 2021/6 | C4: =+VLOOKUP(C$3,Bilanço!$A$1:$P$110,16,0) -> 1264411168 | D4: =+VLOOKUP(D$3,Bilanço!$A$1:$P$110,16,0) -> 4993565699 | E4: =+VLOOKUP(E$3,Bilanço!$A$1:$P$110,16,0) -> 1185272503 | F4: =+VLOOKUP(F$3,Bilanço!$A$1:$P$110,16,0) -> 1796442970 | H4: =+VLOOKUP(H$3,Bilanço!$A$1:$P$110,16,0) -> 3276261394 | I4: =+VLOOKUP(I$3,'Gelir Tablosu (Dönemsel)'!$A:$R,16,0) -> 898069650 | J4: =+VLOOKUP(J$3,'Gelir Tablosu (Dönemsel)'!$A:$R,16,0)*(-1) -> 27251268 | K4: =+VLOOKUP(K$3,'Gelir Tablosu (Dönemsel)'!$A:$R,16,0)*(-1) -> 0 | L4: =+VLOOKUP(L$3,'Gelir Tablosu (Dönemsel)'!$A:$R,16,0)*(-1) -> 0 | M4: =+VLOOKUP(M$3,'Gelir Tablosu (Dönemsel)'!$A:$R,16,0) -> 99009701 | N4: =+VLOOKUP(N$3,'Gelir Tablosu (Dönemsel)'!$A:$R,16,0) -> 915768394 | O4: =+VLOOKUP(O$3,'Gelir Tablosu (Dönemsel)'!$A:$R,16,0) -> 1988694905
B5: 2022/9 | C5: =+VLOOKUP(C$3,Bilanço!$A$1:$P$110,15,0) -> 1536055433 | D5: =+VLOOKUP(D$3,Bilanço!$A$1:$P$110,15,0) -> 5424734984 | E5: =+VLOOKUP(E$3,Bilanço!$A$1:$P$110,15,0) -> 1111099276 | F5: =+VLOOKUP(F$3,Bilanço!$A$1:$P$110,15,0) -> 1887522547 | H5: =+VLOOKUP(H$3,Bilanço!$A$1:$P$110,15,0) -> 3962168594 | I5: =+VLOOKUP(I$3,'Gelir Tablosu (Dönemsel)'!$A:$R,15,0) -> 1280819916 | J5: =+VLOOKUP(J$3,'Gelir Tablosu (Dönemsel)'!$A:$R,15,0)*(-1) -> 35583045 | K5: =+VLOOKUP(K$3,'Gelir Tablosu (Dönemsel)'!$A:$R,15,0)*(-1) -> 0 | L5: =+VLOOKUP(L$3,'Gelir Tablosu (Dönemsel)'!$A:$R,15,0)*(-1) -> 0 | M5: =+VLOOKUP(M$3,'Gelir Tablosu (Dönemsel)'!$A:$R,15,0) -> 148735912 | N5: =+VLOOKUP(N$3,'Gelir Tablosu (Dönemsel)'!$A:$R,15,0) -> 1669264404 | O5: =+VLOOKUP(O$3,'Gelir Tablosu (Dönemsel)'!$A:$R,15,0) -> 3217285731 | P5: =+I5-I4 -> 382750266 | Q5: =+J5-J4 -> 8331777 | R5: =+K5-K4 -> 0 | S5: =+L5-L4 -> 0 | T5: =+M5-M4 -> 49726211 | U5: =+P5-Q5-R5-S5+T5 -> 424144700 | W5: =+N5-N4 -> 753496010 | Y5: =+O5-O4 -> 1228590826
B6: 2022/12 | C6: =+VLOOKUP(C$3,Bilanço!$A$1:$N$110,14,0) -> 6.7413967e+09 | D6: =+VLOOKUP(D$3,Bilanço!$A$1:$N$110,14,0) -> 2.555408e+10 | E6: =+VLOOKUP(E$3,Bilanço!$A$1:$N$110,14,0) -> 3.8638979e+09 | F6: =+VLOOKUP(F$3,Bilanço!$A$1:$N$110,14,0) -> 6.0883093e+09 | H6: =+VLOOKUP(H$3,Bilanço!$A$1:$N$110,14,0) -> 2.2343269e+10 | I6: =+VLOOKUP(I$3,'Gelir Tablosu (Dönemsel)'!$A:$R,14,0) -> 7.3834023e+09 | J6: =+VLOOKUP(J$3,'Gelir Tablosu (Dönemsel)'!$A:$R,14,0)*(-1) -> 2.3239264e+08 | K6: =+VLOOKUP(K$3,'Gelir Tablosu (Dönemsel)'!$A:$R,14,0)*(-1) -> 0 | L6: =+VLOOKUP(L$3,'Gelir Tablosu (Dönemsel)'!$A:$R,14,0)*(-1) -> 0 | M6: =+VLOOKUP(M$3,'Gelir Tablosu (Dönemsel)'!$A:$R,14,0) -> 9.098003e+08 | N6: =+VLOOKUP(N$3,'Gelir Tablosu (Dönemsel)'!$A:$R,14,0) -> 4.9285987e+09 | O6: =+VLOOKUP(O$3,'Gelir Tablosu (Dönemsel)'!$A:$R,14,0) -> 2.1543002e+10 | P6: =+I6-I5 -> 6.1025824e+09 | Q6: =+J6-J5 -> 1.968096e+08 | R6: =+K6-K5 -> 0 | S6: =+L6-L5 -> 0 | T6: =+M6-M5 -> 7.6106438e+08 | U6: =+P6-Q6-R6-S6+T6 -> 6.6668372e+09 | W6: =+N6-N5 -> 3.2593343e+09 | Y6: =+O6-O5 -> 1.8325716e+10
B7: 2023/3 | C7: =+VLOOKUP(C$3,Bilanço!$A$1:$N$110,13,0) -> 3577129340 | D7: =+VLOOKUP(D$3,Bilanço!$A$1:$N$110,13,0) -> 5635702198 | E7: =+VLOOKUP(E$3,Bilanço!$A$1:$N$110,13,0) -> 2444994629 | F7: =+VLOOKUP(F$3,Bilanço!$A$1:$N$110,13,0) -> 2055937598 | H7: =+VLOOKUP(H$3,Bilanço!$A$1:$N$110,13,0) -> 4711899311 | I7: =+VLOOKUP(I$3,'Gelir Tablosu (Dönemsel)'!$A:$R,13,0) -> 7.1269036e+08 | J7: =+VLOOKUP(J$3,'Gelir Tablosu (Dönemsel)'!$A:$R,13,0)*(-1) -> 1.9419115e+08 | K7: =+VLOOKUP(K$3,'Gelir Tablosu (Dönemsel)'!$A:$R,13,0)*(-1) -> 3660900.8 | L7: =+VLOOKUP(L$3,'Gelir Tablosu (Dönemsel)'!$A:$R,13,0)*(-1) -> 0 | M7: =+VLOOKUP(M$3,'Gelir Tablosu (Dönemsel)'!$A:$R,13,0) -> 87411757 | N7: =+VLOOKUP(N$3,'Gelir Tablosu (Dönemsel)'!$A:$R,13,0) -> 7.4165287e+08 | O7: =+VLOOKUP(O$3,'Gelir Tablosu (Dönemsel)'!$A:$R,13,0) -> 3.4386314e+09 | P7: =+I7 -> 7.1269036e+08 | Q7: =+J7 -> 1.9419115e+08 | R7: =+K7 -> 3660900.8 | S7: =+L7 -> 0 | T7: =+M7 -> 87411757 | U7: =+P7-Q7-R7-S7+T7 -> 6.0225007e+08 | W7: =+N7 -> 7.4165287e+08 | Y7: =+O7 -> 3.4386314e+09
B8: 2023/6 | C8: =+VLOOKUP(C$3,Bilanço!$A$1:$N$110,12,0) -> 3822427951 | D8: =+VLOOKUP(D$3,Bilanço!$A$1:$N$110,12,0) -> 6020645881 | E8: =+VLOOKUP(E$3,Bilanço!$A$1:$N$110,12,0) -> 2927392677 | F8: =+VLOOKUP(F$3,Bilanço!$A$1:$N$110,12,0) -> 2602935680 | H8: =+VLOOKUP(H$3,Bilanço!$A$1:$N$110,12,0) -> 4312745475 | I8: =+VLOOKUP(I$3,'Gelir Tablosu (Dönemsel)'!$A:$R,12,0) -> 1.2299606e+09 | J8: =+VLOOKUP(J$3,'Gelir Tablosu (Dönemsel)'!$A:$R,12,0)*(-1) -> 2.904767e+08 | K8: =+VLOOKUP(K$3,'Gelir Tablosu (Dönemsel)'!$A:$R,12,0)*(-1) -> 16330442 | L8: =+VLOOKUP(L$3,'Gelir Tablosu (Dönemsel)'!$A:$R,12,0)*(-1) -> 0 | M8: =+VLOOKUP(M$3,'Gelir Tablosu (Dönemsel)'!$A:$R,12,0) -> 4.8460653e+08 | N8: =+VLOOKUP(N$3,'Gelir Tablosu (Dönemsel)'!$A:$R,12,0) -> 8.5958901e+08 | O8: =+VLOOKUP(O$3,'Gelir Tablosu (Dönemsel)'!$A:$R,12,0) -> 6.0087895e+09 | P8: =+I8-I7 -> 5.1727025e+08 | Q8: =+J8-J7 -> 96285551 | R8: =+K8-K7 -> 12669541 | S8: =+L8-L7 -> 0 | T8: =+M8-M7 -> 3.9719478e+08 | U8: =+P8-Q8-R8-S8+T8 -> 8.0550993e+08 | V8: =+SUM(U5:U8) -> 8.4987419e+09 | W8: =+N8-N7 -> 1.1793613e+08 | X8: =+SUM(W5:W8) -> 4.8724193e+09 | Y8: =+O8-O7 -> 2.5701581e+09 | Z8: =+SUM(Y5:Y8) -> 2.5563097e+10
B9: 2023/9 | C9: =+VLOOKUP(C$3,Bilanço!$A$1:$N$110,11,0) -> 4123927185 | D9: =+VLOOKUP(D$3,Bilanço!$A$1:$N$110,11,0) -> 6144718013 | E9: =+VLOOKUP(E$3,Bilanço!$A$1:$N$110,11,0) -> 2149524884 | F9: =+VLOOKUP(F$3,Bilanço!$A$1:$N$110,11,0) -> 198176948 | H9: =+VLOOKUP(H$3,Bilanço!$A$1:$N$110,11,0) -> 7920943366 | I9: =+VLOOKUP(I$3,'Gelir Tablosu (Dönemsel)'!$A:$R,11,0) -> 1.8859258e+09 | J9: =+VLOOKUP(J$3,'Gelir Tablosu (Dönemsel)'!$A:$R,11,0)*(-1) -> 5.7721822e+08 | K9: =+VLOOKUP(K$3,'Gelir Tablosu (Dönemsel)'!$A:$R,11,0)*(-1) -> 54144637 | L9: =+VLOOKUP(L$3,'Gelir Tablosu (Dönemsel)'!$A:$R,11,0)*(-1) -> 0 | M9: =+VLOOKUP(M$3,'Gelir Tablosu (Dönemsel)'!$A:$R,11,0) -> 9.8143826e+08 | N9: =+VLOOKUP(N$3,'Gelir Tablosu (Dönemsel)'!$A:$R,11,0) -> 1.619689e+09 | O9: =+VLOOKUP(O$3,'Gelir Tablosu (Dönemsel)'!$A:$R,11,0) -> 8.6171527e+09 | P9: =+I9-I8 -> 6.5596516e+08 | Q9: =+J9-J8 -> 2.8674152e+08 | R9: =+K9-K8 -> 37814194 | S9: =+L9-L8 -> 0 | T9: =+M9-M8 -> 4.9683173e+08 | U9: =+P9-Q9-R9-S9+T9 -> 8.2824117e+08 | V9: =+SUM(U6:U9) -> 8.9028384e+09 | W9: =+N9-N8 -> 7.6010003e+08 | X9: =+SUM(W6:W9) -> 4.8790233e+09 | Y9: =+O9-O8 -> 2.6083632e+09 | Z9: =+SUM(Y6:Y9) -> 2.6942869e+10
B10: 2023/12 | C10: =+VLOOKUP(C$3,Bilanço!$A$1:$N$110,10,0) -> 8.0157217e+09 | D10: =+VLOOKUP(D$3,Bilanço!$A$1:$N$110,10,0) -> 2.5553471e+10 | E10: =+VLOOKUP(E$3,Bilanço!$A$1:$N$110,10,0) -> 1.5436441e+09 | F10: =+VLOOKUP(F$3,Bilanço!$A$1:$N$110,10,0) -> 2.2360882e+08 | H10: =+VLOOKUP(H$3,Bilanço!$A$1:$N$110,10,0) -> 3.180194e+10 | I10: =+VLOOKUP(I$3,'Gelir Tablosu (Dönemsel)'!$A:$R,10,0) -> 1.8339108e+09 | J10: =+VLOOKUP(J$3,'Gelir Tablosu (Dönemsel)'!$A:$R,10,0)*(-1) -> 2.1113636e+08 | K10: =+VLOOKUP(K$3,'Gelir Tablosu (Dönemsel)'!$A:$R,10,0)*(-1) -> 1.3824506e+08 | L10: =+VLOOKUP(L$3,'Gelir Tablosu (Dönemsel)'!$A:$R,10,0)*(-1) -> 0 | M10: =+VLOOKUP(M$3,'Gelir Tablosu (Dönemsel)'!$A:$R,10,0) -> 1.5075778e+09 | N10: =+VLOOKUP(N$3,'Gelir Tablosu (Dönemsel)'!$A:$R,10,0) -> 8.4429213e+08 | O10: =+VLOOKUP(O$3,'Gelir Tablosu (Dönemsel)'!$A:$R,10,0) -> 1.1019319e+10 | P10: =+I10-I9 -> -52015003 | Q10: =+J10-J9 -> -3.6608186e+08 | R10: =+K10-K9 -> 84100427 | S10: =+L10-L9 -> 0 | T10: =+M10-M9 -> 5.2613957e+08 | U10: =+P10-Q10-R10-S10+T10 -> 7.5610599e+08 | V10: =+SUM(U7:U10) -> 2.9921072e+09 | W10: =+N10-N9 -> -7.753969e+08 | X10: =+SUM(W7:W10) -> 8.4429213e+08 | Y10: =+O10-O9 -> 2.4021661e+09 | Z10: =+SUM(Y7:Y10) -> 1.1019319e+10
B11: 2024/3 | C11: =+VLOOKUP(C$3,Bilanço!$A$1:$N$110,9,0) -> 7.9904012e+09 | D11: =+VLOOKUP(D$3,Bilanço!$A$1:$N$110,9,0) -> 2.4446086e+10 | E11: =+VLOOKUP(E$3,Bilanço!$A$1:$N$110,9,0) -> 1.2888592e+09 | F11: =+VLOOKUP(F$3,Bilanço!$A$1:$N$110,9,0) -> 1.1690042e+08 | H11: =+VLOOKUP(H$3,Bilanço!$A$1:$N$110,9,0) -> 3.1030728e+10 | I11: =+VLOOKUP(I$3,'Gelir Tablosu (Dönemsel)'!$A:$R,9,0) -> 3.5904219e+08 | J11: =+VLOOKUP(J$3,'Gelir Tablosu (Dönemsel)'!$A:$R,9,0)*(-1) -> 1.7067395e+08 | K11: =+VLOOKUP(K$3,'Gelir Tablosu (Dönemsel)'!$A:$R,9,0)*(-1) -> 42470788 | L11: =+VLOOKUP(L$3,'Gelir Tablosu (Dönemsel)'!$A:$R,9,0)*(-1) -> 0 | M11: =+VLOOKUP(M$3,'Gelir Tablosu (Dönemsel)'!$A:$R,9,0) -> 6.5436743e+08 | N11: =+VLOOKUP(N$3,'Gelir Tablosu (Dönemsel)'!$A:$R,9,0) -> -8.730419e+08 | O11: =+VLOOKUP(O$3,'Gelir Tablosu (Dönemsel)'!$A:$R,9,0) -> 2.058052e+09 | P11: =+I11 -> 3.5904219e+08 | Q11: =+J11 -> 1.7067395e+08 | R11: =+K11 -> 42470788 | S11: =+L11 -> 0 | T11: =+M11 -> 6.5436743e+08 | U11: =+P11-Q11-R11-S11+T11 -> 8.0026487e+08 | V11: =+SUM(U8:U11) -> 3.190122e+09 | W11: =+N11 -> -8.730419e+08 | X11: =+SUM(W8:W11) -> -7.7040265e+08 | Y11: =+O11 -> 2.058052e+09 | Z11: =+SUM(Y8:Y11) -> 9.6387394e+09
B12: 2024/6 | C12: =+VLOOKUP(C$3,Bilanço!$A$1:$N$110,8,0) -> 8.3320614e+09 | D12: =+VLOOKUP(D$3,Bilanço!$A$1:$N$110,8,0) -> 2.6579593e+10 | E12: =+VLOOKUP(E$3,Bilanço!$A$1:$N$110,8,0) -> 4.1495553e+09 | F12: =+VLOOKUP(F$3,Bilanço!$A$1:$N$110,8,0) -> 1.0263405e+08 | H12: =+VLOOKUP(H$3,Bilanço!$A$1:$N$110,8,0) -> 3.0659465e+10 | I12: =+VLOOKUP(I$3,'Gelir Tablosu (Dönemsel)'!$A:$R,8,0) -> 5.2443142e+08 | J12: =+VLOOKUP(J$3,'Gelir Tablosu (Dönemsel)'!$A:$R,8,0)*(-1) -> 4.0776767e+08 | K12: =+VLOOKUP(K$3,'Gelir Tablosu (Dönemsel)'!$A:$R,8,0)*(-1) -> 50564035 | L12: =+VLOOKUP(L$3,'Gelir Tablosu (Dönemsel)'!$A:$R,8,0)*(-1) -> 0 | M12: =+VLOOKUP(M$3,'Gelir Tablosu (Dönemsel)'!$A:$R,8,0) -> 1.1078266e+09 | N12: =+VLOOKUP(N$3,'Gelir Tablosu (Dönemsel)'!$A:$R,8,0) -> -1.1338215e+09 | O12: =+VLOOKUP(O$3,'Gelir Tablosu (Dönemsel)'!$A:$R,8,0) -> 3.4242551e+09 | P12: =+I12-I11 -> 1.6538923e+08 | Q12: =+J12-J11 -> 2.3709372e+08 | R12: =+K12-K11 -> 8093246.4 | S12: =+L12-L11 -> 0 | T12: =+M12-M11 -> 4.5345918e+08 | U12: =+P12-Q12-R12-S12+T12 -> 3.7366145e+08 | V12: =+SUM(U9:U12) -> 2.7582735e+09 | W12: =+N12-N11 -> -2.6077963e+08 | X12: =+SUM(W9:W12) -> -1.1491184e+09 | Y12: =+O12-O11 -> 1.3662031e+09 | Z12: =+SUM(Y9:Y12) -> 8.4347844e+09
B13: 2024/9 | C13: =+VLOOKUP(C$3,Bilanço!$A$1:$N$110,7,0) -> 7.2331321e+09 | D13: =+VLOOKUP(D$3,Bilanço!$A$1:$N$110,7,0) -> 2.6532141e+10 | E13: =+VLOOKUP(E$3,Bilanço!$A$1:$N$110,7,0) -> 4.0393625e+09 | F13: =+VLOOKUP(F$3,Bilanço!$A$1:$N$110,7,0) -> 1.5757731e+08 | H13: =+VLOOKUP(H$3,Bilanço!$A$1:$N$110,7,0) -> 2.9568333e+10 | I13: =+VLOOKUP(I$3,'Gelir Tablosu (Dönemsel)'!$A:$R,7,0) -> 1.4318831e+09 | J13: =+VLOOKUP(J$3,'Gelir Tablosu (Dönemsel)'!$A:$R,7,0)*(-1) -> 6.4623899e+08 | K13: =+VLOOKUP(K$3,'Gelir Tablosu (Dönemsel)'!$A:$R,7,0)*(-1) -> 86850692 | L13: =+VLOOKUP(L$3,'Gelir Tablosu (Dönemsel)'!$A:$R,7,0)*(-1) -> 0 | M13: =+VLOOKUP(M$3,'Gelir Tablosu (Dönemsel)'!$A:$R,7,0) -> 1.5754072e+09 | N13: =+VLOOKUP(N$3,'Gelir Tablosu (Dönemsel)'!$A:$R,7,0) -> -1.2029682e+09 | O13: =+VLOOKUP(O$3,'Gelir Tablosu (Dönemsel)'!$A:$R,7,0) -> 5.7929999e+09 | P13: =+I13-I12 -> 9.0745169e+08 | Q13: =+J13-J12 -> 2.3847132e+08 | R13: =+K13-K12 -> 36286657 | S13: =+L13-L12 -> 0 | T13: =+M13-M12 -> 4.6758059e+08 | U13: =+P13-Q13-R13-S13+T13 -> 1.1002743e+09 | V13: =+SUM(U10:U13) -> 3.0303066e+09 | W13: =+N13-N12 -> -69146634 | X13: =+SUM(W10:W13) -> -1.9783651e+09 | Y13: =+O13-O12 -> 2.3687448e+09 | Z13: =+SUM(Y10:Y13) -> 8.1951661e+09
B14: 2024/12 | C14: =+VLOOKUP(C$3,Bilanço!$A$1:$N$110,6,0) -> 6991364688 | D14: =+VLOOKUP(D$3,Bilanço!$A$1:$N$110,6,0) -> 26819209735 | E14: =+VLOOKUP(E$3,Bilanço!$A$1:$N$110,6,0) -> 4181599888 | F14: =+VLOOKUP(F$3,Bilanço!$A$1:$N$110,6,0) -> 120316414 | H14: =+VLOOKUP(H$3,Bilanço!$A$1:$N$110,6,0) -> 29508658121 | I14: =+VLOOKUP(I$3,'Gelir Tablosu (Dönemsel)'!$A:$R,6,0) -> 1320023576 | J14: =+VLOOKUP(J$3,'Gelir Tablosu (Dönemsel)'!$A:$R,6,0)*(-1) -> 208471637 | K14: =+VLOOKUP(K$3,'Gelir Tablosu (Dönemsel)'!$A:$R,6,0)*(-1) -> 122916073 | L14: =+VLOOKUP(L$3,'Gelir Tablosu (Dönemsel)'!$A:$R,6,0)*(-1) -> 707204 | M14: =+VLOOKUP(M$3,'Gelir Tablosu (Dönemsel)'!$A:$R,6,0) -> 1967312850 | N14: =+VLOOKUP(N$3,'Gelir Tablosu (Dönemsel)'!$A:$R,6,0) -> -1613206473 | O14: =+VLOOKUP(O$3,'Gelir Tablosu (Dönemsel)'!$A:$R,6,0) -> 7989409873 | P14: =+I14-I13 -> -1.1185953e+08 | Q14: =+J14-J13 -> -4.3776735e+08 | R14: =+K14-K13 -> 36065381 | S14: =+L14-L13 -> 707204 | T14: =+M14-M13 -> 3.9190566e+08 | U14: =+P14-Q14-R14-S14+T14 -> 6.8104089e+08 | V14: =+SUM(U11:U14) -> 2955241512 | W14: =+N14-N13 -> -4.1023831e+08 | X14: =+SUM(W11:W14) -> -1613206473 | Y14: =+O14-O13 -> 2.1964099e+09 | Z14: =+SUM(Y11:Y14) -> 7989409873
B15: 2025/3 | C15: =+VLOOKUP(C$3,Bilanço!$A$1:$N$110,5,0) -> 8.5366325e+09 | D15: =+VLOOKUP(D$3,Bilanço!$A$1:$N$110,5,0) -> 2.7567605e+10 | E15: =+VLOOKUP(E$3,Bilanço!$A$1:$N$110,5,0) -> 2.2965352e+09 | F15: =+VLOOKUP(F$3,Bilanço!$A$1:$N$110,5,0) -> 2.5789071e+09 | H15: =+VLOOKUP(H$3,Bilanço!$A$1:$N$110,5,0) -> 3.1228796e+10 | I15: =+VLOOKUP(I$3,'Gelir Tablosu (Dönemsel)'!$A:$R,5,0) -> 52858508 | J15: =+VLOOKUP(J$3,'Gelir Tablosu (Dönemsel)'!$A:$R,5,0)*(-1) -> 61811489 | K15: =+VLOOKUP(K$3,'Gelir Tablosu (Dönemsel)'!$A:$R,5,0)*(-1) -> 3338284.8 | L15: =+VLOOKUP(L$3,'Gelir Tablosu (Dönemsel)'!$A:$R,5,0)*(-1) -> 0 | M15: =+VLOOKUP(M$3,'Gelir Tablosu (Dönemsel)'!$A:$R,5,0) -> 6.4712551e+08 | N15: =+VLOOKUP(N$3,'Gelir Tablosu (Dönemsel)'!$A:$R,5,0) -> -3.5174859e+08 | O15: =+VLOOKUP(O$3,'Gelir Tablosu (Dönemsel)'!$A:$R,5,0) -> 1.1612108e+09 | P15: =+I15 -> 52858508 | Q15: =+J15 -> 61811489 | R15: =+K15 -> 3338284.8 | S15: =+L15 -> 0 | T15: =+M15 -> 6.4712551e+08 | U15: =+P15-Q15-R15-S15+T15 -> 6.3483424e+08 | V15: =+SUM(U12:U15) -> 2.7898109e+09 | W15: =+N15 -> -3.5174859e+08 | X15: =+SUM(W12:W15) -> -1.0919132e+09 | Y15: =+O15 -> 1.1612108e+09 | Z15: =+SUM(Y12:Y15) -> 7.0925687e+09
B16: 2025/6 | C16: =+VLOOKUP(C$3,Bilanço!$A$1:$N$110,4,0) -> 7.1421284e+09 | D16: =+VLOOKUP(D$3,Bilanço!$A$1:$N$110,4,0) -> 2.7434415e+10 | E16: =+VLOOKUP(E$3,Bilanço!$A$1:$N$110,4,0) -> 2.55308e+09 | F16: =+VLOOKUP(F$3,Bilanço!$A$1:$N$110,4,0) -> 2.5736652e+09 | H16: =+VLOOKUP(H$3,Bilanço!$A$1:$N$110,4,0) -> 2.9449798e+10 | I16: =+VLOOKUP(I$3,'Gelir Tablosu (Dönemsel)'!$A:$R,4,0) -> 1.7807736e+08 | J16: =+VLOOKUP(J$3,'Gelir Tablosu (Dönemsel)'!$A:$R,4,0)*(-1) -> 1.2481204e+08 | K16: =+VLOOKUP(K$3,'Gelir Tablosu (Dönemsel)'!$A:$R,4,0)*(-1) -> 8822702.8 | L16: =+VLOOKUP(L$3,'Gelir Tablosu (Dönemsel)'!$A:$R,4,0)*(-1) -> 0 | M16: =+VLOOKUP(M$3,'Gelir Tablosu (Dönemsel)'!$A:$R,4,0) -> 1.090657e+09 | N16: =+VLOOKUP(N$3,'Gelir Tablosu (Dönemsel)'!$A:$R,4,0) -> -2.1046352e+09 | O16: =+VLOOKUP(O$3,'Gelir Tablosu (Dönemsel)'!$A:$R,4,0) -> 2.862495e+09 | P16: =+I16-I15 -> 1.2521885e+08 | Q16: =+J16-J15 -> 63000548 | R16: =+K16-K15 -> 5484418.1 | S16: =+L16-L15 -> 0 | T16: =+M16-M15 -> 4.4353145e+08 | U16: =+P16-Q16-R16-S16+T16 -> 5.0026533e+08 | V16: =+SUM(U13:U16) -> 2.9164148e+09 | W16: =+N16-N15 -> -1.7528866e+09 | X16: =+SUM(W13:W16) -> -2.5840201e+09 | Y16: =+O16-O15 -> 1.7012843e+09 | Z16: =+SUM(Y13:Y16) -> 7.4276498e+09
B17: 2025/9 | C17: =+VLOOKUP(C$3,Bilanço!$A$1:$N$110,3,0) -> 5.0840876e+09 | D17: =+VLOOKUP(D$3,Bilanço!$A$1:$N$110,3,0) -> 2.6811134e+10 | E17: =+VLOOKUP(E$3,Bilanço!$A$1:$N$110,3,0) -> 1.7458715e+09 | F17: =+VLOOKUP(F$3,Bilanço!$A$1:$N$110,3,0) -> 2.5168768e+09 | H17: =+VLOOKUP(H$3,Bilanço!$A$1:$N$110,3,0) -> 2.7632473e+10 | I17: =+VLOOKUP(I$3,'Gelir Tablosu (Dönemsel)'!$A:$R,3,0) -> 3.4258261e+08 | J17: =+VLOOKUP(J$3,'Gelir Tablosu (Dönemsel)'!$A:$R,3,0)*(-1) -> 1.6741673e+08 | K17: =+VLOOKUP(K$3,'Gelir Tablosu (Dönemsel)'!$A:$R,3,0)*(-1) -> 12685460 | L17: =+VLOOKUP(L$3,'Gelir Tablosu (Dönemsel)'!$A:$R,3,0)*(-1) -> 0 | M17: =+VLOOKUP(M$3,'Gelir Tablosu (Dönemsel)'!$A:$R,3,0) -> 1.5951017e+09 | N17: =+VLOOKUP(N$3,'Gelir Tablosu (Dönemsel)'!$A:$R,3,0) -> -3.1251221e+09 | O17: =+VLOOKUP(O$3,'Gelir Tablosu (Dönemsel)'!$A:$R,3,0) -> 4.7638092e+09 | P17: =+I17-I16 -> 1.6450525e+08 | Q17: =+J17-J16 -> 42604693 | R17: =+K17-K16 -> 3862756.9 | S17: =+L17-L16 -> 0 | T17: =+M17-M16 -> 5.044448e+08 | U17: =+P17-Q17-R17-S17+T17 -> 6.2248259e+08 | V17: =+SUM(U14:U17) -> 2.4386231e+09 | W17: =+N17-N16 -> -1.0204869e+09 | X17: =+SUM(W14:W17) -> -3.5353604e+09 | Y17: =+O17-O16 -> 1.9013142e+09 | Z17: =+SUM(Y14:Y17) -> 6.9602191e+09
B18: 2025/12 | C18: =+VLOOKUP(C$3,Bilanço!$A$1:$N$110,2,0) -> 4631084706 | D18: =+VLOOKUP(D$3,Bilanço!$A$1:$N$110,2,0) -> 26297371946 | E18: =+VLOOKUP(E$3,Bilanço!$A$1:$N$110,2,0) -> 2084481187 | F18: =+VLOOKUP(F$3,Bilanço!$A$1:$N$110,2,0) -> 77456863 | H18: =+VLOOKUP(H$3,Bilanço!$A$1:$N$110,2,0) -> 28766518602 | I18: =+VLOOKUP(I$3,'Gelir Tablosu (Dönemsel)'!$A:$R,2,0) -> 386320551 | J18: =+VLOOKUP(J$3,'Gelir Tablosu (Dönemsel)'!$A:$R,2,0)*(-1) -> 231245015 | K18: =+VLOOKUP(K$3,'Gelir Tablosu (Dönemsel)'!$A:$R,2,0)*(-1) -> 14343462 | L18: =+VLOOKUP(L$3,'Gelir Tablosu (Dönemsel)'!$A:$R,2,0)*(-1) -> 0 | M18: =+VLOOKUP(M$3,'Gelir Tablosu (Dönemsel)'!$A:$R,2,0) -> 2026180373 | N18: =+VLOOKUP(N$3,'Gelir Tablosu (Dönemsel)'!$A:$R,2,0) -> -1000876001 | O18: =+VLOOKUP(O$3,'Gelir Tablosu (Dönemsel)'!$A:$R,2,0) -> 6160091890 | P18: =+I18-I17 -> 43737945 | Q18: =+J18-J17 -> 63828285 | R18: =+K18-K17 -> 1658002.3 | S18: =+L18-L17 -> 0 | T18: =+M18-M17 -> 4.3107862e+08 | U18: =+P18-Q18-R18-S18+T18 -> 4.0933028e+08 | V18: =+SUM(U15:U18) -> 2166912447 | W18: =+N18-N17 -> 2.1242461e+09 | X18: =+SUM(W15:W18) -> -1000876001 | Y18: =+O18-O17 -> 1.3962827e+09 | Z18: =+SUM(Y15:Y18) -> 6160091890
B22: FAVÖK (Yıllıklandırılmış) (Mln TL) | C22: NET BORÇ | D22: NET KAR YILLIK | E22: NET SATIŞLAR | F22: Özkaynak Karlılığı
A23: 2023/06 | B23: =+V8 -> 8.4987419e+09 | C23: =+D43+E43-B43-C43 -> 3019954272 | D23: =+X8 -> 4.8724193e+09 | E23: =+Z8 -> 2.5563097e+10 | F23: =+D23/((İcmal!H8+İcmal!H4)/2) -> 1.284073
A24: 2023/09 | B24: =+V9 -> 8.9028384e+09 | C24: =+D44+E44-B44-C44 -> -171894816 | D24: =+X9 -> 4.8790233e+09 | E24: =+Z9 -> 2.6942869e+10 | F24: =+D24/((İcmal!H9+İcmal!H5)/2) -> 0.82116929
A25: 2023/12 | B25: =+V10 -> 2.9921072e+09 | C25: =+D45+E45-B45-C45 -> -1.8639349e+08 | D25: =+X10 -> 8.4429213e+08 | E25: =+Z10 -> 1.1019319e+10 | F25: =+D25/((İcmal!H10+İcmal!H6)/2) -> 0.031186217
A26: 2024/03 | B26: =+V11 -> 3.190122e+09 | C26: =+D46+E46-B46-C46 -> -2.8603549e+08 | D26: =+X11 -> -7.7040265e+08 | E26: =+Z11 -> 9.6387394e+09 | F26: =+D26/((İcmal!H11+İcmal!H7)/2) -> -0.04310834
A27: 2024/06 | B27: =+V12 -> 2.7582735e+09 | C27: =+D47+E47-B47-C47 -> 17885795 | D27: =+X12 -> -1.1491184e+09 | E27: =+Z12 -> 8.4347844e+09 | F27: =+D27/((İcmal!H12+İcmal!H8)/2) -> -0.065716087
A28: 2024/09 | B28: =+V13 -> 3.0303066e+09 | C28: =+D48+E48-B48-C48 -> 9929848.6 | D28: =+X13 -> -1.9783651e+09 | E28: =+Z13 -> 8.1951661e+09 | F28: =+D28/((İcmal!H13+İcmal!H9)/2) -> -0.10554298
A29: 2024/12 | B29: =+V14 -> 2955241512 | C29: =+D49+E49-B49-C49 -> -102295721 | D29: =+X14 -> -1613206473 | E29: =+Z14 -> 7989409873 | F29: =+D29/((İcmal!H14+İcmal!H10)/2) -> -0.052624066
A30: 2025/03 | B30: =+V15 -> 2.7898109e+09 | C30: =+D50+E50-B50-C50 -> 5.1548065e+08 | D30: =+X15 -> -1.0919132e+09 | E30: =+Z15 -> 7.0925687e+09 | F30: =+D30/((İcmal!H15+İcmal!H11)/2) -> -0.035076181
A31: 2025/06 | B31: =+V16 -> 2.9164148e+09 | C31: =+D51+E51-B51-C51 -> 5.7248051e+08 | D31: =+X16 -> -2.5840201e+09 | E31: =+Z16 -> 7.4276498e+09 | F31: =+D31/((İcmal!H16+İcmal!H12)/2) -> -0.085977435
A32: 2025/09 | B32: =+V17 -> 2.4386231e+09 | C32: =+D52+E52-B52-C52 -> -2.5715395e+08 | D32: =+X17 -> -3.5353604e+09 | E32: =+Z17 -> 6.9602191e+09 | F32: =+D32/((İcmal!H17+İcmal!H13)/2) -> -0.12361226
A33: 2025/12 | B33: =+V18 -> 2166912447 | C33: =+D53+E53-B53-C53 -> 167895716 | D33: =+X18 -> -1000876001 | E33: =+Z18 -> 6160091890 | F33: =+D33/((İcmal!H18+İcmal!H14)/2) -> -0.034349995
K35: 147
K36: 134.6
K37: =+K35-K36 -> 12.4
B38: Nakit ve Nakit Benzerleri | C38: Finansal Yatırımlar | D38: Finansal Borçlar | E38: Finansal Borçlar
A39: 2021/6 | B39: =+VLOOKUP(B$38,Bilanço!$A$1:$P$110,16,0) -> 606911088 | C39: =+VLOOKUP(C$38,Bilanço!$A$1:$P$110,16,0) -> 0 | D39: =+VLOOKUP(D$38,Bilanço!$A$1:$P$110,16,0) -> 434886189 | E39: =+SUMIFS(Bilanço!P$2:P$144,Bilanço!A$2:A$144,İcmal!$E$38)-D39 -> 1772780053
A40: 2022/9 | B40: =+VLOOKUP(B$38,Bilanço!$A$1:$P$110,15,0) -> 641360719 | C40: =+VLOOKUP(C$38,Bilanço!$A$1:$P$110,15,0) -> 0 | D40: =+VLOOKUP(D$38,Bilanço!$A$1:$P$110,15,0) -> 465549230 | E40: =+SUMIFS(Bilanço!O$2:O$144,Bilanço!A$2:A$144,İcmal!$E$38)-D40 -> 1876779365
A41: 2022/12 | B41: =+VLOOKUP(B$38,Bilanço!$A$1:$N$110,14,0) -> 6.5221151e+08 | C41: =+VLOOKUP(C$38,Bilanço!$A$1:$N$110,14,0) -> 0 | D41: =+VLOOKUP(D$38,Bilanço!$A$1:$N$110,14,0) -> 9.1759213e+08 | E41: =+SUMIFS(Bilanço!N$2:N$144,Bilanço!A$2:A$144,İcmal!$E$38)-D41 -> 6.0155348e+09
A42: 2023/3 | B42: =+VLOOKUP(B$38,Bilanço!$A$1:$N$110,13,0) -> 112515995 | C42: =+VLOOKUP(C$38,Bilanço!$A$1:$N$110,13,0) -> 0 | D42: =+VLOOKUP(D$38,Bilanço!$A$1:$N$110,13,0) -> 310012661 | E42: =+SUMIFS(Bilanço!M$2:M$144,Bilanço!A$2:A$144,İcmal!$E$38)-D42 -> 2043582845
A43: 2023/6 | B43: =+VLOOKUP(B$38,Bilanço!$A$1:$N$110,12,0) -> 34721476 | C43: =+VLOOKUP(C$38,Bilanço!$A$1:$N$110,12,0) -> 0 | D43: =+VLOOKUP(D$38,Bilanço!$A$1:$N$110,12,0) -> 555689600 | E43: =+SUMIFS(Bilanço!L$2:L$144,Bilanço!A$2:A$144,İcmal!$E$38)-D43 -> 2498986148
A44: 2023/9 | B44: =+VLOOKUP(B$38,Bilanço!$A$1:$N$110,11,0) -> 312197369 | C44: =+VLOOKUP(C$38,Bilanço!$A$1:$N$110,11,0) -> 0 | D44: =+VLOOKUP(D$38,Bilanço!$A$1:$N$110,11,0) -> 53264928 | E44: =+SUMIFS(Bilanço!K$2:K$144,Bilanço!A$2:A$144,İcmal!$E$38)-D44 -> 87037625
A45: 2023/12 | B45: =+VLOOKUP(B$38,Bilanço!$A$1:$N$110,10,0) -> 2.1203439e+08 | C45: =+VLOOKUP(C$38,Bilanço!$A$1:$N$110,10,0) -> 0 | D45: =+VLOOKUP(D$38,Bilanço!$A$1:$N$110,10,0) -> 21563396 | E45: =+SUMIFS(Bilanço!J$2:J$144,Bilanço!A$2:A$144,İcmal!$E$38)-D45 -> 4077501.5
A46: 2024/3 | B46: =+VLOOKUP(B$38,Bilanço!$A$1:$N$110,9,0) -> 3.1625297e+08 | C46: =+VLOOKUP(C$38,Bilanço!$A$1:$N$110,9,0) -> 0 | D46: =+VLOOKUP(D$38,Bilanço!$A$1:$N$110,9,0) -> 28718583 | E46: =+SUMIFS(Bilanço!I$2:I$144,Bilanço!A$2:A$144,İcmal!$E$38)-D46 -> 1498890.6
...

Sheet Bilanço
A1: Kalem | B1: 2025/12 | C1: 2025/9 | D1: 2025/6 | E1: 2025/3 | F1: 2024/12 | G1: 2024/9 | H1: 2024/6 | I1: 2024/3 | J1: 2023/12 | K1: 2023/9 | L1: 2023/6 | M1: 2023/3 | N1: 2022/12 | O1: 2022/9 | P1: 2022/6 | Q1: 2022/3 | R1: 2021/12 | S1: 2021/9 | T1: 2021/6 | U1: 2021/3 | V1: 2020/12 | W1: 2019/12 | X1: 2018/12 | Y1: 2017/12
A2: Dönen Varlıklar
A3: Nakit ve Nakit Benzerleri | B3: 509357799 | C3: 6.7486017e+08 | D3: 1.7502301e+08 | E3: 21684213 | F3: 205988794 | G3: 69675128 | H3: 54576001 | I3: 3.1625297e+08 | J3: 2.1203439e+08 | K3: 312197369 | L3: 34721476 | M3: 112515995 | N3: 6.5221151e+08 | O3: 641360719 | P3: 606911088 | Q3: 251781236 | R3: 23552721 | S3: 38435497 | T3: 11137736 | U3: 1304897 | V3: 1203171 | W3: 2968335 | X3: 1107559 | Y3: 5945169
A4: Gayrimenkul Projeleri Kapsamında Açılan Nakit Hesapları
A5: Finansal Yatırımlar | B5: 0 | C5: 0 | D5: 0 | E5: 0 | H5: 0 | I5: 0 | N5: 0
A6: Teminata Verilen Finansal Varlıklar
A7: Ticari Alacaklar | B7: 1247553023 | C7: 7.8459238e+08 | D7: 2.2473457e+09 | E7: 2.5969341e+09 | F7: 2443157646 | G7: 3.7827428e+09 | H7: 4.0841507e+09 | I7: 3.5884193e+09 | J7: 4.2030279e+09 | K7: 2376946213 | L7: 2522628775 | M7: 2642149968 | N7: 2.8489547e+09 | O7: 307259938 | P7: 224408539 | Q7: 138913825 | R7: 155198509 | S7: 114160586 | T7: 122381495 | U7: 103064264 | V7: 118131072 | W7: 70816425 | X7: 23785433 | Y7: 4543342
A8: Finans Sektörü Faaliyetlerinden Alacaklar | H8: 0 | I8: 0 | N8: 0
A9: Türkiye Cumhuriyet Merkez Bankası Hesabı
A10: Diğer Alacaklar | B10: 299067995 | C10: 2.4524156e+08 | D10: 1.4110811e+09 | E10: 1.3026736e+09 | F10: 1324715927 | G10: 3.1109896e+08 | H10: 4.5793848e+08 | I10: 45364269 | J10: 24627896 | K10: 12601443 | L10: 67540169 | M10: 63196138 | N10: 39205877 | O10: 12946543 | P10: 12924044 | Q10: 12228011 | R10: 3333243 | S10: 3487702 | T10: 3225311 | U10: 3941130 | V10: 24657091 | W10: 155509567 | X10: 55407807 | Y10: 7982111
A11: Müşteri Sözleşmelerinden Doğan Varlıklar | H11: 0 | I11: 0 | N11: 0
A12: İmtiyaz Sözleşmelerine İlişkin Finansal Varlıklar
A13: Türev Araçlar | H13: 0 | I13: 0 | K13: 0 | L13: 0 | M13: 0 | O13: 0 | P13: 0 | Q13: 1274039 | R13: 0
A14: Stoklar | B14: 2307675971 | C14: 2.5046462e+09 | D14: 2.5899614e+09 | E14: 4.0704889e+09 | F14: 2104598052 | G14: 2.0885528e+09 | H14: 2.7723874e+09 | I14: 2.9723671e+09 | J14: 2.3875347e+09 | K14: 882953339 | L14: 747778442 | M14: 640732718 | N14: 1.8554687e+09 | O14: 417099461 | P14: 323412184 | Q14: 272173921 | R14: 222076764 | S14: 193013321 | T14: 175055784 | U14: 155053193 | V14: 127864319 | W14: 85036278 | X14: 46020949
A15: Proje Halindeki Stoklar
A16: Canlı Varlıklar
A17: Peşin Ödenmiş Giderler | B17: 94751108 | C17: 1.7938175e+08 | D17: 77103981 | E17: 70605210 | F17: 86943407 | G17: 1.9609488e+08 | H17: 2.3243169e+08 | I17: 2.6713229e+08 | J17: 3.2096927e+08 | K17: 104298828 | L17: 46205099 | M17: 46045964 | N17: 1.5987425e+08 | O17: 4674286 | P17: 13034451 | Q17: 55262227 | R17: 15182551 | S17: 9792674 | T17: 17792484 | U17: 16917422 | V17: 13970747 | W17: 16044542 | X17: 3535148 | Y17: 457850
A18: Ertelenmiş Sigortacılık Üretim Giderleri
A19: Cari Dönem Vergisiyle İlgili Varlıklar | B19: 5357724 | C19: 4750489.8 | D19: 1421785.9 | E19: 659424.59 | F19: 1032974 | G19: 3390230.2 | H19: 357351.8 | I19: 279610.74 | J19: 10873476 | K19: 5431268 | L19: 5155900 | M19: 88721 | N19: 10178858 | O19: 266195 | P19: 228443 | Q19: 47349 | R19: 0 | S19: 38426 | T19: 12333 | U19: 179 | V19: 0
A20: Nakit Dışı Serbest Kullanılabilir Teminatlar
A21: Diğer Dönen Varlıklar | B21: 167321086 | C21: 6.9061511e+08 | D21: 6.4019139e+08 | E21: 4.7358706e+08 | F21: 824927888 | G21: 7.8157733e+08 | H21: 7.3021983e+08 | I21: 8.0058571e+08 | J21: 8.5665404e+08 | K21: 429498725 | L21: 398398090 | M21: 72399836 | N21: 1.1755029e+09 | O21: 152448291 | P21: 83492419 | Q21: 368758154 | R21: 122166556 | S21: 100426112 | T21: 53794838 | U21: 52189887 | V21: 35165872 | W21: 119283806 | X21: 99121655 | Y21: 47842810
A22: Satış Amacıyla Elde Tutulan Duran Varlıklar
A23: Ortaklara Dağıtılmak Üzere Elde Tutulan Duran Varlıklar
A24: Toplam Dönen Varlıklar | B24: 4631084706 | C24: 5.0840876e+09 | D24: 7.1421284e+09 | E24: 8.5366325e+09 | F24: 6991364688 | G24: 7.2331321e+09 | H24: 8.3320614e+09 | I24: 7.9904012e+09 | J24: 8.0157217e+09 | K24: 4123927185 | L24: 3822427951 | M24: 3577129340 | N24: 6.7413967e+09 | O24: 1536055433 | P24: 1264411168 | Q24: 1100438762 | R24: 541510344 | S24: 459354318 | T24: 383399981 | U24: 332470972 | V24: 320992272 | W24: 449658953 | X24: 228978551 | Y24: 66771282
A25: Duran Varlıklar
A26: Finansal Yatırımlar | H26: 0 | I26: 0 | N26: 0
A27: İştirakler, İş Ortaklıkları ve Bağlı Ortaklıklardaki Yatırımlar
A28: Ticari Alacaklar | B28: 1808822744 | C28: 1.8296992e+09 | D28: 1.8926483e+09 | E28: 1.9108603e+09 | F28: 1656476847 | G28: 1.7024936e+09 | H28: 1.7884518e+09 | I28: 0 | J28: 0 | N28: 0
A29: Finans Sektörü Faaliyetlerinden Alacaklar | H29: 0 | I29: 0 | N29: 0
A30: Diğer Alacaklar | B30: 205412 | C30: 214358.15 | D30: 230444.41 | E30: 244286.56 | F30: 268632 | G30: 285476.2 | H30: 310937.85 | I30: 337071.82 | J30: 387847.06 | K30: 209963 | L30: 209963 | M30: 209963 | N30: 653803.42 | O30: 210605 | P30: 209744 | Q30: 209745 | R30: 209743 | S30: 209744 | T30: 209744 | U30: 209744 | V30: 209740 | W30: 33214 | X30: 32829 | Y30: 37180
A31: Müşteri Sözleşmelerinden Doğan Varlıklar | H31: 0 | I31: 0 | N31: 0
A32: İmtiyaz Sözleşmelerine İlişkin Finansal Varlıklar
A33: Türev Araçlar | H33: 0 | I33: 0 | N33: 0
A34: Stoklar
A35: Özkaynak Yöntemiyle Değerlenen Yatırımlar
A36: Canlı Varlıklar
A37: Yatırım Amaçlı Gayrimenkuller
A38: Proje Halindeki Yatırım Amaçlı Gayrimenkuller
A39: Maddi Duran Varlıklar | B39: 22464184164 | C39: 2.3686076e+10 | D39: 2.4048366e+10 | E39: 2.4226922e+10 | F39: 22557785948 | G39: 2.2111331e+10 | H39: 2.2157117e+10 | I39: 2.222478e+10 | J39: 2.2419052e+10 | K39: 4972443008 | L39: 4993264664 | M39: 4941354200 | N39: 2.2652934e+10 | O39: 4902272152 | P39: 4899420780 | Q39: 4909848800 | R39: 4921667543 | S39: 2161934168 | T39: 2151162353 | U39: 2160353543 | V39: 2173562940 | W39: 2147845716 | X39: 2212911598 | Y39: 797302037
A40: Kullanım Hakkı Varlıkları | B40: 7899902 | C40: 11286733 | D40: 12133733 | E40: 20972335 | F40: 13907448 | G40: 14840420 | H40: 16807186 | I40: 28498491 | J40: 22597818 | K40: 7994066 | L40: 8170750 | M40: 1497428 | N40: 5334516.1 | O40: 2027247 | P40: 2443100 | Q40: 2866826 | R40: 3290763 | S40: 3465886 | T40: 3767694 | U40: 4110559 | V40: 4491134 | W40: 1881031
...

Sheet Gelir Tablosu (Dönemsel)
A1: Kalem | B1: 2025/12 | C1: 2025/9 | D1: 2025/6 | E1: 2025/3 | F1: 2024/12 | G1: 2024/9 | H1: 2024/6 | I1: 2024/3 | J1: 2023/12 | K1: 2023/9 | L1: 2023/6 | M1: 2023/3 | N1: 2022/12 | O1: 2022/9 | P1: 2022/6 | Q1: 2022/3 | R1: 2021/12 | S1: 2021/9 | T1: 2021/6 | U1: 2021/3 | V1: 2020/12 | W1: 2020/9 | X1: 2020/6 | Y1: 2020/3 | Z1: 2019/12 | AA1: 2018/12 | AB1: 2017/12
A3: Satış Gelirleri | B3: 6160091890 | C3: 4.7638092e+09 | D3: 2.862495e+09 | E3: 1.1612108e+09 | F3: 7989409873 | G3: 5.7929999e+09 | H3: 3.4242551e+09 | I3: 2.058052e+09 | J3: 1.1019319e+10 | K3: 8.6171527e+09 | L3: 6.0087895e+09 | M3: 3.4386314e+09 | N3: 2.1543002e+10 | O3: 3217285731 | P3: 1988694905 | Q3: 907059213 | R3: 1192936521 | S3: 826376117 | T3: 500782637 | U3: 237729655 | V3: 739549313 | W3: 516129703 | X3: 366381237 | Y3: 151643506 | Z3: 741955505 | AA3: 234157733
A4: Toplam Hasılat
A5: Yurt İçi Satışlar | J5: 1.0369173e+10 | K5: 4.8627962e+09 | L5: 3.264052e+09 | M5: 1.8584027e+09 | N5: 2.1543002e+10 | O5: 3227930337 | P5: 1997872806 | Q5: 907059213 | R5: 1192936521
A6: Yurt Dışı Satışlar
A7: Satışların Maliyeti (-) | B7: -5773771339 | C7: -4.4212266e+09 | D7: -2.6844177e+09 | E7: -1.1083522e+09 | F7: -6669386297 | G7: -4.3611168e+09 | H7: -2.8998237e+09 | I7: -1.6990098e+09 | J7: -9.1854081e+09 | K7: -6.7312269e+09 | L7: -4.7788289e+09 | M7: -2.725941e+09 | N7: -1.41596e+10 | O7: -1936465815 | P7: -1090625255 | Q7: -399744400 | R7: -865358998 | S7: -614773542 | T7: -376118586 | U7: -186097006 | V7: -527296553 | W7: -363539389 | X7: -249027985 | Y7: -119619822 | Z7: -575342199 | AA7: -216495769
A8: Ticari Faaliyetlerden Brüt Kar (Zarar) | B8: 386320551 | C8: 3.4258261e+08 | D8: 1.7807736e+08 | E8: 52858508 | F8: 1320023576 | G8: 1.4318831e+09 | H8: 5.2443142e+08 | I8: 3.5904219e+08 | J8: 1.8339108e+09 | K8: 1.8859258e+09 | L8: 1.2299606e+09 | M8: 7.1269036e+08 | N8: 7.3834023e+09 | O8: 1280819916 | P8: 898069650 | Q8: 507314813 | R8: 327577523 | S8: 211602575 | T8: 124664051 | U8: 51632649 | V8: 212252760 | W8: 152590314 | X8: 117353252 | Y8: 32023684 | Z8: 166613306 | AA8: 17661964
A9: Faiz, Ücret, Prim, Komisyon ve Diğer Gelirler
A10: Faiz, Ücret, Prim, Komisyon ve Diğer Giderler (-)
A11: Finans Sektörü Faaliyetlerinden Brüt Kar (Zarar)
A12: Canlı Varlıklar Gerçeğe Uygun Değer Farkları
A13: Brüt Kar (Zarar) | B13: 386320551 | C13: 3.4258261e+08 | D13: 1.7807736e+08 | E13: 52858508 | F13: 1320023576 | G13: 1.4318831e+09 | H13: 5.2443142e+08 | I13: 3.5904219e+08 | J13: 1.8339108e+09 | K13: 1.8859258e+09 | L13: 1.2299606e+09 | M13: 7.1269036e+08 | N13: 7.3834023e+09 | O13: 1280819916 | P13: 898069650 | Q13: 507314813 | R13: 327577523 | S13: 211602575 | T13: 124664051 | U13: 51632649 | V13: 212252760 | W13: 152590314 | X13: 117353252 | Y13: 32023684 | Z13: 166613306 | AA13: 17661964
A15: Genel Yönetim Giderleri (-) | B15: -231245015 | C15: -1.6741673e+08 | D15: -1.2481204e+08 | E15: -61811489 | F15: -208471637 | G15: -6.4623899e+08 | H15: -4.0776767e+08 | I15: -1.7067395e+08 | J15: -2.1113636e+08 | K15: -5.7721822e+08 | L15: -2.904767e+08 | M15: -1.9419115e+08 | N15: -2.3239264e+08 | O15: -35583045 | P15: -27251268 | Q15: -14208451 | R15: -25637218 | S15: -18449237 | T15: -13695822 | U15: -4593501 | V15: -21305394 | W15: -16299420 | X15: -11189193 | Y15: -5103602 | Z15: -14883051 | AA15: -5564511 | AB15: -2221294
A16: Pazarlama, Satış ve Dağıtım Giderleri (-) | B16: -14343462 | C16: -12685460 | D16: -8822702.8 | E16: -3338284.8 | F16: -122916073 | G16: -86850692 | H16: -50564035 | I16: -42470788 | J16: -1.3824506e+08 | K16: -54144637 | L16: -16330442 | M16: -3660900.8 | N16: 0 | T16: 0 | U16: 0 | V16: -7404935 | W16: -4159163 | X16: -219547 | Y16: -70035 | Z16: -1669771 | AA16: -2992659
A17: Araştırma ve Geliştirme Giderleri (-) | B17: 0 | C17: 0 | D17: 0 | F17: -707204 | G17: 0 | H17: 0 | J17: 0
A18: Diğer Faaliyet Gelirleri | B18: 123366579 | C18: 1.1273968e+08 | D18: 1.5545136e+08 | E18: 63454396 | F18: 198455027 | G18: 1.1026821e+08 | H18: 96774005 | I18: 61128892 | J18: 2.4981171e+08 | K18: 2.1257279e+08 | L18: 1.3026501e+08 | M18: 20243595 | N18: 1.6326225e+08 | O18: 32562838 | P18: 21700207 | Q18: 3836630 | R18: 32960780 | S18: 27583064 | T18: 16010927 | U18: 10263812 | V18: 43848261 | W18: 26831395 | X18: 23227699 | Y18: 18119933 | Z18: 21264586 | AA18: 16579191 | AB18: 1937960
A19: Diğer Faaliyet Giderleri (-) | B19: -1116889722 | C19: -6.5852114e+08 | D19: -4.8255292e+08 | E19: -2.9514728e+08 | F19: -631360447 | G19: -4.3152729e+08 | H19: -3.3523909e+08 | I19: -59737427 | J19: -5.9186425e+08 | K19: -3.6032806e+08 | L19: -91591610 | M19: -39507881 | N19: -3.5242296e+08 | O19: -54775229 | P19: -24465842 | Q19: -13237026 | R19: -83984436 | S19: -57419009 | T19: -12706338 | U19: -7483812 | V19: -22533024 | W19: -27521318 | X19: -35896177 | Y19: -32868312 | Z19: -80883234 | AA19: -5617404 | AB19: -4923054
A20: Diğer Kazançlar (Kayıplar)
A21: Faaliyet Karı (Zararı) | B21: -852791069 | C21: -3.8330104e+08 | D21: -2.8265894e+08 | E21: -2.4398415e+08 | F21: 555023242 | G21: 3.7753435e+08 | H21: -1.7236537e+08 | I21: 1.4728891e+08 | J21: 1.1424768e+09 | K21: 1.1068076e+09 | L21: 9.6182686e+08 | M21: 4.9557403e+08 | N21: 6.961849e+09 | O21: 1223024480 | P21: 868052747 | Q21: 483705966 | R21: 250916649 | S21: 163317393 | T21: 114272818 | U21: 49819148 | V21: 204857668 | W21: 131441808 | X21: 93276034 | Y21: 12101668 | Z21: 90441836 | AA21: 20066581 | AB21: -5206388
A23: Ödenecek Kar Paylarının Defter Değeri ile Dağıtılan Nakit Dışı Varlıkların Değeri Arasındaki Fark
A24: İtfa Edilmiş Maliyetinden Ölçülen Finansal Varlıkların Finansal Tablo Dışı Bırakılmasından Kaynaklanan Kazançlar (Kayıplar)
A25: Yatırım Faaliyetlerinden Gelirler | B25: 35080377 | C25: 28334847 | D25: 23726534 | E25: 0 | F25: 1388738 | G25: 1299488.7 | H25: 1353733.6 | I25: 0 | J25: 5164674.9 | K25: 5425938.2 | L25: 4852668.9 | M25: 1288760.9 | N25: 1.1462234e+08 | O25: 26315520 | P25: 0 | Q25: 0 | R25: 124648 | S25: 124647 | T25: 124647 | U25: 150071 | V25: 389456 | W25: 389456 | X25: 51695 | Y25: 51695 | AB25: 12549
A26: Yatırım Faaliyetlerinden Giderler (-) | B26: -16180 | C26: 0 | D26: 0 | F26: -86030990 | G26: -94508197 | H26: -1.0942919e+08 | I26: 0 | J26: -2052398.3 | K26: -2237678.8 | L26: -2509522.7 | M26: 0 | N26: -6646.4525 | O26: -133367 | P26: -133366 | Q26: -133366 | R26: 0 | S26: 0 | T26: 0 | U26: 0 | V26: 0 | W26: 0 | X26: 0 | AA26: -3358 | AB26: -1137
A27: TFRS 9 Uyarınca Belirlenen Değer Düşüklüğü Kazançları (Zararları) ve Değer Düşüklüğü Zararlarının İptalleri
A28: Özkaynak Yöntemiyle Değerlenen Yatırımların Karlarından (Zararlarından) Paylar
A29: İştirakler, Müşterek Kontrol Edilen İşletmeler ve Bağlı Ortaklıklardan Diğer Gelirler (Giderler)
A30: İtfa Edilmiş Maliyetinden Ölçülen Finansal Varlıkların Gerçeğe Uygun Değer Farkı Kar veya Zarara Yansıtılan Olarak Sınıflandırılmasından Kazançlar (Kayıplar)
A31: Gerçeğe Uygun Değer Farkı Diğer Kapsamlı Gelire Yansıtılan Finansal Varlıkların Gerçeğe Uygun Değer Farkı Kar veya Zarara Yansıtılan Olarak Sınıflandırılmasından Kazançlar (Kayıplar)
A32: Risk Pozisyonlarını Netleştiren Kalemler Grubuna Yönelik Finansal Riskten Korunma Kazançları (Kayıpları)
A33: Finansman Geliri (Gideri) Öncesi Faaliyet Karı (Zararı) | B33: -817726872 | C33: -3.5496619e+08 | D33: -2.589324e+08 | E33: -2.4398415e+08 | F33: 470380990 | G33: 2.8432564e+08 | H33: -2.8044083e+08 | I33: 1.4728891e+08 | J33: 1.1455891e+09 | K33: 1.1099959e+09 | L33: 9.6417001e+08 | M33: 4.9686279e+08 | N33: 7.0764647e+09 | O33: 1249206633 | P33: 867919381 | Q33: 483572600 | R33: 251041297 | S33: 163442040 | T33: 114397465 | U33: 49969219 | V33: 205247124 | W33: 131831264 | X33: 93327729 | Y33: 12153363 | Z33: 90441836 | AA33: 20063223 | AB33: -5194976
A35: (Esas Faaliyet Dışı) Finansal Gelirler | B35: 2248978879 | C35: 1.0358777e+08 | D35: 41158227 | E35: 24651622 | F35: 224541353 | G35: 2.1830805e+08 | H35: 1.230338e+08 | I35: 16288502 | J35: 2.1191645e+09 | K35: 1.6367199e+09 | L35: 9.2278862e+08 | M35: 7.7833902e+08 | N35: 1.4979981e+09 | O35: 339770225 | P35: 260898303 | Q35: 75480959 | R35: 132480998 | S35: 119284154 | T35: 48085072 | U35: 30204146 | V35: 346899862 | W35: 236980573 | X35: 52726528 | Y35: 49937233 | Z35: 188042288 | AA35: 224238640 | AB35: 24268752
A36: (Esas Faaliyet Dışı) Finansal Giderler (-) | B36: -1359610899 | C36: -1.3248778e+09 | D36: -1.0109547e+09 | E36: -7.5419152e+08 | F36: -1414069338 | G36: -9.4598677e+08 | H36: -7.0085457e+08 | I36: -2.2695049e+08 | J36: -1.729152e+09 | K36: -1.2002373e+09 | L36: -8.7413543e+08 | M36: -6.479609e+08 | N36: -4.1089199e+09 | O36: -441059484 | P36: -306783367 | Q36: -103238485 | R36: -656608597 | S36: -433209696 | T36: -340263643 | U36: -252239162 | V36: -702076801 | W36: -591039969 | X36: -304672112 | Y36: -174963204 | Z36: -435365238 | AA36: -298706313 | AB36: -52005276
A37: Net Parasal Pozisyon Kazançları (Kayıpları) | B37: -1121069651 | C37: -7.4073117e+08 | D37: -1.1915335e+08 | E37: 1.5375066e+09 | F37: -923608227 | G37: -6.7452703e+08 | H37: -5.0313963e+08 | I37: -3.3985385e+08 | J37: -1.7331972e+09 | K37: -4.6431101e+08 | L37: -4.3667165e+08 | M37: -63021634 | N37: -1.2201233e+09
A38: Sürdürülen Faaliyetler Vergi Öncesi Karı (Zararı) | B38: -1049428543 | C38: -2.3169874e+09 | D38: -1.3478822e+09 | E38: 5.6398254e+08 | F38: -1642755222 | G38: -1.1178801e+09 | H38: -1.3614012e+09 | I38: -4.0322693e+08 | J38: -1.975956e+08 | K38: 1.0821675e+09 | L38: 5.7615156e+08 | M38: 5.6421927e+08 | N38: 3.2454195e+09 | O38: 1147917374 | P38: 822034317 | Q38: 455815074 | R38: -273086302 | S38: -150483502 | T38: -177781106 | U38: -172065797 | V38: -149929815 | W38: -222228132 | X38: -158617855 | Y38: -112872608 | Z38: -156881114 | AA38: -54404450 | AB38: -32931500
A40: Sürdürülen Faaliyetler Vergi Geliri (Gideri) | B40: 48552542 | C40: -8.0813474e+08 | D40: -7.5675299e+08 | E40: -9.1573113e+08 | F40: 29548749 | G40: -85088062 | H40: 2.275797e+08 | I40: -4.6981497e+08 | J40: 1.0418877e+09 | K40: 5.3752156e+08 | L40: 2.8343745e+08 | M40: 1.7743361e+08 | N40: 1.6831792e+09 | O40: 521347030 | P40: 93734077 | Q40: -42067178 | R40: 92123295 | S40: 28153079 | T40: 790069 | U40: 11457669 | V40: 187282520 | W40: -37386063 | X40: -439001 | Y40: -1331812 | Z40: 8992544 | AA40: -28147365 | AB40: 142830069
A41: Dönem Vergi Geliri (Gideri) | B41: 0 | C41: 0 | D41: 0 | F41: 0 | G41: 0 | H41: 0 | I41: -3550553.8 | J41: -265216.65 | K41: -31970.575 | N41: -1.1315672e+08 | O41: -2201004 | P41: 0 | Q41: 0 | R41: 0 | S41: 0 | AA41: -956468
A42: Ertelenmiş Vergi Geliri (Gideri) | B42: 48552542 | C42: -8.0813474e+08 | D42: -7.5675299e+08 | E42: -9.1573113e+08 | F42: 29548749 | G42: -85088062 | H42: 2.275797e+08 | I42: -4.6626442e+08 | J42: 1.0421529e+09 | K42: 5.3755353e+08 | L42: 2.8343745e+08 | M42: 1.9031068e+08 | N42: 1.7963359e+09 | O42: 523548034 | P42: 93734077 | Q42: -42067178 | R42: 92123295 | S42: 28153079 | T42: 790069 | U42: 11457669 | V42: 187282520 | W42: -37386063 | X42: -439001 | Y42: -1331812 | Z42: 8992544 | AA42: -27190897 | AB42: 142830069
A43: Sürdürülen Faaliyetler Dönem Karı/Zararı | B43: -1000876001 | C43: -3.1251221e+09 | D43: -2.1046352e+09 | E43: -3.5174859e+08 | F43: -1613206473 | G43: -1.2029682e+09 | H43: -1.1338215e+09 | I43: -8.730419e+08 | J43: 8.4429213e+08 | K43: 1.619689e+09 | L43: 8.5958901e+08 | M43: 7.4165287e+08 | N43: 4.9285987e+09 | O43: 1669264404 | P43: 915768394 | Q43: 413747896 | R43: -180963007 | S43: -122330423 | T43: -176991037 | U43: -160608128 | V43: 37352705 | W43: -259614195 | X43: -159056856 | Y43: -114204420 | Z43: -147888570 | AA43: -82551815 | AB43: 109898569
A44: Durdurulan Faaliyetler Dönem Karı/Zararı
A46: Dönem Karı (Zararı) | B46: -1000876001 | C46: -3.1251221e+09 | D46: -2.1046352e+09 | E46: -3.5174859e+08 | F46: -1613206473 | G46: -1.2029682e+09 | H46: -1.1338215e+09 | I46: -8.730419e+08 | J46: 8.4429213e+08 | K46: 1.619689e+09 | L46: 8.5958901e+08 | M46: 7.4165287e+08 | N46: 4.9285987e+09 | O46: 1669264404 | P46: 915768394 | Q46: 413747896 | R46: -180963007 | S46: -122330423 | T46: -176991037 | U46: -160608128 | V46: 37352705 | W46: -259614195 | X46: -159056856 | Y46: -114204420 | Z46: -147888570 | AA46: -82551815 | AB46: 109898569
...

Sheet Sayfa1
F2: ımmobıle
F3: Semih
F4: Mustafa
C6: Rafa | F6: muci | I6: rachia
C7: Arroyo
E9: mario
E10: chamberla | G10: Gedson
F12: Musrati
F13: Amir
F14: Salih
C16: Masuaku | E16: felix | G16: Paulista | I16: svenson
C17: Emrecan | E17: Emirhan | G17: Tayyip | I17: Onur
E18: Necip
F21: Mert
F22: Ersin

Sheet Gelir Tablosu (Çeyreklik)
A1: Kalem | B1: 2025/3 | C1: 2024/12 | D1: 2024/9 | E1: 2024/6 | F1: 2024/3 | G1: 2023/12 | H1: 2023/9 | I1: 2023/6 | J1: 2023/3 | K1: 2022/12 | L1: 2022/9 | M1: 2022/6 | N1: 2022/3 | O1: 2021/12 | P1: 2021/9 | Q1: 2021/6 | R1: 2021/3 | S1: 2020/12 | T1: 2020/9 | U1: 2020/6 | V1: 2020/3 | W1: 2019/12 | X1: 2019/9 | Y1: 2019/6 | Z1: 2019/3 | AA1: 2018/12 | AB1: 2018/9 | AC1: 2018/6 | AD1: 2018/3 | AE1: 2017/12 | AF1: 2017/9 | AG1: 2017/6 | AH1: 2017/3 | AI1: 2016/12 | AJ1: 2016/9 | AK1: 2016/6 | AL1: 2016/3
A3: Satış Gelirleri | B3: 109117642000 | C3: 1.1918733e+11 | D3: 1.2326893e+11 | E3: 1.2941471e+11 | F3: 99801065000 | G3: 9.9749756e+10 | H3: 1.0836545e+11 | I3: 1.0519271e+11 | J3: 9.5248668e+10 | L3: 34254600000 | M3: 32304633000 | N3: 28164395000 | O3: 22518529000 | P3: 18147680000 | Q3: 14534414000 | R3: 12983814000 | S3: 13334671000 | T3: 11938155000 | U3: 7832129000 | V3: 7767528000 | W3: 8366065000 | X3: 8245951000 | Y3: 8427600000 | Z3: 6902157000 | AA3: 7414262000 | AB3: 7696011000 | AC3: 6511893000 | AD3: 5282218000 | AE3: 5705672000 | AF3: 5439610000 | AG3: 5061077000 | AH3: 4634254000 | AI3: 4525929000 | AJ3: 4083238000 | AK3: 3959556000 | AL3: 3527449000
A4: Toplam Hasılat
A5: Yurt İçi Satışlar | C5: 3.2058018e+10 | D5: 3.751848e+10 | E5: 4.7695531e+10 | F5: 3.5575604e+10 | G5: 3.3801114e+10 | H5: 4.1821791e+10 | I5: 4.4060584e+10 | J5: 3.310852e+10 | L5: 10127510000 | M5: 9736626000 | N5: 8378846000
A6: Yurt Dışı Satışlar | C6: 8.7129308e+10 | D6: 8.5750448e+10 | E6: 9.7874107e+10 | F6: 4.8070534e+10 | G6: 6.5948642e+10 | H6: 6.6543661e+10 | I6: 6.8516968e+10 | J6: 5.4755307e+10 | L6: 24127090000 | M6: 22568007000 | N6: 19785549000
A7: Satışların Maliyeti (-) | B7: -77842714000 | C7: -8.718702e+10 | D7: -9.0721905e+10 | E7: -9.3594719e+10 | F7: -70182018000 | G7: -7.1783273e+10 | H7: -7.6625507e+10 | I7: -7.2520403e+10 | J7: -6.7846276e+10 | L7: -24393399000 | M7: -22736217000 | N7: -19477778000 | O7: -16041717000 | P7: -13022200000 | Q7: -10141203000 | R7: -8500972000 | S7: -8531464000 | T7: -7810877000 | U7: -5423959000 | V7: -5299810000 | W7: -5758661000 | X7: -5520482000 | Y7: -5784268000 | Z7: -4663460000 | AA7: -5003928000 | AB7: -5185275000 | AC7: -4537873000 | AD7: -3631546000 | AE7: -3956411000 | AF7: -3714987000 | AG7: -3506684000 | AH7: -3156332000 | AI7: -3094120000 | AJ7: -2722219000 | AK7: -2606889000 | AL7: -2333384000
A8: Ticari Faaliyetlerden Brüt Kar (Zarar) | B8: 31274928000 | C8: 3.2000305e+10 | D8: 3.2547023e+10 | E8: 3.5819993e+10 | F8: 29619047000 | G8: 2.7966483e+10 | H8: 3.1739945e+10 | I8: 3.2672307e+10 | J8: 2.7402392e+10 | L8: 9861201000 | M8: 9568416000 | N8: 8686617000 | O8: 6476812000 | P8: 5125480000 | Q8: 4393211000 | R8: 4482842000 | S8: 4803207000 | T8: 4127278000 | U8: 2408170000 | V8: 2467718000 | W8: 2607404000 | X8: 2725469000 | Y8: 2643332000 | Z8: 2238697000 | AA8: 2410334000 | AB8: 2510736000 | AC8: 1974020000 | AD8: 1650672000 | AE8: 1749261000 | AF8: 1724623000 | AG8: 1554393000 | AH8: 1477922000 | AI8: 1431809000 | AJ8: 1361019000 | AK8: 1352667000 | AL8: 1194065000
A9: Faiz, Ücret, Prim, Komisyon ve Diğer Gelirler | AJ9: 0 | AK9: 0 | AL9: 0
A10: Faiz, Ücret, Prim, Komisyon ve Diğer Giderler (-) | AJ10: 0 | AK10: 0 | AL10: 0
A11: Finans Sektörü Faaliyetlerinden Brüt Kar (Zarar) | AJ11: 0 | AK11: 0 | AL11: 0
A12: Canlı Varlıklar Gerçeğe Uygun Değer Farkları
A13: Brüt Kar (Zarar) | B13: 31274928000 | C13: 3.2000305e+10 | D13: 3.2547023e+10 | E13: 3.5819993e+10 | F13: 29619047000 | G13: 2.7966483e+10 | H13: 3.1739945e+10 | I13: 3.2672307e+10 | J13: 2.7402392e+10 | L13: 9861201000 | M13: 9568416000 | N13: 8686617000 | O13: 6476812000 | P13: 5125480000 | Q13: 4393211000 | R13: 4482842000 | S13: 4803207000 | T13: 4127278000 | U13: 2408170000 | V13: 2467718000 | W13: 2607404000 | X13: 2725469000 | Y13: 2643332000 | Z13: 2238697000 | AA13: 2410334000 | AB13: 2510736000 | AC13: 1974020000 | AD13: 1650672000 | AE13: 1749261000 | AF13: 1724623000 | AG13: 1554393000 | AH13: 1477922000 | AI13: 1431809000 | AJ13: 1361019000 | AK13: 1352667000 | AL13: 1194065000
A15: Genel Yönetim Giderleri (-) | B15: -7544236000 | C15: -7.173808e+09 | D15: -6.8408989e+09 | E15: -7.3298351e+09 | F15: -5929432000 | G15: -5.5351301e+09 | H15: -6.3350632e+09 | I15: -5.5616734e+09 | J15: -6.0537315e+09 | L15: -1286400000 | M15: -1552445000 | N15: -1312152000 | O15: -1058708000 | P15: -796232000 | Q15: -681005000 | R15: -570825000 | S15: -721271000 | T15: -551101000 | U15: -416333000 | V15: -487243000 | W15: -400554000 | X15: -409140000 | Y15: -430451000 | Z15: -354253000 | AA15: -317969000 | AB15: -353604000 | AC15: -278671000 | AD15: -259228000 | AE15: -277616000 | AF15: -231867000 | AG15: -207823000 | AH15: -219273000 | AI15: -223508000 | AJ15: -176328000 | AK15: -173168000 | AL15: -189787000
A16: Pazarlama, Satış ve Dağıtım Giderleri (-) | B16: -21430415000 | C16: -2.299554e+10 | D16: -2.3544919e+10 | E16: -2.6020431e+10 | F16: -18489273000 | G16: -1.9050865e+10 | H16: -1.9538989e+10 | I16: -1.9091621e+10 | J16: -1.7066703e+10 | L16: -6347539000 | M16: -6285679000 | N16: -4929141000 | O16: -4148183000 | P16: -2916239000 | Q16: -2569861000 | R16: -2285710000 | S16: -2413314000 | T16: -2088466000 | U16: -1433104000 | V16: -1534375000 | W16: -1640145000 | X16: -1603703000 | Y16: -1500715000 | Z16: -1379958000 | AA16: -1342139000 | AB16: -1509756000 | AC16: -1262253000 | AD16: -980286000 | AE16: -1140608000 | AF16: -1047777000 | AG16: -948681000 | AH16: -890633000 | AI16: -895499000 | AJ16: -809101000 | AK16: -830625000 | AL16: -692099000
A17: Araştırma ve Geliştirme Giderleri (-) | B17: -1297230000 | C17: -1.2917744e+09 | D17: -1.7597289e+09 | E17: -1.439537e+09 | F17: -845507000 | G17: -7.9116492e+08 | H17: -6.0556272e+08 | I17: -8.0803916e+08 | J17: -8.8408202e+08 | L17: -192720000 | M17: -171056000 | N17: -154577000 | O17: -149232000 | P17: -113079000 | Q17: -94285000 | R17: -87472000 | S17: -88887000 | T17: -84407000 | U17: -72199000 | V17: -72718000 | W17: -70287000 | X17: -64921000 | Y17: -61998000 | Z17: -59545000 | AA17: -63728000 | AB17: -51018000 | AC17: -46571000 | AD17: -43475000 | AE17: -46694000 | AF17: -39978000 | AG17: -42988000 | AH17: -40517000 | AI17: -37864000 | AJ17: -39898000 | AK17: -39134000 | AL17: -34772000
A18: Diğer Faaliyet Gelirleri | B18: 6657341000 | C18: 2.0999924e+10 | D18: 3.8627824e+09 | E18: 2.1361147e+09 | F18: 4553076000 | G18: 5.9672693e+09 | H18: 3.0578547e+09 | I18: 1.0582183e+10 | J18: 1.7452136e+09 | L18: 1188400000 | M18: 1776289000 | N18: 1901218000 | O18: 4128430000 | P18: 296991000 | Q18: 460985000 | R18: 890017000 | S18: -23775000 | T18: 786082000 | U18: 432001000 | V18: 575052000 | W18: 241653000 | X18: 161467000 | Y18: 167282000 | Z18: 348333000 | AA18: -476484000 | AB18: 1133164000 | AC18: 397237000 | AD18: 270898000 | AE18: 286064000 | AF18: 155483000 | AG18: 41598000 | AH18: 228693000 | AI18: 389312000 | AJ18: 129118000 | AK18: 81330000 | AL18: 90307000
A19: Diğer Faaliyet Giderleri (-) | B19: -5155468000 | C19: -1.5402191e+10 | D19: -6.5192923e+09 | E19: -3.0271191e+09 | F19: -5089839000 | G19: -4.3955664e+09 | H19: -5.1766031e+09 | I19: -1.1220934e+10 | J19: -2.8766598e+09 | L19: -1389399000 | M19: -1415510000 | N19: -1470073000 | O19: -2239376000 | P19: -331811000 | Q19: -441878000 | R19: -750728000 | S19: -63043000 | T19: -315269000 | U19: -206297000 | V19: -175410000 | W19: -106577000 | X19: -90618000 | Y19: -153679000 | Z19: -153335000 | AA19: -67721000 | AB19: -345858000 | AC19: -176824000 | AD19: -134154000 | AE19: -141300000 | AF19: -57061000 | AG19: -40838000 | AH19: -132552000 | AI19: -205086000 | AJ19: -27263000 | AK19: -80286000 | AL19: -77138000
A20: Diğer Kazançlar (Kayıplar) | U20: 0 | V20: 0 | AI20: 0 | AJ20: 0 | AK20: 0 | AL20: 0
A21: Faaliyet Karı (Zararı) | B21: 2504920000 | C21: 6.1369162e+09 | D21: -2.2550341e+09 | E21: 1.3918496e+08 | F21: 3818072000 | G21: 4.1610264e+09 | H21: 3.1415812e+09 | I21: 6.572223e+09 | J21: 2.2664289e+09 | L21: 1833543000 | M21: 1920015000 | N21: 2721892000 | O21: 3009743000 | P21: 1265110000 | Q21: 1067167000 | R21: 1678124000 | S21: 1492917000 | T21: 1874117000 | U21: 712238000 | V21: 773024000 | W21: 631494000 | X21: 718554000 | Y21: 663771000 | Z21: 639939000 | AA21: 142293000 | AB21: 1383664000 | AC21: 606938000 | AD21: 504427000 | AE21: 429107000 | AF21: 503423000 | AG21: 355661000 | AH21: 423640000 | AI21: 459164000 | AJ21: 437547000 | AK21: 310784000 | AL21: 290576000
A23: Ödenecek Kar Paylarının Defter Değeri ile Dağıtılan Nakit Dışı Varlıkların Değeri Arasındaki Fark
A24: İtfa Edilmiş Maliyetinden Ölçülen Finansal Varlıkların Finansal Tablo Dışı Bırakılmasından Kaynaklanan Kazançlar (Kayıplar)
A25: Yatırım Faaliyetlerinden Gelirler | B25: 30586000 | C25: 40344524 | D25: 10533869 | E25: 1.2558238e+09 | F25: 35543000 | G25: 25175135 | H25: 15378192 | I25: 10012076 | J25: 30210762 | L25: 13551000 | M25: 36060000 | N25: 4701000 | O25: 311710000 | P25: 1707000 | Q25: 1150000 | R25: 2273000 | S25: 11813000 | T25: 611000 | U25: 227349000 | V25: 895000 | W25: 3720000 | X25: 1622000 | Y25: 924000 | Z25: 550000 | AA25: 5074000 | AB25: 1457000 | AC25: 4277000 | AD25: 2470000 | AE25: 1004000 | AF25: 5071000 | AG25: 1783000 | AH25: 427000 | AI25: 1055000 | AJ25: 1705000 | AK25: 415021000 | AL25: 961000
A26: Yatırım Faaliyetlerinden Giderler (-) | B26: -4896000 | C26: -1.7887659e+08 | D26: -28572156 | E26: -1.2948056e+08 | F26: -35183000 | G26: -84854788 | H26: -13064885 | I26: -13861993 | J26: -51110128 | L26: -6084000 | M26: -2069000 | N26: -21186000 | O26: -6548000 | P26: -266000 | Q26: -169000 | R26: -2596000 | S26: -13816000 | T26: -49218000 | U26: -776000 | V26: -675000 | W26: -1821000 | X26: -4582000 | Y26: -1131000 | Z26: -1022000 | AA26: -2899000 | AB26: -150000 | AC26: -1306000 | AD26: -2440000 | AE26: -2093000 | AF26: -3159000 | AG26: -1847000 | AH26: -248000 | AI26: -1662000 | AJ26: -66000 | AK26: -159000 | AL26: -526000
A27: TFRS 9 Uyarınca Belirlenen Değer Düşüklüğü Kazançları (Zararları) ve Değer Düşüklüğü Zararlarının İptalleri
A28: Özkaynak Yöntemiyle Değerlenen Yatırımların Karlarından (Zararlarından) Paylar | B28: -103304000 | C28: 78058330 | D28: 23826991 | E28: -1.5553183e+08 | F28: -140141000 | G28: -1.3699427e+08 | H28: -3.9246066e+08 | I28: 49427222 | J28: -2.8498556e+08 | L28: -31345000 | M28: -13421000 | N28: -8748000 | O28: -32624000 | P28: 1513000 | Q28: -17946000 | R28: 4543000 | S28: -5464000 | T28: 22032000 | U28: 17122000 | V28: 7536000 | W28: -3347000 | X28: 8016000 | Y28: 1404000 | Z28: 14968000 | AA28: -3255000 | AB28: -18797000 | AC28: 23587000 | AD28: 10691000 | AE28: 1846000 | AF28: 11429000 | AG28: 11949000 | AH28: 13866000 | AI28: 6920000 | AJ28: 8760000 | AK28: 12510000 | AL28: 6667000
A29: İştirakler, Müşterek Kontrol Edilen İşletmeler ve Bağlı Ortaklıklardan Diğer Gelirler (Giderler)
A30: İtfa Edilmiş Maliyetinden Ölçülen Finansal Varlıkların Gerçeğe Uygun Değer Farkı Kar veya Zarara Yansıtılan Olarak Sınıflandırılmasından Kazançlar (Kayıplar)
A31: Gerçeğe Uygun Değer Farkı Diğer Kapsamlı Gelire Yansıtılan Finansal Varlıkların Gerçeğe Uygun Değer Farkı Kar veya Zarara Yansıtılan Olarak Sınıflandırılmasından Kazançlar (Kayıplar)
A32: Risk Pozisyonlarını Netleştiren Kalemler Grubuna Yönelik Finansal Riskten Korunma Kazançları (Kayıpları)
A33: Finansman Geliri (Gideri) Öncesi Faaliyet Karı (Zararı) | B33: 2427306000 | C33: 6.0764425e+09 | D33: -2.2492454e+09 | E33: 1.1099963e+09 | F33: 3678291000 | G33: 3.9643525e+09 | H33: 2.7514338e+09 | I33: 6.6178003e+09 | J33: 1.9605439e+09 | L33: 1809665000 | M33: 1940585000 | N33: 2696659000 | O33: 3282281000 | P33: 1268064000 | Q33: 1050202000 | R33: 1682344000 | S33: 1485450000 | T33: 1847542000 | U33: 955933000 | V33: 780780000 | W33: 630046000 | X33: 723610000 | Y33: 664968000 | Z33: 654435000 | AA33: 141213000 | AB33: 1366174000 | AC33: 633496000 | AD33: 515148000 | AE33: 429864000 | AF33: 516764000 | AG33: 367546000 | AH33: 437685000 | AI33: 465477000 | AJ33: 447946000 | AK33: 738156000 | AL33: 297678000
A35: (Esas Faaliyet Dışı) Finansal Gelirler | B35: 3178527000 | C35: 4.4360745e+09 | D35: 6.7996775e+09 | E35: 4.0808886e+09 | F35: 8952752000 | G35: 7.9116806e+09 | H35: 7.7292876e+09 | I35: 1.5267507e+10 | J35: 4.9946872e+09 | L35: 1749160000 | M35: 2026927000 | N35: 1973364000 | O35: 7902035000 | P35: 851615000 | Q35: 779523000 | R35: 1776185000 | S35: 1144608000 | T35: 1222428000 | U35: 791376000 | V35: 694084000 | W35: 631587000 | X35: 1114988000 | Y35: 648009000 | Z35: 719739000 | AA35: 467643000 | AB35: 1599003000 | AC35: 563946000 | AD35: 334627000 | AE35: 296623000 | AF35: 62450000 | AG35: 208015000 | AH35: 334451000 | AI35: 274772000 | AJ35: 140096000 | AK35: 97431000 | AL35: 157747000
A36: (Esas Faaliyet Dışı) Finansal Giderler (-) | B36: -10901018000 | C36: -1.2111188e+10 | D36: -1.5166984e+10 | E36: -9.4419553e+09 | F36: -15338274000 | G36: -1.3587223e+10 | H36: -1.257321e+10 | I36: -2.0854755e+10 | J36: -8.5200159e+09 | L36: -3327472000 | M36: -3663606000 | N36: -3218575000 | O36: -10209935000 | P36: -1349240000 | Q36: -1246187000 | R36: -2164273000 | S36: -1251326000 | T36: -1784935000 | U36: -1221575000 | V36: -1166460000 | W36: -979445000 | X36: -1569052000 | Y36: -1011373000 | Z36: -1113332000 | AA36: -338560000 | AB36: -2633333000 | AC36: -1007997000 | AD36: -691954000 | AE36: -614177000 | AF36: -320766000 | AG36: -361988000 | AH36: -535570000 | AI36: -631951000 | AJ36: -304769000 | AK36: -179933000 | AL36: -300969000
A37: Net Parasal Pozisyon Kazançları (Kayıpları) | B37: 4342139000 | C37: 7.8062674e+09 | D37: 2.8436362e+09 | E37: 3.9578425e+08 | F37: 6355372000 | G37: 1.179639e+10 | H37: 7.4379741e+09 | I37: 1.8821175e+09 | J37: 3.88106e+09
A38: Sürdürülen Faaliyetler Vergi Öncesi Karı (Zararı) | B38: -953046000 | C38: 6.2075968e+09 | D38: -7.7729156e+09 | E38: -3.8552861e+09 | F38: 3648141000 | G38: 1.00852e+10 | H38: 5.3454853e+09 | I38: 2.9126696e+09 | J38: 2.3162752e+09 | L38: 231353000 | M38: 303906000 | N38: 1451448000 | O38: 974381000 | P38: 770439000 | Q38: 583538000 | R38: 1294256000 | S38: 1378732000 | T38: 1285035000 | U38: 525734000 | V38: 308404000 | W38: 282188000 | X38: 269546000 | Y38: 301604000 | Z38: 260842000 | AA38: 270296000 | AB38: 331844000 | AC38: 189445000 | AD38: 157821000 | AE38: 112310000 | AF38: 258448000 | AG38: 213573000 | AH38: 236566000 | AI38: 108298000 | AJ38: 283273000 | AK38: 655654000 | AL38: 154456000
A40: Sürdürülen Faaliyetler Vergi Geliri (Gideri) | B40: -998533000 | C40: -1.7954874e+09 | D40: 1.2136773e+09 | E40: 9.4981584e+08 | F40: -1024944000 | G40: 6.3613758e+09 | H40: -3.6220914e+09 | I40: -4.3916185e+08 | J40: -3.3451597e+08 | L40: 263546000 | M40: 36143000 | N40: -227086000 | O40: -81537000 | P40: -53621000 | Q40: -42383000 | R40: -194064000 | S40: -208958000 | T40: -243828000 | U40: -117171000 | V40: -48959000 | W40: -40283000 | X40: -16514000 | Y40: -69609000 | Z40: -34748000 | AA40: 10611000 | AB40: -79087000 | AC40: -44855000 | AD40: 19766000 | AE40: -22232000 | AF40: -909000 | AG40: 43374000 | AH40: 4173000 | AI40: 122065000 | AJ40: -19146000 | AK40: -2599000 | AL40: 2149000
A41: Dönem Vergi Geliri (Gideri) | B41: -850654000 | C41: 4.3168733e+08 | D41: -1.3789619e+08 | E41: -3.5095471e+08 | F41: -1494465000 | G41: 3.927451e+08 | H41: -1.2573401e+09 | I41: -9.2191872e+08 | J41: -1.25014e+09 | L41: -413754000 | M41: -195339000 | N41: -352588000 | O41: -227070000 | P41: -159662000 | Q41: -152109000 | R41: -220655000 | S41: -110566000 | T41: -228717000 | U41: -65670000 | V41: -76079000 | W41: -14552000 | X41: -47253000 | Y41: -122017000 | Z41: -60704000 | AA41: -44486000 | AB41: -122949000 | AC41: -50966000 | AD41: -30347000 | AE41: -55035000 | AF41: -36077000 | AG41: -37389000 | AH41: -65533000 | AI41: -17611000 | AJ41: -33489000 | AK41: -29711000 | AL41: -19384000
A42: Ertelenmiş Vergi Geliri (Gideri) | B42: -147879000 | C42: -2.2271747e+09 | D42: 1.3515735e+09 | E42: 1.3007706e+09 | F42: 469521000 | G42: 5.9686307e+09 | H42: -2.3647513e+09 | I42: 4.8275687e+08 | J42: 9.1562407e+08 | L42: 677300000 | M42: 231482000 | N42: 125502000 | O42: 145533000 | P42: 106041000 | Q42: 109726000 | R42: 26591000 | S42: -98392000 | T42: -15111000 | U42: -51501000 | V42: 27120000 | W42: -25731000 | X42: 30739000 | Y42: 52408000 | Z42: 25956000 | AA42: 55097000 | AB42: 43862000 | AC42: 6111000 | AD42: 50113000 | AE42: 32803000 | AF42: 35168000 | AG42: 80763000 | AH42: 69706000 | AI42: 139676000 | AJ42: 14343000 | AK42: 27112000 | AL42: 21533000
A43: Sürdürülen Faaliyetler Dönem Karı/Zararı | B43: -1951579000 | C43: 4.4121094e+09 | D43: -6.5592383e+09 | E43: -2.9054703e+09 | F43: 2623197000 | G43: 1.6446576e+10 | H43: 1.7233938e+09 | I43: 2.4735077e+09 | J43: 1.9817592e+09 | L43: 494899000 | M43: 340049000 | N43: 1224362000 | O43: 892844000 | P43: 716818000 | Q43: 541155000 | R43: 1100192000 | S43: 1169774000 | T43: 1041207000 | U43: 408563000 | V43: 259445000 | W43: 241905000 | X43: 253032000 | Y43: 231995000 | Z43: 226094000 | AA43: 280907000 | AB43: 252757000 | AC43: 144590000 | AD43: 177587000 | AE43: 90078000 | AF43: 257539000 | AG43: 256947000 | AH43: 240739000 | AI43: 230363000 | AJ43: 264127000 | AK43: 653055000 | AL43: 156605000
A44: Durdurulan Faaliyetler Dönem Karı/Zararı
A46: Dönem Karı (Zararı) | B46: -1951579000 | C46: 4.4121094e+09 | D46: -6.5592383e+09 | E46: -2.9054703e+09 | F46: 2623197000 | G46: 1.6446576e+10 | H46: 1.7233938e+09 | I46: 2.4735077e+09 | J46: 1.9817592e+09 | L46: 494899000 | M46: 340049000 | N46: 1224362000 | O46: 892844000 | P46: 716818000 | Q46: 541155000 | R46: 1100192000 | S46: 1169774000 | T46: 1041207000 | U46: 408563000 | V46: 259445000 | W46: 241905000 | X46: 253032000 | Y46: 231995000 | Z46: 226094000 | AA46: 280907000 | AB46: 252757000 | AC46: 144590000 | AD46: 177587000 | AE46: 90078000 | AF46: 257539000 | AG46: 256947000 | AH46: 240739000 | AI46: 230363000 | AJ46: 264127000 | AK46: 653055000 | AL46: 156605000
...

Sheet Gelir Tablosu (Yıllıklan.)
