Workbook

Sheet Portföy
A1: Hisse | B1: Sektör | C1: Adet | D1: Maliyet | E1: Toplam Maliyet | F1: Fiyat | G1: Toplam Tutar | H1: Kar/Zarar
A2: ADEL | B2: İMALAT | C2: =SUMIFS(Tablo1[Adet],Tablo1[Hisse],Portföy!A2,Tablo1[İşlem],"ALIŞ")-SUMIFS(Tablo1[Adet],Tablo1[Hisse],Portföy!A2,Tablo1[İşlem],"SATIŞ") -> 985 | D2: =IFERROR((SUMIFS(Tablo1[Toplam],Tablo1[Hisse],Portföy!A2,Tablo1[İşlem],"ALIŞ")-SUMIFS(Tablo1[Toplam],Tablo1[Hisse],Portföy!A2,Tablo1[İşlem],"SATIŞ"))/C2,0) -> 36.942883 | E2: =+D2*C2 -> 36388.74 | F2: =SUMIFS(Tablo2[Son Fiyat],Tablo2[Şirket],Portföy!A2) -> 32 | G2: =+F2*C2 -> 31520 | H2: =+G2-E2+IF(Portföy!C2=0,SUMIFS(Tablo1[Toplam],Tablo1[Hisse],Portföy!A2,Tablo1[İşlem],"SATIŞ")-SUMIFS(Tablo1[Toplam],Tablo1[Hisse],Portföy!A2,Tablo1[İşlem],"ALIŞ"),0) -> -4868.74
A3: ALARK | B3: HOLDİNG | C3: =SUMIFS(Tablo1[Adet],Tablo1[Hisse],Portföy!A3,Tablo1[İşlem],"ALIŞ")-SUMIFS(Tablo1[Adet],Tablo1[Hisse],Portföy!A3,Tablo1[İşlem],"SATIŞ") -> 0 | D3: =IFERROR((SUMIFS(Tablo1[Toplam],Tablo1[Hisse],Portföy!A3,Tablo1[İşlem],"ALIŞ")-SUMIFS(Tablo1[Toplam],Tablo1[Hisse],Portföy!A3,Tablo1[İşlem],"SATIŞ"))/C3,0) -> 0 | E3: =+D3*C3 -> 0 | F3: =SUMIFS(Tablo2[Son Fiyat],Tablo2[Şirket],Portföy!A3) -> 86.05 | G3: =+F3*C3 -> 0 | H3: =+G3-E3+IF(Portföy!C3=0,SUMIFS(Tablo1[Toplam],Tablo1[Hisse],Portföy!A3,Tablo1[İşlem],"SATIŞ")-SUMIFS(Tablo1[Toplam],Tablo1[Hisse],Portföy!A3,Tablo1[İşlem],"ALIŞ"),0) -> -5017
A4: ALCTL | B4: HABERLEŞME | C4: =SUMIFS(Tablo1[Adet],Tablo1[Hisse],Portföy!A4,Tablo1[İşlem],"ALIŞ")-SUMIFS(Tablo1[Adet],Tablo1[Hisse],Portföy!A4,Tablo1[İşlem],"SATIŞ") -> 0 | D4: =IFERROR((SUMIFS(Tablo1[Toplam],Tablo1[Hisse],Portföy!A4,Tablo1[İşlem],"ALIŞ")-SUMIFS(Tablo1[Toplam],Tablo1[Hisse],Portföy!A4,Tablo1[İşlem],"SATIŞ"))/C4,0) -> 0 | E4: =+D4*C4 -> 0 | F4: =SUMIFS(Tablo2[Son Fiyat],Tablo2[Şirket],Portföy!A4) -> 137.7 | G4: =+F4*C4 -> 0 | H4: =+G4-E4+IF(Portföy!C4=0,SUMIFS(Tablo1[Toplam],Tablo1[Hisse],Portföy!A4,Tablo1[İşlem],"SATIŞ")-SUMIFS(Tablo1[Toplam],Tablo1[Hisse],Portföy!A4,Tablo1[İşlem],"ALIŞ"),0) -> 125
A5: ALMAD | B5: TAŞ TOPRAK MADEN | C5: =SUMIFS(Tablo1[Adet],Tablo1[Hisse],Portföy!A5,Tablo1[İşlem],"ALIŞ")-SUMIFS(Tablo1[Adet],Tablo1[Hisse],Portföy!A5,Tablo1[İşlem],"SATIŞ") -> 0 | D5: =IFERROR((SUMIFS(Tablo1[Toplam],Tablo1[Hisse],Portföy!A5,Tablo1[İşlem],"ALIŞ")-SUMIFS(Tablo1[Toplam],Tablo1[Hisse],Portföy!A5,Tablo1[İşlem],"SATIŞ"))/C5,0) -> 0 | E5: =+D5*C5 -> 0 | F5: =SUMIFS(Tablo2[Son Fiyat],Tablo2[Şirket],Portföy!A5) -> 7.52 | G5: =+F5*C5 -> 0 | H5: =+G5-E5+IF(Portföy!C5=0,SUMIFS(Tablo1[Toplam],Tablo1[Hisse],Portföy!A5,Tablo1[İşlem],"SATIŞ")-SUMIFS(Tablo1[Toplam],Tablo1[Hisse],Portföy!A5,Tablo1[İşlem],"ALIŞ"),0) -> 704.5
A6: ARASE | B6: ENERJİ ÜRETİM DAĞ. | C6: =SUMIFS(Tablo1[Adet],Tablo1[Hisse],Portföy!A6,Tablo1[İşlem],"ALIŞ")-SUMIFS(Tablo1[Adet],Tablo1[Hisse],Portföy!A6,Tablo1[İşlem],"SATIŞ") -> 410 | D6: =IFERROR((SUMIFS(Tablo1[Toplam],Tablo1[Hisse],Portföy!A6,Tablo1[İşlem],"ALIŞ")-SUMIFS(Tablo1[Toplam],Tablo1[Hisse],Portföy!A6,Tablo1[İşlem],"SATIŞ"))/C6,0) -> 58.365244 | E6: =+D6*C6 -> 23929.75 | F6: =SUMIFS(Tablo2[Son Fiyat],Tablo2[Şirket],Portföy!A6) -> 49.72 | G6: =+F6*C6 -> 20385.2 | H6: =+G6-E6+IF(Portföy!C6=0,SUMIFS(Tablo1[Toplam],Tablo1[Hisse],Portföy!A6,Tablo1[İşlem],"SATIŞ")-SUMIFS(Tablo1[Toplam],Tablo1[Hisse],Portföy!A6,Tablo1[İşlem],"ALIŞ"),0) -> -3544.55
A7: ARENA | B7: TEKNOLOJİK ÜRÜN T. | C7: =SUMIFS(Tablo1[Adet],Tablo1[Hisse],Portföy!A7,Tablo1[İşlem],"ALIŞ")-SUMIFS(Tablo1[Adet],Tablo1[Hisse],Portföy!A7,Tablo1[İşlem],"SATIŞ") -> 0 | D7: =IFERROR((SUMIFS(Tablo1[Toplam],Tablo1[Hisse],Portföy!A7,Tablo1[İşlem],"ALIŞ")-SUMIFS(Tablo1[Toplam],Tablo1[Hisse],Portföy!A7,Tablo1[İşlem],"SATIŞ"))/C7,0) -> 0 | E7: =+D7*C7 -> 0 | F7: =SUMIFS(Tablo2[Son Fiyat],Tablo2[Şirket],Portföy!A7) -> 35.94 | G7: =+F7*C7 -> 0 | H7: =+G7-E7+IF(Portföy!C7=0,SUMIFS(Tablo1[Toplam],Tablo1[Hisse],Portföy!A7,Tablo1[İşlem],"SATIŞ")-SUMIFS(Tablo1[Toplam],Tablo1[Hisse],Portföy!A7,Tablo1[İşlem],"ALIŞ"),0) -> -2793.6
A8: ASELS | C8: =SUMIFS(Tablo1[Adet],Tablo1[Hisse],Portföy!A8,Tablo1[İşlem],"ALIŞ")-SUMIFS(Tablo1[Adet],Tablo1[Hisse],Portföy!A8,Tablo1[İşlem],"SATIŞ") -> 2 | D8: =IFERROR((SUMIFS(Tablo1[Toplam],Tablo1[Hisse],Portföy!A8,Tablo1[İşlem],"ALIŞ")-SUMIFS(Tablo1[Toplam],Tablo1[Hisse],Portföy!A8,Tablo1[İşlem],"SATIŞ"))/C8,0) -> 75 | E8: =+D8*C8 -> 150 | F8: =SUMIFS(Tablo2[Son Fiyat],Tablo2[Şirket],Portföy!A8) -> 88.7 | G8: =+F8*C8 -> 177.4 | H8: =+G8-E8+IF(Portföy!C8=0,SUMIFS(Tablo1[Toplam],Tablo1[Hisse],Portföy!A8,Tablo1[İşlem],"SATIŞ")-SUMIFS(Tablo1[Toplam],Tablo1[Hisse],Portföy!A8,Tablo1[İşlem],"ALIŞ"),0) -> 27.4
A9: ASTOR | B9: ENERJİ TEK. | C9: =SUMIFS(Tablo1[Adet],Tablo1[Hisse],Portföy!A9,Tablo1[İşlem],"ALIŞ")-SUMIFS(Tablo1[Adet],Tablo1[Hisse],Portföy!A9,Tablo1[İşlem],"SATIŞ") -> 18 | D9: =IFERROR((SUMIFS(Tablo1[Toplam],Tablo1[Hisse],Portföy!A9,Tablo1[İşlem],"ALIŞ")-SUMIFS(Tablo1[Toplam],Tablo1[Hisse],Portföy!A9,Tablo1[İşlem],"SATIŞ"))/C9,0) -> -9.1166667 | E9: =+D9*C9 -> -164.1 | F9: =SUMIFS(Tablo2[Son Fiyat],Tablo2[Şirket],Portföy!A9) -> 117.6 | G9: =+F9*C9 -> 2116.8 | H9: =+G9-E9+IF(Portföy!C9=0,SUMIFS(Tablo1[Toplam],Tablo1[Hisse],Portföy!A9,Tablo1[İşlem],"SATIŞ")-SUMIFS(Tablo1[Toplam],Tablo1[Hisse],Portföy!A9,Tablo1[İşlem],"ALIŞ"),0) -> 2280.9
A10: BAYRK | B10: TEKSTİL | C10: =SUMIFS(Tablo1[Adet],Tablo1[Hisse],Portföy!A10,Tablo1[İşlem],"ALIŞ")-SUMIFS(Tablo1[Adet],Tablo1[Hisse],Portföy!A10,Tablo1[İşlem],"SATIŞ") -> 720 | D10: =IFERROR((SUMIFS(Tablo1[Toplam],Tablo1[Hisse],Portföy!A10,Tablo1[İşlem],"ALIŞ")-SUMIFS(Tablo1[Toplam],Tablo1[Hisse],Portföy!A10,Tablo1[İşlem],"SATIŞ"))/C10,0) -> 18.861042 | E10: =+D10*C10 -> 13579.95 | F10: =SUMIFS(Tablo2[Son Fiyat],Tablo2[Şirket],Portföy!A10) -> 18.35 | G10: =+F10*C10 -> 13212 | H10: =+G10-E10+IF(Portföy!C10=0,SUMIFS(Tablo1[Toplam],Tablo1[Hisse],Portföy!A10,Tablo1[İşlem],"SATIŞ")-SUMIFS(Tablo1[Toplam],Tablo1[Hisse],Portföy!A10,Tablo1[İşlem],"ALIŞ"),0) -> -367.95
A11: BFREN | B11: OTO YAN SAN. | C11: =SUMIFS(Tablo1[Adet],Tablo1[Hisse],Portföy!A11,Tablo1[İşlem],"ALIŞ")-SUMIFS(Tablo1[Adet],Tablo1[Hisse],Portföy!A11,Tablo1[İşlem],"SATIŞ") -> 4 | D11: =IFERROR((SUMIFS(Tablo1[Toplam],Tablo1[Hisse],Portföy!A11,Tablo1[İşlem],"ALIŞ")-SUMIFS(Tablo1[Toplam],Tablo1[Hisse],Portföy!A11,Tablo1[İşlem],"SATIŞ"))/C11,0) -> 682 | E11: =+D11*C11 -> 2728 | F11: =SUMIFS(Tablo2[Son Fiyat],Tablo2[Şirket],Portföy!A11) -> 640 | G11: =+F11*C11 -> 2560 | H11: =+G11-E11+IF(Portföy!C11=0,SUMIFS(Tablo1[Toplam],Tablo1[Hisse],Portföy!A11,Tablo1[İşlem],"SATIŞ")-SUMIFS(Tablo1[Toplam],Tablo1[Hisse],Portföy!A11,Tablo1[İşlem],"ALIŞ"),0) -> -168
A12: BIMAS | B12: GIDA PARAKENDE | C12: =SUMIFS(Tablo1[Adet],Tablo1[Hisse],Portföy!A12,Tablo1[İşlem],"ALIŞ")-SUMIFS(Tablo1[Adet],Tablo1[Hisse],Portföy!A12,Tablo1[İşlem],"SATIŞ") -> 0 | D12: =IFERROR((SUMIFS(Tablo1[Toplam],Tablo1[Hisse],Portföy!A12,Tablo1[İşlem],"ALIŞ")-SUMIFS(Tablo1[Toplam],Tablo1[Hisse],Portföy!A12,Tablo1[İşlem],"SATIŞ"))/C12,0) -> 0 | E12: =+D12*C12 -> 0 | F12: =SUMIFS(Tablo2[Son Fiyat],Tablo2[Şirket],Portföy!A12) -> 550 | G12: =+F12*C12 -> 0 | H12: =+G12-E12+IF(Portföy!C12=0,SUMIFS(Tablo1[Toplam],Tablo1[Hisse],Portföy!A12,Tablo1[İşlem],"SATIŞ")-SUMIFS(Tablo1[Toplam],Tablo1[Hisse],Portföy!A12,Tablo1[İşlem],"ALIŞ"),0) -> 0
A13: BNTAS | C13: =SUMIFS(Tablo1[Adet],Tablo1[Hisse],Portföy!A13,Tablo1[İşlem],"ALIŞ")-SUMIFS(Tablo1[Adet],Tablo1[Hisse],Portföy!A13,Tablo1[İşlem],"SATIŞ") -> 0 | D13: =IFERROR((SUMIFS(Tablo1[Toplam],Tablo1[Hisse],Portföy!A13,Tablo1[İşlem],"ALIŞ")-SUMIFS(Tablo1[Toplam],Tablo1[Hisse],Portföy!A13,Tablo1[İşlem],"SATIŞ"))/C13,0) -> 0 | E13: =+D13*C13 -> 0 | F13: =SUMIFS(Tablo2[Son Fiyat],Tablo2[Şirket],Portföy!A13) -> 11.02 | G13: =+F13*C13 -> 0 | H13: =+G13-E13+IF(Portföy!C13=0,SUMIFS(Tablo1[Toplam],Tablo1[Hisse],Portföy!A13,Tablo1[İşlem],"SATIŞ")-SUMIFS(Tablo1[Toplam],Tablo1[Hisse],Portföy!A13,Tablo1[İşlem],"ALIŞ"),0) -> -135.5
A14: BRLSM | B14: ENERJİ TEK. | C14: =SUMIFS(Tablo1[Adet],Tablo1[Hisse],Portföy!A14,Tablo1[İşlem],"ALIŞ")-SUMIFS(Tablo1[Adet],Tablo1[Hisse],Portföy!A14,Tablo1[İşlem],"SATIŞ") -> 1900 | D14: =IFERROR((SUMIFS(Tablo1[Toplam],Tablo1[Hisse],Portföy!A14,Tablo1[İşlem],"ALIŞ")-SUMIFS(Tablo1[Toplam],Tablo1[Hisse],Portföy!A14,Tablo1[İşlem],"SATIŞ"))/C14,0) -> 22.264789 | E14: =+D14*C14 -> 42303.1 | F14: =SUMIFS(Tablo2[Son Fiyat],Tablo2[Şirket],Portföy!A14) -> 14.97 | G14: =+F14*C14 -> 28443 | H14: =+G14-E14+IF(Portföy!C14=0,SUMIFS(Tablo1[Toplam],Tablo1[Hisse],Portföy!A14,Tablo1[İşlem],"SATIŞ")-SUMIFS(Tablo1[Toplam],Tablo1[Hisse],Portföy!A14,Tablo1[İşlem],"ALIŞ"),0) -> -13860.1
A15: BRSAN | C15: =SUMIFS(Tablo1[Adet],Tablo1[Hisse],Portföy!A15,Tablo1[İşlem],"ALIŞ")-SUMIFS(Tablo1[Adet],Tablo1[Hisse],Portföy!A15,Tablo1[İşlem],"SATIŞ") -> 0 | D15: =IFERROR((SUMIFS(Tablo1[Toplam],Tablo1[Hisse],Portföy!A15,Tablo1[İşlem],"ALIŞ")-SUMIFS(Tablo1[Toplam],Tablo1[Hisse],Portföy!A15,Tablo1[İşlem],"SATIŞ"))/C15,0) -> 0 | E15: =+D15*C15 -> 0 | F15: =SUMIFS(Tablo2[Son Fiyat],Tablo2[Şirket],Portföy!A15) -> 394.25 | G15: =+F15*C15 -> 0 | H15: =+G15-E15+IF(Portföy!C15=0,SUMIFS(Tablo1[Toplam],Tablo1[Hisse],Portföy!A15,Tablo1[İşlem],"SATIŞ")-SUMIFS(Tablo1[Toplam],Tablo1[Hisse],Portföy!A15,Tablo1[İşlem],"ALIŞ"),0) -> 140
A16: BTCIM | B16: ÇİMENTO | C16: =SUMIFS(Tablo1[Adet],Tablo1[Hisse],Portföy!A16,Tablo1[İşlem],"ALIŞ")-SUMIFS(Tablo1[Adet],Tablo1[Hisse],Portföy!A16,Tablo1[İşlem],"SATIŞ") -> 0 | D16: =IFERROR((SUMIFS(Tablo1[Toplam],Tablo1[Hisse],Portföy!A16,Tablo1[İşlem],"ALIŞ")-SUMIFS(Tablo1[Toplam],Tablo1[Hisse],Portföy!A16,Tablo1[İşlem],"SATIŞ"))/C16,0) -> 0 | E16: =+D16*C16 -> 0 | F16: =SUMIFS(Tablo2[Son Fiyat],Tablo2[Şirket],Portföy!A16) -> 4.37 | G16: =+F16*C16 -> 0 | H16: =+G16-E16+IF(Portföy!C16=0,SUMIFS(Tablo1[Toplam],Tablo1[Hisse],Portföy!A16,Tablo1[İşlem],"SATIŞ")-SUMIFS(Tablo1[Toplam],Tablo1[Hisse],Portföy!A16,Tablo1[İşlem],"ALIŞ"),0) -> 122
A17: BURVA | B17: İMALAT | C17: =SUMIFS(Tablo1[Adet],Tablo1[Hisse],Portföy!A17,Tablo1[İşlem],"ALIŞ")-SUMIFS(Tablo1[Adet],Tablo1[Hisse],Portföy!A17,Tablo1[İşlem],"SATIŞ") -> 15 | D17: =IFERROR((SUMIFS(Tablo1[Toplam],Tablo1[Hisse],Portföy!A17,Tablo1[İşlem],"ALIŞ")-SUMIFS(Tablo1[Toplam],Tablo1[Hisse],Portföy!A17,Tablo1[İşlem],"SATIŞ"))/C17,0) -> 72.046667 | E17: =+D17*C17 -> 1080.7 | F17: =SUMIFS(Tablo2[Son Fiyat],Tablo2[Şirket],Portföy!A17) -> 105.8 | G17: =+F17*C17 -> 1587 | H17: =+G17-E17+IF(Portföy!C17=0,SUMIFS(Tablo1[Toplam],Tablo1[Hisse],Portföy!A17,Tablo1[İşlem],"SATIŞ")-SUMIFS(Tablo1[Toplam],Tablo1[Hisse],Portföy!A17,Tablo1[İşlem],"ALIŞ"),0) -> 506.3
A18: BVSAN | B18: İMALAT | C18: =SUMIFS(Tablo1[Adet],Tablo1[Hisse],Portföy!A18,Tablo1[İşlem],"ALIŞ")-SUMIFS(Tablo1[Adet],Tablo1[Hisse],Portföy!A18,Tablo1[İşlem],"SATIŞ") -> 0 | D18: =IFERROR((SUMIFS(Tablo1[Toplam],Tablo1[Hisse],Portföy!A18,Tablo1[İşlem],"ALIŞ")-SUMIFS(Tablo1[Toplam],Tablo1[Hisse],Portföy!A18,Tablo1[İşlem],"SATIŞ"))/C18,0) -> 0 | E18: =+D18*C18 -> 0 | F18: =SUMIFS(Tablo2[Son Fiyat],Tablo2[Şirket],Portföy!A18) -> 105.9 | G18: =+F18*C18 -> 0 | H18: =+G18-E18+IF(Portföy!C18=0,SUMIFS(Tablo1[Toplam],Tablo1[Hisse],Portföy!A18,Tablo1[İşlem],"SATIŞ")-SUMIFS(Tablo1[Toplam],Tablo1[Hisse],Portföy!A18,Tablo1[İşlem],"ALIŞ"),0) -> 246.2
A19: CATES | C19: =SUMIFS(Tablo1[Adet],Tablo1[Hisse],Portföy!A19,Tablo1[İşlem],"ALIŞ")-SUMIFS(Tablo1[Adet],Tablo1[Hisse],Portföy!A19,Tablo1[İşlem],"SATIŞ") -> 0 | D19: =IFERROR((SUMIFS(Tablo1[Toplam],Tablo1[Hisse],Portföy!A19,Tablo1[İşlem],"ALIŞ")-SUMIFS(Tablo1[Toplam],Tablo1[Hisse],Portföy!A19,Tablo1[İşlem],"SATIŞ"))/C19,0) -> 0 | E19: =+D19*C19 -> 0 | F19: =SUMIFS(Tablo2[Son Fiyat],Tablo2[Şirket],Portföy!A19) -> 35 | G19: =+F19*C19 -> 0 | H19: =+G19-E19+IF(Portföy!C19=0,SUMIFS(Tablo1[Toplam],Tablo1[Hisse],Portföy!A19,Tablo1[İşlem],"SATIŞ")-SUMIFS(Tablo1[Toplam],Tablo1[Hisse],Portföy!A19,Tablo1[İşlem],"ALIŞ"),0) -> -992.77
A20: CEOEM | B20: DESTEK HİZ. | C20: =SUMIFS(Tablo1[Adet],Tablo1[Hisse],Portföy!A20,Tablo1[İşlem],"ALIŞ")-SUMIFS(Tablo1[Adet],Tablo1[Hisse],Portföy!A20,Tablo1[İşlem],"SATIŞ") -> 130 | D20: =IFERROR((SUMIFS(Tablo1[Toplam],Tablo1[Hisse],Portföy!A20,Tablo1[İşlem],"ALIŞ")-SUMIFS(Tablo1[Toplam],Tablo1[Hisse],Portföy!A20,Tablo1[İşlem],"SATIŞ"))/C20,0) -> 25.21 | E20: =+D20*C20 -> 3277.3 | F20: =SUMIFS(Tablo2[Son Fiyat],Tablo2[Şirket],Portföy!A20) -> 25 | G20: =+F20*C20 -> 3250 | H20: =+G20-E20+IF(Portföy!C20=0,SUMIFS(Tablo1[Toplam],Tablo1[Hisse],Portföy!A20,Tablo1[İşlem],"SATIŞ")-SUMIFS(Tablo1[Toplam],Tablo1[Hisse],Portföy!A20,Tablo1[İşlem],"ALIŞ"),0) -> -27.3
A21: CIMSA | B21: ÇİMENTO | C21: =SUMIFS(Tablo1[Adet],Tablo1[Hisse],Portföy!A21,Tablo1[İşlem],"ALIŞ")-SUMIFS(Tablo1[Adet],Tablo1[Hisse],Portföy!A21,Tablo1[İşlem],"SATIŞ") -> 5 | D21: =IFERROR((SUMIFS(Tablo1[Toplam],Tablo1[Hisse],Portföy!A21,Tablo1[İşlem],"ALIŞ")-SUMIFS(Tablo1[Toplam],Tablo1[Hisse],Portföy!A21,Tablo1[İşlem],"SATIŞ"))/C21,0) -> 16.692 | E21: =+D21*C21 -> 83.46 | F21: =SUMIFS(Tablo2[Son Fiyat],Tablo2[Şirket],Portföy!A21) -> 53.35 | G21: =+F21*C21 -> 266.75 | H21: =+G21-E21+IF(Portföy!C21=0,SUMIFS(Tablo1[Toplam],Tablo1[Hisse],Portföy!A21,Tablo1[İşlem],"SATIŞ")-SUMIFS(Tablo1[Toplam],Tablo1[Hisse],Portföy!A21,Tablo1[İşlem],"ALIŞ"),0) -> 183.29
A22: CWENE | C22: =SUMIFS(Tablo1[Adet],Tablo1[Hisse],Portföy!A22,Tablo1[İşlem],"ALIŞ")-SUMIFS(Tablo1[Adet],Tablo1[Hisse],Portföy!A22,Tablo1[İşlem],"SATIŞ") -> 0 | D22: =IFERROR((SUMIFS(Tablo1[Toplam],Tablo1[Hisse],Portföy!A22,Tablo1[İşlem],"ALIŞ")-SUMIFS(Tablo1[Toplam],Tablo1[Hisse],Portföy!A22,Tablo1[İşlem],"SATIŞ"))/C22,0) -> 0 | E22: =+D22*C22 -> 0 | F22: =SUMIFS(Tablo2[Son Fiyat],Tablo2[Şirket],Portföy!A22) -> 19.95 | G22: =+F22*C22 -> 0 | H22: =+G22-E22+IF(Portföy!C22=0,SUMIFS(Tablo1[Toplam],Tablo1[Hisse],Portföy!A22,Tablo1[İşlem],"SATIŞ")-SUMIFS(Tablo1[Toplam],Tablo1[Hisse],Portföy!A22,Tablo1[İşlem],"ALIŞ"),0) -> -5526.5
A23: DAGI | B23: TEKSTİL | C23: =SUMIFS(Tablo1[Adet],Tablo1[Hisse],Portföy!A23,Tablo1[İşlem],"ALIŞ")-SUMIFS(Tablo1[Adet],Tablo1[Hisse],Portföy!A23,Tablo1[İşlem],"SATIŞ") -> 0 | D23: =IFERROR((SUMIFS(Tablo1[Toplam],Tablo1[Hisse],Portföy!A23,Tablo1[İşlem],"ALIŞ")-SUMIFS(Tablo1[Toplam],Tablo1[Hisse],Portföy!A23,Tablo1[İşlem],"SATIŞ"))/C23,0) -> 0 | E23: =+D23*C23 -> 0 | F23: =SUMIFS(Tablo2[Son Fiyat],Tablo2[Şirket],Portföy!A23) -> 15.58 | G23: =+F23*C23 -> 0 | H23: =+G23-E23+IF(Portföy!C23=0,SUMIFS(Tablo1[Toplam],Tablo1[Hisse],Portföy!A23,Tablo1[İşlem],"SATIŞ")-SUMIFS(Tablo1[Toplam],Tablo1[Hisse],Portföy!A23,Tablo1[İşlem],"ALIŞ"),0) -> 0
A24: DAPGM | B24: GYO | C24: =SUMIFS(Tablo1[Adet],Tablo1[Hisse],Portföy!A24,Tablo1[İşlem],"ALIŞ")-SUMIFS(Tablo1[Adet],Tablo1[Hisse],Portföy!A24,Tablo1[İşlem],"SATIŞ") -> 0 | D24: =IFERROR((SUMIFS(Tablo1[Toplam],Tablo1[Hisse],Portföy!A24,Tablo1[İşlem],"ALIŞ")-SUMIFS(Tablo1[Toplam],Tablo1[Hisse],Portföy!A24,Tablo1[İşlem],"SATIŞ"))/C24,0) -> 0 | E24: =+D24*C24 -> 0 | F24: =SUMIFS(Tablo2[Son Fiyat],Tablo2[Şirket],Portföy!A24) -> 7.52 | G24: =+F24*C24 -> 0 | H24: =+G24-E24+IF(Portföy!C24=0,SUMIFS(Tablo1[Toplam],Tablo1[Hisse],Portföy!A24,Tablo1[İşlem],"SATIŞ")-SUMIFS(Tablo1[Toplam],Tablo1[Hisse],Portföy!A24,Tablo1[İşlem],"ALIŞ"),0) -> 170.57
A25: DESA | B25: TEKSTİL | C25: =SUMIFS(Tablo1[Adet],Tablo1[Hisse],Portföy!A25,Tablo1[İşlem],"ALIŞ")-SUMIFS(Tablo1[Adet],Tablo1[Hisse],Portföy!A25,Tablo1[İşlem],"SATIŞ") -> 175 | D25: =IFERROR((SUMIFS(Tablo1[Toplam],Tablo1[Hisse],Portföy!A25,Tablo1[İşlem],"ALIŞ")-SUMIFS(Tablo1[Toplam],Tablo1[Hisse],Portföy!A25,Tablo1[İşlem],"SATIŞ"))/C25,0) -> 8.708 | E25: =+D25*C25 -> 1523.9 | F25: =SUMIFS(Tablo2[Son Fiyat],Tablo2[Şirket],Portföy!A25) -> 9.74 | G25: =+F25*C25 -> 1704.5 | H25: =+G25-E25+IF(Portföy!C25=0,SUMIFS(Tablo1[Toplam],Tablo1[Hisse],Portföy!A25,Tablo1[İşlem],"SATIŞ")-SUMIFS(Tablo1[Toplam],Tablo1[Hisse],Portföy!A25,Tablo1[İşlem],"ALIŞ"),0) -> 180.6
A26: DEVA | B26: SAĞLIK İLAÇ | C26: =SUMIFS(Tablo1[Adet],Tablo1[Hisse],Portföy!A26,Tablo1[İşlem],"ALIŞ")-SUMIFS(Tablo1[Adet],Tablo1[Hisse],Portföy!A26,Tablo1[İşlem],"SATIŞ") -> 0 | D26: =IFERROR((SUMIFS(Tablo1[Toplam],Tablo1[Hisse],Portföy!A26,Tablo1[İşlem],"ALIŞ")-SUMIFS(Tablo1[Toplam],Tablo1[Hisse],Portföy!A26,Tablo1[İşlem],"SATIŞ"))/C26,0) -> 0 | E26: =+D26*C26 -> 0 | F26: =SUMIFS(Tablo2[Son Fiyat],Tablo2[Şirket],Portföy!A26) -> 71.4 | G26: =+F26*C26 -> 0 | H26: =+G26-E26+IF(Portföy!C26=0,SUMIFS(Tablo1[Toplam],Tablo1[Hisse],Portföy!A26,Tablo1[İşlem],"SATIŞ")-SUMIFS(Tablo1[Toplam],Tablo1[Hisse],Portföy!A26,Tablo1[İşlem],"ALIŞ"),0) -> 28.35
A27: DOAS | B27: OTOMOTİV | C27: =SUMIFS(Tablo1[Adet],Tablo1[Hisse],Portföy!A27,Tablo1[İşlem],"ALIŞ")-SUMIFS(Tablo1[Adet],Tablo1[Hisse],Portföy!A27,Tablo1[İşlem],"SATIŞ") -> 101 | D27: =IFERROR((SUMIFS(Tablo1[Toplam],Tablo1[Hisse],Portföy!A27,Tablo1[İşlem],"ALIŞ")-SUMIFS(Tablo1[Toplam],Tablo1[Hisse],Portföy!A27,Tablo1[İşlem],"SATIŞ"))/C27,0) -> 373.75743 | E27: =+D27*C27 -> 37749.5 | F27: =SUMIFS(Tablo2[Son Fiyat],Tablo2[Şirket],Portföy!A27) -> 188.1 | G27: =+F27*C27 -> 18998.1 | H27: =+G27-E27+IF(Portföy!C27=0,SUMIFS(Tablo1[Toplam],Tablo1[Hisse],Portföy!A27,Tablo1[İşlem],"SATIŞ")-SUMIFS(Tablo1[Toplam],Tablo1[Hisse],Portföy!A27,Tablo1[İşlem],"ALIŞ"),0) -> -18751.4
A28: DOKTA | C28: =SUMIFS(Tablo1[Adet],Tablo1[Hisse],Portföy!A28,Tablo1[İşlem],"ALIŞ")-SUMIFS(Tablo1[Adet],Tablo1[Hisse],Portföy!A28,Tablo1[İşlem],"SATIŞ") -> 0 | D28: =IFERROR((SUMIFS(Tablo1[Toplam],Tablo1[Hisse],Portföy!A28,Tablo1[İşlem],"ALIŞ")-SUMIFS(Tablo1[Toplam],Tablo1[Hisse],Portföy!A28,Tablo1[İşlem],"SATIŞ"))/C28,0) -> 0 | E28: =+D28*C28 -> 0 | F28: =SUMIFS(Tablo2[Son Fiyat],Tablo2[Şirket],Portföy!A28) -> 22.9 | G28: =+F28*C28 -> 0 | H28: =+G28-E28+IF(Portföy!C28=0,SUMIFS(Tablo1[Toplam],Tablo1[Hisse],Portföy!A28,Tablo1[İşlem],"SATIŞ")-SUMIFS(Tablo1[Toplam],Tablo1[Hisse],Portföy!A28,Tablo1[İşlem],"ALIŞ"),0) -> -9714.5
A29: EDATA | B29: BİLİŞİM YAZILIM | C29: =SUMIFS(Tablo1[Adet],Tablo1[Hisse],Portföy!A29,Tablo1[İşlem],"ALIŞ")-SUMIFS(Tablo1[Adet],Tablo1[Hisse],Portföy!A29,Tablo1[İşlem],"SATIŞ") -> 1150 | D29: =IFERROR((SUMIFS(Tablo1[Toplam],Tablo1[Hisse],Portföy!A29,Tablo1[İşlem],"ALIŞ")-SUMIFS(Tablo1[Toplam],Tablo1[Hisse],Portföy!A29,Tablo1[İşlem],"SATIŞ"))/C29,0) -> 17.134783 | E29: =+D29*C29 -> 19705 | F29: =SUMIFS(Tablo2[Son Fiyat],Tablo2[Şirket],Portföy!A29) -> 13.12 | G29: =+F29*C29 -> 15088 | H29: =+G29-E29+IF(Portföy!C29=0,SUMIFS(Tablo1[Toplam],Tablo1[Hisse],Portföy!A29,Tablo1[İşlem],"SATIŞ")-SUMIFS(Tablo1[Toplam],Tablo1[Hisse],Portföy!A29,Tablo1[İşlem],"ALIŞ"),0) -> -4617
A30: EDIP | B30: İNŞAAT | C30: =SUMIFS(Tablo1[Adet],Tablo1[Hisse],Portföy!A30,Tablo1[İşlem],"ALIŞ")-SUMIFS(Tablo1[Adet],Tablo1[Hisse],Portföy!A30,Tablo1[İşlem],"SATIŞ") -> 0 | D30: =IFERROR((SUMIFS(Tablo1[Toplam],Tablo1[Hisse],Portföy!A30,Tablo1[İşlem],"ALIŞ")-SUMIFS(Tablo1[Toplam],Tablo1[Hisse],Portföy!A30,Tablo1[İşlem],"SATIŞ"))/C30,0) -> 0 | E30: =+D30*C30 -> 0 | F30: =SUMIFS(Tablo2[Son Fiyat],Tablo2[Şirket],Portföy!A30) -> 20.5 | G30: =+F30*C30 -> 0 | H30: =+G30-E30+IF(Portföy!C30=0,SUMIFS(Tablo1[Toplam],Tablo1[Hisse],Portföy!A30,Tablo1[İşlem],"SATIŞ")-SUMIFS(Tablo1[Toplam],Tablo1[Hisse],Portföy!A30,Tablo1[İşlem],"ALIŞ"),0) -> -231
A31: EGEPO | B31: SAĞLIK İLAÇ | C31: =SUMIFS(Tablo1[Adet],Tablo1[Hisse],Portföy!A31,Tablo1[İşlem],"ALIŞ")-SUMIFS(Tablo1[Adet],Tablo1[Hisse],Portföy!A31,Tablo1[İşlem],"SATIŞ") -> 0 | D31: =IFERROR((SUMIFS(Tablo1[Toplam],Tablo1[Hisse],Portföy!A31,Tablo1[İşlem],"ALIŞ")-SUMIFS(Tablo1[Toplam],Tablo1[Hisse],Portföy!A31,Tablo1[İşlem],"SATIŞ"))/C31,0) -> 0 | E31: =+D31*C31 -> 0 | F31: =SUMIFS(Tablo2[Son Fiyat],Tablo2[Şirket],Portföy!A31) -> 24.4 | G31: =+F31*C31 -> 0 | H31: =+G31-E31+IF(Portföy!C31=0,SUMIFS(Tablo1[Toplam],Tablo1[Hisse],Portföy!A31,Tablo1[İşlem],"SATIŞ")-SUMIFS(Tablo1[Toplam],Tablo1[Hisse],Portföy!A31,Tablo1[İşlem],"ALIŞ"),0) -> 215.28
A32: EKGYO | B32: GYO | C32: =SUMIFS(Tablo1[Adet],Tablo1[Hisse],Portföy!A32,Tablo1[İşlem],"ALIŞ")-SUMIFS(Tablo1[Adet],Tablo1[Hisse],Portföy!A32,Tablo1[İşlem],"SATIŞ") -> 0 | D32: =IFERROR((SUMIFS(Tablo1[Toplam],Tablo1[Hisse],Portföy!A32,Tablo1[İşlem],"ALIŞ")-SUMIFS(Tablo1[Toplam],Tablo1[Hisse],Portföy!A32,Tablo1[İşlem],"SATIŞ"))/C32,0) -> 0 | E32: =+D32*C32 -> 0 | F32: =SUMIFS(Tablo2[Son Fiyat],Tablo2[Şirket],Portföy!A32) -> 15.27 | G32: =+F32*C32 -> 0 | H32: =+G32-E32+IF(Portföy!C32=0,SUMIFS(Tablo1[Toplam],Tablo1[Hisse],Portföy!A32,Tablo1[İşlem],"SATIŞ")-SUMIFS(Tablo1[Toplam],Tablo1[Hisse],Portföy!A32,Tablo1[İşlem],"ALIŞ"),0) -> 1361.5
A33: ENJSA | C33: =SUMIFS(Tablo1[Adet],Tablo1[Hisse],Portföy!A33,Tablo1[İşlem],"ALIŞ")-SUMIFS(Tablo1[Adet],Tablo1[Hisse],Portföy!A33,Tablo1[İşlem],"SATIŞ") -> 0 | D33: =IFERROR((SUMIFS(Tablo1[Toplam],Tablo1[Hisse],Portföy!A33,Tablo1[İşlem],"ALIŞ")-SUMIFS(Tablo1[Toplam],Tablo1[Hisse],Portföy!A33,Tablo1[İşlem],"SATIŞ"))/C33,0) -> 0 | E33: =+D33*C33 -> 0 | F33: =SUMIFS(Tablo2[Son Fiyat],Tablo2[Şirket],Portföy!A33) -> 61.3 | G33: =+F33*C33 -> 0 | H33: =+G33-E33+IF(Portföy!C33=0,SUMIFS(Tablo1[Toplam],Tablo1[Hisse],Portföy!A33,Tablo1[İşlem],"SATIŞ")-SUMIFS(Tablo1[Toplam],Tablo1[Hisse],Portföy!A33,Tablo1[İşlem],"ALIŞ"),0) -> 368.5
A34: ERCB | C34: =SUMIFS(Tablo1[Adet],Tablo1[Hisse],Portföy!A34,Tablo1[İşlem],"ALIŞ")-SUMIFS(Tablo1[Adet],Tablo1[Hisse],Portföy!A34,Tablo1[İşlem],"SATIŞ") -> 0 | D34: =IFERROR((SUMIFS(Tablo1[Toplam],Tablo1[Hisse],Portföy!A34,Tablo1[İşlem],"ALIŞ")-SUMIFS(Tablo1[Toplam],Tablo1[Hisse],Portföy!A34,Tablo1[İşlem],"SATIŞ"))/C34,0) -> 0 | E34: =+D34*C34 -> 0 | F34: =SUMIFS(Tablo2[Son Fiyat],Tablo2[Şirket],Portföy!A34) -> 88.7 | G34: =+F34*C34 -> 0 | H34: =+G34-E34+IF(Portföy!C34=0,SUMIFS(Tablo1[Toplam],Tablo1[Hisse],Portföy!A34,Tablo1[İşlem],"SATIŞ")-SUMIFS(Tablo1[Toplam],Tablo1[Hisse],Portföy!A34,Tablo1[İşlem],"ALIŞ"),0) -> 290
A35: EREGL | B35: ANA METAL | C35: =SUMIFS(Tablo1[Adet],Tablo1[Hisse],Portföy!A35,Tablo1[İşlem],"ALIŞ")-SUMIFS(Tablo1[Adet],Tablo1[Hisse],Portföy!A35,Tablo1[İşlem],"SATIŞ") -> 130 | D35: =IFERROR((SUMIFS(Tablo1[Toplam],Tablo1[Hisse],Portföy!A35,Tablo1[İşlem],"ALIŞ")-SUMIFS(Tablo1[Toplam],Tablo1[Hisse],Portföy!A35,Tablo1[İşlem],"SATIŞ"))/C35,0) -> 18.759231 | E35: =+D35*C35 -> 2438.7 | F35: =SUMIFS(Tablo2[Son Fiyat],Tablo2[Şirket],Portföy!A35) -> 22.44 | G35: =+F35*C35 -> 2917.2 | H35: =+G35-E35+IF(Portföy!C35=0,SUMIFS(Tablo1[Toplam],Tablo1[Hisse],Portföy!A35,Tablo1[İşlem],"SATIŞ")-SUMIFS(Tablo1[Toplam],Tablo1[Hisse],Portföy!A35,Tablo1[İşlem],"ALIŞ"),0) -> 478.5
A36: EUPWR | C36: =SUMIFS(Tablo1[Adet],Tablo1[Hisse],Portföy!A36,Tablo1[İşlem],"ALIŞ")-SUMIFS(Tablo1[Adet],Tablo1[Hisse],Portföy!A36,Tablo1[İşlem],"SATIŞ") -> 0 | D36: =IFERROR((SUMIFS(Tablo1[Toplam],Tablo1[Hisse],Portföy!A36,Tablo1[İşlem],"ALIŞ")-SUMIFS(Tablo1[Toplam],Tablo1[Hisse],Portföy!A36,Tablo1[İşlem],"SATIŞ"))/C36,0) -> 0 | E36: =+D36*C36 -> 0 | F36: =SUMIFS(Tablo2[Son Fiyat],Tablo2[Şirket],Portföy!A36) -> 37 | G36: =+F36*C36 -> 0 | H36: =+G36-E36+IF(Portföy!C36=0,SUMIFS(Tablo1[Toplam],Tablo1[Hisse],Portföy!A36,Tablo1[İşlem],"SATIŞ")-SUMIFS(Tablo1[Toplam],Tablo1[Hisse],Portföy!A36,Tablo1[İşlem],"ALIŞ"),0) -> 0
A37: FMIZP | B37: OTO YAN SAN. | C37: =SUMIFS(Tablo1[Adet],Tablo1[Hisse],Portföy!A37,Tablo1[İşlem],"ALIŞ")-SUMIFS(Tablo1[Adet],Tablo1[Hisse],Portföy!A37,Tablo1[İşlem],"SATIŞ") -> 2 | D37: =IFERROR((SUMIFS(Tablo1[Toplam],Tablo1[Hisse],Portföy!A37,Tablo1[İşlem],"ALIŞ")-SUMIFS(Tablo1[Toplam],Tablo1[Hisse],Portföy!A37,Tablo1[İşlem],"SATIŞ"))/C37,0) -> 312.5 | E37: =+D37*C37 -> 625 | F37: =SUMIFS(Tablo2[Son Fiyat],Tablo2[Şirket],Portföy!A37) -> 306 | G37: =+F37*C37 -> 612 | H37: =+G37-E37+IF(Portföy!C37=0,SUMIFS(Tablo1[Toplam],Tablo1[Hisse],Portföy!A37,Tablo1[İşlem],"SATIŞ")-SUMIFS(Tablo1[Toplam],Tablo1[Hisse],Portföy!A37,Tablo1[İşlem],"ALIŞ"),0) -> -13
A38: FROTO | B38: OTOMOTİV | C38: =SUMIFS(Tablo1[Adet],Tablo1[Hisse],Portföy!A38,Tablo1[İşlem],"ALIŞ")-SUMIFS(Tablo1[Adet],Tablo1[Hisse],Portföy!A38,Tablo1[İşlem],"SATIŞ") -> 11 | D38: =IFERROR((SUMIFS(Tablo1[Toplam],Tablo1[Hisse],Portföy!A38,Tablo1[İşlem],"ALIŞ")-SUMIFS(Tablo1[Toplam],Tablo1[Hisse],Portföy!A38,Tablo1[İşlem],"SATIŞ"))/C38,0) -> 1097.7655 | E38: =+D38*C38 -> 12075.42 | F38: =SUMIFS(Tablo2[Son Fiyat],Tablo2[Şirket],Portföy!A38) -> 929.5 | G38: =+F38*C38 -> 10224.5 | H38: =+G38-E38+IF(Portföy!C38=0,SUMIFS(Tablo1[Toplam],Tablo1[Hisse],Portföy!A38,Tablo1[İşlem],"SATIŞ")-SUMIFS(Tablo1[Toplam],Tablo1[Hisse],Portföy!A38,Tablo1[İşlem],"ALIŞ"),0) -> -1850.92
A39: GESAN | B39: ENERJİ TEK. | C39: =SUMIFS(Tablo1[Adet],Tablo1[Hisse],Portföy!A39,Tablo1[İşlem],"ALIŞ")-SUMIFS(Tablo1[Adet],Tablo1[Hisse],Portföy!A39,Tablo1[İşlem],"SATIŞ") -> 40 | D39: =IFERROR((SUMIFS(Tablo1[Toplam],Tablo1[Hisse],Portföy!A39,Tablo1[İşlem],"ALIŞ")-SUMIFS(Tablo1[Toplam],Tablo1[Hisse],Portföy!A39,Tablo1[İşlem],"SATIŞ"))/C39,0) -> 31.2075 | E39: =+D39*C39 -> 1248.3 | F39: =SUMIFS(Tablo2[Son Fiyat],Tablo2[Şirket],Portföy!A39) -> 51.25 | G39: =+F39*C39 -> 2050 | H39: =+G39-E39+IF(Portföy!C39=0,SUMIFS(Tablo1[Toplam],Tablo1[Hisse],Portföy!A39,Tablo1[İşlem],"SATIŞ")-SUMIFS(Tablo1[Toplam],Tablo1[Hisse],Portföy!A39,Tablo1[İşlem],"ALIŞ"),0) -> 801.7
A40: GMTAS | C40: =SUMIFS(Tablo1[Adet],Tablo1[Hisse],Portföy!A40,Tablo1[İşlem],"ALIŞ")-SUMIFS(Tablo1[Adet],Tablo1[Hisse],Portföy!A40,Tablo1[İşlem],"SATIŞ") -> 0 | D40: =IFERROR((SUMIFS(Tablo1[Toplam],Tablo1[Hisse],Portföy!A40,Tablo1[İşlem],"ALIŞ")-SUMIFS(Tablo1[Toplam],Tablo1[Hisse],Portföy!A40,Tablo1[İşlem],"SATIŞ"))/C40,0) -> 0 | E40: =+D40*C40 -> 0 | F40: =SUMIFS(Tablo2[Son Fiyat],Tablo2[Şirket],Portföy!A40) -> 11.04 | G40: =+F40*C40 -> 0 | H40: =+G40-E40+IF(Portföy!C40=0,SUMIFS(Tablo1[Toplam],Tablo1[Hisse],Portföy!A40,Tablo1[İşlem],"SATIŞ")-SUMIFS(Tablo1[Toplam],Tablo1[Hisse],Portföy!A40,Tablo1[İşlem],"ALIŞ"),0) -> 237.5
...

Sheet İşlem
A1: Tarih | B1: Hisse | C1: İşlem | D1: Adet | E1: Fiyat | F1: Toplam | K1: Şirket | L1: Son Fiyat | M1: 1 Hafta % | N1: 1 Ay % | O1: 3 Ay % | P1: 6 Ay % | Q1: 2025 % | R1: 1 Yıl % | S1: 3 Yıl % | T1: 5 Yıl %
A2: 45462 | B2: ADEL | C2: ALIŞ | D2: 4 | E2: 579.63 | F2: =+E2*D2 -> 2318.52 | K2: A1CAP | L2: 24.16 | M2: -3.21 | N2: -13.71 | O2: -1.71 | P2: -8.83 | Q2: -13.71 | R2: -21.56
A3: 45462 | B3: ALARK | C3: ALIŞ | D3: 100 | E3: 137.17 | F3: =+E3*D3 -> 13717 | K3: ACSEL | L3: 119.3 | M3: 0.34 | N3: 4.65 | O3: 8.65 | P3: -14.02 | Q3: 4.65 | R3: -9.46 | S3: 484.52 | T3: 1463.56
A4: 45462 | B4: ARASE | C4: ALIŞ | D4: 200 | E4: 67.41 | F4: =+E4*D4 -> 13482 | K4: ADEL | L4: 32 | M4: -3.32 | N4: -4.42 | O4: -21.84 | P4: -33.99 | Q4: -4.42 | R4: -21.38 | S4: 1126.05 | T4: 2005.26
A5: 45462 | B5: ARENA | C5: ALIŞ | D5: 160 | E5: 45.58 | F5: =+E5*D5 -> 7292.8 | K5: ADESE | L5: 2.06 | M5: -5.94 | N5: -5.5 | O5: 11.96 | P5: -4.19 | Q5: -5.5 | R5: -11.97 | S5: 174.67 | T5: 52.59
A6: 45462 | B6: ASTOR | C6: ALIŞ | D6: 310 | E6: 97.04 | F6: =+E6*D6 -> 30082.4 | K6: ADGYO | L6: 29.48 | M6: -3.79 | N6: -11.84 | O6: -7.7 | P6: -14.7 | Q6: -11.84 | R6: -11.47
A7: 45462 | B7: BRLSM | C7: ALIŞ | D7: 1600 | E7: 24.06 | F7: =+E7*D7 -> 38496 | K7: AEFES | L7: 161.4 | M7: -2.65 | N7: -15.76 | O7: -15.81 | P7: -39.55 | Q7: -15.76 | R7: 15.94 | S7: 516.03 | T7: 749.92
A8: 45462 | B8: BURVA | C8: ALIŞ | D8: 60 | E8: 135.2 | F8: =+E8*D8 -> 8112 | K8: AFYON | L8: 15.62 | M8: -1.76 | N8: 5.47 | O8: -1.7 | P8: 8.55 | Q8: 5.47 | R8: 29.63 | S8: 388.12 | T8: 553.56
A9: 45462 | B9: CATES | C9: ALIŞ | D9: 113 | E9: 55.94 | F9: =+E9*D9 -> 6321.22 | K9: AGESA | L9: 140.6 | M9: -4.68 | N9: -13.58 | O9: 34.29 | P9: 7.99 | Q9: -13.58 | R9: 147.06 | S9: 426.39 | T9: 1073.62
A10: 45462 | B10: CWENE | C10: ALIŞ | D10: 50 | E10: 282.18 | F10: =+E10*D10 -> 14109 | K10: AGHOL | L10: 300.75 | M10: -4.52 | N10: -3.91 | O10: 3.8 | P10: -29.44 | Q10: -3.91 | R10: 32.45 | S10: 714.16 | T10: 1456.68
A11: 45462 | B11: DEVA | C11: ALIŞ | D11: 30 | E11: 78.93 | F11: =+E11*D11 -> 2367.9 | K11: AGROT | L11: 10.03 | M11: -6.52 | N11: -6.09 | O11: -31.58 | P11: -50.05 | Q11: -6.09 | R11: -63.63
A12: 45462 | B12: DOAS | C12: ALIŞ | D12: 140 | E12: 330.6 | F12: =+E12*D12 -> 46284 | K12: AGYO | L12: 7.32 | M12: -0.27 | N12: -3.68 | O12: 2.66 | P12: -2.79 | Q12: -3.68 | R12: -20.78 | S12: 146.46 | T12: 283.25
A13: 45462 | B13: DOKTA | C13: ALIŞ | D13: 650 | E13: 35.63 | F13: =+E13*D13 -> 23159.5 | K13: AHGAZ | L13: 19.23 | M13: -3.71 | N13: -7.28 | O13: -1.64 | P13: 47.24 | Q13: -7.28 | R13: 51.9
A14: 45462 | B14: EDATA | C14: ALIŞ | D14: 650 | E14: 22.45 | F14: =+E14*D14 -> 14592.5 | K14: AHSGY | L14: 25.32 | M14: 1.44 | N14: 16.68 | O14: 30.65 | Q14: 16.68
A15: 45462 | B15: EDIP | C15: ALIŞ | D15: 150 | E15: 24.21 | F15: =+E15*D15 -> 3631.5 | K15: AKBNK | L15: 64.85 | M15: -2.41 | N15: 0 | O15: 28.16 | P15: 4.77 | Q15: 0 | R15: 71.15 | S15: 857.9 | T15: 856.49
A16: 45462 | B16: ENJSA | C16: ALIŞ | D16: 50 | E16: 59.85 | F16: =+E16*D16 -> 2992.5 | K16: AKCNS | L16: 208.2 | M16: 0.92 | N16: 15.67 | O16: 33.89 | P16: 39.36 | Q16: 15.67 | R16: 26.7 | S16: 1212.74 | T16: 2167.97
A17: 45462 | B17: FROTO | C17: ALIŞ | D17: 11 | E17: 1112.22 | F17: =+E17*D17 -> 12234.42 | K17: AKENR | L17: 14.1 | M17: -0.28 | N17: 6.98 | O17: 21.34 | P17: 12.44 | Q17: 6.98 | R17: 187.76 | S17: 775.78 | T17: 1046.34
A18: 45462 | B18: HTTBT | C18: ALIŞ | D18: 30 | E18: 72.08 | F18: =+E18*D18 -> 2162.4 | K18: AKFGY | L18: 1.99 | M18: -5.24 | N18: -3.86 | O18: 4.19 | P18: -13.85 | Q18: -3.86 | R18: -2.93 | S18: -2.45 | T18: 165.33
A19: 45462 | B19: HUNER | C19: ALIŞ | D19: 250 | E19: 4.38 | F19: =+E19*D19 -> 1095 | K19: AKFIS | L19: 26.4 | M19: -15.92
A20: 45462 | B20: KBORU | C20: ALIŞ | D20: 100 | E20: 111.98 | F20: =+E20*D20 -> 11198 | K20: AKFYE | L20: 18 | M20: -5.81 | N20: -8.21 | O20: 2.68 | P20: -24.75 | Q20: -8.21 | R20: -11.76
A21: 45462 | B21: KCHOL | C21: ALIŞ | D21: 20 | E21: 214.65 | F21: =+E21*D21 -> 4293 | K21: AKGRT | L21: 8.04 | M21: -2.31 | N21: 5.24 | O21: 35.58 | P21: 23.5 | Q21: 5.24 | R21: 23.69 | S21: 296.06 | T21: 482.61
A22: 45462 | B22: KONTR | C22: ALIŞ | D22: 50 | E22: 232.97 | F22: =+E22*D22 -> 11648.5 | K22: AKMGY | L22: 211 | M22: -3.08 | N22: -6.06 | O22: 4.09 | P22: -16.1 | Q22: -6.06 | R22: 11.87 | S22: 455.56 | T22: 949.75
A23: 45462 | B23: ONCSM | C23: ALIŞ | D23: 110 | E23: 176.42 | F23: =+E23*D23 -> 19406.2 | K23: AKSA | L23: 11.54 | M23: 4.91 | N23: -10.82 | O23: 38.37 | P23: 13.92 | Q23: -10.82 | R23: 56.58 | S23: 388.98 | T23: 2208
A24: 45462 | B24: ORGE | C24: ALIŞ | D24: 125 | E24: 70.09 | F24: =+E24*D24 -> 8761.25 | K24: AKSEN | L24: 41.1 | M24: -3.48 | N24: 4.85 | O24: 24.55 | P24: -0.44 | Q24: 4.85 | R24: 17.29 | S24: 254.92 | T24: 2074.6
A25: 45462 | B25: OZRDN | C25: ALIŞ | D25: 100 | E25: 57.88 | F25: =+E25*D25 -> 5788 | K25: AKSGY | L25: 7.17 | M25: -0.42 | N25: -4.4 | O25: 17.16 | P25: 5.6 | Q25: -4.4 | R25: 52.55 | S25: 1203.64 | T25: 696.67
A26: 45462 | B26: SAHOL | C26: ALIŞ | D26: 10 | E26: 103.8 | F26: =+E26*D26 -> 1038 | K26: AKSUE | L26: 10.93 | M26: -4.21 | N26: -6.66 | O26: -0.73 | P26: -15.73 | Q26: -6.66 | R26: -28.52 | S26: -30.43 | T26: 212.29
A27: 45462 | B27: SMART | C27: ALIŞ | D27: 300 | E27: 42.85 | F27: =+E27*D27 -> 12855 | K27: AKYHO | L27: 2.55 | M27: -3.77 | N27: -5.56 | O27: -1.92 | P27: -52.51 | Q27: -5.56 | R27: -3.77 | S27: 140.57 | T27: 332.2
A28: 45462 | B28: SMRTG | C28: ALIŞ | D28: 300 | E28: 57.77 | F28: =+E28*D28 -> 17331 | K28: ALARK | L28: 86.05 | M28: -4.12 | N28: -6.47 | O28: -0.35 | P28: -17.89 | Q28: -6.47 | R28: -19.15 | S28: 380.19 | T28: 1383.62
A29: 45462 | B29: TARKM | C29: ALIŞ | D29: 10 | E29: 527.73 | F29: =+E29*D29 -> 5277.3 | K29: ALBRK | L29: 7.16 | M29: -5.17 | N29: 11.35 | O29: 36.12 | P29: 14.19 | Q29: 11.35 | R29: 68.87 | S29: 411.43 | T29: 434.33
A30: 45462 | B30: THYAO | C30: ALIŞ | D30: 10 | E30: 289.22 | F30: =+E30*D30 -> 2892.2 | K30: ALCAR | L30: 958 | M30: -3.57 | N30: -10.72 | O30: 3.79 | P30: -13.69 | Q30: -10.72 | R30: -17.41 | S30: 251.43 | T30: 1422.57
A31: 45462 | B31: TNZTP | C31: ALIŞ | D31: 247 | E31: 65.99 | F31: =+E31*D31 -> 16299.53 | K31: ALCTL | L31: 137.7 | M31: 0.66 | N31: 14.85 | O31: 14.85 | P31: 42.92 | Q31: 14.85 | R31: 29.78 | S31: 395.32 | T31: 783.83
A32: 45462 | B32: TOASO | C32: ALIŞ | D32: 25 | E32: 262.48 | F32: =+E32*D32 -> 6562 | K32: ALFAS | L32: 73.35 | M32: -1.68 | N32: 7.95 | O32: 35.96 | P32: 10.58 | Q32: 7.95 | R32: -26.01
A33: 45462 | B33: TTRAK | C33: ALIŞ | D33: 10 | E33: 909.85 | F33: =+E33*D33 -> 9098.5 | K33: ALGYO | L33: 20.28 | M33: -7.73 | N33: -3.15 | O33: 16.75 | P33: -21.24 | Q33: -3.15 | R33: -0.98 | S33: 179.34 | T33: 611.58
A34: 45462 | B34: TUCLK | C34: ALIŞ | D34: 300 | E34: 13.16 | F34: =+E34*D34 -> 3948 | K34: ALKA | L34: 8.2 | M34: -9.89 | N34: -10.28 | O34: 28.73 | P34: 18.16 | Q34: -10.28 | R34: 9.63 | S34: 666.36 | T34: 1950
A35: 45462 | B35: TUPRS | C35: ALIŞ | D35: 130 | E35: 181.95 | F35: =+E35*D35 -> 23653.5 | K35: ALKIM | L35: 17.34 | M35: -8.06 | N35: -8.93 | O35: 5.8 | P35: 4.46 | Q35: -8.93 | R35: -9.26 | S35: 86.45 | T35: 445.28
A36: 45462 | B36: UNLU | C36: ALIŞ | D36: 250 | E36: 16.25 | F36: =+E36*D36 -> 4062.5 | K36: ALKLC | L36: 25.52 | M36: -2.97 | N36: -28.91 | O36: -19.55 | P36: 4.42 | Q36: -28.91
A37: 45462 | B37: YEOTK | C37: ALIŞ | D37: 60 | E37: 213.3 | F37: =+E37*D37 -> 12798 | K37: ALMAD | L37: 7.52 | M37: -6.58 | N37: -0.13 | O37: 4.44 | P37: -9.29 | Q37: -0.13 | R37: -0.79 | S37: 297.88 | T37: 1828.21
A38: 45463 | B38: EDATA | C38: ALIŞ | D38: 100 | E38: 16.73 | F38: =+E38*D38 -> 1673 | K38: ALTNY | L38: 76.25 | M38: -0.2 | N38: -7.24 | O38: -22.19 | P38: -38.21 | Q38: -7.24
A39: 45463 | B39: DEVA | C39: SATIŞ | D39: 15 | E39: 90.75 | F39: =+E39*D39 -> 1361.25 | K39: ALVES | L39: 35.3 | M39: -9.02 | N39: -7.74 | O39: 5.82 | P39: -34.02 | Q39: -7.74
A40: 45463 | B40: EDIP | C40: SATIŞ | D40: 50 | E40: 26.7 | F40: =+E40*D40 -> 1335 | K40: ANELE | L40: 14.22 | M40: -4.11 | N40: -10.9 | O40: -7.12 | P40: -12.22 | Q40: -10.9 | R40: 4.64 | S40: 526.43 | T40: 817.42
...

Sheet Sayfa4
G1: =SUM(G2:G1286) -> 27477.63 | K1: =IF(F1=0,1,0) -> 1 | L1: =+D1*E1 -> 0
B2: Tarih | C2: hisse | G2: =IF(F2="","",(F2-E2)*D2) | K2: =IF(F2=0,1,0) -> 1 | L2: =+D2*E2 -> 0
B3: 45583 | C3: MARKA | D3: 25 | E3: 72 | F3: 57.85 | G3: =IF(E3=0,"",IF(F3="","",(F3-E3)*D3)) -> -353.75 | O3: ADEL | P3: 20 | Q3: 39
B4: 45602 | C4: MARKA | D4: 35 | E4: 64 | F4: 57.85 | G4: =IF(E4=0,"",IF(F4="","",(F4-E4)*D4)) -> -215.25 | O4: ADEL | P4: 30 | Q4: 40
B5: 45608 | C5: MARKA | D5: 30 | E5: 64.2 | F5: 57.85 | G5: =IF(E5=0,"",IF(F5="","",(F5-E5)*D5)) -> -190.5 | O5: ADEL | P5: 40 | Q5: 41
B6: 45582 | C6: MARKA | D6: 15 | E6: 65.95 | F6: 57.85 | G6: =IF(E6=0,"",IF(F6="","",(F6-E6)*D6)) -> -121.5 | O6: ADEL | P6: 50 | Q6: 42
B7: 45559 | C7: ARASE | D7: 30 | E7: 56 | F7: 57 | G7: =IF(F7="","",(F7-E7)*D7) -> 30 | O7: ALMAD | P7: 50 | Q7: 6.7
B8: 45618 | C8: MARKA | D8: 30 | E8: 60 | F8: 57.85 | G8: =IF(E8=0,"",IF(F8="","",(F8-E8)*D8)) -> -64.5 | O8: ALMAD | P8: 50 | Q8: 6.8
B9: 45609 | C9: MARKA | D9: 8 | E9: 63 | F9: 57.85 | G9: =IF(E9=0,"",IF(F9="","",(F9-E9)*D9)) -> -41.2 | O9: ALMAD | P9: 50 | Q9: 6.9
B10: 45545 | C10: BURVA | D10: 10 | E10: 117.9 | F10: 130 | G10: =IF(F10="","",(F10-E10)*D10) -> 121
B11: 45545 | C11: BURVA | D11: 10 | E11: 118 | F11: 127 | G11: =IF(F11="","",(F11-E11)*D11) -> 90
B12: 45547 | C12: BURVA | D12: 10 | E12: 112 | F12: 119 | G12: =IF(F12="","",(F12-E12)*D12) -> 70
B13: 45551 | C13: BAYRK | D13: 50 | E13: 23 | F13: 24 | G13: =IF(F13="","",(F13-E13)*D13) -> 50
B14: 45547 | C14: MARKA | D14: 30 | E14: 53.8 | F14: 56 | G14: =IF(F14="","",(F14-E14)*D14) -> 66
B15: 45621 | C15: MARKA | D15: 32 | E15: 58 | F15: 57.85 | G15: =IF(E15=0,"",IF(F15="","",(F15-E15)*D15)) -> -4.8 | O15: ALMAD | P15: 50 | Q15: 7
B16: 45544 | C16: PKART | D16: 20 | E16: 67 | F16: 69 | G16: =IF(F16="","",(F16-E16)*D16) -> 40
B17: 45545 | C17: ADEL | D17: 50 | E17: 48.2 | G17: =IF(E17=0,"",IF(F17="","",(F17-E17)*D17)) | I17: =+E17*1.1 -> 53.02 | K17: =IF(F17=0,1,0) -> 1 | L17: =+D17*E17 -> 2410
B18: 45544 | C18: SMART | D18: 40 | E18: 28.2 | F18: 32 | G18: =IF(F18="","",(F18-E18)*D18) -> 152
B19: 45544 | C19: SMART | D19: 40 | E19: 28.2 | F19: 29.2 | G19: =IF(F19="","",(F19-E19)*D19) -> 40
B20: 45544 | C20: SMART | D20: 50 | E20: 28.2 | F20: 30 | G20: =IF(F20="","",(F20-E20)*D20) -> 90
B21: 45546 | C21: SMART | D21: 100 | E21: 29.5 | F21: 31.94 | G21: =IF(F21="","",(F21-E21)*D21) -> 244
B22: 45579 | C22: ADEL | D22: 25 | E22: 35.5 | F22: 37 | G22: =IF(E22=0,"",IF(F22="","",(F22-E22)*D22)) -> 37.5 | O22: ARASE | P22: 20 | Q22: 58
B23: 45569 | C23: ALMAD | D23: 200 | E23: 5.75 | F23: 6.1 | G23: =IF(E23=0,"",IF(F23="","",(F23-E23)*D23)) -> 70 | O23: ARASE | P23: 20 | Q23: 59
B24: 45560 | C24: ALMAD | D24: 100 | E24: 6.5 | F24: 7.5 | G24: =IF(E24=0,"",IF(F24="","",(F24-E24)*D24)) -> 100 | O24: ARASE | P24: 20 | Q24: 60
B25: 45581 | C25: ALMAD | D25: 100 | E25: 6.2 | F25: 6.9 | G25: =IF(E25=0,"",IF(F25="","",(F25-E25)*D25)) -> 70 | O25: ALARK | P25: 10 | Q25: 96
B26: 45551 | C26: BRLSM | D26: 70 | E26: 14.5 | F26: 15 | G26: =IF(F26="","",(F26-E26)*D26) -> 35
B27: 45582 | C27: ALMAD | D27: 100 | E27: 6.7 | F27: 7.2 | G27: =IF(E27=0,"",IF(F27="","",(F27-E27)*D27)) -> 50 | O27: ALARK | P27: 20 | Q27: 98
B28: 45551 | C28: MARKA | D28: 40 | E28: 54 | F28: 56 | G28: =IF(F28="","",(F28-E28)*D28) -> 80
B29: 45544 | C29: MEGAP | D29: 750 | E29: 2.45 | F29: 2.6 | G29: =IF(F29="","",(F29-E29)*D29) -> 112.5
B30: 45553 | C30: KONTR | D30: 50 | E30: 43.8 | F30: 45 | G30: =IF(F30="","",(F30-E30)*D30) -> 60
B31: 45552 | C31: SMART | D31: 50 | E31: 32 | F31: 35 | G31: =IF(F31="","",(F31-E31)*D31) -> 150
B32: 45560 | C32: BAYRK | D32: 100 | E32: 19.9 | F32: 20 | G32: =IF(F32="","",(F32-E32)*D32) -> 10
B33: 45545 | C33: PRKAB | D33: 50 | E33: 32 | F33: 34 | G33: =IF(F33="","",(F33-E33)*D33) -> 100
B34: 45553 | C34: ADEL | D34: 50 | E34: 44.8 | F34: 47.74 | G34: =IF(F34="","",(F34-E34)*D34) -> 147
B35: 45553 | C35: BAYRK | D35: 50 | E35: 22 | F35: 23.5 | G35: =IF(F35="","",(F35-E35)*D35) -> 75
B36: 45546 | C36: ADEL | D36: 50 | E36: 46 | G36: =IF(E36=0,"",IF(F36="","",(F36-E36)*D36)) | I36: =+E36*1.1 -> 50.6 | K36: =IF(F36=0,1,0) -> 1 | L36: =+D36*E36 -> 2300 | O36: ALARK | P36: 30 | Q36: 100
B37: 45555 | C37: BURVA | D37: 10 | E37: 124 | F37: 135 | G37: =IF(F37="","",(F37-E37)*D37) -> 110
B38: 45561 | C38: BAYRK | D38: 100 | E38: 19.3 | F38: 19.75 | G38: =IF(F38="","",(F38-E38)*D38) -> 45 | O38: ARENA | P38: 40 | Q38: 32
B39: 45586 | C39: ADEL | D39: 15 | E39: 35.14 | F39: 43.06 | G39: =IF(E39=0,"",IF(F39="","",(F39-E39)*D39)) -> 118.8 | O39: ARENA | P39: 40 | Q39: 32.5
B40: 45555 | C40: ERCB | D40: 20 | E40: 98 | F40: 100 | G40: =IF(F40="","",(F40-E40)*D40) -> 40
...

Sheet ALSAT
C1: 1500 | E1: 1000 | R1: 36
C2: SATIŞ | E2: ALIŞ
C3: ADET | D3: FİYAT | E3: ADET | F3: FİYAT | H3: ADET | I3: DURUM | J3: MALİYET | K3: Haftalık | L3: 1 Aylık | M3: 3 Aylık | N3: 6 Aylık | O3: YTD | P3: 1 Yıllık | Q3: 3 Yıllık | R3: 5 Yıllık | T3: SATIŞ SKOR | U3: ALIŞ SKOR | W3: TABAN | X3: TAVAN | AB3: AL/SAT
A4: ADEL | B4: =SUMIFS(Tablo2[Son Fiyat],Tablo2[Şirket],A4) -> 32 | C4: =H4/4 -> 246.25 | D4: =IFERROR(Z4*1.1,"") -> 42.241346 | E4: =IF(U4<0.4,0,IFERROR($E$1/F4,0)*U4) -> 31.25 | F4: =IF(U4<0.5,B4*0.95,B4*0.98) -> 31.36 | G4: =+F4*E4 -> 980 | H4: =SUMIFS(Portföy!$C$2:$C$93,Portföy!$A$2:$A$93,ALSAT!A4) -> 985 | I4: =SUMIFS(Portföy!$H$2:$H$93,Portföy!$A$2:$A$93,ALSAT!A4) -> -4868.74 | J4: =IF(SUMIFS(Portföy!$D$2:$D$93,Portföy!$A$2:$A$93,ALSAT!A4)<0,0,SUMIFS(Portföy!$D$2:$D$93,Portföy!$A$2:$A$93,ALSAT!A4)) -> 36.942883 | K4: =VLOOKUP($A4,Tablo2[],3,FALSE)/100 -> -0.0332 | L4: =VLOOKUP($A4,Tablo2[],4,FALSE)/100 -> -0.0442 | M4: =VLOOKUP($A4,Tablo2[],5,FALSE)/100 -> -0.2184 | N4: =VLOOKUP($A4,Tablo2[],6,FALSE)/100 -> -0.3399 | O4: =VLOOKUP($A4,Tablo2[],7,FALSE)/100 -> -0.0442 | P4: =VLOOKUP($A4,Tablo2[],8,FALSE)/100 -> -0.2138 | Q4: =VLOOKUP($A4,Tablo2[],9,FALSE)/100 -> 11.2605 | R4: =VLOOKUP($A4,Tablo2[],10,FALSE)/100 -> 20.0526 | S4: =IF(K4<0,8,4)+IF(L4<0,7,3)+IF(M4<0,6,3)+IF(N4<0,5,2)+IF(O4<0,4,2)+IF(P4<0.5,3,1)+IF(Q4<1,2,1)+IF(R4<2,1,0) -> 34 | T4: =(IF(J4<B4,32,0)+IF(B4>J4*1.1,32,0)+(36-S4))/100 -> 0.02 | U4: =1-T4 -> 0.98 | W4: =+B4*0.9 -> 28.8 | X4: =+B4*1.1 -> 35.2 | Z4: =SUMIFS(Sayfa4!$L$3:$L$3000,Sayfa4!$C$3:$C$3000,ALSAT!A4,Sayfa4!$K$3:$K$3000,"1")/SUMIFS(Sayfa4!$D$3:$D$3000,Sayfa4!$C$3:$C$3000,ALSAT!A4,Sayfa4!$K$3:$K$3000,"1") -> 38.401223
A5: ALCTL | B5: =SUMIFS(Tablo2[Son Fiyat],Tablo2[Şirket],A5) -> 137.7 | C5: =H5/4 -> 0 | D5: =IFERROR(Z5*1.1,"") | E5: =IF(U5<0.4,0,IFERROR($E$1/F5,0)*U5) -> 0 | F5: =IF(U5<0.5,B5*0.95,B5*0.98) -> 130.815 | G5: =+F5*E5 -> 0 | H5: =SUMIFS(Portföy!$C$2:$C$93,Portföy!$A$2:$A$93,ALSAT!A5) -> 0 | I5: =SUMIFS(Portföy!$H$2:$H$93,Portföy!$A$2:$A$93,ALSAT!A5) -> 125 | J5: =IF(SUMIFS(Portföy!$D$2:$D$93,Portföy!$A$2:$A$93,ALSAT!A5)<0,0,SUMIFS(Portföy!$D$2:$D$93,Portföy!$A$2:$A$93,ALSAT!A5)) -> 0 | K5: =VLOOKUP($A5,Tablo2[],3,FALSE)/100 -> 0.0066 | L5: =VLOOKUP($A5,Tablo2[],4,FALSE)/100 -> 0.1485 | M5: =VLOOKUP($A5,Tablo2[],5,FALSE)/100 -> 0.1485 | N5: =VLOOKUP($A5,Tablo2[],6,FALSE)/100 -> 0.4292 | O5: =VLOOKUP($A5,Tablo2[],7,FALSE)/100 -> 0.1485 | P5: =VLOOKUP($A5,Tablo2[],8,FALSE)/100 -> 0.2978 | Q5: =VLOOKUP($A5,Tablo2[],9,FALSE)/100 -> 3.9532 | R5: =VLOOKUP($A5,Tablo2[],10,FALSE)/100 -> 7.8383 | S5: =IF(K5<0,8,4)+IF(L5<0,7,3)+IF(M5<0,6,3)+IF(N5<0,5,2)+IF(O5<0,4,2)+IF(P5<0.5,3,1)+IF(Q5<1,2,1)+IF(R5<2,1,0) -> 18 | T5: =(IF(J5<B5,32,0)+IF(B5>J5*1.1,32,0)+(36-S5))/100 -> 0.82 | U5: =1-T5 -> 0.18 | W5: =+B5*0.9 -> 123.93 | X5: =+B5*1.1 -> 151.47 | Z5: =SUMIFS(Sayfa4!$L$3:$L$3000,Sayfa4!$C$3:$C$3000,ALSAT!A5,Sayfa4!$K$3:$K$3000,"1")/SUMIFS(Sayfa4!$D$3:$D$3000,Sayfa4!$C$3:$C$3000,ALSAT!A5,Sayfa4!$K$3:$K$3000,"1") -> #DIV/0!
A6: ARASE | B6: =SUMIFS(Tablo2[Son Fiyat],Tablo2[Şirket],A6) -> 49.72 | C6: =H6/4 -> 102.5 | D6: =IFERROR(Z6*1.1,"") -> 59.047593 | E6: =IF(U6<0.4,0,IFERROR($E$1/F6,0)*U6) -> 20.317862 | F6: =IF(U6<0.5,B6*0.95,B6*0.98) -> 48.7256 | G6: =+F6*E6 -> 990 | H6: =SUMIFS(Portföy!$C$2:$C$93,Portföy!$A$2:$A$93,ALSAT!A6) -> 410 | I6: =SUMIFS(Portföy!$H$2:$H$93,Portföy!$A$2:$A$93,ALSAT!A6) -> -3544.55 | J6: =IF(SUMIFS(Portföy!$D$2:$D$93,Portföy!$A$2:$A$93,ALSAT!A6)<0,0,SUMIFS(Portföy!$D$2:$D$93,Portföy!$A$2:$A$93,ALSAT!A6)) -> 58.365244 | K6: =VLOOKUP($A6,Tablo2[],3,FALSE)/100 -> -0.0213 | L6: =VLOOKUP($A6,Tablo2[],4,FALSE)/100 -> -0.1121 | M6: =VLOOKUP($A6,Tablo2[],5,FALSE)/100 -> -0.1292 | N6: =VLOOKUP($A6,Tablo2[],6,FALSE)/100 -> -0.0582 | O6: =VLOOKUP($A6,Tablo2[],7,FALSE)/100 -> -0.1121 | P6: =VLOOKUP($A6,Tablo2[],8,FALSE)/100 -> -0.2153 | Q6: =VLOOKUP($A6,Tablo2[],9,FALSE)/100 -> 1.1257 | R6: =VLOOKUP($A6,Tablo2[],10,FALSE)/100 -> 0 | S6: =IF(K6<0,8,4)+IF(L6<0,7,3)+IF(M6<0,6,3)+IF(N6<0,5,2)+IF(O6<0,4,2)+IF(P6<0.5,3,1)+IF(Q6<1,2,1)+IF(R6<2,1,0) -> 35 | T6: =(IF(J6<B6,32,0)+IF(B6>J6*1.1,32,0)+(36-S6))/100 -> 0.01 | U6: =1-T6 -> 0.99 | W6: =+B6*0.9 -> 44.748 | X6: =+B6*1.1 -> 54.692 | Z6: =SUMIFS(Sayfa4!$L$3:$L$3000,Sayfa4!$C$3:$C$3000,ALSAT!A6,Sayfa4!$K$3:$K$3000,"1")/SUMIFS(Sayfa4!$D$3:$D$3000,Sayfa4!$C$3:$C$3000,ALSAT!A6,Sayfa4!$K$3:$K$3000,"1") -> 53.67963
A7: ASELS | B7: =SUMIFS(Tablo2[Son Fiyat],Tablo2[Şirket],A7) -> 88.7 | C7: =H7/4 -> 0.5 | D7: =IFERROR(Z7*1.1,"") -> 82.5 | E7: =IF(U7<0.4,0,IFERROR($E$1/F7,0)*U7) -> 0 | F7: =IF(U7<0.5,B7*0.95,B7*0.98) -> 84.265 | G7: =+F7*E7 -> 0 | H7: =SUMIFS(Portföy!$C$2:$C$93,Portföy!$A$2:$A$93,ALSAT!A7) -> 2 | I7: =SUMIFS(Portföy!$H$2:$H$93,Portföy!$A$2:$A$93,ALSAT!A7) -> 27.4 | J7: =IF(SUMIFS(Portföy!$D$2:$D$93,Portföy!$A$2:$A$93,ALSAT!A7)<0,0,SUMIFS(Portföy!$D$2:$D$93,Portföy!$A$2:$A$93,ALSAT!A7)) -> 75 | K7: =VLOOKUP($A7,Tablo2[],3,FALSE)/100 -> 0.0417 | L7: =VLOOKUP($A7,Tablo2[],4,FALSE)/100 -> 0.2234 | M7: =VLOOKUP($A7,Tablo2[],5,FALSE)/100 -> 0.4601 | N7: =VLOOKUP($A7,Tablo2[],6,FALSE)/100 -> 0.4215 | O7: =VLOOKUP($A7,Tablo2[],7,FALSE)/100 -> 0.2234 | P7: =VLOOKUP($A7,Tablo2[],8,FALSE)/100 -> 0.7557 | Q7: =VLOOKUP($A7,Tablo2[],9,FALSE)/100 -> 7.282 | R7: =VLOOKUP($A7,Tablo2[],10,FALSE)/100 -> 14.5342 | S7: =IF(K7<0,8,4)+IF(L7<0,7,3)+IF(M7<0,6,3)+IF(N7<0,5,2)+IF(O7<0,4,2)+IF(P7<0.5,3,1)+IF(Q7<1,2,1)+IF(R7<2,1,0) -> 16 | T7: =(IF(J7<B7,32,0)+IF(B7>J7*1.1,32,0)+(36-S7))/100 -> 0.84 | U7: =1-T7 -> 0.16 | W7: =+B7*0.9 -> 79.83 | X7: =+B7*1.1 -> 97.57 | Z7: =SUMIFS(Sayfa4!$L$3:$L$3000,Sayfa4!$C$3:$C$3000,ALSAT!A7,Sayfa4!$K$3:$K$3000,"1")/SUMIFS(Sayfa4!$D$3:$D$3000,Sayfa4!$C$3:$C$3000,ALSAT!A7,Sayfa4!$K$3:$K$3000,"1") -> 75
A8: ASTOR | B8: =SUMIFS(Tablo2[Son Fiyat],Tablo2[Şirket],A8) -> 117.6 | C8: =H8/4 -> 4.5 | D8: =IFERROR(Z8*1.1,"") -> 132 | E8: =IF(U8<0.4,0,IFERROR($E$1/F8,0)*U8) -> 0 | F8: =IF(U8<0.5,B8*0.95,B8*0.98) -> 111.72 | G8: =+F8*E8 -> 0 | H8: =SUMIFS(Portföy!$C$2:$C$93,Portföy!$A$2:$A$93,ALSAT!A8) -> 18 | I8: =SUMIFS(Portföy!$H$2:$H$93,Portföy!$A$2:$A$93,ALSAT!A8) -> 2280.9 | J8: =IF(SUMIFS(Portföy!$D$2:$D$93,Portföy!$A$2:$A$93,ALSAT!A8)<0,0,SUMIFS(Portföy!$D$2:$D$93,Portföy!$A$2:$A$93,ALSAT!A8)) -> 0 | K8: =VLOOKUP($A8,Tablo2[],3,FALSE)/100 -> -0.0813 | L8: =VLOOKUP($A8,Tablo2[],4,FALSE)/100 -> 0.0325 | M8: =VLOOKUP($A8,Tablo2[],5,FALSE)/100 -> 0.5077 | N8: =VLOOKUP($A8,Tablo2[],6,FALSE)/100 -> 0.2666 | O8: =VLOOKUP($A8,Tablo2[],7,FALSE)/100 -> 0.0325 | P8: =VLOOKUP($A8,Tablo2[],8,FALSE)/100 -> 0.0112 | Q8: =VLOOKUP($A8,Tablo2[],9,FALSE)/100 -> 0 | R8: =VLOOKUP($A8,Tablo2[],10,FALSE)/100 -> 0 | S8: =IF(K8<0,8,4)+IF(L8<0,7,3)+IF(M8<0,6,3)+IF(N8<0,5,2)+IF(O8<0,4,2)+IF(P8<0.5,3,1)+IF(Q8<1,2,1)+IF(R8<2,1,0) -> 24 | T8: =(IF(J8<B8,32,0)+IF(B8>J8*1.1,32,0)+(36-S8))/100 -> 0.76 | U8: =1-T8 -> 0.24 | W8: =+B8*0.9 -> 105.84 | X8: =+B8*1.1 -> 129.36 | Z8: =SUMIFS(Sayfa4!$L$3:$L$3000,Sayfa4!$C$3:$C$3000,ALSAT!A8,Sayfa4!$K$3:$K$3000,"1")/SUMIFS(Sayfa4!$D$3:$D$3000,Sayfa4!$C$3:$C$3000,ALSAT!A8,Sayfa4!$K$3:$K$3000,"1") -> 120
A9: BAYRK | B9: =SUMIFS(Tablo2[Son Fiyat],Tablo2[Şirket],A9) -> 18.35 | C9: =H9/4 -> 180 | D9: =IFERROR(Z9*1.1,"") -> 25.049286 | E9: =IF(U9<0.4,0,IFERROR($E$1/F9,0)*U9) -> 50.047267 | F9: =IF(U9<0.5,B9*0.95,B9*0.98) -> 17.983 | G9: =+F9*E9 -> 900 | H9: =SUMIFS(Portföy!$C$2:$C$93,Portföy!$A$2:$A$93,ALSAT!A9) -> 720 | I9: =SUMIFS(Portföy!$H$2:$H$93,Portföy!$A$2:$A$93,ALSAT!A9) -> -367.95 | J9: =IF(SUMIFS(Portföy!$D$2:$D$93,Portföy!$A$2:$A$93,ALSAT!A9)<0,0,SUMIFS(Portföy!$D$2:$D$93,Portföy!$A$2:$A$93,ALSAT!A9)) -> 18.861042 | K9: =VLOOKUP($A9,Tablo2[],3,FALSE)/100 -> -0.058 | L9: =VLOOKUP($A9,Tablo2[],4,FALSE)/100 -> 0.0522 | M9: =VLOOKUP($A9,Tablo2[],5,FALSE)/100 -> 0.0269 | N9: =VLOOKUP($A9,Tablo2[],6,FALSE)/100 -> -0.2683 | O9: =VLOOKUP($A9,Tablo2[],7,FALSE)/100 -> 0.0522 | P9: =VLOOKUP($A9,Tablo2[],8,FALSE)/100 -> -0.6059 | Q9: =VLOOKUP($A9,Tablo2[],9,FALSE)/100 -> 4.6988 | R9: =VLOOKUP($A9,Tablo2[],10,FALSE)/100 -> 0 | S9: =IF(K9<0,8,4)+IF(L9<0,7,3)+IF(M9<0,6,3)+IF(N9<0,5,2)+IF(O9<0,4,2)+IF(P9<0.5,3,1)+IF(Q9<1,2,1)+IF(R9<2,1,0) -> 26 | T9: =(IF(J9<B9,32,0)+IF(B9>J9*1.1,32,0)+(36-S9))/100 -> 0.1 | U9: =1-T9 -> 0.9 | W9: =+B9*0.9 -> 16.515 | X9: =+B9*1.1 -> 20.185 | Z9: =SUMIFS(Sayfa4!$L$3:$L$3000,Sayfa4!$C$3:$C$3000,ALSAT!A9,Sayfa4!$K$3:$K$3000,"1")/SUMIFS(Sayfa4!$D$3:$D$3000,Sayfa4!$C$3:$C$3000,ALSAT!A9,Sayfa4!$K$3:$K$3000,"1") -> 22.772078
A10: BFREN | B10: =SUMIFS(Tablo2[Son Fiyat],Tablo2[Şirket],A10) -> 640 | C10: =H10/4 -> 1 | D10: =IFERROR(Z10*1.1,"") -> 765.325 | E10: =IF(U10<0.4,0,IFERROR($E$1/F10,0)*U10) -> 1.5625 | F10: =IF(U10<0.5,B10*0.95,B10*0.98) -> 627.2 | G10: =+F10*E10 -> 980 | H10: =SUMIFS(Portföy!$C$2:$C$93,Portföy!$A$2:$A$93,ALSAT!A10) -> 4 | I10: =SUMIFS(Portföy!$H$2:$H$93,Portföy!$A$2:$A$93,ALSAT!A10) -> -168 | J10: =IF(SUMIFS(Portföy!$D$2:$D$93,Portföy!$A$2:$A$93,ALSAT!A10)<0,0,SUMIFS(Portföy!$D$2:$D$93,Portföy!$A$2:$A$93,ALSAT!A10)) -> 682 | K10: =VLOOKUP($A10,Tablo2[],3,FALSE)/100 -> -0.0184 | L10: =VLOOKUP($A10,Tablo2[],4,FALSE)/100 -> -0.0567 | M10: =VLOOKUP($A10,Tablo2[],5,FALSE)/100 -> -0.203 | N10: =VLOOKUP($A10,Tablo2[],6,FALSE)/100 -> -0.2104 | O10: =VLOOKUP($A10,Tablo2[],7,FALSE)/100 -> -0.0567 | P10: =VLOOKUP($A10,Tablo2[],8,FALSE)/100 -> -0.293 | Q10: =VLOOKUP($A10,Tablo2[],9,FALSE)/100 -> 5.5153 | R10: =VLOOKUP($A10,Tablo2[],10,FALSE)/100 -> 26.1416 | S10: =IF(K10<0,8,4)+IF(L10<0,7,3)+IF(M10<0,6,3)+IF(N10<0,5,2)+IF(O10<0,4,2)+IF(P10<0.5,3,1)+IF(Q10<1,2,1)+IF(R10<2,1,0) -> 34 | T10: =(IF(J10<B10,32,0)+IF(B10>J10*1.1,32,0)+(36-S10))/100 -> 0.02 | U10: =1-T10 -> 0.98 | W10: =+B10*0.9 -> 576 | X10: =+B10*1.1 -> 704 | Z10: =SUMIFS(Sayfa4!$L$3:$L$3000,Sayfa4!$C$3:$C$3000,ALSAT!A10,Sayfa4!$K$3:$K$3000,"1")/SUMIFS(Sayfa4!$D$3:$D$3000,Sayfa4!$C$3:$C$3000,ALSAT!A10,Sayfa4!$K$3:$K$3000,"1") -> 695.75
A11: BRLSM | B11: =SUMIFS(Tablo2[Son Fiyat],Tablo2[Şirket],A11) -> 14.97 | C11: =H11/4 -> 475 | D11: =IFERROR(Z11*1.1,"") -> 17.1578 | E11: =IF(U11<0.4,0,IFERROR($E$1/F11,0)*U11) -> 63.39209 | F11: =IF(U11<0.5,B11*0.95,B11*0.98) -> 14.6706 | G11: =+F11*E11 -> 930 | H11: =SUMIFS(Portföy!$C$2:$C$93,Portföy!$A$2:$A$93,ALSAT!A11) -> 1900 | I11: =SUMIFS(Portföy!$H$2:$H$93,Portföy!$A$2:$A$93,ALSAT!A11) -> -13860.1 | J11: =IF(SUMIFS(Portföy!$D$2:$D$93,Portföy!$A$2:$A$93,ALSAT!A11)<0,0,SUMIFS(Portföy!$D$2:$D$93,Portföy!$A$2:$A$93,ALSAT!A11)) -> 22.264789 | K11: =VLOOKUP($A11,Tablo2[],3,FALSE)/100 -> -0.0267 | L11: =VLOOKUP($A11,Tablo2[],4,FALSE)/100 -> 0.002 | M11: =VLOOKUP($A11,Tablo2[],5,FALSE)/100 -> -0.0754 | N11: =VLOOKUP($A11,Tablo2[],6,FALSE)/100 -> -0.1864 | O11: =VLOOKUP($A11,Tablo2[],7,FALSE)/100 -> 0.002 | P11: =VLOOKUP($A11,Tablo2[],8,FALSE)/100 -> -0.5444 | Q11: =VLOOKUP($A11,Tablo2[],9,FALSE)/100 -> 2.3193 | R11: =VLOOKUP($A11,Tablo2[],10,FALSE)/100 -> 0 | S11: =IF(K11<0,8,4)+IF(L11<0,7,3)+IF(M11<0,6,3)+IF(N11<0,5,2)+IF(O11<0,4,2)+IF(P11<0.5,3,1)+IF(Q11<1,2,1)+IF(R11<2,1,0) -> 29 | T11: =(IF(J11<B11,32,0)+IF(B11>J11*1.1,32,0)+(36-S11))/100 -> 0.07 | U11: =1-T11 -> 0.93 | W11: =+B11*0.9 -> 13.473 | X11: =+B11*1.1 -> 16.467 | Z11: =SUMIFS(Sayfa4!$L$3:$L$3000,Sayfa4!$C$3:$C$3000,ALSAT!A11,Sayfa4!$K$3:$K$3000,"1")/SUMIFS(Sayfa4!$D$3:$D$3000,Sayfa4!$C$3:$C$3000,ALSAT!A11,Sayfa4!$K$3:$K$3000,"1") -> 15.598
A12: BURVA | B12: =SUMIFS(Tablo2[Son Fiyat],Tablo2[Şirket],A12) -> 105.8 | C12: =H12/4 -> 3.75 | D12: =IFERROR(Z12*1.1,"") -> 139.99333 | E12: =IF(U12<0.4,0,IFERROR($E$1/F12,0)*U12) -> 0 | F12: =IF(U12<0.5,B12*0.95,B12*0.98) -> 100.51 | G12: =+F12*E12 -> 0 | H12: =SUMIFS(Portföy!$C$2:$C$93,Portföy!$A$2:$A$93,ALSAT!A12) -> 15 | I12: =SUMIFS(Portföy!$H$2:$H$93,Portföy!$A$2:$A$93,ALSAT!A12) -> 506.3 | J12: =IF(SUMIFS(Portföy!$D$2:$D$93,Portföy!$A$2:$A$93,ALSAT!A12)<0,0,SUMIFS(Portföy!$D$2:$D$93,Portföy!$A$2:$A$93,ALSAT!A12)) -> 72.046667 | K12: =VLOOKUP($A12,Tablo2[],3,FALSE)/100 -> -0.0204 | L12: =VLOOKUP($A12,Tablo2[],4,FALSE)/100 -> -0.0477 | M12: =VLOOKUP($A12,Tablo2[],5,FALSE)/100 -> -0.2399 | N12: =VLOOKUP($A12,Tablo2[],6,FALSE)/100 -> -0.0918 | O12: =VLOOKUP($A12,Tablo2[],7,FALSE)/100 -> -0.0477 | P12: =VLOOKUP($A12,Tablo2[],8,FALSE)/100 -> -0.1669 | Q12: =VLOOKUP($A12,Tablo2[],9,FALSE)/100 -> 3.2252 | R12: =VLOOKUP($A12,Tablo2[],10,FALSE)/100 -> 7.1073 | S12: =IF(K12<0,8,4)+IF(L12<0,7,3)+IF(M12<0,6,3)+IF(N12<0,5,2)+IF(O12<0,4,2)+IF(P12<0.5,3,1)+IF(Q12<1,2,1)+IF(R12<2,1,0) -> 34 | T12: =(IF(J12<B12,32,0)+IF(B12>J12*1.1,32,0)+(36-S12))/100 -> 0.66 | U12: =1-T12 -> 0.34 | W12: =+B12*0.9 -> 95.22 | X12: =+B12*1.1 -> 116.38 | Z12: =SUMIFS(Sayfa4!$L$3:$L$3000,Sayfa4!$C$3:$C$3000,ALSAT!A12,Sayfa4!$K$3:$K$3000,"1")/SUMIFS(Sayfa4!$D$3:$D$3000,Sayfa4!$C$3:$C$3000,ALSAT!A12,Sayfa4!$K$3:$K$3000,"1") -> 127.26667
A13: BVSAN | B13: =SUMIFS(Tablo2[Son Fiyat],Tablo2[Şirket],A13) -> 105.9 | C13: =H13/4 -> 0 | D13: =IFERROR(Z13*1.1,"") | E13: =IF(U13<0.4,0,IFERROR($E$1/F13,0)*U13) -> 0 | F13: =IF(U13<0.5,B13*0.95,B13*0.98) -> 100.605 | G13: =+F13*E13 -> 0 | H13: =SUMIFS(Portföy!$C$2:$C$93,Portföy!$A$2:$A$93,ALSAT!A13) -> 0 | I13: =SUMIFS(Portföy!$H$2:$H$93,Portföy!$A$2:$A$93,ALSAT!A13) -> 246.2 | J13: =IF(SUMIFS(Portföy!$D$2:$D$93,Portföy!$A$2:$A$93,ALSAT!A13)<0,0,SUMIFS(Portföy!$D$2:$D$93,Portföy!$A$2:$A$93,ALSAT!A13)) -> 0 | K13: =VLOOKUP($A13,Tablo2[],3,FALSE)/100 -> -0.0194 | L13: =VLOOKUP($A13,Tablo2[],4,FALSE)/100 -> 0.1786 | M13: =VLOOKUP($A13,Tablo2[],5,FALSE)/100 -> 0.2744 | N13: =VLOOKUP($A13,Tablo2[],6,FALSE)/100 -> 0.0019 | O13: =VLOOKUP($A13,Tablo2[],7,FALSE)/100 -> 0.1786 | P13: =VLOOKUP($A13,Tablo2[],8,FALSE)/100 -> 0.0706 | Q13: =VLOOKUP($A13,Tablo2[],9,FALSE)/100 -> 0 | R13: =VLOOKUP($A13,Tablo2[],10,FALSE)/100 -> 0 | S13: =IF(K13<0,8,4)+IF(L13<0,7,3)+IF(M13<0,6,3)+IF(N13<0,5,2)+IF(O13<0,4,2)+IF(P13<0.5,3,1)+IF(Q13<1,2,1)+IF(R13<2,1,0) -> 24 | T13: =(IF(J13<B13,32,0)+IF(B13>J13*1.1,32,0)+(36-S13))/100 -> 0.76 | U13: =1-T13 -> 0.24 | W13: =+B13*0.9 -> 95.31 | X13: =+B13*1.1 -> 116.49 | Z13: =SUMIFS(Sayfa4!$L$3:$L$3000,Sayfa4!$C$3:$C$3000,ALSAT!A13,Sayfa4!$K$3:$K$3000,"1")/SUMIFS(Sayfa4!$D$3:$D$3000,Sayfa4!$C$3:$C$3000,ALSAT!A13,Sayfa4!$K$3:$K$3000,"1") -> #DIV/0!
A14: CEOEM | B14: =SUMIFS(Tablo2[Son Fiyat],Tablo2[Şirket],A14) -> 25 | C14: =H14/4 -> 32.5 | D14: =IFERROR(Z14*1.1,"") -> 30.080769 | E14: =IF(U14<0.4,0,IFERROR($E$1/F14,0)*U14) -> 40.408163 | F14: =IF(U14<0.5,B14*0.95,B14*0.98) -> 24.5 | G14: =+F14*E14 -> 990 | H14: =SUMIFS(Portföy!$C$2:$C$93,Portföy!$A$2:$A$93,ALSAT!A14) -> 130 | I14: =SUMIFS(Portföy!$H$2:$H$93,Portföy!$A$2:$A$93,ALSAT!A14) -> -27.3 | J14: =IF(SUMIFS(Portföy!$D$2:$D$93,Portföy!$A$2:$A$93,ALSAT!A14)<0,0,SUMIFS(Portföy!$D$2:$D$93,Portföy!$A$2:$A$93,ALSAT!A14)) -> 25.21 | K14: =VLOOKUP($A14,Tablo2[],3,FALSE)/100 -> -0.0443 | L14: =VLOOKUP($A14,Tablo2[],4,FALSE)/100 -> -0.1033 | M14: =VLOOKUP($A14,Tablo2[],5,FALSE)/100 -> -0.5895 | N14: =VLOOKUP($A14,Tablo2[],6,FALSE)/100 -> -0.2183 | O14: =VLOOKUP($A14,Tablo2[],7,FALSE)/100 -> -0.1033 | P14: =VLOOKUP($A14,Tablo2[],8,FALSE)/100 -> 0.2401 | Q14: =VLOOKUP($A14,Tablo2[],9,FALSE)/100 -> 0.7781 | R14: =VLOOKUP($A14,Tablo2[],10,FALSE)/100 -> 7.1433 | S14: =IF(K14<0,8,4)+IF(L14<0,7,3)+IF(M14<0,6,3)+IF(N14<0,5,2)+IF(O14<0,4,2)+IF(P14<0.5,3,1)+IF(Q14<1,2,1)+IF(R14<2,1,0) -> 35 | T14: =(IF(J14<B14,32,0)+IF(B14>J14*1.1,32,0)+(36-S14))/100 -> 0.01 | U14: =1-T14 -> 0.99 | W14: =+B14*0.9 -> 22.5 | X14: =+B14*1.1 -> 27.5 | Z14: =SUMIFS(Sayfa4!$L$3:$L$3000,Sayfa4!$C$3:$C$3000,ALSAT!A14,Sayfa4!$K$3:$K$3000,"1")/SUMIFS(Sayfa4!$D$3:$D$3000,Sayfa4!$C$3:$C$3000,ALSAT!A14,Sayfa4!$K$3:$K$3000,"1") -> 27.346154
A15: CIMSA | B15: =SUMIFS(Tablo2[Son Fiyat],Tablo2[Şirket],A15) -> 53.35 | C15: =H15/4 -> 1.25 | D15: =IFERROR(Z15*1.1,"") -> 55 | E15: =IF(U15<0.4,0,IFERROR($E$1/F15,0)*U15) -> 0 | F15: =IF(U15<0.5,B15*0.95,B15*0.98) -> 50.6825 | G15: =+F15*E15 -> 0 | H15: =SUMIFS(Portföy!$C$2:$C$93,Portföy!$A$2:$A$93,ALSAT!A15) -> 5 | I15: =SUMIFS(Portföy!$H$2:$H$93,Portföy!$A$2:$A$93,ALSAT!A15) -> 183.29 | J15: =IF(SUMIFS(Portföy!$D$2:$D$93,Portföy!$A$2:$A$93,ALSAT!A15)<0,0,SUMIFS(Portföy!$D$2:$D$93,Portföy!$A$2:$A$93,ALSAT!A15)) -> 16.692 | K15: =VLOOKUP($A15,Tablo2[],3,FALSE)/100 -> -0.0387 | L15: =VLOOKUP($A15,Tablo2[],4,FALSE)/100 -> 0.1448 | M15: =VLOOKUP($A15,Tablo2[],5,FALSE)/100 -> 0.5304 | N15: =VLOOKUP($A15,Tablo2[],6,FALSE)/100 -> 0.5821 | O15: =VLOOKUP($A15,Tablo2[],7,FALSE)/100 -> 0.1448 | P15: =VLOOKUP($A15,Tablo2[],8,FALSE)/100 -> 0.6756 | Q15: =VLOOKUP($A15,Tablo2[],9,FALSE)/100 -> 11.2926 | R15: =VLOOKUP($A15,Tablo2[],10,FALSE)/100 -> 41.0079 | S15: =IF(K15<0,8,4)+IF(L15<0,7,3)+IF(M15<0,6,3)+IF(N15<0,5,2)+IF(O15<0,4,2)+IF(P15<0.5,3,1)+IF(Q15<1,2,1)+IF(R15<2,1,0) -> 20 | T15: =(IF(J15<B15,32,0)+IF(B15>J15*1.1,32,0)+(36-S15))/100 -> 0.8 | U15: =1-T15 -> 0.2 | W15: =+B15*0.9 -> 48.015 | X15: =+B15*1.1 -> 58.685 | Z15: =SUMIFS(Sayfa4!$L$3:$L$3000,Sayfa4!$C$3:$C$3000,ALSAT!A15,Sayfa4!$K$3:$K$3000,"1")/SUMIFS(Sayfa4!$D$3:$D$3000,Sayfa4!$C$3:$C$3000,ALSAT!A15,Sayfa4!$K$3:$K$3000,"1") -> 50
... A51: YEOTK | B51: =SUMIFS(Tablo2[Son Fiyat],Tablo2[Şirket],A51) -> 54.5 | C51: =H51/4 -> 0 | D51: =IFERROR(Z51*1.1,"") | E51: =IF(U51<0.4,0,IFERROR($E$1/F51,0)*U51) -> 0 | F51: =IF(U51<0.5,B51*0.95,B51*0.98) -> 51.775 | G51: =+F51*E51 -> 0 | H51: =SUMIFS(Portföy!$C$2:$C$93,Portföy!$A$2:$A$93,ALSAT!A51) -> 0 | I51: =SUMIFS(Portföy!$H$2:$H$93,Portföy!$A$2:$A$93,ALSAT!A51) -> 574.15 | J51: =IF(SUMIFS(Portföy!$D$2:$D$93,Portföy!$A$2:$A$93,ALSAT!A51)<0,0,SUMIFS(Portföy!$D$2:$D$93,Portföy!$A$2:$A$93,ALSAT!A51)) -> 0 | K51: =VLOOKUP($A51,Tablo2[],3,FALSE)/100 -> 0.0273 | L51: =VLOOKUP($A51,Tablo2[],4,FALSE)/100 -> 0.0542 | M51: =VLOOKUP($A51,Tablo2[],5,FALSE)/100 -> 0.0693 | N51: =VLOOKUP($A51,Tablo2[],6,FALSE)/100 -> -0.0789 | O51: =VLOOKUP($A51,Tablo2[],7,FALSE)/100 -> 0.0542 | P51: =VLOOKUP($A51,Tablo2[],8,FALSE)/100 -> -0.0851 | Q51: =VLOOKUP($A51,Tablo2[],9,FALSE)/100 -> 12.7626 | R51: =VLOOKUP($A51,Tablo2[],10,FALSE)/100 -> 0 | S51: =IF(K51<0,8,4)+IF(L51<0,7,3)+IF(M51<0,6,3)+IF(N51<0,5,2)+IF(O51<0,4,2)+IF(P51<0.5,3,1)+IF(Q51<1,2,1)+IF(R51<2,1,0) -> 22 | T51: =(IF(J51<B51,32,0)+IF(B51>J51*1.1,32,0)+(36-S51))/100 -> 0.78 | U51: =1-T51 -> 0.22 | W51: =+B51*0.9 -> 49.05 | X51: =+B51*1.1 -> 59.95 | Z51: =SUMIFS(Sayfa4!$L$3:$L$3000,Sayfa4!$C$3:$C$3000,ALSAT!A51,Sayfa4!$K$3:$K$3000,"1")/SUMIFS(Sayfa4!$D$3:$D$3000,Sayfa4!$C$3:$C$3000,ALSAT!A51,Sayfa4!$K$3:$K$3000,"1") -> #DIV/0!
Z52: =SUMIFS(Sayfa4!$L$3:$L$3000,Sayfa4!$C$3:$C$3000,ALSAT!A52,Sayfa4!$K$3:$K$3000,"1")/SUMIFS(Sayfa4!$D$3:$D$3000,Sayfa4!$C$3:$C$3000,ALSAT!A52,Sayfa4!$K$3:$K$3000,"1") -> #DIV/0!
Z53: =SUMIFS(Sayfa4!$L$3:$L$3000,Sayfa4!$C$3:$C$3000,ALSAT!A53,Sayfa4!$K$3:$K$3000,"1")/SUMIFS(Sayfa4!$D$3:$D$3000,Sayfa4!$C$3:$C$3000,ALSAT!A53,Sayfa4!$K$3:$K$3000,"1") -> #DIV/0!
Z54: =SUMIFS(Sayfa4!$L$3:$L$3000,Sayfa4!$C$3:$C$3000,ALSAT!A54,Sayfa4!$K$3:$K$3000,"1")/SUMIFS(Sayfa4!$D$3:$D$3000,Sayfa4!$C$3:$C$3000,ALSAT!A54,Sayfa4!$K$3:$K$3000,"1") -> #DIV/0!
Z55: =SUMIFS(Sayfa4!$L$3:$L$3000,Sayfa4!$C$3:$C$3000,ALSAT!A55,Sayfa4!$K$3:$K$3000,"1")/SUMIFS(Sayfa4!$D$3:$D$3000,Sayfa4!$C$3:$C$3000,ALSAT!A55,Sayfa4!$K$3:$K$3000,"1") -> #DIV/0!
Z56: =SUMIFS(Sayfa4!$L$3:$L$3000,Sayfa4!$C$3:$C$3000,ALSAT!A56,Sayfa4!$K$3:$K$3000,"1")/SUMIFS(Sayfa4!$D$3:$D$3000,Sayfa4!$C$3:$C$3000,ALSAT!A56,Sayfa4!$K$3:$K$3000,"1") -> #DIV/0!
Z57: =SUMIFS(Sayfa4!$L$3:$L$3000,Sayfa4!$C$3:$C$3000,ALSAT!A57,Sayfa4!$K$3:$K$3000,"1")/SUMIFS(Sayfa4!$D$3:$D$3000,Sayfa4!$C$3:$C$3000,ALSAT!A57,Sayfa4!$K$3:$K$3000,"1") -> #DIV/0!
Z58: =SUMIFS(Sayfa4!$L$3:$L$3000,Sayfa4!$C$3:$C$3000,ALSAT!A58,Sayfa4!$K$3:$K$3000,"1")/SUMIFS(Sayfa4!$D$3:$D$3000,Sayfa4!$C$3:$C$3000,ALSAT!A58,Sayfa4!$K$3:$K$3000,"1") -> #DIV/0!
Z59: =SUMIFS(Sayfa4!$L$3:$L$3000,Sayfa4!$C$3:$C$3000,ALSAT!A59,Sayfa4!$K$3:$K$3000,"1")/SUMIFS(Sayfa4!$D$3:$D$3000,Sayfa4!$C$3:$C$3000,ALSAT!A59,Sayfa4!$K$3:$K$3000,"1") -> #DIV/0!
Z60: =SUMIFS(Sayfa4!$L$3:$L$3000,Sayfa4!$C$3:$C$3000,ALSAT!A60,Sayfa4!$K$3:$K$3000,"1")/SUMIFS(Sayfa4!$D$3:$D$3000,Sayfa4!$C$3:$C$3000,ALSAT!A60,Sayfa4!$K$3:$K$3000,"1") -> #DIV/0!
Z61: =SUMIFS(Sayfa4!$L$3:$L$3000,Sayfa4!$C$3:$C$3000,ALSAT!A61,Sayfa4!$K$3:$K$3000,"1")/SUMIFS(Sayfa4!$D$3:$D$3000,Sayfa4!$C$3:$C$3000,ALSAT!A61,Sayfa4!$K$3:$K$3000,"1") -> #DIV/0!
Z62: =SUMIFS(Sayfa4!$L$3:$L$3000,Sayfa4!$C$3:$C$3000,ALSAT!A62,Sayfa4!$K$3:$K$3000,"1")/SUMIFS(Sayfa4!$D$3:$D$3000,Sayfa4!$C$3:$C$3000,ALSAT!A62,Sayfa4!$K$3:$K$3000,"1") -> #DIV/0!
Z63: =SUMIFS(Sayfa4!$L$3:$L$3000,Sayfa4!$C$3:$C$3000,ALSAT!A63,Sayfa4!$K$3:$K$3000,"1")/SUMIFS(Sayfa4!$D$3:$D$3000,Sayfa4!$C$3:$C$3000,ALSAT!A63,Sayfa4!$K$3:$K$3000,"1") -> #DIV/0!
... Z116: =SUMIFS(Sayfa4!$L$3:$L$3000,Sayfa4!$C$3:$C$3000,ALSAT!A116,Sayfa4!$K$3:$K$3000,"1")/SUMIFS(Sayfa4!$D$3:$D$3000,Sayfa4!$C$3:$C$3000,ALSAT!A116,Sayfa4!$K$3:$K$3000,"1") -> #DIV/0!
Z117: =+_xlfn.MINIFS(Sayfa4!$E$3:$E$3000,Sayfa4!$C$3:$C$3000,A117,Sayfa4!$K$3:$K$3000,"1") -> 0
Z118: =+_xlfn.MINIFS(Sayfa4!$E$3:$E$3000,Sayfa4!$C$3:$C$3000,A118,Sayfa4!$K$3:$K$3000,"1") -> 0
Z119: =+_xlfn.MINIFS(Sayfa4!$E$3:$E$3000,Sayfa4!$C$3:$C$3000,A119,Sayfa4!$K$3:$K$3000,"1") -> 0
Z120: =+_xlfn.MINIFS(Sayfa4!$E$3:$E$3000,Sayfa4!$C$3:$C$3000,A120,Sayfa4!$K$3:$K$3000,"1") -> 0
Z121: =+_xlfn.MINIFS(Sayfa4!$E$3:$E$3000,Sayfa4!$C$3:$C$3000,A121,Sayfa4!$K$3:$K$3000,"1") -> 0

Sheet işlem btc
A1: Tarih | B1: Hisse | C1: İşlem | D1: Adet | E1: Fiyat | F1: Toplam
A2: 45619 | B2: PIXEL | C2: ALIŞ | D2: 116.8 | E2: 0.214 | F2: =+E2*D2 -> 24.9952
A3: 45619 | B3: GRT | C3: ALIŞ | D3: 100 | E3: 0.25 | F3: =+E3*D3 -> 25
A4: 45619 | B4: PEPE | C4: ALIŞ | D4: 1144164 | E4: 2.185e-05 | F4: =+E4*D4 -> 24.999983
A5: 45619 | B5: PEPE | C5: SATIŞ | D5: 0 | E5: 2.185e-05 | F5: =+E5*D5 -> 0
A6: 45619 | B6: BONK | C6: ALIŞ | D6: 491159 | E6: 5.09e-05 | F6: =+E6*D6 -> 24.999993
