Workbook

Sheet Sayfa2
A1: =+C1*0.5 -> 22861.5 | B1: =+C1*0.75 -> 34292.25 | C1: =TODAY() -> 45723 | D1: =+C1*1.25 -> 57153.75 | F1: =+C1*1.5 -> 68584.5 | G1: =+C1*2 -> 91446 | J1: 45627
J2: 45657
A3: 1 | B3: 45627 | C3: 2500 | D3: =SUMIFS(Tablo1[Tutar],Tablo1[Tarih],Sayfa2!B3) -> 5739.04 | E3: =+D3 -> 5739.04 | F3: =D3 -> 5739.04 | H3: Samet | I3: 7500 | J3: =SUMIFS(Tablo1[Tutar],Tablo1[Harcama],Sayfa2!H3,Tablo1[Tarih],">="&Sayfa2!J$1,Tablo1[Tarih],"<="&Sayfa2!J$2) -> 7429.31 | K3: =J3/I3 -> 0.99057467 | M3: Samet | N3: =SUMIF($H$3:$H$292,M3,$I$3:$I$292) -> 22500 | O3: =SUMIF($H$3:$H$292,M3,$J$3:$J$292) -> 52818.53 | P3: =O3/N3 -> 2.3474902
A4: =+A3+1 -> 2 | B4: 45628 | C4: 2500 | D4: =SUMIFS(Tablo1[Tutar],Tablo1[Tarih],Sayfa2!B4) -> 2228.94 | E4: =+E3+D4 -> 7967.98 | F4: =(D4+E3)/A4 -> 3983.99 | H4: Halime | I4: 7500 | J4: =SUMIFS(Tablo1[Tutar],Tablo1[Harcama],Sayfa2!H4,Tablo1[Tarih],">="&Sayfa2!J$1,Tablo1[Tarih],"<="&Sayfa2!J$2) -> 8429.66 | K4: =J4/I4 -> 1.1239547 | M4: Halime | N4: =SUMIF($H$3:$H$292,M4,$I$3:$I$292) -> 22500 | O4: =SUMIF($H$3:$H$292,M4,$J$3:$J$292) -> 32249.4 | P4: =O4/N4 -> 1.4333067
A5: =+A4+1 -> 3 | B5: 45629 | C5: 2500 | D5: =SUMIFS(Tablo1[Tutar],Tablo1[Tarih],Sayfa2!B5) -> 2519.88 | E5: =+E4+D5 -> 10487.86 | F5: =(D5+E4)/A5 -> 3495.9533 | H5: Safa | I5: 5000 | J5: =SUMIFS(Tablo1[Tutar],Tablo1[Harcama],Sayfa2!H5,Tablo1[Tarih],">="&Sayfa2!J$1,Tablo1[Tarih],"<="&Sayfa2!J$2) -> 4638.46 | K5: =J5/I5 -> 0.927692 | M5: Safa | N5: =SUMIF($H$3:$H$292,M5,$I$3:$I$292) -> 15000 | O5: =SUMIF($H$3:$H$292,M5,$J$3:$J$292) -> 11612.13 | P5: =O5/N5 -> 0.774142
A6: =+A5+1 -> 4 | B6: 45630 | C6: 2500 | D6: =SUMIFS(Tablo1[Tutar],Tablo1[Tarih],Sayfa2!B6) -> 4466.76 | E6: =+E5+D6 -> 14954.62 | F6: =(D6+E5)/A6 -> 3738.655 | H6: Kaan | I6: 7000 | J6: =SUMIFS(Tablo1[Tutar],Tablo1[Harcama],Sayfa2!H6,Tablo1[Tarih],">="&Sayfa2!J$1,Tablo1[Tarih],"<="&Sayfa2!J$2) -> 6602.3 | K6: =J6/I6 -> 0.94318571 | M6: Kaan | N6: =SUMIF($H$3:$H$292,M6,$I$3:$I$292) -> 21000 | O6: =SUMIF($H$3:$H$292,M6,$J$3:$J$292) -> 16332.83 | P6: =O6/N6 -> 0.77775381
A7: =+A6+1 -> 5 | B7: 45631 | C7: 2500 | D7: =SUMIFS(Tablo1[Tutar],Tablo1[Tarih],Sayfa2!B7) -> 25 | E7: =+E6+D7 -> 14979.62 | F7: =(D7+E6)/A7 -> 2995.924 | H7: Zeynep | I7: 3000 | J7: =SUMIFS(Tablo1[Tutar],Tablo1[Harcama],Sayfa2!H7,Tablo1[Tarih],">="&Sayfa2!J$1,Tablo1[Tarih],"<="&Sayfa2!J$2) -> 1099.98 | K7: =J7/I7 -> 0.36666 | M7: Zeynep | N7: =SUMIF($H$3:$H$292,M7,$I$3:$I$292) -> 9000 | O7: =SUMIF($H$3:$H$292,M7,$J$3:$J$292) -> 6843.08 | P7: =O7/N7 -> 0.76034222
A8: =+A7+1 -> 6 | B8: 45632 | C8: 2500 | D8: =SUMIFS(Tablo1[Tutar],Tablo1[Tarih],Sayfa2!B8) -> 879.99 | E8: =+E7+D8 -> 15859.61 | F8: =(D8+E7)/A8 -> 2643.2683 | H8: Ev | I8: 30000 | J8: =SUMIFS(Tablo1[Tutar],Tablo1[Harcama],Sayfa2!H8,Tablo1[Tarih],">="&Sayfa2!J$1,Tablo1[Tarih],"<="&Sayfa2!J$2) -> 32418.54 | K8: =J8/I8 -> 1.080618 | M8: Ev | N8: =SUMIF($H$3:$H$292,M8,$I$3:$I$292) -> 90000 | O8: =SUMIF($H$3:$H$292,M8,$J$3:$J$292) -> 205125.44 | P8: =O8/N8 -> 2.2791716
A9: =+A8+1 -> 7 | B9: 45633 | C9: 2500 | D9: =SUMIFS(Tablo1[Tutar],Tablo1[Tarih],Sayfa2!B9) -> 1999.56 | E9: =+E8+D9 -> 17859.17 | F9: =(D9+E8)/A9 -> 2551.31 | H9: Diğer | I9: 15000 | J9: =SUMIFS(Tablo1[Tutar],Tablo1[Harcama],Sayfa2!H9,Tablo1[Tarih],">="&Sayfa2!J$1,Tablo1[Tarih],"<="&Sayfa2!J$2) -> 25635.21 | K9: =J9/I9 -> 1.709014 | M9: Diğer | N9: =SUMIF($H$3:$H$292,M9,$I$3:$I$292) -> 45000 | O9: =SUMIF($H$3:$H$292,M9,$J$3:$J$292) -> 70020.25 | P9: =O9/N9 -> 1.5560056
A10: =+A9+1 -> 8 | B10: 45634 | C10: 2500 | D10: =SUMIFS(Tablo1[Tutar],Tablo1[Tarih],Sayfa2!B10) -> 1185.47 | E10: =+E9+D10 -> 19044.64 | F10: =(D10+E9)/A10 -> 2380.58
A11: =+A10+1 -> 9 | B11: 45635 | C11: 2500 | D11: =SUMIFS(Tablo1[Tutar],Tablo1[Tarih],Sayfa2!B11) -> 455.74 | E11: =+E10+D11 -> 19500.38 | F11: =(D11+E10)/A11 -> 2166.7089 | H11: Toplam | I11: =SUM(I3:I9) -> 75000 | J11: =SUMIFS(Tablo1[Tutar],Tablo1[Tarih],">="&Sayfa2!J$1,Tablo1[Tarih],"<="&Sayfa2!J$2) -> 86253.46 | K11: =J11/I11 -> 1.1500461 | M11: Toplam | N11: =SUMIF($H$3:$H$292,M11,$I$3:$I$292) -> 225000 | O11: =SUMIF($H$3:$H$292,M11,$J$3:$J$292) -> 395001.66 | P11: =O11/N11 -> 1.7555629
A12: =+A11+1 -> 10 | B12: 45636 | C12: 2500 | D12: =SUMIFS(Tablo1[Tutar],Tablo1[Tarih],Sayfa2!B12) -> 1105 | E12: =+E11+D12 -> 20605.38 | F12: =(D12+E11)/A12 -> 2060.538
A13: =+A12+1 -> 11 | B13: 45637 | C13: 2500 | D13: =SUMIFS(Tablo1[Tutar],Tablo1[Tarih],Sayfa2!B13) -> 510 | E13: =+E12+D13 -> 21115.38 | F13: =(D13+E12)/A13 -> 1919.58 | O13: =TODAY()-J15 -> 35
A14: =+A13+1 -> 12 | B14: 45638 | C14: 2500 | D14: =SUMIFS(Tablo1[Tutar],Tablo1[Tarih],Sayfa2!B14) -> 778 | E14: =+E13+D14 -> 21893.38 | F14: =(D14+E13)/A14 -> 1824.4483 | J14: 45658 | O14: =+I11+I24+I37*(O13/(J28-J27)) -> 247222.22 | P14: =+O14/N11 -> 1.0987654
A15: =+A14+1 -> 13 | B15: 45639 | C15: 2500 | D15: =SUMIFS(Tablo1[Tutar],Tablo1[Tarih],Sayfa2!B15) -> 868.54 | E15: =+E14+D15 -> 22761.92 | F15: =(D15+E14)/A15 -> 1750.9169 | J15: 45688
A16: =+A15+1 -> 14 | B16: 45640 | C16: 2500 | D16: =SUMIFS(Tablo1[Tutar],Tablo1[Tarih],Sayfa2!B16) -> 9127.93 | E16: =+E15+D16 -> 31889.85 | F16: =(D16+E15)/A16 -> 2277.8464 | H16: Samet | I16: 7500 | J16: =SUMIFS(Tablo1[Tutar],Tablo1[Harcama],Sayfa2!H16,Tablo1[Tarih],">="&Sayfa2!J$14,Tablo1[Tarih],"<="&Sayfa2!J$15) -> 42272.83 | K16: =J16/I16 -> 5.6363773
A17: =+A16+1 -> 15 | B17: 45641 | C17: 2500 | D17: =SUMIFS(Tablo1[Tutar],Tablo1[Tarih],Sayfa2!B17) -> 1862.31 | E17: =+E16+D17 -> 33752.16 | F17: =(D17+E16)/A17 -> 2250.144 | H17: Halime | I17: 7500 | J17: =SUMIFS(Tablo1[Tutar],Tablo1[Harcama],Sayfa2!H17,Tablo1[Tarih],">="&Sayfa2!J$14,Tablo1[Tarih],"<="&Sayfa2!J$15) -> 11423.04 | K17: =J17/I17 -> 1.523072
A18: =+A17+1 -> 16 | B18: 45642 | C18: 2500 | D18: =SUMIFS(Tablo1[Tutar],Tablo1[Tarih],Sayfa2!B18) -> 3713.65 | E18: =+E17+D18 -> 37465.81 | F18: =(D18+E17)/A18 -> 2341.6131 | H18: Safa | I18: 5000 | J18: =SUMIFS(Tablo1[Tutar],Tablo1[Harcama],Sayfa2!H18,Tablo1[Tarih],">="&Sayfa2!J$14,Tablo1[Tarih],"<="&Sayfa2!J$15) -> 4107.94 | K18: =J18/I18 -> 0.821588
A19: =+A18+1 -> 17 | B19: 45643 | C19: 2500 | D19: =SUMIFS(Tablo1[Tutar],Tablo1[Tarih],Sayfa2!B19) -> 1670.99 | E19: =+E18+D19 -> 39136.8 | F19: =(D19+E18)/A19 -> 2302.1647 | H19: Kaan | I19: 7000 | J19: =SUMIFS(Tablo1[Tutar],Tablo1[Harcama],Sayfa2!H19,Tablo1[Tarih],">="&Sayfa2!J$14,Tablo1[Tarih],"<="&Sayfa2!J$15) -> 7174.84 | K19: =J19/I19 -> 1.0249771
A20: =+A19+1 -> 18 | B20: 45644 | C20: 2500 | D20: =SUMIFS(Tablo1[Tutar],Tablo1[Tarih],Sayfa2!B20) -> 4543.43 | E20: =+E19+D20 -> 43680.23 | F20: =(D20+E19)/A20 -> 2426.6794 | H20: Zeynep | I20: 3000 | J20: =SUMIFS(Tablo1[Tutar],Tablo1[Harcama],Sayfa2!H20,Tablo1[Tarih],">="&Sayfa2!J$14,Tablo1[Tarih],"<="&Sayfa2!J$15) -> 3981.13 | K20: =J20/I20 -> 1.3270433
A21: =+A20+1 -> 19 | B21: 45645 | C21: 2500 | D21: =SUMIFS(Tablo1[Tutar],Tablo1[Tarih],Sayfa2!B21) -> 57.5 | E21: =+E20+D21 -> 43737.73 | F21: =(D21+E20)/A21 -> 2301.9858 | H21: Ev | I21: 30000 | J21: =SUMIFS(Tablo1[Tutar],Tablo1[Harcama],Sayfa2!H21,Tablo1[Tarih],">="&Sayfa2!J$14,Tablo1[Tarih],"<="&Sayfa2!J$15) -> 28317.31 | K21: =J21/I21 -> 0.94391033
A22: =+A21+1 -> 20 | B22: 45646 | C22: 2500 | D22: =SUMIFS(Tablo1[Tutar],Tablo1[Tarih],Sayfa2!B22) -> 0 | E22: =+E21+D22 -> 43737.73 | F22: =(D22+E21)/A22 -> 2186.8865 | H22: Diğer | I22: 15000 | J22: =SUMIFS(Tablo1[Tutar],Tablo1[Harcama],Sayfa2!H22,Tablo1[Tarih],">="&Sayfa2!J$14,Tablo1[Tarih],"<="&Sayfa2!J$15) -> 5933.96 | K22: =J22/I22 -> 0.39559733
A23: =+A22+1 -> 21 | B23: 45647 | C23: 2500 | D23: =SUMIFS(Tablo1[Tutar],Tablo1[Tarih],Sayfa2!B23) -> 1701.61 | E23: =+E22+D23 -> 45439.34 | F23: =(D23+E22)/A23 -> 2163.7781
A24: =+A23+1 -> 22 | B24: 45648 | C24: 2500 | D24: =SUMIFS(Tablo1[Tutar],Tablo1[Tarih],Sayfa2!B24) -> 1769.5 | E24: =+E23+D24 -> 47208.84 | F24: =(D24+E23)/A24 -> 2145.8564 | H24: Toplam | I24: =SUM(I16:I22) -> 75000 | J24: =SUMIFS(Tablo1[Tutar],Tablo1[Tarih],">="&Sayfa2!J$14,Tablo1[Tarih],"<="&Sayfa2!J$15) -> 103211.05 | K24: =J24/I24 -> 1.3761473
A25: =+A24+1 -> 23 | B25: 45649 | C25: 2500 | D25: =SUMIFS(Tablo1[Tutar],Tablo1[Tarih],Sayfa2!B25) -> 17976.59 | E25: =+E24+D25 -> 65185.43 | F25: =(D25+E24)/A25 -> 2834.1491
A26: =+A25+1 -> 24 | B26: 45650 | C26: 2500 | D26: =SUMIFS(Tablo1[Tutar],Tablo1[Tarih],Sayfa2!B26) -> 3549.29 | E26: =+E25+D26 -> 68734.72 | F26: =(D26+E25)/A26 -> 2863.9467
A27: =+A26+1 -> 25 | B27: 45651 | C27: 2500 | D27: =SUMIFS(Tablo1[Tutar],Tablo1[Tarih],Sayfa2!B27) -> 5064.49 | E27: =+E26+D27 -> 73799.21 | F27: =(D27+E26)/A27 -> 2951.9684 | J27: 45689
A28: =+A27+1 -> 26 | B28: 45652 | C28: 2500 | D28: =SUMIFS(Tablo1[Tutar],Tablo1[Tarih],Sayfa2!B28) -> 1483.69 | E28: =+E27+D28 -> 75282.9 | F28: =(D28+E27)/A28 -> 2895.4962 | J28: 45716
A29: =+A28+1 -> 27 | B29: 45653 | C29: 2500 | D29: =SUMIFS(Tablo1[Tutar],Tablo1[Tarih],Sayfa2!B29) -> 2108.99 | E29: =+E28+D29 -> 77391.89 | F29: =(D29+E28)/A29 -> 2866.3663 | H29: Samet | I29: 7500 | J29: =SUMIFS(Tablo1[Tutar],Tablo1[Harcama],Sayfa2!H29,Tablo1[Tarih],">="&Sayfa2!J$27,Tablo1[Tarih],"<="&Sayfa2!J$28) -> 3116.39 | K29: =J29/I29 -> 0.41551867
A30: =+A29+1 -> 28 | B30: 45654 | C30: 2500 | D30: =SUMIFS(Tablo1[Tutar],Tablo1[Tarih],Sayfa2!B30) -> 525.12 | E30: =+E29+D30 -> 77917.01 | F30: =(D30+E29)/A30 -> 2782.7504 | H30: Halime | I30: 7500 | J30: =SUMIFS(Tablo1[Tutar],Tablo1[Harcama],Sayfa2!H30,Tablo1[Tarih],">="&Sayfa2!J$27,Tablo1[Tarih],"<="&Sayfa2!J$28) -> 12396.7 | K30: =J30/I30 -> 1.6528933
A31: =+A30+1 -> 29 | B31: 45655 | C31: 2500 | D31: =SUMIFS(Tablo1[Tutar],Tablo1[Tarih],Sayfa2!B31) -> 1423.81 | E31: =+E30+D31 -> 79340.82 | F31: =(D31+E30)/A31 -> 2735.8903 | H31: Safa | I31: 5000 | J31: =SUMIFS(Tablo1[Tutar],Tablo1[Harcama],Sayfa2!H31,Tablo1[Tarih],">="&Sayfa2!J$27,Tablo1[Tarih],"<="&Sayfa2!J$28) -> 2865.73 | K31: =J31/I31 -> 0.573146
A32: =+A31+1 -> 30 | B32: 45656 | C32: 2500 | D32: =SUMIFS(Tablo1[Tutar],Tablo1[Tarih],Sayfa2!B32) -> 5040.53 | E32: =+E31+D32 -> 84381.35 | F32: =(D32+E31)/A32 -> 2812.7117 | H32: Kaan | I32: 7000 | J32: =SUMIFS(Tablo1[Tutar],Tablo1[Harcama],Sayfa2!H32,Tablo1[Tarih],">="&Sayfa2!J$27,Tablo1[Tarih],"<="&Sayfa2!J$28) -> 2555.69 | K32: =J32/I32 -> 0.36509857
A33: =+A32+1 -> 31 | B33: 45657 | C33: 2500 | D33: =SUMIFS(Tablo1[Tutar],Tablo1[Tarih],Sayfa2!B33) -> 1872.11 | E33: =+E32+D33 -> 86253.46 | F33: =(D33+E32)/A33 -> 2782.3697 | H33: Zeynep | I33: 3000 | J33: =SUMIFS(Tablo1[Tutar],Tablo1[Harcama],Sayfa2!H33,Tablo1[Tarih],">="&Sayfa2!J$27,Tablo1[Tarih],"<="&Sayfa2!J$28) -> 1761.97 | K33: =J33/I33 -> 0.58732333
A34: =+A33+1 -> 32 | B34: 45658 | C34: 2500 | D34: =SUMIFS(Tablo1[Tutar],Tablo1[Tarih],Sayfa2!B34) -> 3266.75 | E34: =+E33+D34 -> 89520.21 | F34: =(D34+E33)/A34 -> 2797.5066 | H34: Ev | I34: 30000 | J34: =SUMIFS(Tablo1[Tutar],Tablo1[Harcama],Sayfa2!H34,Tablo1[Tarih],">="&Sayfa2!J$27,Tablo1[Tarih],"<="&Sayfa2!J$28) -> 144389.59 | K34: =J34/I34 -> 4.8129863
A35: =+A34+1 -> 33 | B35: 45659 | C35: 2500 | D35: =SUMIFS(Tablo1[Tutar],Tablo1[Tarih],Sayfa2!B35) -> 1307.19 | E35: =+E34+D35 -> 90827.4 | F35: =(D35+E34)/A35 -> 2752.3455 | H35: Diğer | I35: 15000 | J35: =SUMIFS(Tablo1[Tutar],Tablo1[Harcama],Sayfa2!H35,Tablo1[Tarih],">="&Sayfa2!J$27,Tablo1[Tarih],"<="&Sayfa2!J$28) -> 38451.08 | K35: =J35/I35 -> 2.5634053
A36: =+A35+1 -> 34 | B36: 45660 | C36: 2500 | D36: =SUMIFS(Tablo1[Tutar],Tablo1[Tarih],Sayfa2!B36) -> 2969.85 | E36: =+E35+D36 -> 93797.25 | F36: =(D36+E35)/A36 -> 2758.7426
A37: =+A36+1 -> 35 | B37: 45661 | C37: 2500 | D37: =SUMIFS(Tablo1[Tutar],Tablo1[Tarih],Sayfa2!B37) -> 744 | E37: =+E36+D37 -> 94541.25 | F37: =(D37+E36)/A37 -> 2701.1786 | H37: Toplam | I37: =SUM(I29:I35) -> 75000 | J37: =SUMIFS(Tablo1[Tutar],Tablo1[Tarih],">="&Sayfa2!J$27,Tablo1[Tarih],"<="&Sayfa2!J$28) -> 205537.15 | K37: =J37/I37 -> 2.7404953
A38: =+A37+1 -> 36 | B38: 45662 | C38: 2500 | D38: =SUMIFS(Tablo1[Tutar],Tablo1[Tarih],Sayfa2!B38) -> 2677.23 | E38: =+E37+D38 -> 97218.48 | F38: =(D38+E37)/A38 -> 2700.5133
A39: =+A38+1 -> 37 | B39: 45663 | C39: 2500 | D39: =SUMIFS(Tablo1[Tutar],Tablo1[Tarih],Sayfa2!B39) -> 2480.96 | E39: =+E38+D39 -> 99699.44 | F39: =(D39+E38)/A39 -> 2694.5795
A40: =+A39+1 -> 38 | B40: 45664 | C40: 2500 | D40: =SUMIFS(Tablo1[Tutar],Tablo1[Tarih],Sayfa2!B40) -> 0 | E40: =+E39+D40 -> 99699.44 | F40: =(D40+E39)/A40 -> 2623.6695
...

Sheet Sayfa1
A1: Tarih | B1: Sütun1 | C1: Harcama | D1: Kategori | E1: Açıklama | F1: Tutar
A2: 45627 | C2: Samet | D2: Samet | E2: Diğer | F2: 3505
A3: 45627 | C3: Kaan | D3: Eğitim | E3: İlim Yayma | F3: 1505
A4: 45627 | C4: Ev | D4: Market | E4: Bim | F4: 499.04
A5: 45627 | C5: Samet | D5: Yemek | E5: Beka Simit | F5: 230
A6: 45628 | C6: Ev | D6: Market | E6: Bim | F6: 725.72
A7: 45628 | C7: Safa | D7: Yemek | E7: Mikel | F7: 350
A8: 45628 | C8: Kaan | D8: Yemek | E8: Mikel | F8: 350
A9: 45628 | C9: Samet | D9: Giyim | E9: Çamaşır | F9: 500
A10: 45628 | C10: Ev | D10: Ev | E10: Şarj Kablo | F10: 303.22
A11: 45629 | C11: Zeynep | D11: Giyim | E11: Lc Waikiki | F11: 1099.98
A12: 45629 | C12: Ev | D12: Ev | E12: Yataş | F12: 629.9
A13: 45629 | C13: Safa | D13: Eğlence | E13: Buz Pateni | F13: 310
... A15: 45629 | C15: Ev | D15: Market | E15: Şok | F15: 320
A16: 45630 | C16: Diğer | D16: Diğer | E16: Kredi | F16: =665.71+66.57+99.86+2476.49 -> 3308.63
A17: 45630 | C17: Ev | D17: Market | E17: Bim | F17: 658.13
A18: 45630 | C18: Ev | D18: Ev | E18: Arçelik | F18: 500
A19: 45631 | C19: Ev | D19: Ev | E19: Market | F19: 25
A20: 45632 | C20: Halime | D20: Yemek | E20: Huqqabaz | F20: 550
A21: 45632 | C21: Ev | D21: Giyim | E21: Flo | F21: 79.99
A22: 45632 | C22: Ev | D22: Yemek | E22: Trendyol Yemek | F22: 250
A23: 45633 | C23: Ev | D23: Market | E23: Kasaba Fırın | F23: 57.5
A24: 45633 | C24: Ev | D24: Market | E24: Kooparatif | F24: 1942.06
A25: 45634 | C25: Ev | D25: Market | E25: Bim | F25: 658.11
A26: 45634 | C26: Ev | D26: Ev | E26: Baza Ayak | F26: 527.36
A27: 45635 | C27: Halime | D27: Giyim | E27: Terzi | F27: 129
A28: 45635 | C28: Ev | D28: Market | E28: Saimoğlu | F28: 52.5
... A72: 45644 | C72: Halime | D72: Diğer | E72: Diğer | F72: 350
A73: 45644 | C73: Ev | D73: Fatura | E73: Su | F73: =3211.53+112.4 -> 3323.93
A74: 45644 | C74: Ev | D74: Market | E74: a101 | F74: 132.25
A75: 45645 | C75: Ev | D75: Market | E75: ekmek | F75: 57.5
A76: 45647 | C76: Ev | D76: Market | E76: Et Süt Kurumu | F76: 501
A77: 45647 | C77: Ev | D77: Market | E77: Market | F77: 811.07
A78: 45647 | C78: Ev | D78: Market | E78: cadde fırın | F78: 188
A79: 45647 | C79: Ev | D79: Market | E79: Market | F79: 201.54
A80: 45648 | C80: Halime | D80: Diğer | E80: gratis | F80: 200
A81: 45648 | C81: Halime | D81: Diğer | E81: gratis | F81: 311
A82: 45648 | C82: Ev | D82: Market | E82: Şok | F82: 100
A83: 45648 | C83: Samet | D83: Yemek | E83: Beka Simit | F83: 360
A84: 45648 | C84: Ev | D84: Market | E84: Market | F84: 663.5
...

Sheet Artvin
F2: =SUM(F3:F914) -> 1762386.7 | Q2: =+Q4-SUM(Q5:Q22) -> 27400
J3: Planlanan | K3: Gerçekleşen | Q3: FATİH
D4: Teminat | E4: Teminat | F4: 101000 | I4: İşçilik | J4: 400000 | K4: =SUMIFS($F$4:$F$250,$D$4:$D$250,I4) -> 461060 | L4: =K4/J4 -> 1.15265 | Q4: 30000
D5: Vergi | E5: Damga Vergisi | F5: 27000 | I5: Malzeme | J5: 400000 | K5: =SUMIFS($F$4:$F$250,$D$4:$D$250,I5) -> 647009.52 | L5: =K5/J5 -> 1.6175238 | Q5: 2600
D6: Malzeme | E6: Malzeme-1 | F6: 96000 | I6: Pvc | J6: 150000 | K6: =SUMIFS($F$4:$F$250,$D$4:$D$250,I6) -> 104500 | L6: =K6/J6 -> 0.69666667
D7: Malzeme | E7: Malzeme-2 | F7: 150000 | I7: Sahne | J7: 50000 | K7: =SUMIFS($F$4:$F$250,$D$4:$D$250,I7) -> 24333 | L7: =K7/J7 -> 0.48666
D8: Diğer | E8: All Risk | F8: 2265 | I8: Asfalt | J8: 50000 | K8: =SUMIFS($F$4:$F$250,$D$4:$D$250,I8) -> 0 | L8: =K8/J8 -> 0
D9: Malzeme | E9: Andezit | F9: 31900 | I9: Elektrik | J9: 200000 | K9: =SUMIFS($F$4:$F$250,$D$4:$D$250,I9) -> 206117 | L9: =K9/J9 -> 1.030585
C10: Ödenmedi | D10: Malzeme | E10: Andezit Nakliye | F10: 8000 | I10: Sgk | J10: 85000 | K10: =SUMIFS($F$4:$F$250,$D$4:$D$250,I10) -> 89476 | L10: =K10/J10 -> 1.0526588
D11: Malzeme | E11: Çatı | F11: 95000 | I11: Vergi | J11: 50000 | K11: =SUMIFS($F$4:$F$250,$D$4:$D$250,I11) -> 37638.12 | L11: =K11/J11 -> 0.7527624
D12: Malzeme | E12: Çatı | F12: 25000 | I12: Diğer | J12: 50000 | K12: =SUMIFS($F$4:$F$250,$D$4:$D$250,I12) -> 91253.05 | L12: =K12/J12 -> 1.825061
D13: Vergi | E13: Gelir Geçici | F13: 482.2 | I13: Teminat | J13: 101000 | K13: =SUMIFS($F$4:$F$250,$D$4:$D$250,I13) -> 101000 | L13: =K13/J13 -> 1
D14: Vergi | E14: Kdv | F14: 316.62 | R14: Garanti
D15: Malzeme | E15: Asma Tavan | F15: 50000 | J15: =SUM(J4:J13) -> 1536000 | K15: =SUM(K4:K13) -> 1762386.7
D16: Malzeme | E16: Tesisat | F16: 2000
D17: Elektrik | E17: Elektrik | F17: 4200
D18: Malzeme | E18: Nalbur | F18: 975
D19: Malzeme | E19: Nalbur | F19: 10000 | N19: =11150*33.1 -> 369065
D20: Vergi | E20: Muhasebe | F20: 1480
D21: Vergi | E21: Gelir Geçici | F21: 308.3 | I21: 1.Hak | J21: 971854.84
D22: Malzeme | E22: Kablo | F22: 11600 | I22: 2.Hak | J22: 1013273.2
D23: Malzeme | E23: Malzeme | F23: =560+90+90 -> 740 | I23: Geçici KABUL | J23: 60479.99
D24: İşçilik | E24: Özgen Çapar | F24: 50000
D25: PVC | E25: Ödeme | F25: 30000 | I25: Harcanan | J25: =+K15 -> 1762386.7
D26: Elektrik | E26: Elektrik | F26: 65952
D27: Elektrik | E27: Elektrik | F27: =70850+4960 -> 75810 | I27: Net | J27: =+J21+J22+J23-J25 -> 283221.34
D28: Malzeme | E28: Malzeme | F28: 22700
D29: Elektrik | E29: Projeksiyon | F29: 13555 | I29: Burak | J29: =Burak!H4 -> 344203.72
D30: İşçilik | E30: işçilik | F30: 100000 | I30: Samet | J30: =+J27-J29 -> -60982.38
D31: Vergi | E31: Kdv | F31: 314
D32: Malzeme | E32: MALZEME | F32: 165
D33: Malzeme | E33: MALZEME | F33: 1350 | I33: İçerideki Para | Q33: 1138280.6 | R33: 1079319
D34: Malzeme | E34: MALZEME | F34: 750 | I34: Teminat | J34: 101000 | Q34: 8992.42 | R34: 8526.62
D35: Diğer | E35: İsg | F35: 2150 | I35: Hak Teminat | J35: 10079.98 | Q35: 75885.38 | R35: 71954.6
D36: Sahne | E36: Profil | F36: 18333 | Q36: 11672.62
D37: Elektrik | E37: Projeksiyon Askı | F37: 1000 | Q37: 28457.02 | R37: 26982.98
D38: Malzeme | E38: Malzeme | F38: 1930 | Q38: =+Q33-Q35-Q36-Q37-Q34 -> 1013273.2 | R38: =+R33-R35-R36-R37-R34 -> 971854.84
D39: Sgk | E39: Prim | F39: 52000 | I39: Tüm Kalan | J39: =J36+J35+J34+J30+J29 -> 394301.32
D40: Malzeme | E40: Malzeme | F40: 420
D41: Malzeme | E41: Malzeme | F41: 150
...

Sheet Burak
B4: 45650 | C4: Transfer | D4: 150000 | H4: =SUM(D4:D4423) -> 344203.72
B5: 45650 | C5: Transfer | D5: 205000
B6: 45650 | C6: İhale Harcama | D6: -44000
B7: 45650 | C7: Yıldız Restaurant | D7: =172.5*4 -> 690
B8: 45652 | C8: Yıldız Restaurant | D8: 210
B9: 45653 | C9: Mavi Kafe | D9: 325
B10: 45653 | C10: Şok | D10: 118
B11: 45654 | C11: Nestle | D11: 45
B12: 45656 | C12: Lale Lokantısı | D12: 980
B13: 45659 | C13: Yıldız Restaurant | D13: 300
B14: 45656 | C14: Özaydın Petrol | D14: 500
B15: 45662 | C15: Mollaoğlu | D15: 225
B16: 45671 | C16: Yakıt | D16: 4950
B17: 45702 | C17: fırın | D17: =1483.35*6 -> 8900.1
B18: 45713 | C18: Yakıt | D18: 960.62
B19: 45723 | C19: Transfer | D19: 15000
