Workbook

Sheet İcmal
B2: HİSSE | C2: ADET | D2: MALİYET | E2: FİYAT | F2: GÜNCEL TUTAT | G2: KAR/ZARAR
B3: AAPL | C3: =+AAPL!C1 -> 0 | D3: =+AAPL!F1 | E3: 41.66 | F3: =E3*C3 -> 0 | G3: =+AAPL!G1 -> 45.06 | I3: Toplam Yatırım | K3: =50600-15000 -> 35600
B4: ADD | C4: =+ADD!C1 -> 0 | D4: =+ADD!F1 | E4: 70.15 | F4: =E4*C4 -> 0 | G4: =+ADD!G1 -> 1.55 | I4: Anlık Değer | K4: =SUM(Tablo2[GÜNCEL TUTAT]) -> 19918.894
B5: AMD | C5: =+AMD!C1 -> 10 | D5: =+AMD!F1 -> 125.848 | E5: 205.13 | F5: =E5*C5 -> 2051.3 | G5: =+AMD!G1 -> 792.82 | I5: Nakit | K5: 20198.03
B6: AMTX | C6: =+AMTX!C1 -> 0 | D6: =+AMTX!F1 | E6: 52.4 | F6: =E6*C6 -> 0 | G6: =+AMTX!G1 -> -74 | I6: Kar | K6: =+K4+K5-K3 -> 4516.9241
B7: AMZN | C7: =+AMZN!C1 -> 0 | D7: =+AMZN!F1 | E7: 51.2 | F7: =E7*C7 -> 0 | G7: =+AMZN!G1 -> 19.63
B8: ASAP | C8: =+ASAP!C1 -> 0 | D8: =+ASAP!F1 | E8: 0.08 | F8: =E8*C8 -> 0 | G8: =+ASAP!G1 -> -24.828
B9: BBIO | C9: =+BBIO!C1 -> 156 | D9: =+BBIO!F1 -> 30.131026 | E9: 29.6 | F9: =E9*C9 -> 4617.6 | G9: =+BBIO!G1 -> -82.84 | I9: USD
B10: BKCH | C10: =+BKCH!C1 -> 40 | D10: =+BKCH!F1 -> 36.03775 | E10: 44.12 | F10: =E10*C10 -> 1764.8 | G10: =+BKCH!G1 -> 323.29 | I10: TL
B11: CAH | C11: =+CAH!C1 -> 0.75 | D11: =+CAH!F1 -> -67.55 | E11: 112.92 | F11: =E11*C11 -> 84.69 | G11: =+CAH!G1 -> 135.3525 | I11: MIDAS
B12: CLM | C12: =+CLM!C1 -> 0 | D12: =+CLM!F1 | E12: 142.1 | F12: =E12*C12 -> 0 | G12: =+CLM!G1 -> 9.95
B13: COIN | C13: =+COIN!C1 -> 5 | D13: =+COIN!F1 -> -161.41375 | E13: 216.77 | F13: =E13*C13 -> 1083.85 | G13: =+COIN!G1 -> 1890.9187
B14: FANG | C14: =+FANG!C1 -> 0 | D14: =+FANG!F1 | E14: 325 | F14: =E14*C14 -> 0 | G14: =+FANG!G1 -> 2
B15: FNGS | C15: =+FNGS!C1 -> 15 | D15: =+FNGS!F1 -> 38.043333 | E15: 42.21 | F15: =E15*C15 -> 633.15 | G15: =+FNGS!G1 -> 62.5
B16: FORD | C16: =+FORD!C1 -> 0 | D16: =+FORD!F1 | E16: 271.25 | F16: =E16*C16 -> 0 | G16: =+FORD!G1 -> 10.35
B17: GDRX | C17: =+GDRX!C1 -> 0 | D17: =+GDRX!F1 | F17: =E17*C17 -> 0 | G17: =+GDRX!$G$1 -> -2.2
B18: GE | C18: =+GE!$C$1 -> 2 | D18: =+GE!$F$1 -> 80.6 | E18: 157.86 | F18: =E18*C18 -> 315.72 | G18: =+GE!$G$1 -> 154.52
B19: GNLN | C19: =+GNLN!$C$1 -> 0 | D19: =+GNLN!$F$1 | F19: =E19*C19 -> 0 | G19: =+GNLN!$G$1 -> 3.25
B20: GOOGL | C20: =+GOOGL!$C$1 -> 28 | D20: =+GOOGL!$F$1 -> 148.55679 | E20: 132.67 | F20: =E20*C20 -> 3714.76 | G20: =+GOOGL!$G$1 -> -444.83
B21: JEPI | C21: =+JEPI!$C$1 -> 0 | D21: =+JEPI!$F$1 | E21: 56.77 | F21: =E21*C21 -> 0 | G21: =+JEPI!$G$1 -> 15.54
B22: HEPS | C22: =+HEPS!$C$1 -> 1 | D22: =+HEPS!$F$1 -> -0.451 | E22: 1.45 | F22: =E22*C22 -> 1.45 | G22: =+HEPS!$G$1 -> 1.901
B23: KHC | C23: =+KHC!$C$1 -> 0 | D23: =+KHC!$F$1 | F23: =E23*C23 -> 0 | G23: =+KHC!$G$1 -> 5.31
B24: MDT | C24: =+MDT!$C$1 -> 0 | D24: =+MDT!$F$1 | F24: =E24*C24 -> 0 | G24: =+MDT!$G$1 -> 22.46
B25: NAMS | C25: =+NAMS!$C$1 -> 0 | D25: =+NAMS!$F$1 | F25: =E25*C25 -> 0 | G25: =+NAMS!$G$1 -> 20.55
B26: NIO | C26: =+NIO!$C$1 -> 55 | D26: =+NIO!$F$1 -> 6.2981818 | E26: 5.48 | F26: =E26*C26 -> 301.4 | G26: =+NIO!$G$1 -> -45
B27: NKLA | C27: =+NKLA!$C$1 -> 313 | D27: =+NKLA!$F$1 -> 0.76578275 | E27: 0.6757 | F27: =E27*C27 -> 211.4941 | G27: =+NKLA!$G$1 -> -28.1959
B28: NVDA | C28: =+NVDA!$C$1 -> 1 | D28: =+NVDA!$F$1 -> -694.43 | E28: 859.64 | F28: =E28*C28 -> 859.64 | G28: =+NVDA!$G$1 -> 1554.07
B29: ORCL | C29: =+ORCL!$C$1 -> 0 | D29: =+ORCL!$F$1 | F29: =E29*C29 -> 0 | G29: =+ORCL!$G$1 -> 16.53
B30: PTRCY | C30: =+PTRCY!$C$1 -> 0 | D30: =+PTRCY!$F$1 | F30: =E30*C30 -> 0 | G30: =+PTRCY!$G$1 -> 2
B31: SCDH | C31: =+SCDH!$C$1 -> 8 | D31: =+SCDH!$F$1 -> 75.91125 | E31: 78.12 | F31: =E31*C31 -> 624.96 | G31: =+SCDH!$G$1 -> 17.67
B32: SPYI | C32: =+SPYI!$C$1 -> 11 | D32: =+SPYI!$F$1 -> 48.957273 | E32: 49.58 | F32: =E32*C32 -> 545.38 | G32: =+SPYI!$G$1 -> 6.85
B33: SQ | C33: =+SQ!$C$1 -> 0 | D33: =+SQ!$F$1 | F33: =E33*C33 -> 0 | G33: =+SQ!$G$1 -> -34.5
B34: TSLA | C34: =+TSLA!$C$1 -> 5 | D34: =+TSLA!$F$1 -> 219.012 | E34: 180.74 | F34: =E34*C34 -> 903.7 | G34: =+TSLA!$G$1 -> -191.36
B35: TUR | C35: =+TUR!$C$1 -> 25 | D35: =+TUR!$F$1 -> 35.52 | E35: 35.84 | F35: =E35*C35 -> 896 | G35: =+TUR!$G$1 -> 8
B36: UAL | C36: =+UAL!$C$1 -> 0 | D36: =+UAL!$F$1 | F36: =E36*C36 -> 0 | G36: =+UAL!$G$1 -> 4.74
B37: UPS | C37: =+UPS!$C$1 -> 2 | D37: =+UPS!$F$1 -> 181.1 | E37: 149.66 | F37: =E37*C37 -> 299.32 | G37: =+UPS!$G$1 -> -62.88
B38: VIG | C38: =+VIG!$C$1 -> 0 | D38: =+VIG!$F$1 | E38: 177.73 | F38: =E38*C38 -> 0 | G38: =+VIG!$G$1 -> 28.02
B39: VUG | C39: =+VUG!$C$1 -> 3 | D39: =+VUG!$F$1 -> 328.35667 | E39: 336.56 | F39: =E39*C39 -> 1009.68 | G39: =+VUG!$G$1 -> 24.61

Sheet AAPL
B1: ANA SAYFA | C1: =SUMIF(Tablo1[KAR],"Açık",Tablo1[ADET]) -> 0 | E1: =C1*D1 -> 0 | F1: =IFERROR(((SUM(Tablo1[ALIŞ TUTAR])-SUM(Tablo1[SATIŞ TUTAR]))/C1),"") | G1: =IF(M3=0,L3,C1*(D1-F1)) -> 45.06 | J1: 0.02 | L1: =M1*(1-$J$1) -> #VALUE! | M1: =F1 | N1: =M1*(1+$J$1) -> #VALUE! | P1: =Q1*(1-$J$1) -> 0 | Q1: =+D1 -> 0 | R1: =Q1*(1+$J$1) -> 0
B3: TARİH | C3: ADET | D3: ALIŞ | E3: SATIŞ | F3: KAR | G3: ALIŞ TUTAR | H3: SATIŞ TUTAR | L3: =SUM(Tablo1[KAR]) -> 45.06 | M3: =C1 -> 0
B4: 44725 | C4: 2 | D4: 135.02 | E4: 142.5 | F4: =IF(Tablo1[[#This Row],[SATIŞ]]=0,"Açık",(E4-D4)*C4-3) -> 11.96 | G4: =IF(Tablo1[[#This Row],[ALIŞ]]>0,Tablo1[[#This Row],[ADET]]*Tablo1[[#This Row],[ALIŞ]]+1.5,0) -> 271.54 | H4: =IF(Tablo1[[#This Row],[SATIŞ]]>0,(Tablo1[[#This Row],[ADET]]*Tablo1[[#This Row],[SATIŞ]]-1.5),0) -> 283.5
B5: 45487 | C5: 3 | D5: 145 | E5: 148 | F5: =IF(Tablo1[[#This Row],[SATIŞ]]=0,"Açık",(E5-D5)*C5-3) -> 6 | G5: =IF(Tablo1[[#This Row],[ALIŞ]]>0,Tablo1[[#This Row],[ADET]]*Tablo1[[#This Row],[ALIŞ]]+1.5,0) -> 436.5 | H5: =IF(Tablo1[[#This Row],[SATIŞ]]>0,(Tablo1[[#This Row],[ADET]]*Tablo1[[#This Row],[SATIŞ]]-1.5),0) -> 442.5
B6: 44760 | C6: 4 | D6: 149.5 | E6: 150.5 | F6: =IF(Tablo1[[#This Row],[SATIŞ]]=0,"Açık",(E6-D6)*C6-3) -> 1 | G6: =IF(Tablo1[[#This Row],[ALIŞ]]>0,Tablo1[[#This Row],[ADET]]*Tablo1[[#This Row],[ALIŞ]]+1.5,0) -> 599.5 | H6: =IF(Tablo1[[#This Row],[SATIŞ]]>0,(Tablo1[[#This Row],[ADET]]*Tablo1[[#This Row],[SATIŞ]]-1.5),0) -> 600.5
B7: 44770 | C7: 3 | D7: 155 | E7: 159 | F7: =IF(Tablo1[[#This Row],[SATIŞ]]=0,"Açık",(E7-D7)*C7-3) -> 9 | G7: =IF(Tablo1[[#This Row],[ALIŞ]]>0,Tablo1[[#This Row],[ADET]]*Tablo1[[#This Row],[ALIŞ]]+1.5,0) -> 466.5 | H7: =IF(Tablo1[[#This Row],[SATIŞ]]>0,(Tablo1[[#This Row],[ADET]]*Tablo1[[#This Row],[SATIŞ]]-1.5),0) -> 475.5
B8: 44774 | C8: 3 | D8: 161.5 | E8: 162.5 | F8: =IF(Tablo1[[#This Row],[SATIŞ]]=0,"Açık",(E8-D8)*C8-3) -> 0 | G8: =IF(Tablo1[[#This Row],[ALIŞ]]>0,Tablo1[[#This Row],[ADET]]*Tablo1[[#This Row],[ALIŞ]]+1.5,0) -> 486 | H8: =IF(Tablo1[[#This Row],[SATIŞ]]>0,(Tablo1[[#This Row],[ADET]]*Tablo1[[#This Row],[SATIŞ]]-1.5),0) -> 486
B9: 44789 | C9: 6 | D9: 172 | E9: 174.5 | F9: =IF(Tablo1[[#This Row],[SATIŞ]]=0,"Açık",(E9-D9)*C9-3) -> 12 | G9: =IF(Tablo1[[#This Row],[ALIŞ]]>0,Tablo1[[#This Row],[ADET]]*Tablo1[[#This Row],[ALIŞ]]+1.5,0) -> 1033.5 | H9: =IF(Tablo1[[#This Row],[SATIŞ]]>0,(Tablo1[[#This Row],[ADET]]*Tablo1[[#This Row],[SATIŞ]]-1.5),0) -> 1045.5
B10: 45063 | C10: 2 | D10: 170.95 | E10: 175 | F10: =IF(Tablo1[[#This Row],[SATIŞ]]=0,"Açık",(E10-D10)*C10-3) -> 5.1 | G10: =IF(Tablo1[[#This Row],[ALIŞ]]>0,Tablo1[[#This Row],[ADET]]*Tablo1[[#This Row],[ALIŞ]]+1.5,0) -> 343.4 | H10: =IF(Tablo1[[#This Row],[SATIŞ]]>0,(Tablo1[[#This Row],[ADET]]*Tablo1[[#This Row],[SATIŞ]]-1.5),0) -> 348.5
F11: =IF(Tablo1[[#This Row],[SATIŞ]]=0,"Açık",(E11-D11)*C11-3) -> Açık | G11: =IF(Tablo1[[#This Row],[ALIŞ]]>0,Tablo1[[#This Row],[ADET]]*Tablo1[[#This Row],[ALIŞ]]+1.5,0) -> 0 | H11: =IF(Tablo1[[#This Row],[SATIŞ]]>0,(Tablo1[[#This Row],[ADET]]*Tablo1[[#This Row],[SATIŞ]]-1.5),0) -> 0 | J11: =+Tablo1[[#This Row],[ALIŞ]]*1.02 -> 0
F12: =IF(Tablo1[[#This Row],[SATIŞ]]=0,"Açık",(E12-D12)*C12-3) -> Açık | G12: =IF(Tablo1[[#This Row],[ALIŞ]]>0,Tablo1[[#This Row],[ADET]]*Tablo1[[#This Row],[ALIŞ]]+1.5,0) -> 0 | H12: =IF(Tablo1[[#This Row],[SATIŞ]]>0,(Tablo1[[#This Row],[ADET]]*Tablo1[[#This Row],[SATIŞ]]-1.5),0) -> 0
F13: =IF(Tablo1[[#This Row],[SATIŞ]]=0,"Açık",(E13-D13)*C13-3) -> Açık | G13: =IF(Tablo1[[#This Row],[ALIŞ]]>0,Tablo1[[#This Row],[ADET]]*Tablo1[[#This Row],[ALIŞ]]+1.5,0) -> 0 | H13: =IF(Tablo1[[#This Row],[SATIŞ]]>0,(Tablo1[[#This Row],[ADET]]*Tablo1[[#This Row],[SATIŞ]]-1.5),0) -> 0
F14: =IF(Tablo1[[#This Row],[SATIŞ]]=0,"Açık",(E14-D14)*C14-3) -> Açık | G14: =IF(Tablo1[[#This Row],[ALIŞ]]>0,Tablo1[[#This Row],[ADET]]*Tablo1[[#This Row],[ALIŞ]]+1.5,0) -> 0 | H14: =IF(Tablo1[[#This Row],[SATIŞ]]>0,(Tablo1[[#This Row],[ADET]]*Tablo1[[#This Row],[SATIŞ]]-1.5),0) -> 0
F15: =IF(Tablo1[[#This Row],[SATIŞ]]=0,"Açık",(E15-D15)*C15-3) -> Açık | G15: =IF(Tablo1[[#This Row],[ALIŞ]]>0,Tablo1[[#This Row],[ADET]]*Tablo1[[#This Row],[ALIŞ]]+1.5,0) -> 0 | H15: =IF(Tablo1[[#This Row],[SATIŞ]]>0,(Tablo1[[#This Row],[ADET]]*Tablo1[[#This Row],[SATIŞ]]-1.5),0) -> 0
F16: =IF(Tablo1[[#This Row],[SATIŞ]]=0,"Açık",(E16-D16)*C16-3) -> Açık | G16: =IF(Tablo1[[#This Row],[ALIŞ]]>0,Tablo1[[#This Row],[ADET]]*Tablo1[[#This Row],[ALIŞ]]+1.5,0) -> 0 | H16: =IF(Tablo1[[#This Row],[SATIŞ]]>0,(Tablo1[[#This Row],[ADET]]*Tablo1[[#This Row],[SATIŞ]]-1.5),0) -> 0
F17: =IF(Tablo1[[#This Row],[SATIŞ]]=0,"Açık",(E17-D17)*C17-3) -> Açık | G17: =IF(Tablo1[[#This Row],[ALIŞ]]>0,Tablo1[[#This Row],[ADET]]*Tablo1[[#This Row],[ALIŞ]]+1.5,0) -> 0 | H17: =IF(Tablo1[[#This Row],[SATIŞ]]>0,(Tablo1[[#This Row],[ADET]]*Tablo1[[#This Row],[SATIŞ]]-1.5),0) -> 0
F18: =IF(Tablo1[[#This Row],[SATIŞ]]=0,"Açık",(E18-D18)*C18-3) -> Açık | G18: =IF(Tablo1[[#This Row],[ALIŞ]]>0,Tablo1[[#This Row],[ADET]]*Tablo1[[#This Row],[ALIŞ]]+1.5,0) -> 0 | H18: =IF(Tablo1[[#This Row],[SATIŞ]]>0,(Tablo1[[#This Row],[ADET]]*Tablo1[[#This Row],[SATIŞ]]-1.5),0) -> 0
F19: =IF(Tablo1[[#This Row],[SATIŞ]]=0,"Açık",(E19-D19)*C19-3) -> Açık | G19: =IF(Tablo1[[#This Row],[ALIŞ]]>0,Tablo1[[#This Row],[ADET]]*Tablo1[[#This Row],[ALIŞ]]+1.5,0) -> 0 | H19: =IF(Tablo1[[#This Row],[SATIŞ]]>0,(Tablo1[[#This Row],[ADET]]*Tablo1[[#This Row],[SATIŞ]]-1.5),0) -> 0
F20: =IF(Tablo1[[#This Row],[SATIŞ]]=0,"Açık",(E20-D20)*C20-3) -> Açık | G20: =IF(Tablo1[[#This Row],[ALIŞ]]>0,Tablo1[[#This Row],[ADET]]*Tablo1[[#This Row],[ALIŞ]]+1.5,0) -> 0 | H20: =IF(Tablo1[[#This Row],[SATIŞ]]>0,(Tablo1[[#This Row],[ADET]]*Tablo1[[#This Row],[SATIŞ]]-1.5),0) -> 0
F21: =IF(Tablo1[[#This Row],[SATIŞ]]=0,"Açık",(E21-D21)*C21-3) -> Açık | G21: =IF(Tablo1[[#This Row],[ALIŞ]]>0,Tablo1[[#This Row],[ADET]]*Tablo1[[#This Row],[ALIŞ]]+1.5,0) -> 0 | H21: =IF(Tablo1[[#This Row],[SATIŞ]]>0,(Tablo1[[#This Row],[ADET]]*Tablo1[[#This Row],[SATIŞ]]-1.5),0) -> 0
F22: =IF(Tablo1[[#This Row],[SATIŞ]]=0,"Açık",(E22-D22)*C22-3) -> Açık | G22: =IF(Tablo1[[#This Row],[ALIŞ]]>0,Tablo1[[#This Row],[ADET]]*Tablo1[[#This Row],[ALIŞ]]+1.5,0) -> 0 | H22: =IF(Tablo1[[#This Row],[SATIŞ]]>0,(Tablo1[[#This Row],[ADET]]*Tablo1[[#This Row],[SATIŞ]]-1.5),0) -> 0
F23: =IF(Tablo1[[#This Row],[SATIŞ]]=0,"Açık",(E23-D23)*C23-3) -> Açık | G23: =IF(Tablo1[[#This Row],[ALIŞ]]>0,Tablo1[[#This Row],[ADET]]*Tablo1[[#This Row],[ALIŞ]]+1.5,0) -> 0 | H23: =IF(Tablo1[[#This Row],[SATIŞ]]>0,(Tablo1[[#This Row],[ADET]]*Tablo1[[#This Row],[SATIŞ]]-1.5),0) -> 0
... F27: =IF(Tablo1[[#This Row],[SATIŞ]]=0,"Açık",(E27-D27)*C27-3) -> Açık | G27: =IF(Tablo1[[#This Row],[ALIŞ]]>0,Tablo1[[#This Row],[ADET]]*Tablo1[[#This Row],[ALIŞ]]+1.5,0) -> 0 | H27: =IF(Tablo1[[#This Row],[SATIŞ]]>0,(Tablo1[[#This Row],[ADET]]*Tablo1[[#This Row],[SATIŞ]]-1.5),0) -> 0

Sheet ADD
B1: ANA SAYFA | C1: =SUMIF(Tablo13489[KAR],"Açık",Tablo13489[ADET]) -> 0 | E1: =C1*D1 -> 0 | F1: =IFERROR(((SUM(Tablo13489[ALIŞ TUTAR])-SUM(Tablo13489[SATIŞ TUTAR]))/C1),"") | G1: =IF(M3=0,L3,C1*(D1-F1)) -> 1.55 | J1: 0.02 | L1: =M1*(1-$J$1) -> #VALUE! | M1: =F1 | N1: =M1*(1+$J$1) -> #VALUE! | P1: =Q1*(1-$J$1) -> 0 | Q1: =+D1 -> 0 | R1: =Q1*(1+$J$1) -> 0
B3: TARİH | C3: ADET | D3: ALIŞ | E3: SATIŞ | F3: KAR | G3: ALIŞ TUTAR | H3: SATIŞ TUTAR | L3: =SUM(Tablo13489[KAR]) -> 1.55 | M3: =C1 -> 0
B4: 44743 | C4: 350 | D4: 0.12 | E4: 0.133 | F4: =IF(Tablo13489[[#This Row],[SATIŞ]]=0,"Açık",(E4-D4)*C4-3) -> 1.55 | G4: =IF(Tablo13489[[#This Row],[ALIŞ]]>0,Tablo13489[[#This Row],[ADET]]*Tablo13489[[#This Row],[ALIŞ]]+1.5,0) -> 43.5 | H4: =IF(Tablo13489[[#This Row],[SATIŞ]]>0,(Tablo13489[[#This Row],[ADET]]*Tablo13489[[#This Row],[SATIŞ]]-1.5),0) -> 45.05
F5: =IF(Tablo13489[[#This Row],[SATIŞ]]=0,"Açık",(E5-D5)*C5-3) -> Açık | G5: =IF(Tablo13489[[#This Row],[ALIŞ]]>0,Tablo13489[[#This Row],[ADET]]*Tablo13489[[#This Row],[ALIŞ]]+1.5,0) -> 0 | H5: =IF(Tablo13489[[#This Row],[SATIŞ]]>0,(Tablo13489[[#This Row],[ADET]]*Tablo13489[[#This Row],[SATIŞ]]-1.5),0) -> 0
F6: =IF(Tablo13489[[#This Row],[SATIŞ]]=0,"Açık",(E6-D6)*C6-3) -> Açık | G6: =IF(Tablo13489[[#This Row],[ALIŞ]]>0,Tablo13489[[#This Row],[ADET]]*Tablo13489[[#This Row],[ALIŞ]]+1.5,0) -> 0 | H6: =IF(Tablo13489[[#This Row],[SATIŞ]]>0,(Tablo13489[[#This Row],[ADET]]*Tablo13489[[#This Row],[SATIŞ]]-1.5),0) -> 0
F7: =IF(Tablo13489[[#This Row],[SATIŞ]]=0,"Açık",(E7-D7)*C7-3) -> Açık | G7: =IF(Tablo13489[[#This Row],[ALIŞ]]>0,Tablo13489[[#This Row],[ADET]]*Tablo13489[[#This Row],[ALIŞ]]+1.5,0) -> 0 | H7: =IF(Tablo13489[[#This Row],[SATIŞ]]>0,(Tablo13489[[#This Row],[ADET]]*Tablo13489[[#This Row],[SATIŞ]]-1.5),0) -> 0
F8: =IF(Tablo13489[[#This Row],[SATIŞ]]=0,"Açık",(E8-D8)*C8-3) -> Açık | G8: =IF(Tablo13489[[#This Row],[ALIŞ]]>0,Tablo13489[[#This Row],[ADET]]*Tablo13489[[#This Row],[ALIŞ]]+1.5,0) -> 0 | H8: =IF(Tablo13489[[#This Row],[SATIŞ]]>0,(Tablo13489[[#This Row],[ADET]]*Tablo13489[[#This Row],[SATIŞ]]-1.5),0) -> 0
F9: =IF(Tablo13489[[#This Row],[SATIŞ]]=0,"Açık",(E9-D9)*C9-3) -> Açık | G9: =IF(Tablo13489[[#This Row],[ALIŞ]]>0,Tablo13489[[#This Row],[ADET]]*Tablo13489[[#This Row],[ALIŞ]]+1.5,0) -> 0 | H9: =IF(Tablo13489[[#This Row],[SATIŞ]]>0,(Tablo13489[[#This Row],[ADET]]*Tablo13489[[#This Row],[SATIŞ]]-1.5),0) -> 0
F10: =IF(Tablo13489[[#This Row],[SATIŞ]]=0,"Açık",(E10-D10)*C10-3) -> Açık | G10: =IF(Tablo13489[[#This Row],[ALIŞ]]>0,Tablo13489[[#This Row],[ADET]]*Tablo13489[[#This Row],[ALIŞ]]+1.5,0) -> 0 | H10: =IF(Tablo13489[[#This Row],[SATIŞ]]>0,(Tablo13489[[#This Row],[ADET]]*Tablo13489[[#This Row],[SATIŞ]]-1.5),0) -> 0
F11: =IF(Tablo13489[[#This Row],[SATIŞ]]=0,"Açık",(E11-D11)*C11-3) -> Açık | G11: =IF(Tablo13489[[#This Row],[ALIŞ]]>0,Tablo13489[[#This Row],[ADET]]*Tablo13489[[#This Row],[ALIŞ]]+1.5,0) -> 0 | H11: =IF(Tablo13489[[#This Row],[SATIŞ]]>0,(Tablo13489[[#This Row],[ADET]]*Tablo13489[[#This Row],[SATIŞ]]-1.5),0) -> 0 | J11: =+Tablo13489[[#This Row],[ALIŞ]]*1.02 -> 0
F12: =IF(Tablo13489[[#This Row],[SATIŞ]]=0,"Açık",(E12-D12)*C12-3) -> Açık | G12: =IF(Tablo13489[[#This Row],[ALIŞ]]>0,Tablo13489[[#This Row],[ADET]]*Tablo13489[[#This Row],[ALIŞ]]+1.5,0) -> 0 | H12: =IF(Tablo13489[[#This Row],[SATIŞ]]>0,(Tablo13489[[#This Row],[ADET]]*Tablo13489[[#This Row],[SATIŞ]]-1.5),0) -> 0
F13: =IF(Tablo13489[[#This Row],[SATIŞ]]=0,"Açık",(E13-D13)*C13-3) -> Açık | G13: =IF(Tablo13489[[#This Row],[ALIŞ]]>0,Tablo13489[[#This Row],[ADET]]*Tablo13489[[#This Row],[ALIŞ]]+1.5,0) -> 0 | H13: =IF(Tablo13489[[#This Row],[SATIŞ]]>0,(Tablo13489[[#This Row],[ADET]]*Tablo13489[[#This Row],[SATIŞ]]-1.5),0) -> 0
F14: =IF(Tablo13489[[#This Row],[SATIŞ]]=0,"Açık",(E14-D14)*C14-3) -> Açık | G14: =IF(Tablo13489[[#This Row],[ALIŞ]]>0,Tablo13489[[#This Row],[ADET]]*Tablo13489[[#This Row],[ALIŞ]]+1.5,0) -> 0 | H14: =IF(Tablo13489[[#This Row],[SATIŞ]]>0,(Tablo13489[[#This Row],[ADET]]*Tablo13489[[#This Row],[SATIŞ]]-1.5),0) -> 0
F15: =IF(Tablo13489[[#This Row],[SATIŞ]]=0,"Açık",(E15-D15)*C15-3) -> Açık | G15: =IF(Tablo13489[[#This Row],[ALIŞ]]>0,Tablo13489[[#This Row],[ADET]]*Tablo13489[[#This Row],[ALIŞ]]+1.5,0) -> 0 | H15: =IF(Tablo13489[[#This Row],[SATIŞ]]>0,(Tablo13489[[#This Row],[ADET]]*Tablo13489[[#This Row],[SATIŞ]]-1.5),0) -> 0
F16: =IF(Tablo13489[[#This Row],[SATIŞ]]=0,"Açık",(E16-D16)*C16-3) -> Açık | G16: =IF(Tablo13489[[#This Row],[ALIŞ]]>0,Tablo13489[[#This Row],[ADET]]*Tablo13489[[#This Row],[ALIŞ]]+1.5,0) -> 0 | H16: =IF(Tablo13489[[#This Row],[SATIŞ]]>0,(Tablo13489[[#This Row],[ADET]]*Tablo13489[[#This Row],[SATIŞ]]-1.5),0) -> 0
F17: =IF(Tablo13489[[#This Row],[SATIŞ]]=0,"Açık",(E17-D17)*C17-3) -> Açık | G17: =IF(Tablo13489[[#This Row],[ALIŞ]]>0,Tablo13489[[#This Row],[ADET]]*Tablo13489[[#This Row],[ALIŞ]]+1.5,0) -> 0 | H17: =IF(Tablo13489[[#This Row],[SATIŞ]]>0,(Tablo13489[[#This Row],[ADET]]*Tablo13489[[#This Row],[SATIŞ]]-1.5),0) -> 0
F18: =IF(Tablo13489[[#This Row],[SATIŞ]]=0,"Açık",(E18-D18)*C18-3) -> Açık | G18: =IF(Tablo13489[[#This Row],[ALIŞ]]>0,Tablo13489[[#This Row],[ADET]]*Tablo13489[[#This Row],[ALIŞ]]+1.5,0) -> 0 | H18: =IF(Tablo13489[[#This Row],[SATIŞ]]>0,(Tablo13489[[#This Row],[ADET]]*Tablo13489[[#This Row],[SATIŞ]]-1.5),0) -> 0
F19: =IF(Tablo13489[[#This Row],[SATIŞ]]=0,"Açık",(E19-D19)*C19-3) -> Açık | G19: =IF(Tablo13489[[#This Row],[ALIŞ]]>0,Tablo13489[[#This Row],[ADET]]*Tablo13489[[#This Row],[ALIŞ]]+1.5,0) -> 0 | H19: =IF(Tablo13489[[#This Row],[SATIŞ]]>0,(Tablo13489[[#This Row],[ADET]]*Tablo13489[[#This Row],[SATIŞ]]-1.5),0) -> 0
F20: =IF(Tablo13489[[#This Row],[SATIŞ]]=0,"Açık",(E20-D20)*C20-3) -> Açık | G20: =IF(Tablo13489[[#This Row],[ALIŞ]]>0,Tablo13489[[#This Row],[ADET]]*Tablo13489[[#This Row],[ALIŞ]]+1.5,0) -> 0 | H20: =IF(Tablo13489[[#This Row],[SATIŞ]]>0,(Tablo13489[[#This Row],[ADET]]*Tablo13489[[#This Row],[SATIŞ]]-1.5),0) -> 0
F21: =IF(Tablo13489[[#This Row],[SATIŞ]]=0,"Açık",(E21-D21)*C21-3) -> Açık | G21: =IF(Tablo13489[[#This Row],[ALIŞ]]>0,Tablo13489[[#This Row],[ADET]]*Tablo13489[[#This Row],[ALIŞ]]+1.5,0) -> 0 | H21: =IF(Tablo13489[[#This Row],[SATIŞ]]>0,(Tablo13489[[#This Row],[ADET]]*Tablo13489[[#This Row],[SATIŞ]]-1.5),0) -> 0
F22: =IF(Tablo13489[[#This Row],[SATIŞ]]=0,"Açık",(E22-D22)*C22-3) -> Açık | G22: =IF(Tablo13489[[#This Row],[ALIŞ]]>0,Tablo13489[[#This Row],[ADET]]*Tablo13489[[#This Row],[ALIŞ]]+1.5,0) -> 0 | H22: =IF(Tablo13489[[#This Row],[SATIŞ]]>0,(Tablo13489[[#This Row],[ADET]]*Tablo13489[[#This Row],[SATIŞ]]-1.5),0) -> 0
F23: =IF(Tablo13489[[#This Row],[SATIŞ]]=0,"Açık",(E23-D23)*C23-3) -> Açık | G23: =IF(Tablo13489[[#This Row],[ALIŞ]]>0,Tablo13489[[#This Row],[ADET]]*Tablo13489[[#This Row],[ALIŞ]]+1.5,0) -> 0 | H23: =IF(Tablo13489[[#This Row],[SATIŞ]]>0,(Tablo13489[[#This Row],[ADET]]*Tablo13489[[#This Row],[SATIŞ]]-1.5),0) -> 0
... F27: =IF(Tablo13489[[#This Row],[SATIŞ]]=0,"Açık",(E27-D27)*C27-3) -> Açık | G27: =IF(Tablo13489[[#This Row],[ALIŞ]]>0,Tablo13489[[#This Row],[ADET]]*Tablo13489[[#This Row],[ALIŞ]]+1.5,0) -> 0 | H27: =IF(Tablo13489[[#This Row],[SATIŞ]]>0,(Tablo13489[[#This Row],[ADET]]*Tablo13489[[#This Row],[SATIŞ]]-1.5),0) -> 0

Sheet AMD
B1: ANA SAYFA | C1: =SUMIF(Tablo134262728293031353637[KAR],"Açık",Tablo134262728293031353637[ADET]) -> 10 | D1: =+İcmal!E5 -> 205.13 | E1: =C1*D1 -> 2051.3 | F1: =IFERROR(((SUM(Tablo134262728293031353637[ALIŞ TUTAR])-SUM(Tablo134262728293031353637[SATIŞ TUTAR]))/C1),"") -> 125.848 | G1: =IF(M3=0,L3,C1*(D1-F1)) -> 792.82 | J1: 0.02 | L1: =M1*(1-$J$1) -> 123.33104 | M1: =F1 -> 125.848 | N1: =M1*(1+$J$1) -> 128.36496 | P1: =Q1*(1-$J$1) -> 201.0274 | Q1: =+D1 -> 205.13 | R1: =Q1*(1+$J$1) -> 209.2326
B3: TARİH | C3: ADET | D3: ALIŞ | E3: SATIŞ | F3: KAR | G3: ALIŞ TUTAR | H3: SATIŞ TUTAR | L3: =SUM(Tablo134262728293031353637[KAR]) -> 819.52 | M3: =C1 -> 10
B4: 45328 | C4: 4 | D4: 171.05 | E4: 176 | F4: =IF(Tablo134262728293031353637[[#This Row],[SATIŞ]]=0,"Açık",(E4-D4)*C4-3) -> 16.8 | G4: =IF(Tablo134262728293031353637[[#This Row],[ALIŞ]]>0,Tablo134262728293031353637[[#This Row],[ADET]]*Tablo134262728293031353637[[#This Row],[ALIŞ]]+1.5,0) -> 685.7 | H4: =IF(Tablo134262728293031353637[[#This Row],[SATIŞ]]>0,(Tablo134262728293031353637[[#This Row],[ADET]]*Tablo134262728293031353637[[#This Row],[SATIŞ]]-1.5),0) -> 702.5
B5: 45328 | C5: 6 | D5: 171.05 | E5: 166 | F5: =IF(Tablo134262728293031353637[[#This Row],[SATIŞ]]=0,"Açık",(E5-D5)*C5-3) -> -33.3 | G5: =IF(Tablo134262728293031353637[[#This Row],[ALIŞ]]>0,Tablo134262728293031353637[[#This Row],[ADET]]*Tablo134262728293031353637[[#This Row],[ALIŞ]]+1.5,0) -> 1027.8 | H5: =IF(Tablo134262728293031353637[[#This Row],[SATIŞ]]>0,(Tablo134262728293031353637[[#This Row],[ADET]]*Tablo134262728293031353637[[#This Row],[SATIŞ]]-1.5),0) -> 994.5
B6: 45328 | C6: 2 | D6: 167.43 | E6: 166 | F6: =IF(Tablo134262728293031353637[[#This Row],[SATIŞ]]=0,"Açık",(E6-D6)*C6-3) -> -5.86 | G6: =IF(Tablo134262728293031353637[[#This Row],[ALIŞ]]>0,Tablo134262728293031353637[[#This Row],[ADET]]*Tablo134262728293031353637[[#This Row],[ALIŞ]]+1.5,0) -> 336.36 | H6: =IF(Tablo134262728293031353637[[#This Row],[SATIŞ]]>0,(Tablo134262728293031353637[[#This Row],[ADET]]*Tablo134262728293031353637[[#This Row],[SATIŞ]]-1.5),0) -> 330.5
B7: 45342 | C7: 2 | D7: 166.71 | E7: 166 | F7: =IF(Tablo134262728293031353637[[#This Row],[SATIŞ]]=0,"Açık",(E7-D7)*C7-3) -> -4.42 | G7: =IF(Tablo134262728293031353637[[#This Row],[ALIŞ]]>0,Tablo134262728293031353637[[#This Row],[ADET]]*Tablo134262728293031353637[[#This Row],[ALIŞ]]+1.5,0) -> 334.92 | H7: =IF(Tablo134262728293031353637[[#This Row],[SATIŞ]]>0,(Tablo134262728293031353637[[#This Row],[ADET]]*Tablo134262728293031353637[[#This Row],[SATIŞ]]-1.5),0) -> 330.5
B8: 45342 | C8: 20 | D8: 163.91 | E8: 166 | F8: =IF(Tablo134262728293031353637[[#This Row],[SATIŞ]]=0,"Açık",(E8-D8)*C8-3) -> 38.8 | G8: =IF(Tablo134262728293031353637[[#This Row],[ALIŞ]]>0,Tablo134262728293031353637[[#This Row],[ADET]]*Tablo134262728293031353637[[#This Row],[ALIŞ]]+1.5,0) -> 3279.7 | H8: =IF(Tablo134262728293031353637[[#This Row],[SATIŞ]]>0,(Tablo134262728293031353637[[#This Row],[ADET]]*Tablo134262728293031353637[[#This Row],[SATIŞ]]-1.5),0) -> 3318.5
B9: 45342 | C9: 10 | D9: 163.91 | E9: 175 | F9: =IF(Tablo134262728293031353637[[#This Row],[SATIŞ]]=0,"Açık",(E9-D9)*C9-3) -> 107.9 | G9: =IF(Tablo134262728293031353637[[#This Row],[ALIŞ]]>0,Tablo134262728293031353637[[#This Row],[ADET]]*Tablo134262728293031353637[[#This Row],[ALIŞ]]+1.5,0) -> 1640.6 | H9: =IF(Tablo134262728293031353637[[#This Row],[SATIŞ]]>0,(Tablo134262728293031353637[[#This Row],[ADET]]*Tablo134262728293031353637[[#This Row],[SATIŞ]]-1.5),0) -> 1748.5
B10: 45342 | C10: 5 | D10: 163.91 | E10: 183 | F10: =IF(Tablo134262728293031353637[[#This Row],[SATIŞ]]=0,"Açık",(E10-D10)*C10-3) -> 92.45 | G10: =IF(Tablo134262728293031353637[[#This Row],[ALIŞ]]>0,Tablo134262728293031353637[[#This Row],[ADET]]*Tablo134262728293031353637[[#This Row],[ALIŞ]]+1.5,0) -> 821.05 | H10: =IF(Tablo134262728293031353637[[#This Row],[SATIŞ]]>0,(Tablo134262728293031353637[[#This Row],[ADET]]*Tablo134262728293031353637[[#This Row],[SATIŞ]]-1.5),0) -> 913.5
B11: 45342 | C11: 5 | D11: 163.91 | E11: 177 | F11: =IF(Tablo134262728293031353637[[#This Row],[SATIŞ]]=0,"Açık",(E11-D11)*C11-3) -> 62.45 | G11: =IF(Tablo134262728293031353637[[#This Row],[ALIŞ]]>0,Tablo134262728293031353637[[#This Row],[ADET]]*Tablo134262728293031353637[[#This Row],[ALIŞ]]+1.5,0) -> 821.05 | H11: =IF(Tablo134262728293031353637[[#This Row],[SATIŞ]]>0,(Tablo134262728293031353637[[#This Row],[ADET]]*Tablo134262728293031353637[[#This Row],[SATIŞ]]-1.5),0) -> 883.5
B12: 45343 | C12: 10 | D12: 162 | E12: 168 | F12: =IF(Tablo134262728293031353637[[#This Row],[SATIŞ]]=0,"Açık",(E12-D12)*C12-3) -> 57 | G12: =IF(Tablo134262728293031353637[[#This Row],[ALIŞ]]>0,Tablo134262728293031353637[[#This Row],[ADET]]*Tablo134262728293031353637[[#This Row],[ALIŞ]]+1.5,0) -> 1621.5 | H12: =IF(Tablo134262728293031353637[[#This Row],[SATIŞ]]>0,(Tablo134262728293031353637[[#This Row],[ADET]]*Tablo134262728293031353637[[#This Row],[SATIŞ]]-1.5),0) -> 1678.5
B13: 45345 | C13: 5 | D13: 180 | E13: 190 | F13: =IF(Tablo134262728293031353637[[#This Row],[SATIŞ]]=0,"Açık",(E13-D13)*C13-3) -> 47 | G13: =IF(Tablo134262728293031353637[[#This Row],[ALIŞ]]>0,Tablo134262728293031353637[[#This Row],[ADET]]*Tablo134262728293031353637[[#This Row],[ALIŞ]]+1.5,0) -> 901.5 | H13: =IF(Tablo134262728293031353637[[#This Row],[SATIŞ]]>0,(Tablo134262728293031353637[[#This Row],[ADET]]*Tablo134262728293031353637[[#This Row],[SATIŞ]]-1.5),0) -> 948.5 | J13: =+Tablo134262728293031353637[[#This Row],[ALIŞ]]*1.02 -> 183.6
B14: 45345 | C14: 5 | D14: 178 | E14: 195 | F14: =IF(Tablo134262728293031353637[[#This Row],[SATIŞ]]=0,"Açık",(E14-D14)*C14-3) -> 82 | G14: =IF(Tablo134262728293031353637[[#This Row],[ALIŞ]]>0,Tablo134262728293031353637[[#This Row],[ADET]]*Tablo134262728293031353637[[#This Row],[ALIŞ]]+1.5,0) -> 891.5 | H14: =IF(Tablo134262728293031353637[[#This Row],[SATIŞ]]>0,(Tablo134262728293031353637[[#This Row],[ADET]]*Tablo134262728293031353637[[#This Row],[SATIŞ]]-1.5),0) -> 973.5
B15: 45345 | C15: 5 | D15: 178 | E15: 210 | F15: =IF(Tablo134262728293031353637[[#This Row],[SATIŞ]]=0,"Açık",(E15-D15)*C15-3) -> 157 | G15: =IF(Tablo134262728293031353637[[#This Row],[ALIŞ]]>0,Tablo134262728293031353637[[#This Row],[ADET]]*Tablo134262728293031353637[[#This Row],[ALIŞ]]+1.5,0) -> 891.5 | H15: =IF(Tablo134262728293031353637[[#This Row],[SATIŞ]]>0,(Tablo134262728293031353637[[#This Row],[ADET]]*Tablo134262728293031353637[[#This Row],[SATIŞ]]-1.5),0) -> 1048.5
B16: 45349 | C16: 10 | D16: 173 | E16: 185.37 | F16: =IF(Tablo134262728293031353637[[#This Row],[SATIŞ]]=0,"Açık",(E16-D16)*C16-3) -> 120.7 | G16: =IF(Tablo134262728293031353637[[#This Row],[ALIŞ]]>0,Tablo134262728293031353637[[#This Row],[ADET]]*Tablo134262728293031353637[[#This Row],[ALIŞ]]+1.5,0) -> 1731.5 | H16: =IF(Tablo134262728293031353637[[#This Row],[SATIŞ]]>0,(Tablo134262728293031353637[[#This Row],[ADET]]*Tablo134262728293031353637[[#This Row],[SATIŞ]]-1.5),0) -> 1852.2
B17: 45355 | C17: 5 | D17: 205 | E17: 204 | F17: =IF(Tablo134262728293031353637[[#This Row],[SATIŞ]]=0,"Açık",(E17-D17)*C17-3) -> -8 | G17: =IF(Tablo134262728293031353637[[#This Row],[ALIŞ]]>0,Tablo134262728293031353637[[#This Row],[ADET]]*Tablo134262728293031353637[[#This Row],[ALIŞ]]+1.5,0) -> 1026.5 | H17: =IF(Tablo134262728293031353637[[#This Row],[SATIŞ]]>0,(Tablo134262728293031353637[[#This Row],[ADET]]*Tablo134262728293031353637[[#This Row],[SATIŞ]]-1.5),0) -> 1018.5
B18: 45355 | C18: 5 | D18: 205 | E18: 220 | F18: =IF(Tablo134262728293031353637[[#This Row],[SATIŞ]]=0,"Açık",(E18-D18)*C18-3) -> 72 | G18: =IF(Tablo134262728293031353637[[#This Row],[ALIŞ]]>0,Tablo134262728293031353637[[#This Row],[ADET]]*Tablo134262728293031353637[[#This Row],[ALIŞ]]+1.5,0) -> 1026.5 | H18: =IF(Tablo134262728293031353637[[#This Row],[SATIŞ]]>0,(Tablo134262728293031353637[[#This Row],[ADET]]*Tablo134262728293031353637[[#This Row],[SATIŞ]]-1.5),0) -> 1098.5
B19: 45356 | C19: 10 | D19: 200 | E19: 202 | F19: =IF(Tablo134262728293031353637[[#This Row],[SATIŞ]]=0,"Açık",(E19-D19)*C19-3) -> 17 | G19: =IF(Tablo134262728293031353637[[#This Row],[ALIŞ]]>0,Tablo134262728293031353637[[#This Row],[ADET]]*Tablo134262728293031353637[[#This Row],[ALIŞ]]+1.5,0) -> 2001.5 | H19: =IF(Tablo134262728293031353637[[#This Row],[SATIŞ]]>0,(Tablo134262728293031353637[[#This Row],[ADET]]*Tablo134262728293031353637[[#This Row],[SATIŞ]]-1.5),0) -> 2018.5
B20: 45359 | C20: 5 | D20: 205 | F20: =IF(Tablo134262728293031353637[[#This Row],[SATIŞ]]=0,"Açık",(E20-D20)*C20-3) -> Açık | G20: =IF(Tablo134262728293031353637[[#This Row],[ALIŞ]]>0,Tablo134262728293031353637[[#This Row],[ADET]]*Tablo134262728293031353637[[#This Row],[ALIŞ]]+1.5,0) -> 1026.5 | H20: =IF(Tablo134262728293031353637[[#This Row],[SATIŞ]]>0,(Tablo134262728293031353637[[#This Row],[ADET]]*Tablo134262728293031353637[[#This Row],[SATIŞ]]-1.5),0) -> 0
B21: 45359 | C21: 5 | D21: 210 | F21: =IF(Tablo134262728293031353637[[#This Row],[SATIŞ]]=0,"Açık",(E21-D21)*C21-3) -> Açık | G21: =IF(Tablo134262728293031353637[[#This Row],[ALIŞ]]>0,Tablo134262728293031353637[[#This Row],[ADET]]*Tablo134262728293031353637[[#This Row],[ALIŞ]]+1.5,0) -> 1051.5 | H21: =IF(Tablo134262728293031353637[[#This Row],[SATIŞ]]>0,(Tablo134262728293031353637[[#This Row],[ADET]]*Tablo134262728293031353637[[#This Row],[SATIŞ]]-1.5),0) -> 0
F22: =IF(Tablo134262728293031353637[[#This Row],[SATIŞ]]=0,"Açık",(E22-D22)*C22-3) -> Açık | G22: =IF(Tablo134262728293031353637[[#This Row],[ALIŞ]]>0,Tablo134262728293031353637[[#This Row],[ADET]]*Tablo134262728293031353637[[#This Row],[ALIŞ]]+1.5,0) -> 0 | H22: =IF(Tablo134262728293031353637[[#This Row],[SATIŞ]]>0,(Tablo134262728293031353637[[#This Row],[ADET]]*Tablo134262728293031353637[[#This Row],[SATIŞ]]-1.5),0) -> 0
F23: =IF(Tablo134262728293031353637[[#This Row],[SATIŞ]]=0,"Açık",(E23-D23)*C23-3) -> Açık | G23: =IF(Tablo134262728293031353637[[#This Row],[ALIŞ]]>0,Tablo134262728293031353637[[#This Row],[ADET]]*Tablo134262728293031353637[[#This Row],[ALIŞ]]+1.5,0) -> 0 | H23: =IF(Tablo134262728293031353637[[#This Row],[SATIŞ]]>0,(Tablo134262728293031353637[[#This Row],[ADET]]*Tablo134262728293031353637[[#This Row],[SATIŞ]]-1.5),0) -> 0
F24: =IF(Tablo134262728293031353637[[#This Row],[SATIŞ]]=0,"Açık",(E24-D24)*C24-3) -> Açık | G24: =IF(Tablo134262728293031353637[[#This Row],[ALIŞ]]>0,Tablo134262728293031353637[[#This Row],[ADET]]*Tablo134262728293031353637[[#This Row],[ALIŞ]]+1.5,0) -> 0 | H24: =IF(Tablo134262728293031353637[[#This Row],[SATIŞ]]>0,(Tablo134262728293031353637[[#This Row],[ADET]]*Tablo134262728293031353637[[#This Row],[SATIŞ]]-1.5),0) -> 0
F25: =IF(Tablo134262728293031353637[[#This Row],[SATIŞ]]=0,"Açık",(E25-D25)*C25-3) -> Açık | G25: =IF(Tablo134262728293031353637[[#This Row],[ALIŞ]]>0,Tablo134262728293031353637[[#This Row],[ADET]]*Tablo134262728293031353637[[#This Row],[ALIŞ]]+1.5,0) -> 0 | H25: =IF(Tablo134262728293031353637[[#This Row],[SATIŞ]]>0,(Tablo134262728293031353637[[#This Row],[ADET]]*Tablo134262728293031353637[[#This Row],[SATIŞ]]-1.5),0) -> 0
F26: =IF(Tablo134262728293031353637[[#This Row],[SATIŞ]]=0,"Açık",(E26-D26)*C26-3) -> Açık | G26: =IF(Tablo134262728293031353637[[#This Row],[ALIŞ]]>0,Tablo134262728293031353637[[#This Row],[ADET]]*Tablo134262728293031353637[[#This Row],[ALIŞ]]+1.5,0) -> 0 | H26: =IF(Tablo134262728293031353637[[#This Row],[SATIŞ]]>0,(Tablo134262728293031353637[[#This Row],[ADET]]*Tablo134262728293031353637[[#This Row],[SATIŞ]]-1.5),0) -> 0
F27: =IF(Tablo134262728293031353637[[#This Row],[SATIŞ]]=0,"Açık",(E27-D27)*C27-3) -> Açık | G27: =IF(Tablo134262728293031353637[[#This Row],[ALIŞ]]>0,Tablo134262728293031353637[[#This Row],[ADET]]*Tablo134262728293031353637[[#This Row],[ALIŞ]]+1.5,0) -> 0 | H27: =IF(Tablo134262728293031353637[[#This Row],[SATIŞ]]>0,(Tablo134262728293031353637[[#This Row],[ADET]]*Tablo134262728293031353637[[#This Row],[SATIŞ]]-1.5),0) -> 0
F28: =IF(Tablo134262728293031353637[[#This Row],[SATIŞ]]=0,"Açık",(E28-D28)*C28-3) -> Açık | G28: =IF(Tablo134262728293031353637[[#This Row],[ALIŞ]]>0,Tablo134262728293031353637[[#This Row],[ADET]]*Tablo134262728293031353637[[#This Row],[ALIŞ]]+1.5,0) -> 0 | H28: =IF(Tablo134262728293031353637[[#This Row],[SATIŞ]]>0,(Tablo134262728293031353637[[#This Row],[ADET]]*Tablo134262728293031353637[[#This Row],[SATIŞ]]-1.5),0) -> 0
F29: =IF(Tablo134262728293031353637[[#This Row],[SATIŞ]]=0,"Açık",(E29-D29)*C29-3) -> Açık | G29: =IF(Tablo134262728293031353637[[#This Row],[ALIŞ]]>0,Tablo134262728293031353637[[#This Row],[ADET]]*Tablo134262728293031353637[[#This Row],[ALIŞ]]+1.5,0) -> 0 | H29: =IF(Tablo134262728293031353637[[#This Row],[SATIŞ]]>0,(Tablo134262728293031353637[[#This Row],[ADET]]*Tablo134262728293031353637[[#This Row],[SATIŞ]]-1.5),0) -> 0

Sheet AMTX
B1: ANA SAYFA | C1: =SUMIF(Tablo1348913141516171819[KAR],"Açık",Tablo1348913141516171819[ADET]) -> 0 | E1: =C1*D1 -> 0 | F1: =IFERROR(((SUM(Tablo1348913141516171819[ALIŞ TUTAR])-SUM(Tablo1348913141516171819[SATIŞ TUTAR]))/C1),"") | G1: =IF(M3=0,L3,C1*(D1-F1)) -> -74 | J1: 0.02 | L1: =M1*(1-$J$1) -> #VALUE! | M1: =F1 | N1: =M1*(1+$J$1) -> #VALUE! | P1: =Q1*(1-$J$1) -> 0 | Q1: =+D1 -> 0 | R1: =Q1*(1+$J$1) -> 0
B3: TARİH | C3: ADET | D3: ALIŞ | E3: SATIŞ | F3: KAR | G3: ALIŞ TUTAR | H3: SATIŞ TUTAR | L3: =SUM(Tablo1348913141516171819[KAR]) -> -74 | M3: =C1 -> 0
B4: 44897 | C4: 20 | D4: 5.53 | E4: 1.98 | F4: =IF(Tablo1348913141516171819[[#This Row],[SATIŞ]]=0,"Açık",(E4-D4)*C4-3) -> -74 | G4: =IF(Tablo1348913141516171819[[#This Row],[ALIŞ]]>0,Tablo1348913141516171819[[#This Row],[ADET]]*Tablo1348913141516171819[[#This Row],[ALIŞ]]+1.5,0) -> 112.1 | H4: =IF(Tablo1348913141516171819[[#This Row],[SATIŞ]]>0,(Tablo1348913141516171819[[#This Row],[ADET]]*Tablo1348913141516171819[[#This Row],[SATIŞ]]-1.5),0) -> 38.1
F5: =IF(Tablo1348913141516171819[[#This Row],[SATIŞ]]=0,"Açık",(E5-D5)*C5-3) -> Açık | G5: =IF(Tablo1348913141516171819[[#This Row],[ALIŞ]]>0,Tablo1348913141516171819[[#This Row],[ADET]]*Tablo1348913141516171819[[#This Row],[ALIŞ]]+1.5,0) -> 0 | H5: =IF(Tablo1348913141516171819[[#This Row],[SATIŞ]]>0,(Tablo1348913141516171819[[#This Row],[ADET]]*Tablo1348913141516171819[[#This Row],[SATIŞ]]-1.5),0) -> 0
F6: =IF(Tablo1348913141516171819[[#This Row],[SATIŞ]]=0,"Açık",(E6-D6)*C6-3) -> Açık | G6: =IF(Tablo1348913141516171819[[#This Row],[ALIŞ]]>0,Tablo1348913141516171819[[#This Row],[ADET]]*Tablo1348913141516171819[[#This Row],[ALIŞ]]+1.5,0) -> 0 | H6: =IF(Tablo1348913141516171819[[#This Row],[SATIŞ]]>0,(Tablo1348913141516171819[[#This Row],[ADET]]*Tablo1348913141516171819[[#This Row],[SATIŞ]]-1.5),0) -> 0
F7: =IF(Tablo1348913141516171819[[#This Row],[SATIŞ]]=0,"Açık",(E7-D7)*C7-3) -> Açık | G7: =IF(Tablo1348913141516171819[[#This Row],[ALIŞ]]>0,Tablo1348913141516171819[[#This Row],[ADET]]*Tablo1348913141516171819[[#This Row],[ALIŞ]]+1.5,0) -> 0 | H7: =IF(Tablo1348913141516171819[[#This Row],[SATIŞ]]>0,(Tablo1348913141516171819[[#This Row],[ADET]]*Tablo1348913141516171819[[#This Row],[SATIŞ]]-1.5),0) -> 0
F8: =IF(Tablo1348913141516171819[[#This Row],[SATIŞ]]=0,"Açık",(E8-D8)*C8-3) -> Açık | G8: =IF(Tablo1348913141516171819[[#This Row],[ALIŞ]]>0,Tablo1348913141516171819[[#This Row],[ADET]]*Tablo1348913141516171819[[#This Row],[ALIŞ]]+1.5,0) -> 0 | H8: =IF(Tablo1348913141516171819[[#This Row],[SATIŞ]]>0,(Tablo1348913141516171819[[#This Row],[ADET]]*Tablo1348913141516171819[[#This Row],[SATIŞ]]-1.5),0) -> 0
F9: =IF(Tablo1348913141516171819[[#This Row],[SATIŞ]]=0,"Açık",(E9-D9)*C9-3) -> Açık | G9: =IF(Tablo1348913141516171819[[#This Row],[ALIŞ]]>0,Tablo1348913141516171819[[#This Row],[ADET]]*Tablo1348913141516171819[[#This Row],[ALIŞ]]+1.5,0) -> 0 | H9: =IF(Tablo1348913141516171819[[#This Row],[SATIŞ]]>0,(Tablo1348913141516171819[[#This Row],[ADET]]*Tablo1348913141516171819[[#This Row],[SATIŞ]]-1.5),0) -> 0
F10: =IF(Tablo1348913141516171819[[#This Row],[SATIŞ]]=0,"Açık",(E10-D10)*C10-3) -> Açık | G10: =IF(Tablo1348913141516171819[[#This Row],[ALIŞ]]>0,Tablo1348913141516171819[[#This Row],[ADET]]*Tablo1348913141516171819[[#This Row],[ALIŞ]]+1.5,0) -> 0 | H10: =IF(Tablo1348913141516171819[[#This Row],[SATIŞ]]>0,(Tablo1348913141516171819[[#This Row],[ADET]]*Tablo1348913141516171819[[#This Row],[SATIŞ]]-1.5),0) -> 0
F11: =IF(Tablo1348913141516171819[[#This Row],[SATIŞ]]=0,"Açık",(E11-D11)*C11-3) -> Açık | G11: =IF(Tablo1348913141516171819[[#This Row],[ALIŞ]]>0,Tablo1348913141516171819[[#This Row],[ADET]]*Tablo1348913141516171819[[#This Row],[ALIŞ]]+1.5,0) -> 0 | H11: =IF(Tablo1348913141516171819[[#This Row],[SATIŞ]]>0,(Tablo1348913141516171819[[#This Row],[ADET]]*Tablo1348913141516171819[[#This Row],[SATIŞ]]-1.5),0) -> 0 | J11: =+Tablo1348913141516171819[[#This Row],[ALIŞ]]*1.02 -> 0
F12: =IF(Tablo1348913141516171819[[#This Row],[SATIŞ]]=0,"Açık",(E12-D12)*C12-3) -> Açık | G12: =IF(Tablo1348913141516171819[[#This Row],[ALIŞ]]>0,Tablo1348913141516171819[[#This Row],[ADET]]*Tablo1348913141516171819[[#This Row],[ALIŞ]]+1.5,0) -> 0 | H12: =IF(Tablo1348913141516171819[[#This Row],[SATIŞ]]>0,(Tablo1348913141516171819[[#This Row],[ADET]]*Tablo1348913141516171819[[#This Row],[SATIŞ]]-1.5),0) -> 0
F13: =IF(Tablo1348913141516171819[[#This Row],[SATIŞ]]=0,"Açık",(E13-D13)*C13-3) -> Açık | G13: =IF(Tablo1348913141516171819[[#This Row],[ALIŞ]]>0,Tablo1348913141516171819[[#This Row],[ADET]]*Tablo1348913141516171819[[#This Row],[ALIŞ]]+1.5,0) -> 0 | H13: =IF(Tablo1348913141516171819[[#This Row],[SATIŞ]]>0,(Tablo1348913141516171819[[#This Row],[ADET]]*Tablo1348913141516171819[[#This Row],[SATIŞ]]-1.5),0) -> 0
F14: =IF(Tablo1348913141516171819[[#This Row],[SATIŞ]]=0,"Açık",(E14-D14)*C14-3) -> Açık | G14: =IF(Tablo1348913141516171819[[#This Row],[ALIŞ]]>0,Tablo1348913141516171819[[#This Row],[ADET]]*Tablo1348913141516171819[[#This Row],[ALIŞ]]+1.5,0) -> 0 | H14: =IF(Tablo1348913141516171819[[#This Row],[SATIŞ]]>0,(Tablo1348913141516171819[[#This Row],[ADET]]*Tablo1348913141516171819[[#This Row],[SATIŞ]]-1.5),0) -> 0
F15: =IF(Tablo1348913141516171819[[#This Row],[SATIŞ]]=0,"Açık",(E15-D15)*C15-3) -> Açık | G15: =IF(Tablo1348913141516171819[[#This Row],[ALIŞ]]>0,Tablo1348913141516171819[[#This Row],[ADET]]*Tablo1348913141516171819[[#This Row],[ALIŞ]]+1.5,0) -> 0 | H15: =IF(Tablo1348913141516171819[[#This Row],[SATIŞ]]>0,(Tablo1348913141516171819[[#This Row],[ADET]]*Tablo1348913141516171819[[#This Row],[SATIŞ]]-1.5),0) -> 0
F16: =IF(Tablo1348913141516171819[[#This Row],[SATIŞ]]=0,"Açık",(E16-D16)*C16-3) -> Açık | G16: =IF(Tablo1348913141516171819[[#This Row],[ALIŞ]]>0,Tablo1348913141516171819[[#This Row],[ADET]]*Tablo1348913141516171819[[#This Row],[ALIŞ]]+1.5,0) -> 0 | H16: =IF(Tablo1348913141516171819[[#This Row],[SATIŞ]]>0,(Tablo1348913141516171819[[#This Row],[ADET]]*Tablo1348913141516171819[[#This Row],[SATIŞ]]-1.5),0) -> 0
F17: =IF(Tablo1348913141516171819[[#This Row],[SATIŞ]]=0,"Açık",(E17-D17)*C17-3) -> Açık | G17: =IF(Tablo1348913141516171819[[#This Row],[ALIŞ]]>0,Tablo1348913141516171819[[#This Row],[ADET]]*Tablo1348913141516171819[[#This Row],[ALIŞ]]+1.5,0) -> 0 | H17: =IF(Tablo1348913141516171819[[#This Row],[SATIŞ]]>0,(Tablo1348913141516171819[[#This Row],[ADET]]*Tablo1348913141516171819[[#This Row],[SATIŞ]]-1.5),0) -> 0
F18: =IF(Tablo1348913141516171819[[#This Row],[SATIŞ]]=0,"Açık",(E18-D18)*C18-3) -> Açık | G18: =IF(Tablo1348913141516171819[[#This Row],[ALIŞ]]>0,Tablo1348913141516171819[[#This Row],[ADET]]*Tablo1348913141516171819[[#This Row],[ALIŞ]]+1.5,0) -> 0 | H18: =IF(Tablo1348913141516171819[[#This Row],[SATIŞ]]>0,(Tablo1348913141516171819[[#This Row],[ADET]]*Tablo1348913141516171819[[#This Row],[SATIŞ]]-1.5),0) -> 0
F19: =IF(Tablo1348913141516171819[[#This Row],[SATIŞ]]=0,"Açık",(E19-D19)*C19-3) -> Açık | G19: =IF(Tablo1348913141516171819[[#This Row],[ALIŞ]]>0,Tablo1348913141516171819[[#This Row],[ADET]]*Tablo1348913141516171819[[#This Row],[ALIŞ]]+1.5,0) -> 0 | H19: =IF(Tablo1348913141516171819[[#This Row],[SATIŞ]]>0,(Tablo1348913141516171819[[#This Row],[ADET]]*Tablo1348913141516171819[[#This Row],[SATIŞ]]-1.5),0) -> 0
F20: =IF(Tablo1348913141516171819[[#This Row],[SATIŞ]]=0,"Açık",(E20-D20)*C20-3) -> Açık | G20: =IF(Tablo1348913141516171819[[#This Row],[ALIŞ]]>0,Tablo1348913141516171819[[#This Row],[ADET]]*Tablo1348913141516171819[[#This Row],[ALIŞ]]+1.5,0) -> 0 | H20: =IF(Tablo1348913141516171819[[#This Row],[SATIŞ]]>0,(Tablo1348913141516171819[[#This Row],[ADET]]*Tablo1348913141516171819[[#This Row],[SATIŞ]]-1.5),0) -> 0
F21: =IF(Tablo1348913141516171819[[#This Row],[SATIŞ]]=0,"Açık",(E21-D21)*C21-3) -> Açık | G21: =IF(Tablo1348913141516171819[[#This Row],[ALIŞ]]>0,Tablo1348913141516171819[[#This Row],[ADET]]*Tablo1348913141516171819[[#This Row],[ALIŞ]]+1.5,0) -> 0 | H21: =IF(Tablo1348913141516171819[[#This Row],[SATIŞ]]>0,(Tablo1348913141516171819[[#This Row],[ADET]]*Tablo1348913141516171819[[#This Row],[SATIŞ]]-1.5),0) -> 0
F22: =IF(Tablo1348913141516171819[[#This Row],[SATIŞ]]=0,"Açık",(E22-D22)*C22-3) -> Açık | G22: =IF(Tablo1348913141516171819[[#This Row],[ALIŞ]]>0,Tablo1348913141516171819[[#This Row],[ADET]]*Tablo1348913141516171819[[#This Row],[ALIŞ]]+1.5,0) -> 0 | H22: =IF(Tablo1348913141516171819[[#This Row],[SATIŞ]]>0,(Tablo1348913141516171819[[#This Row],[ADET]]*Tablo1348913141516171819[[#This Row],[SATIŞ]]-1.5),0) -> 0
F23: =IF(Tablo1348913141516171819[[#This Row],[SATIŞ]]=0,"Açık",(E23-D23)*C23-3) -> Açık | G23: =IF(Tablo1348913141516171819[[#This Row],[ALIŞ]]>0,Tablo1348913141516171819[[#This Row],[ADET]]*Tablo1348913141516171819[[#This Row],[ALIŞ]]+1.5,0) -> 0 | H23: =IF(Tablo1348913141516171819[[#This Row],[SATIŞ]]>0,(Tablo1348913141516171819[[#This Row],[ADET]]*Tablo1348913141516171819[[#This Row],[SATIŞ]]-1.5),0) -> 0
... F27: =IF(Tablo1348913141516171819[[#This Row],[SATIŞ]]=0,"Açık",(E27-D27)*C27-3) -> Açık | G27: =IF(Tablo1348913141516171819[[#This Row],[ALIŞ]]>0,Tablo1348913141516171819[[#This Row],[ADET]]*Tablo1348913141516171819[[#This Row],[ALIŞ]]+1.5,0) -> 0 | H27: =IF(Tablo1348913141516171819[[#This Row],[SATIŞ]]>0,(Tablo1348913141516171819[[#This Row],[ADET]]*Tablo1348913141516171819[[#This Row],[SATIŞ]]-1.5),0) -> 0

Sheet AMZN
B1: ANA SAYFA | C1: =SUMIF(Tablo13456[KAR],"Açık",Tablo13456[ADET]) -> 0 | E1: =C1*D1 -> 0 | F1: =IFERROR(((SUM(Tablo13456[ALIŞ TUTAR])-SUM(Tablo13456[SATIŞ TUTAR]))/C1),"") | G1: =IF(M3=0,L3,C1*(D1-F1)) -> 19.63 | J1: 0.02 | L1: =M1*(1-$J$1) -> #VALUE! | M1: =F1 | N1: =M1*(1+$J$1) -> #VALUE! | P1: =Q1*(1-$J$1) -> 0 | Q1: =+D1 -> 0 | R1: =Q1*(1+$J$1) -> 0
B3: TARİH | C3: ADET | D3: ALIŞ | E3: SATIŞ | F3: KAR | G3: ALIŞ TUTAR | H3: SATIŞ TUTAR | L3: =SUM(Tablo13456[KAR]) -> 19.63 | M3: =C1 -> 0
B4: 44725 | C4: 3 | D4: 104.78 | E4: 111.03 | F4: =IF(Tablo13456[[#This Row],[SATIŞ]]=0,"Açık",(E4-D4)*C4-3) -> 15.75 | G4: =IF(Tablo13456[[#This Row],[ALIŞ]]>0,Tablo13456[[#This Row],[ADET]]*Tablo13456[[#This Row],[ALIŞ]]+1.5,0) -> 315.84 | H4: =IF(Tablo13456[[#This Row],[SATIŞ]]>0,(Tablo13456[[#This Row],[ADET]]*Tablo13456[[#This Row],[SATIŞ]]-1.5),0) -> 331.59
B5: 44742 | C5: 2 | D5: 102.7 | E5: 107.5 | F5: =IF(Tablo13456[[#This Row],[SATIŞ]]=0,"Açık",(E5-D5)*C5-3) -> 6.6 | G5: =IF(Tablo13456[[#This Row],[ALIŞ]]>0,Tablo13456[[#This Row],[ADET]]*Tablo13456[[#This Row],[ALIŞ]]+1.5,0) -> 206.9 | H5: =IF(Tablo13456[[#This Row],[SATIŞ]]>0,(Tablo13456[[#This Row],[ADET]]*Tablo13456[[#This Row],[SATIŞ]]-1.5),0) -> 213.5
B6: 44742 | C6: 2 | D6: 106 | E6: 109.1 | F6: =IF(Tablo13456[[#This Row],[SATIŞ]]=0,"Açık",(E6-D6)*C6-3) -> 3.2 | G6: =IF(Tablo13456[[#This Row],[ALIŞ]]>0,Tablo13456[[#This Row],[ADET]]*Tablo13456[[#This Row],[ALIŞ]]+1.5,0) -> 213.5 | H6: =IF(Tablo13456[[#This Row],[SATIŞ]]>0,(Tablo13456[[#This Row],[ADET]]*Tablo13456[[#This Row],[SATIŞ]]-1.5),0) -> 216.7
B7: 44749 | C7: 3 | D7: 113.8 | E7: 110 | F7: =IF(Tablo13456[[#This Row],[SATIŞ]]=0,"Açık",(E7-D7)*C7-3) -> -14.4 | G7: =IF(Tablo13456[[#This Row],[ALIŞ]]>0,Tablo13456[[#This Row],[ADET]]*Tablo13456[[#This Row],[ALIŞ]]+1.5,0) -> 342.9 | H7: =IF(Tablo13456[[#This Row],[SATIŞ]]>0,(Tablo13456[[#This Row],[ADET]]*Tablo13456[[#This Row],[SATIŞ]]-1.5),0) -> 328.5
B8: 44750 | C8: 1 | D8: 115 | E8: 100 | F8: =IF(Tablo13456[[#This Row],[SATIŞ]]=0,"Açık",(E8-D8)*C8-3) -> -18 | G8: =IF(Tablo13456[[#This Row],[ALIŞ]]>0,Tablo13456[[#This Row],[ADET]]*Tablo13456[[#This Row],[ALIŞ]]+1.5,0) -> 116.5 | H8: =IF(Tablo13456[[#This Row],[SATIŞ]]>0,(Tablo13456[[#This Row],[ADET]]*Tablo13456[[#This Row],[SATIŞ]]-1.5),0) -> 98.5
B9: 44750 | C9: 4 | D9: 115 | E9: 115 | F9: =IF(Tablo13456[[#This Row],[SATIŞ]]=0,"Açık",(E9-D9)*C9-3) -> -3 | G9: =IF(Tablo13456[[#This Row],[ALIŞ]]>0,Tablo13456[[#This Row],[ADET]]*Tablo13456[[#This Row],[ALIŞ]]+1.5,0) -> 461.5 | H9: =IF(Tablo13456[[#This Row],[SATIŞ]]>0,(Tablo13456[[#This Row],[ADET]]*Tablo13456[[#This Row],[SATIŞ]]-1.5),0) -> 458.5
B10: 44779 | C10: 3 | D10: 140 | E10: 143 | F10: =IF(Tablo13456[[#This Row],[SATIŞ]]=0,"Açık",(E10-D10)*C10-3) -> 6 | G10: =IF(Tablo13456[[#This Row],[ALIŞ]]>0,Tablo13456[[#This Row],[ADET]]*Tablo13456[[#This Row],[ALIŞ]]+1.5,0) -> 421.5 | H10: =IF(Tablo13456[[#This Row],[SATIŞ]]>0,(Tablo13456[[#This Row],[ADET]]*Tablo13456[[#This Row],[SATIŞ]]-1.5),0) -> 427.5
B11: 44784 | C11: 7 | D11: 141 | E11: 143 | F11: =IF(Tablo13456[[#This Row],[SATIŞ]]=0,"Açık",(E11-D11)*C11-3) -> 11 | G11: =IF(Tablo13456[[#This Row],[ALIŞ]]>0,Tablo13456[[#This Row],[ADET]]*Tablo13456[[#This Row],[ALIŞ]]+1.5,0) -> 988.5 | H11: =IF(Tablo13456[[#This Row],[SATIŞ]]>0,(Tablo13456[[#This Row],[ADET]]*Tablo13456[[#This Row],[SATIŞ]]-1.5),0) -> 999.5
B12: 45065 | C12: 3 | D12: 116.26 | E12: 121.42 | F12: =IF(Tablo13456[[#This Row],[SATIŞ]]=0,"Açık",(E12-D12)*C12-3) -> 12.48 | G12: =IF(Tablo13456[[#This Row],[ALIŞ]]>0,Tablo13456[[#This Row],[ADET]]*Tablo13456[[#This Row],[ALIŞ]]+1.5,0) -> 350.28 | H12: =IF(Tablo13456[[#This Row],[SATIŞ]]>0,(Tablo13456[[#This Row],[ADET]]*Tablo13456[[#This Row],[SATIŞ]]-1.5),0) -> 362.76
F13: =IF(Tablo13456[[#This Row],[SATIŞ]]=0,"Açık",(E13-D13)*C13-3) -> Açık | G13: =IF(Tablo13456[[#This Row],[ALIŞ]]>0,Tablo13456[[#This Row],[ADET]]*Tablo13456[[#This Row],[ALIŞ]]+1.5,0) -> 0 | H13: =IF(Tablo13456[[#This Row],[SATIŞ]]>0,(Tablo13456[[#This Row],[ADET]]*Tablo13456[[#This Row],[SATIŞ]]-1.5),0) -> 0
F14: =IF(Tablo13456[[#This Row],[SATIŞ]]=0,"Açık",(E14-D14)*C14-3) -> Açık | G14: =IF(Tablo13456[[#This Row],[ALIŞ]]>0,Tablo13456[[#This Row],[ADET]]*Tablo13456[[#This Row],[ALIŞ]]+1.5,0) -> 0 | H14: =IF(Tablo13456[[#This Row],[SATIŞ]]>0,(Tablo13456[[#This Row],[ADET]]*Tablo13456[[#This Row],[SATIŞ]]-1.5),0) -> 0
F15: =IF(Tablo13456[[#This Row],[SATIŞ]]=0,"Açık",(E15-D15)*C15-3) -> Açık | G15: =IF(Tablo13456[[#This Row],[ALIŞ]]>0,Tablo13456[[#This Row],[ADET]]*Tablo13456[[#This Row],[ALIŞ]]+1.5,0) -> 0 | H15: =IF(Tablo13456[[#This Row],[SATIŞ]]>0,(Tablo13456[[#This Row],[ADET]]*Tablo13456[[#This Row],[SATIŞ]]-1.5),0) -> 0
F16: =IF(Tablo13456[[#This Row],[SATIŞ]]=0,"Açık",(E16-D16)*C16-3) -> Açık | G16: =IF(Tablo13456[[#This Row],[ALIŞ]]>0,Tablo13456[[#This Row],[ADET]]*Tablo13456[[#This Row],[ALIŞ]]+1.5,0) -> 0 | H16: =IF(Tablo13456[[#This Row],[SATIŞ]]>0,(Tablo13456[[#This Row],[ADET]]*Tablo13456[[#This Row],[SATIŞ]]-1.5),0) -> 0
F17: =IF(Tablo13456[[#This Row],[SATIŞ]]=0,"Açık",(E17-D17)*C17-3) -> Açık | G17: =IF(Tablo13456[[#This Row],[ALIŞ]]>0,Tablo13456[[#This Row],[ADET]]*Tablo13456[[#This Row],[ALIŞ]]+1.5,0) -> 0 | H17: =IF(Tablo13456[[#This Row],[SATIŞ]]>0,(Tablo13456[[#This Row],[ADET]]*Tablo13456[[#This Row],[SATIŞ]]-1.5),0) -> 0
F18: =IF(Tablo13456[[#This Row],[SATIŞ]]=0,"Açık",(E18-D18)*C18-3) -> Açık | G18: =IF(Tablo13456[[#This Row],[ALIŞ]]>0,Tablo13456[[#This Row],[ADET]]*Tablo13456[[#This Row],[ALIŞ]]+1.5,0) -> 0 | H18: =IF(Tablo13456[[#This Row],[SATIŞ]]>0,(Tablo13456[[#This Row],[ADET]]*Tablo13456[[#This Row],[SATIŞ]]-1.5),0) -> 0
F19: =IF(Tablo13456[[#This Row],[SATIŞ]]=0,"Açık",(E19-D19)*C19-3) -> Açık | G19: =IF(Tablo13456[[#This Row],[ALIŞ]]>0,Tablo13456[[#This Row],[ADET]]*Tablo13456[[#This Row],[ALIŞ]]+1.5,0) -> 0 | H19: =IF(Tablo13456[[#This Row],[SATIŞ]]>0,(Tablo13456[[#This Row],[ADET]]*Tablo13456[[#This Row],[SATIŞ]]-1.5),0) -> 0
F20: =IF(Tablo13456[[#This Row],[SATIŞ]]=0,"Açık",(E20-D20)*C20-3) -> Açık | G20: =IF(Tablo13456[[#This Row],[ALIŞ]]>0,Tablo13456[[#This Row],[ADET]]*Tablo13456[[#This Row],[ALIŞ]]+1.5,0) -> 0 | H20: =IF(Tablo13456[[#This Row],[SATIŞ]]>0,(Tablo13456[[#This Row],[ADET]]*Tablo13456[[#This Row],[SATIŞ]]-1.5),0) -> 0
F21: =IF(Tablo13456[[#This Row],[SATIŞ]]=0,"Açık",(E21-D21)*C21-3) -> Açık | G21: =IF(Tablo13456[[#This Row],[ALIŞ]]>0,Tablo13456[[#This Row],[ADET]]*Tablo13456[[#This Row],[ALIŞ]]+1.5,0) -> 0 | H21: =IF(Tablo13456[[#This Row],[SATIŞ]]>0,(Tablo13456[[#This Row],[ADET]]*Tablo13456[[#This Row],[SATIŞ]]-1.5),0) -> 0
F22: =IF(Tablo13456[[#This Row],[SATIŞ]]=0,"Açık",(E22-D22)*C22-3) -> Açık | G22: =IF(Tablo13456[[#This Row],[ALIŞ]]>0,Tablo13456[[#This Row],[ADET]]*Tablo13456[[#This Row],[ALIŞ]]+1.5,0) -> 0 | H22: =IF(Tablo13456[[#This Row],[SATIŞ]]>0,(Tablo13456[[#This Row],[ADET]]*Tablo13456[[#This Row],[SATIŞ]]-1.5),0) -> 0
F23: =IF(Tablo13456[[#This Row],[SATIŞ]]=0,"Açık",(E23-D23)*C23-3) -> Açık | G23: =IF(Tablo13456[[#This Row],[ALIŞ]]>0,Tablo13456[[#This Row],[ADET]]*Tablo13456[[#This Row],[ALIŞ]]+1.5,0) -> 0 | H23: =IF(Tablo13456[[#This Row],[SATIŞ]]>0,(Tablo13456[[#This Row],[ADET]]*Tablo13456[[#This Row],[SATIŞ]]-1.5),0) -> 0
F24: =IF(Tablo13456[[#This Row],[SATIŞ]]=0,"Açık",(E24-D24)*C24-3) -> Açık | G24: =IF(Tablo13456[[#This Row],[ALIŞ]]>0,Tablo13456[[#This Row],[ADET]]*Tablo13456[[#This Row],[ALIŞ]]+1.5,0) -> 0 | H24: =IF(Tablo13456[[#This Row],[SATIŞ]]>0,(Tablo13456[[#This Row],[ADET]]*Tablo13456[[#This Row],[SATIŞ]]-1.5),0) -> 0
... F27: =IF(Tablo13456[[#This Row],[SATIŞ]]=0,"Açık",(E27-D27)*C27-3) -> Açık | G27: =IF(Tablo13456[[#This Row],[ALIŞ]]>0,Tablo13456[[#This Row],[ADET]]*Tablo13456[[#This Row],[ALIŞ]]+1.5,0) -> 0 | H27: =IF(Tablo13456[[#This Row],[SATIŞ]]>0,(Tablo13456[[#This Row],[ADET]]*Tablo13456[[#This Row],[SATIŞ]]-1.5),0) -> 0

Sheet ASAP
B1: ANA SAYFA | C1: =SUMIF(Tablo1348913[KAR],"Açık",Tablo1348913[ADET]) -> 0 | D1: =+İcmal!E8 -> 0.08 | E1: =C1*D1 -> 0 | F1: =IFERROR(((SUM(Tablo1348913[ALIŞ TUTAR])-SUM(Tablo1348913[SATIŞ TUTAR]))/C1),"") | G1: =IF(M3=0,L3,C1*(D1-F1)) -> -24.828 | J1: 0.02 | L1: =M1*(1-$J$1) -> #VALUE! | M1: =F1 | N1: =M1*(1+$J$1) -> #VALUE! | P1: =Q1*(1-$J$1) -> 0.0784 | Q1: =+D1 -> 0.08 | R1: =Q1*(1+$J$1) -> 0.0816
B3: TARİH | C3: ADET | D3: ALIŞ | E3: SATIŞ | F3: KAR | G3: ALIŞ TUTAR | H3: SATIŞ TUTAR | L3: =SUM(Tablo1348913[KAR]) -> -24.828 | M3: =C1 -> 0
B4: 44864 | C4: 30 | D4: 0.8076 | E4: 0.08 | F4: =IF(Tablo1348913[[#This Row],[SATIŞ]]=0,"Açık",(E4-D4)*C4-3) -> -24.828 | G4: =IF(Tablo1348913[[#This Row],[ALIŞ]]>0,Tablo1348913[[#This Row],[ADET]]*Tablo1348913[[#This Row],[ALIŞ]]+1.5,0) -> 25.728 | H4: =IF(Tablo1348913[[#This Row],[SATIŞ]]>0,(Tablo1348913[[#This Row],[ADET]]*Tablo1348913[[#This Row],[SATIŞ]]-1.5),0) -> 0.9
F5: =IF(Tablo1348913[[#This Row],[SATIŞ]]=0,"Açık",(E5-D5)*C5-3) -> Açık | G5: =IF(Tablo1348913[[#This Row],[ALIŞ]]>0,Tablo1348913[[#This Row],[ADET]]*Tablo1348913[[#This Row],[ALIŞ]]+1.5,0) -> 0 | H5: =IF(Tablo1348913[[#This Row],[SATIŞ]]>0,(Tablo1348913[[#This Row],[ADET]]*Tablo1348913[[#This Row],[SATIŞ]]-1.5),0) -> 0
F6: =IF(Tablo1348913[[#This Row],[SATIŞ]]=0,"Açık",(E6-D6)*C6-3) -> Açık | G6: =IF(Tablo1348913[[#This Row],[ALIŞ]]>0,Tablo1348913[[#This Row],[ADET]]*Tablo1348913[[#This Row],[ALIŞ]]+1.5,0) -> 0 | H6: =IF(Tablo1348913[[#This Row],[SATIŞ]]>0,(Tablo1348913[[#This Row],[ADET]]*Tablo1348913[[#This Row],[SATIŞ]]-1.5),0) -> 0
F7: =IF(Tablo1348913[[#This Row],[SATIŞ]]=0,"Açık",(E7-D7)*C7-3) -> Açık | G7: =IF(Tablo1348913[[#This Row],[ALIŞ]]>0,Tablo1348913[[#This Row],[ADET]]*Tablo1348913[[#This Row],[ALIŞ]]+1.5,0) -> 0 | H7: =IF(Tablo1348913[[#This Row],[SATIŞ]]>0,(Tablo1348913[[#This Row],[ADET]]*Tablo1348913[[#This Row],[SATIŞ]]-1.5),0) -> 0
F8: =IF(Tablo1348913[[#This Row],[SATIŞ]]=0,"Açık",(E8-D8)*C8-3) -> Açık | G8: =IF(Tablo1348913[[#This Row],[ALIŞ]]>0,Tablo1348913[[#This Row],[ADET]]*Tablo1348913[[#This Row],[ALIŞ]]+1.5,0) -> 0 | H8: =IF(Tablo1348913[[#This Row],[SATIŞ]]>0,(Tablo1348913[[#This Row],[ADET]]*Tablo1348913[[#This Row],[SATIŞ]]-1.5),0) -> 0
F9: =IF(Tablo1348913[[#This Row],[SATIŞ]]=0,"Açık",(E9-D9)*C9-3) -> Açık | G9: =IF(Tablo1348913[[#This Row],[ALIŞ]]>0,Tablo1348913[[#This Row],[ADET]]*Tablo1348913[[#This Row],[ALIŞ]]+1.5,0) -> 0 | H9: =IF(Tablo1348913[[#This Row],[SATIŞ]]>0,(Tablo1348913[[#This Row],[ADET]]*Tablo1348913[[#This Row],[SATIŞ]]-1.5),0) -> 0
F10: =IF(Tablo1348913[[#This Row],[SATIŞ]]=0,"Açık",(E10-D10)*C10-3) -> Açık | G10: =IF(Tablo1348913[[#This Row],[ALIŞ]]>0,Tablo1348913[[#This Row],[ADET]]*Tablo1348913[[#This Row],[ALIŞ]]+1.5,0) -> 0 | H10: =IF(Tablo1348913[[#This Row],[SATIŞ]]>0,(Tablo1348913[[#This Row],[ADET]]*Tablo1348913[[#This Row],[SATIŞ]]-1.5),0) -> 0
F11: =IF(Tablo1348913[[#This Row],[SATIŞ]]=0,"Açık",(E11-D11)*C11-3) -> Açık | G11: =IF(Tablo1348913[[#This Row],[ALIŞ]]>0,Tablo1348913[[#This Row],[ADET]]*Tablo1348913[[#This Row],[ALIŞ]]+1.5,0) -> 0 | H11: =IF(Tablo1348913[[#This Row],[SATIŞ]]>0,(Tablo1348913[[#This Row],[ADET]]*Tablo1348913[[#This Row],[SATIŞ]]-1.5),0) -> 0 | J11: =+Tablo1348913[[#This Row],[ALIŞ]]*1.02 -> 0
F12: =IF(Tablo1348913[[#This Row],[SATIŞ]]=0,"Açık",(E12-D12)*C12-3) -> Açık | G12: =IF(Tablo1348913[[#This Row],[ALIŞ]]>0,Tablo1348913[[#This Row],[ADET]]*Tablo1348913[[#This Row],[ALIŞ]]+1.5,0) -> 0 | H12: =IF(Tablo1348913[[#This Row],[SATIŞ]]>0,(Tablo1348913[[#This Row],[ADET]]*Tablo1348913[[#This Row],[SATIŞ]]-1.5),0) -> 0
F13: =IF(Tablo1348913[[#This Row],[SATIŞ]]=0,"Açık",(E13-D13)*C13-3) -> Açık | G13: =IF(Tablo1348913[[#This Row],[ALIŞ]]>0,Tablo1348913[[#This Row],[ADET]]*Tablo1348913[[#This Row],[ALIŞ]]+1.5,0) -> 0 | H13: =IF(Tablo1348913[[#This Row],[SATIŞ]]>0,(Tablo1348913[[#This Row],[ADET]]*Tablo1348913[[#This Row],[SATIŞ]]-1.5),0) -> 0
F14: =IF(Tablo1348913[[#This Row],[SATIŞ]]=0,"Açık",(E14-D14)*C14-3) -> Açık | G14: =IF(Tablo1348913[[#This Row],[ALIŞ]]>0,Tablo1348913[[#This Row],[ADET]]*Tablo1348913[[#This Row],[ALIŞ]]+1.5,0) -> 0 | H14: =IF(Tablo1348913[[#This Row],[SATIŞ]]>0,(Tablo1348913[[#This Row],[ADET]]*Tablo1348913[[#This Row],[SATIŞ]]-1.5),0) -> 0
F15: =IF(Tablo1348913[[#This Row],[SATIŞ]]=0,"Açık",(E15-D15)*C15-3) -> Açık | G15: =IF(Tablo1348913[[#This Row],[ALIŞ]]>0,Tablo1348913[[#This Row],[ADET]]*Tablo1348913[[#This Row],[ALIŞ]]+1.5,0) -> 0 | H15: =IF(Tablo1348913[[#This Row],[SATIŞ]]>0,(Tablo1348913[[#This Row],[ADET]]*Tablo1348913[[#This Row],[SATIŞ]]-1.5),0) -> 0
F16: =IF(Tablo1348913[[#This Row],[SATIŞ]]=0,"Açık",(E16-D16)*C16-3) -> Açık | G16: =IF(Tablo1348913[[#This Row],[ALIŞ]]>0,Tablo1348913[[#This Row],[ADET]]*Tablo1348913[[#This Row],[ALIŞ]]+1.5,0) -> 0 | H16: =IF(Tablo1348913[[#This Row],[SATIŞ]]>0,(Tablo1348913[[#This Row],[ADET]]*Tablo1348913[[#This Row],[SATIŞ]]-1.5),0) -> 0
F17: =IF(Tablo1348913[[#This Row],[SATIŞ]]=0,"Açık",(E17-D17)*C17-3) -> Açık | G17: =IF(Tablo1348913[[#This Row],[ALIŞ]]>0,Tablo1348913[[#This Row],[ADET]]*Tablo1348913[[#This Row],[ALIŞ]]+1.5,0) -> 0 | H17: =IF(Tablo1348913[[#This Row],[SATIŞ]]>0,(Tablo1348913[[#This Row],[ADET]]*Tablo1348913[[#This Row],[SATIŞ]]-1.5),0) -> 0
F18: =IF(Tablo1348913[[#This Row],[SATIŞ]]=0,"Açık",(E18-D18)*C18-3) -> Açık | G18: =IF(Tablo1348913[[#This Row],[ALIŞ]]>0,Tablo1348913[[#This Row],[ADET]]*Tablo1348913[[#This Row],[ALIŞ]]+1.5,0) -> 0 | H18: =IF(Tablo1348913[[#This Row],[SATIŞ]]>0,(Tablo1348913[[#This Row],[ADET]]*Tablo1348913[[#This Row],[SATIŞ]]-1.5),0) -> 0
F19: =IF(Tablo1348913[[#This Row],[SATIŞ]]=0,"Açık",(E19-D19)*C19-3) -> Açık | G19: =IF(Tablo1348913[[#This Row],[ALIŞ]]>0,Tablo1348913[[#This Row],[ADET]]*Tablo1348913[[#This Row],[ALIŞ]]+1.5,0) -> 0 | H19: =IF(Tablo1348913[[#This Row],[SATIŞ]]>0,(Tablo1348913[[#This Row],[ADET]]*Tablo1348913[[#This Row],[SATIŞ]]-1.5),0) -> 0
F20: =IF(Tablo1348913[[#This Row],[SATIŞ]]=0,"Açık",(E20-D20)*C20-3) -> Açık | G20: =IF(Tablo1348913[[#This Row],[ALIŞ]]>0,Tablo1348913[[#This Row],[ADET]]*Tablo1348913[[#This Row],[ALIŞ]]+1.5,0) -> 0 | H20: =IF(Tablo1348913[[#This Row],[SATIŞ]]>0,(Tablo1348913[[#This Row],[ADET]]*Tablo1348913[[#This Row],[SATIŞ]]-1.5),0) -> 0
F21: =IF(Tablo1348913[[#This Row],[SATIŞ]]=0,"Açık",(E21-D21)*C21-3) -> Açık | G21: =IF(Tablo1348913[[#This Row],[ALIŞ]]>0,Tablo1348913[[#This Row],[ADET]]*Tablo1348913[[#This Row],[ALIŞ]]+1.5,0) -> 0 | H21: =IF(Tablo1348913[[#This Row],[SATIŞ]]>0,(Tablo1348913[[#This Row],[ADET]]*Tablo1348913[[#This Row],[SATIŞ]]-1.5),0) -> 0
F22: =IF(Tablo1348913[[#This Row],[SATIŞ]]=0,"Açık",(E22-D22)*C22-3) -> Açık | G22: =IF(Tablo1348913[[#This Row],[ALIŞ]]>0,Tablo1348913[[#This Row],[ADET]]*Tablo1348913[[#This Row],[ALIŞ]]+1.5,0) -> 0 | H22: =IF(Tablo1348913[[#This Row],[SATIŞ]]>0,(Tablo1348913[[#This Row],[ADET]]*Tablo1348913[[#This Row],[SATIŞ]]-1.5),0) -> 0
F23: =IF(Tablo1348913[[#This Row],[SATIŞ]]=0,"Açık",(E23-D23)*C23-3) -> Açık | G23: =IF(Tablo1348913[[#This Row],[ALIŞ]]>0,Tablo1348913[[#This Row],[ADET]]*Tablo1348913[[#This Row],[ALIŞ]]+1.5,0) -> 0 | H23: =IF(Tablo1348913[[#This Row],[SATIŞ]]>0,(Tablo1348913[[#This Row],[ADET]]*Tablo1348913[[#This Row],[SATIŞ]]-1.5),0) -> 0
... F27: =IF(Tablo1348913[[#This Row],[SATIŞ]]=0,"Açık",(E27-D27)*C27-3) -> Açık | G27: =IF(Tablo1348913[[#This Row],[ALIŞ]]>0,Tablo1348913[[#This Row],[ADET]]*Tablo1348913[[#This Row],[ALIŞ]]+1.5,0) -> 0 | H27: =IF(Tablo1348913[[#This Row],[SATIŞ]]>0,(Tablo1348913[[#This Row],[ADET]]*Tablo1348913[[#This Row],[SATIŞ]]-1.5),0) -> 0

Sheet BBIO
B1: ANA SAYFA | C1: =SUMIF(Tablo1348222324[KAR],"Açık",Tablo1348222324[ADET]) -> 156 | D1: =+İcmal!E9 -> 29.6 | E1: =C1*D1 -> 4617.6 | F1: =IFERROR(((SUM(Tablo1348222324[ALIŞ TUTAR])-SUM(Tablo1348222324[SATIŞ TUTAR]))/C1),"") -> 30.131026 | G1: =IF(M3=0,L3,C1*(D1-F1)) -> -82.84 | J1: 0.02 | L1: =M1*(1-$J$1) -> 29.528405 | M1: =F1 -> 30.131026 | N1: =M1*(1+$J$1) -> 30.733646 | P1: =Q1*(1-$J$1) -> 29.008 | Q1: =+D1 -> 29.6 | R1: =Q1*(1+$J$1) -> 30.192
B3: TARİH | C3: ADET | D3: ALIŞ | E3: SATIŞ | F3: KAR | G3: ALIŞ TUTAR | H3: SATIŞ TUTAR | L3: =SUM(Tablo1348222324[KAR]) -> 21.1 | M3: =C1 -> 156
B4: 45096 | C4: 14 | D4: 14.86 | F4: =IF(Tablo1348222324[[#This Row],[SATIŞ]]=0,"Açık",(E4-D4)*C4-3) -> Açık | G4: =IF(Tablo1348222324[[#This Row],[ALIŞ]]>0,Tablo1348222324[[#This Row],[ADET]]*Tablo1348222324[[#This Row],[ALIŞ]]+1.5,0) -> 209.54 | H4: =IF(Tablo1348222324[[#This Row],[SATIŞ]]>0,(Tablo1348222324[[#This Row],[ADET]]*Tablo1348222324[[#This Row],[SATIŞ]]-1.5),0) -> 0
B5: 45339 | C5: 10 | D5: 37 | E5: 34.81 | F5: =IF(Tablo1348222324[[#This Row],[SATIŞ]]=0,"Açık",(E5-D5)*C5-3) -> -24.9 | G5: =IF(Tablo1348222324[[#This Row],[ALIŞ]]>0,Tablo1348222324[[#This Row],[ADET]]*Tablo1348222324[[#This Row],[ALIŞ]]+1.5,0) -> 371.5 | H5: =IF(Tablo1348222324[[#This Row],[SATIŞ]]>0,(Tablo1348222324[[#This Row],[ADET]]*Tablo1348222324[[#This Row],[SATIŞ]]-1.5),0) -> 346.6
B6: 45339 | C6: 17 | D6: 37 | F6: =IF(Tablo1348222324[[#This Row],[SATIŞ]]=0,"Açık",(E6-D6)*C6-3) -> Açık | G6: =IF(Tablo1348222324[[#This Row],[ALIŞ]]>0,Tablo1348222324[[#This Row],[ADET]]*Tablo1348222324[[#This Row],[ALIŞ]]+1.5,0) -> 630.5 | H6: =IF(Tablo1348222324[[#This Row],[SATIŞ]]>0,(Tablo1348222324[[#This Row],[ADET]]*Tablo1348222324[[#This Row],[SATIŞ]]-1.5),0) -> 0
B7: 45355 | C7: 20 | D7: 35 | F7: =IF(Tablo1348222324[[#This Row],[SATIŞ]]=0,"Açık",(E7-D7)*C7-3) -> Açık | G7: =IF(Tablo1348222324[[#This Row],[ALIŞ]]>0,Tablo1348222324[[#This Row],[ADET]]*Tablo1348222324[[#This Row],[ALIŞ]]+1.5,0) -> 701.5 | H7: =IF(Tablo1348222324[[#This Row],[SATIŞ]]>0,(Tablo1348222324[[#This Row],[ADET]]*Tablo1348222324[[#This Row],[SATIŞ]]-1.5),0) -> 0
B8: 45355 | C8: 20 | D8: 32 | F8: =IF(Tablo1348222324[[#This Row],[SATIŞ]]=0,"Açık",(E8-D8)*C8-3) -> Açık | G8: =IF(Tablo1348222324[[#This Row],[ALIŞ]]>0,Tablo1348222324[[#This Row],[ADET]]*Tablo1348222324[[#This Row],[ALIŞ]]+1.5,0) -> 641.5 | H8: =IF(Tablo1348222324[[#This Row],[SATIŞ]]>0,(Tablo1348222324[[#This Row],[ADET]]*Tablo1348222324[[#This Row],[SATIŞ]]-1.5),0) -> 0
B9: 45355 | C9: 10 | D9: 32 | F9: =IF(Tablo1348222324[[#This Row],[SATIŞ]]=0,"Açık",(E9-D9)*C9-3) -> Açık | G9: =IF(Tablo1348222324[[#This Row],[ALIŞ]]>0,Tablo1348222324[[#This Row],[ADET]]*Tablo1348222324[[#This Row],[ALIŞ]]+1.5,0) -> 321.5 | H9: =IF(Tablo1348222324[[#This Row],[SATIŞ]]>0,(Tablo1348222324[[#This Row],[ADET]]*Tablo1348222324[[#This Row],[SATIŞ]]-1.5),0) -> 0
B10: 45356 | C10: 30 | D10: 30 | E10: 31 | F10: =IF(Tablo1348222324[[#This Row],[SATIŞ]]=0,"Açık",(E10-D10)*C10-3) -> 27 | G10: =IF(Tablo1348222324[[#This Row],[ALIŞ]]>0,Tablo1348222324[[#This Row],[ADET]]*Tablo1348222324[[#This Row],[ALIŞ]]+1.5,0) -> 901.5 | H10: =IF(Tablo1348222324[[#This Row],[SATIŞ]]>0,(Tablo1348222324[[#This Row],[ADET]]*Tablo1348222324[[#This Row],[SATIŞ]]-1.5),0) -> 928.5
B11: 45356 | C11: 25 | D11: 29.5 | E11: 30 | F11: =IF(Tablo1348222324[[#This Row],[SATIŞ]]=0,"Açık",(E11-D11)*C11-3) -> 9.5 | G11: =IF(Tablo1348222324[[#This Row],[ALIŞ]]>0,Tablo1348222324[[#This Row],[ADET]]*Tablo1348222324[[#This Row],[ALIŞ]]+1.5,0) -> 739 | H11: =IF(Tablo1348222324[[#This Row],[SATIŞ]]>0,(Tablo1348222324[[#This Row],[ADET]]*Tablo1348222324[[#This Row],[SATIŞ]]-1.5),0) -> 748.5 | J11: =+Tablo1348222324[[#This Row],[ALIŞ]]*1.02 -> 30.09
