Workbook

Sheet Portföy
C1: 45717 | E1: YATIRIM | G1: PORTFÖY | I1: Portföy Büyüme | K1: KAR/ ZARAR
C2: TOPLAM: | E2: =SUM(E3:F6) -> 9284.4376 | G2: =SUM(G3:H6) -> 7478.5199 | I2: =(G2-E2)/E2 -> -0.19451018 | J2: =(I2-H2)/H2 -> #DIV/0! | K2: =SUM(K3:K6) -> -1805.9176 | L2: =+K2/E2 -> -0.19451018
C3: HİSSE: | E3: =VLOOKUP($C$1,$C$9:$G$20,2,FALSE) -> 1050.9254 | G3: =VLOOKUP($C$1,$C$9:$G$20,3,FALSE) -> 1016.874 | I3: =(G3-E3)/E3 -> -0.032401355 | J3: =(I3-H3)/H3 -> #DIV/0! | K3: =VLOOKUP($C$1,$C$9:$G$20,5,FALSE) -> -34.051406 | L3: =+K3/E3 -> -0.032401355
C4: FON: | E4: =VLOOKUP($C$1,$J$9:$N$20,2,FALSE) -> 383.60217 | G4: =VLOOKUP($C$1,$J$9:$N$20,3,FALSE) -> 390.8477 | I4: =(G4-E4)/E4 -> 0.018888139 | J4: =(I4-H4)/H4 -> #DIV/0! | K4: =VLOOKUP($C$1,$J$9:$N$20,5,FALSE) -> 7.245531 | L4: =+K4/E4 -> 0.018888139
C5: AMERİKA: | E5: =VLOOKUP($C$1,$Q$9:$U$20,2,FALSE) -> 4557.91 | G5: =VLOOKUP($C$1,$Q$9:$U$20,3,FALSE) -> 4465.7982 | I5: =(G5-E5)/E5 -> -0.020209209 | J5: =(I5-H5)/H5 -> #DIV/0! | K5: =VLOOKUP($C$1,$Q$9:$U$20,5,FALSE) -> -92.111757 | L5: =+K5/E5 -> -0.020209209
C6: KRİPTO: | E6: =VLOOKUP($C$1,$X$9:$AB$20,2,FALSE) -> 3292 | G6: =VLOOKUP($C$1,$X$9:$AB$20,3,FALSE) -> 1605 | I6: =(G6-E6)/E6 -> -0.51245443 | J6: =(I6-H6)/H6 -> #DIV/0! | K6: =VLOOKUP($C$1,$X$9:$AB$20,5,FALSE) -> -1687 | L6: =+K6/E6 -> -0.51245443
C8: HİSSE | J8: FON | Q8: AMERİCAN | X8: KRİPTO
D9: Yatırım | E9: Portföy | F9: Portföy Büyüme | G9: KAR/ ZARAR | K9: Yatırım | L9: Portföy | M9: Portföy Büyüme | N9: KAR/ ZARAR | R9: Yatırım | S9: Portföy | T9: Portföy Büyüme | U9: KAR/ ZARAR | Y9: Yatırım | Z9: Portföy | AA9: Portföy Büyüme | AB9: KAR/ ZARAR
A10: 45689 | B10: 45716 | C10: 45689 | D10: =SUMIFS(Tablo1[Tutar],Tablo1[Tarih],">="&$A10,Tablo1[Tarih],"<="&$B10) -> 1050.9254 | E10: 1016.874 | F10: =(E10-D10)/D10 -> -0.032401355 | G10: =+E10-D10 -> -34.051406 | H10: =+G10/D10 -> -0.032401355 | J10: 45689 | K10: =SUMIFS(Tablo13[Tutar],Tablo13[Tarih],">="&$A10,Tablo13[Tarih],"<="&$B10) -> 383.60217 | L10: 390.67185 | M10: =(L10-K10)/K10 -> 0.018429723 | N10: =+L10-K10 -> 7.0696817 | O10: =+N10/K10 -> 0.018429723 | Q10: 45689 | R10: =SUMIFS(Tablo134[Tutar],Tablo134[Tarih],">="&$A10,Tablo134[Tarih],"<="&$B10) -> 4557.91 | S10: 4465.7982 | T10: =(S10-R10)/R10 -> -0.020209209 | U10: =+S10-R10 -> -92.111757 | V10: =+U10/R10 -> -0.020209209 | X10: 45689 | Y10: =1950 -> 1950 | Z10: 1605 | AA10: =(Z10-Y10)/Y10 -> -0.17692308 | AB10: =+Z10-Y10 -> -345 | AC10: =+AB10/Y10 -> -0.17692308
A11: 45717 | B11: 45747 | C11: 45717 | D11: =SUMIFS(Tablo1[Tutar],Tablo1[Tarih],">="&$A11,Tablo1[Tarih],"<="&$B11)+D10 -> 1050.9254 | E11: =SUMPRODUCT(F$24:F$41,D$24:D$41) -> 1016.874 | F11: =IFERROR((E11-D11)/D11,"") -> -0.032401355 | G11: =+E11-D11 -> -34.051406 | H11: =IFERROR(G11/D11,"") -> -0.032401355 | J11: 45717 | K11: =SUMIFS(Tablo13[Tutar],Tablo13[Tarih],">="&$A11,Tablo13[Tarih],"<="&$B11)+K10 -> 383.60217 | L11: =SUMPRODUCT(M$24:M$41,K$24:K$41) -> 390.8477 | M11: =IFERROR((L11-K11)/K11,"") -> 0.018888139 | N11: =+L11-K11 -> 7.245531 | O11: =IFERROR(N11/K11,"") -> 0.018888139 | Q11: 45717 | R11: =SUMIFS(Tablo134[Tutar],Tablo134[Tarih],">="&$A11,Tablo134[Tarih],"<="&$B11)+R10 -> 4557.91 | S11: =SUMPRODUCT(T$24:T$41,R$24:R$41) -> 4465.7982 | T11: =IFERROR((S11-R11)/R11,"") -> -0.020209209 | U11: =+S11-R11 -> -92.111757 | V11: =IFERROR(U11/R11,"") -> -0.020209209 | X11: 45717 | Y11: =1342+Y10 -> 3292 | Z11: 1605 | AA11: =(Z11-Y11)/Y11 -> -0.51245443 | AB11: =+Z11-Y11 -> -1687 | AC11: =+AB11/Y11 -> -0.51245443
A12: 45748 | B12: 45777 | C12: 45748 | G12: =SUMIFS('İşlem Hisse'!$L$3:$L$460,'İşlem Hisse'!$J$3:$J$460,">="&$A12,'İşlem Hisse'!$J$3:$J$460,"<="&$B12) -> 0 | J12: 45748 | N12: =SUMIFS('İşlem Hisse'!$M$3:$M$460,'İşlem Hisse'!$J$3:$J$460,">="&$A12,'İşlem Hisse'!$J$3:$J$460,"<="&$B12) -> 0 | Q12: 45748 | U12: =SUMIFS('İşlem Hisse'!$M$3:$M$460,'İşlem Hisse'!$J$3:$J$460,">="&$A12,'İşlem Hisse'!$J$3:$J$460,"<="&$B12) -> 0 | X12: 45748 | AB12: =+Z12-Y12 -> 0
A13: 45778 | B13: 45808 | C13: 45778 | G13: =SUMIFS('İşlem Hisse'!$L$3:$L$460,'İşlem Hisse'!$J$3:$J$460,">="&$A13,'İşlem Hisse'!$J$3:$J$460,"<="&$B13) -> 0 | J13: 45778 | N13: =SUMIFS('İşlem Hisse'!$M$3:$M$460,'İşlem Hisse'!$J$3:$J$460,">="&$A13,'İşlem Hisse'!$J$3:$J$460,"<="&$B13) -> 0 | Q13: 45778 | U13: =SUMIFS('İşlem Hisse'!$M$3:$M$460,'İşlem Hisse'!$J$3:$J$460,">="&$A13,'İşlem Hisse'!$J$3:$J$460,"<="&$B13) -> 0 | X13: 45778 | AB13: =+Z13-Y13 -> 0
A14: 45809 | B14: 45838 | C14: 45809 | G14: =SUMIFS('İşlem Hisse'!$L$3:$L$460,'İşlem Hisse'!$J$3:$J$460,">="&$A14,'İşlem Hisse'!$J$3:$J$460,"<="&$B14) -> 0 | J14: 45809 | N14: =SUMIFS('İşlem Hisse'!$M$3:$M$460,'İşlem Hisse'!$J$3:$J$460,">="&$A14,'İşlem Hisse'!$J$3:$J$460,"<="&$B14) -> 0 | Q14: 45809 | U14: =SUMIFS('İşlem Hisse'!$M$3:$M$460,'İşlem Hisse'!$J$3:$J$460,">="&$A14,'İşlem Hisse'!$J$3:$J$460,"<="&$B14) -> 0 | X14: 45809 | AB14: =+Z14-Y14 -> 0
A15: 45839 | B15: 45869 | C15: 45839 | G15: =SUMIFS('İşlem Hisse'!$L$3:$L$460,'İşlem Hisse'!$J$3:$J$460,">="&$A15,'İşlem Hisse'!$J$3:$J$460,"<="&$B15) -> 0 | J15: 45839 | N15: =SUMIFS('İşlem Hisse'!$M$3:$M$460,'İşlem Hisse'!$J$3:$J$460,">="&$A15,'İşlem Hisse'!$J$3:$J$460,"<="&$B15) -> 0 | Q15: 45839 | U15: =SUMIFS('İşlem Hisse'!$M$3:$M$460,'İşlem Hisse'!$J$3:$J$460,">="&$A15,'İşlem Hisse'!$J$3:$J$460,"<="&$B15) -> 0 | X15: 45839 | AB15: =+Z15-Y15 -> 0
A16: 45870 | B16: 45900 | C16: 45870 | G16: =SUMIFS('İşlem Hisse'!$L$3:$L$460,'İşlem Hisse'!$J$3:$J$460,">="&$A16,'İşlem Hisse'!$J$3:$J$460,"<="&$B16) -> 0 | J16: 45870 | N16: =SUMIFS('İşlem Hisse'!$M$3:$M$460,'İşlem Hisse'!$J$3:$J$460,">="&$A16,'İşlem Hisse'!$J$3:$J$460,"<="&$B16) -> 0 | Q16: 45870 | U16: =SUMIFS('İşlem Hisse'!$M$3:$M$460,'İşlem Hisse'!$J$3:$J$460,">="&$A16,'İşlem Hisse'!$J$3:$J$460,"<="&$B16) -> 0 | X16: 45870 | AB16: =+Z16-Y16 -> 0
A17: 45901 | B17: 45930 | C17: 45901 | G17: =SUMIFS('İşlem Hisse'!$L$3:$L$460,'İşlem Hisse'!$J$3:$J$460,">="&$A17,'İşlem Hisse'!$J$3:$J$460,"<="&$B17) -> 0 | J17: 45901 | N17: =SUMIFS('İşlem Hisse'!$M$3:$M$460,'İşlem Hisse'!$J$3:$J$460,">="&$A17,'İşlem Hisse'!$J$3:$J$460,"<="&$B17) -> 0 | Q17: 45901 | U17: =SUMIFS('İşlem Hisse'!$M$3:$M$460,'İşlem Hisse'!$J$3:$J$460,">="&$A17,'İşlem Hisse'!$J$3:$J$460,"<="&$B17) -> 0 | X17: 45901 | AB17: =SUMIFS('İşlem Hisse'!$M$3:$M$460,'İşlem Hisse'!$J$3:$J$460,">="&$A17,'İşlem Hisse'!$J$3:$J$460,"<="&$B17) -> 0
A18: 45931 | B18: 45961 | C18: 45931 | G18: =SUMIFS('İşlem Hisse'!$L$3:$L$460,'İşlem Hisse'!$J$3:$J$460,">="&$A18,'İşlem Hisse'!$J$3:$J$460,"<="&$B18) -> 0 | J18: 45931 | N18: =SUMIFS('İşlem Hisse'!$M$3:$M$460,'İşlem Hisse'!$J$3:$J$460,">="&$A18,'İşlem Hisse'!$J$3:$J$460,"<="&$B18) -> 0 | Q18: 45931 | U18: =SUMIFS('İşlem Hisse'!$M$3:$M$460,'İşlem Hisse'!$J$3:$J$460,">="&$A18,'İşlem Hisse'!$J$3:$J$460,"<="&$B18) -> 0 | X18: 45931 | AB18: =SUMIFS('İşlem Hisse'!$M$3:$M$460,'İşlem Hisse'!$J$3:$J$460,">="&$A18,'İşlem Hisse'!$J$3:$J$460,"<="&$B18) -> 0
A19: 45962 | B19: 45991 | C19: 45962 | G19: =SUMIFS('İşlem Hisse'!$L$3:$L$460,'İşlem Hisse'!$J$3:$J$460,">="&$A19,'İşlem Hisse'!$J$3:$J$460,"<="&$B19) -> 0 | J19: 45962 | N19: =SUMIFS('İşlem Hisse'!$M$3:$M$460,'İşlem Hisse'!$J$3:$J$460,">="&$A19,'İşlem Hisse'!$J$3:$J$460,"<="&$B19) -> 0 | Q19: 45962 | U19: =SUMIFS('İşlem Hisse'!$M$3:$M$460,'İşlem Hisse'!$J$3:$J$460,">="&$A19,'İşlem Hisse'!$J$3:$J$460,"<="&$B19) -> 0 | X19: 45962 | AB19: =SUMIFS('İşlem Hisse'!$M$3:$M$460,'İşlem Hisse'!$J$3:$J$460,">="&$A19,'İşlem Hisse'!$J$3:$J$460,"<="&$B19) -> 0
A20: 45992 | B20: 46022 | C20: 45992 | G20: =SUMIFS('İşlem Hisse'!$L$3:$L$460,'İşlem Hisse'!$J$3:$J$460,">="&$A20,'İşlem Hisse'!$J$3:$J$460,"<="&$B20) -> 0 | J20: 45992 | N20: =SUMIFS('İşlem Hisse'!$M$3:$M$460,'İşlem Hisse'!$J$3:$J$460,">="&$A20,'İşlem Hisse'!$J$3:$J$460,"<="&$B20) -> 0 | Q20: 45992 | U20: =SUMIFS('İşlem Hisse'!$M$3:$M$460,'İşlem Hisse'!$J$3:$J$460,">="&$A20,'İşlem Hisse'!$J$3:$J$460,"<="&$B20) -> 0 | X20: 45992 | AB20: =SUMIFS('İşlem Hisse'!$M$3:$M$460,'İşlem Hisse'!$J$3:$J$460,">="&$A20,'İşlem Hisse'!$J$3:$J$460,"<="&$B20) -> 0
C23: HİSSE | D23: ADET | E23: MALİYET | F23: HİSSE FİYATI | G23: TUTAR | H23: KAR/ ZARAR | J23: FON | K23: ADET | L23: MALİYET | M23: FON | N23: TUTAR | O23: KAR/ ZARAR | Q23: AMERI. | R23: ADET | S23: MALİYET | T23: FİYAT | U23: TUTAR | V23: KAR/ ZARAR
C24: ADEL | D24: =SUMIFS(Tablo1[Adet],Tablo1[Hisse],C24,Tablo1[Durum],"Alış")-SUMIFS(Tablo1[Adet],Tablo1[Hisse],C24,Tablo1[Durum],"Satış") -> 35 | E24: =IFERROR(SUMIFS(Tablo1[Tutar],Tablo1[Hisse],C24)/D24,"") -> 0.77146776 | F24: =IFERROR(VLOOKUP(C24,Hisse!$A$2:$B$631,2,FALSE)/VLOOKUP(TODAY(),'İşlem Hisse'!$J$3:$K$460,2,FALSE),"") -> 0.76657534 | G24: =IFERROR(F24*D24,"") -> 26.830137 | H24: =IFERROR((F24-E24)*D24,"") -> -0.17123476 | J24: BGP | K24: =SUMIFS(Tablo13[Adet],Tablo13[Hisse],J24,Tablo13[Durum],"Alış")-SUMIFS(Tablo13[Adet],Tablo13[Hisse],J24,Tablo13[Durum],"Satış") -> 237 | L24: =IFERROR(SUMIFS(Tablo13[Tutar],Tablo13[Hisse],J24)/K24,"") -> 0.096066176 | M24: =IFERROR(VLOOKUP(J24,'İşlem Fon'!$J$3:$K$32,2,FALSE)/VLOOKUP(TODAY(),'İşlem Hisse'!$J$3:$K$460,2,FALSE),"") -> 0.098133671 | N24: =IFERROR(M24*K24,"") -> 23.25768 | O24: =IFERROR((M24-L24)*K24,"") -> 0.48999636 | Q24: HEPS | R24: =SUMIFS(Tablo134[Adet],Tablo134[Hisse],Q24,Tablo134[Durum],"Alış")-SUMIFS(Tablo134[Adet],Tablo134[Hisse],Q24,Tablo134[Durum],"Satış") -> 1 | S24: =IFERROR(SUMIFS(Tablo134[Tutar],Tablo134[Hisse],Q24)/R24,"") -> 1.06 | T24: =IFERROR(VLOOKUP(Q24,'İşlem FonA'!$J$3:$K$16,2,FALSE),"") -> 3.32 | U24: =IFERROR(T24*R24,"") -> 3.32 | V24: =IFERROR((T24-S24)*R24,"") -> 2.26
C25: ARASE | D25: =SUMIFS(Tablo1[Adet],Tablo1[Hisse],C25,Tablo1[Durum],"Alış")-SUMIFS(Tablo1[Adet],Tablo1[Hisse],C25,Tablo1[Durum],"Satış") -> 50 | E25: =IFERROR(SUMIFS(Tablo1[Tutar],Tablo1[Hisse],C25)/D25,"") -> 1.2951958 | F25: =IFERROR(VLOOKUP(C25,Hisse!$A$2:$B$631,2,FALSE)/VLOOKUP(TODAY(),'İşlem Hisse'!$J$3:$K$460,2,FALSE),"") -> 1.2750685 | G25: =IFERROR(F25*D25,"") -> 63.753425 | H25: =IFERROR((F25-E25)*D25,"") -> -1.0063643 | J25: ADP | K25: =SUMIFS(Tablo13[Adet],Tablo13[Hisse],J25,Tablo13[Durum],"Alış")-SUMIFS(Tablo13[Adet],Tablo13[Hisse],J25,Tablo13[Durum],"Satış") -> 931 | L25: =IFERROR(SUMIFS(Tablo13[Tutar],Tablo13[Hisse],J25)/K25,"") -> 0.029737008 | M25: =IFERROR(VLOOKUP(J25,'İşlem Fon'!$J$3:$K$32,2,FALSE)/VLOOKUP(TODAY(),'İşlem Hisse'!$J$3:$K$460,2,FALSE),"") -> 0.03082611 | N25: =IFERROR(M25*K25,"") -> 28.699108 | O25: =IFERROR((M25-L25)*K25,"") -> 1.0139533 | Q25: QLYD | R25: =SUMIFS(Tablo134[Adet],Tablo134[Hisse],Q25,Tablo134[Durum],"Alış")-SUMIFS(Tablo134[Adet],Tablo134[Hisse],Q25,Tablo134[Durum],"Satış") -> 60 | S25: =IFERROR(SUMIFS(Tablo134[Tutar],Tablo134[Hisse],Q25)/R25,"") -> 17.88 | T25: =IFERROR(VLOOKUP(Q25,'İşlem FonA'!$J$3:$K$16,2,FALSE),"") -> 17.94 | U25: =IFERROR(T25*R25,"") -> 1076.4 | V25: =IFERROR((T25-S25)*R25,"") -> 3.6
C26: ASTOR | D26: =SUMIFS(Tablo1[Adet],Tablo1[Hisse],C26,Tablo1[Durum],"Alış")-SUMIFS(Tablo1[Adet],Tablo1[Hisse],C26,Tablo1[Durum],"Satış") -> 14 | E26: =IFERROR(SUMIFS(Tablo1[Tutar],Tablo1[Hisse],C26)/D26,"") -> 3.0110803 | F26: =IFERROR(VLOOKUP(C26,Hisse!$A$2:$B$631,2,FALSE)/VLOOKUP(TODAY(),'İşlem Hisse'!$J$3:$K$460,2,FALSE),"") -> 2.9945205 | G26: =IFERROR(F26*D26,"") -> 41.923288 | H26: =IFERROR((F26-E26)*D26,"") -> -0.23183698 | J26: DLY | K26: =SUMIFS(Tablo13[Adet],Tablo13[Hisse],J26,Tablo13[Durum],"Alış")-SUMIFS(Tablo13[Adet],Tablo13[Hisse],J26,Tablo13[Durum],"Satış") -> 303 | L26: =IFERROR(SUMIFS(Tablo13[Tutar],Tablo13[Hisse],J26)/K26,"") -> 0.091454568 | M26: =IFERROR(VLOOKUP(J26,'İşlem Fon'!$J$3:$K$32,2,FALSE)/VLOOKUP(TODAY(),'İşlem Hisse'!$J$3:$K$460,2,FALSE),"") -> 0.091997068 | N26: =IFERROR(M26*K26,"") -> 27.875112 | O26: =IFERROR((M26-L26)*K26,"") -> 0.1643776 | Q26: KBWD | R26: =SUMIFS(Tablo134[Adet],Tablo134[Hisse],Q26,Tablo134[Durum],"Alış")-SUMIFS(Tablo134[Adet],Tablo134[Hisse],Q26,Tablo134[Durum],"Satış") -> 59.446729 | S26: =IFERROR(SUMIFS(Tablo134[Tutar],Tablo134[Hisse],Q26)/R26,"") -> 15.1354 | T26: =IFERROR(VLOOKUP(Q26,'İşlem FonA'!$J$3:$K$16,2,FALSE),"") -> 15.53 | U26: =IFERROR(T26*R26,"") -> 923.2077 | V26: =IFERROR((T26-S26)*R26,"") -> 23.457697
C27: BURVA | D27: =SUMIFS(Tablo1[Adet],Tablo1[Hisse],C27,Tablo1[Durum],"Alış")-SUMIFS(Tablo1[Adet],Tablo1[Hisse],C27,Tablo1[Durum],"Satış") -> 15 | E27: =IFERROR(SUMIFS(Tablo1[Tutar],Tablo1[Hisse],C27)/D27,"") -> 2.8161237 | F27: =IFERROR(VLOOKUP(C27,Hisse!$A$2:$B$631,2,FALSE)/VLOOKUP(TODAY(),'İşlem Hisse'!$J$3:$K$460,2,FALSE),"") -> 2.7534247 | G27: =IFERROR(F27*D27,"") -> 41.30137 | H27: =IFERROR((F27-E27)*D27,"") -> -0.94048547 | J27: GGK | K27: =SUMIFS(Tablo13[Adet],Tablo13[Hisse],J27,Tablo13[Durum],"Alış")-SUMIFS(Tablo13[Adet],Tablo13[Hisse],J27,Tablo13[Durum],"Satış") -> 136 | L27: =IFERROR(SUMIFS(Tablo13[Tutar],Tablo13[Hisse],J27)/K27,"") -> 0.20325316 | M27: =IFERROR(VLOOKUP(J27,'İşlem Fon'!$J$3:$K$32,2,FALSE)/VLOOKUP(TODAY(),'İşlem Hisse'!$J$3:$K$460,2,FALSE),"") -> 0.20306203 | N27: =IFERROR(M27*K27,"") -> 27.616436 | O27: =IFERROR((M27-L27)*K27,"") -> -0.025993748 | Q27: PFFR | R27: =SUMIFS(Tablo134[Adet],Tablo134[Hisse],Q27,Tablo134[Durum],"Alış")-SUMIFS(Tablo134[Adet],Tablo134[Hisse],Q27,Tablo134[Durum],"Satış") -> 100.51364 | S27: =IFERROR(SUMIFS(Tablo134[Tutar],Tablo134[Hisse],Q27)/R27,"") -> 18.594491 | T27: =IFERROR(VLOOKUP(Q27,'İşlem FonA'!$J$3:$K$16,2,FALSE),"") -> 18.73 | U27: =IFERROR(T27*R27,"") -> 1882.6205 | V27: =IFERROR((T27-S27)*R27,"") -> 13.620546
C28: CEOEM | D28: =SUMIFS(Tablo1[Adet],Tablo1[Hisse],C28,Tablo1[Durum],"Alış")-SUMIFS(Tablo1[Adet],Tablo1[Hisse],C28,Tablo1[Durum],"Satış") -> 90 | E28: =IFERROR(SUMIFS(Tablo1[Tutar],Tablo1[Hisse],C28)/D28,"") -> 0.78402683 | F28: =IFERROR(VLOOKUP(C28,Hisse!$A$2:$B$631,2,FALSE)/VLOOKUP(TODAY(),'İşlem Hisse'!$J$3:$K$460,2,FALSE),"") -> 0.72986301 | G28: =IFERROR(F28*D28,"") -> 65.687671 | H28: =IFERROR((F28-E28)*D28,"") -> -4.874743 | J28: GO6 | K28: =SUMIFS(Tablo13[Adet],Tablo13[Hisse],J28,Tablo13[Durum],"Alış")-SUMIFS(Tablo13[Adet],Tablo13[Hisse],J28,Tablo13[Durum],"Satış") -> 455 | L28: =IFERROR(SUMIFS(Tablo13[Tutar],Tablo13[Hisse],J28)/K28,"") -> 0.060926187 | M28: =IFERROR(VLOOKUP(J28,'İşlem Fon'!$J$3:$K$32,2,FALSE)/VLOOKUP(TODAY(),'İşlem Hisse'!$J$3:$K$460,2,FALSE),"") -> 0.061332466 | N28: =IFERROR(M28*K28,"") -> 27.906272 | O28: =IFERROR((M28-L28)*K28,"") -> 0.18485676 | Q28: SOXL | R28: =SUMIFS(Tablo134[Adet],Tablo134[Hisse],Q28,Tablo134[Durum],"Alış")-SUMIFS(Tablo134[Adet],Tablo134[Hisse],Q28,Tablo134[Durum],"Satış") -> 25 | S28: =IFERROR(SUMIFS(Tablo134[Tutar],Tablo134[Hisse],Q28)/R28,"") -> 27.72 | T28: =IFERROR(VLOOKUP(Q28,'İşlem FonA'!$J$3:$K$16,2,FALSE),"") -> 22.73 | U28: =IFERROR(T28*R28,"") -> 568.25 | V28: =IFERROR((T28-S28)*R28,"") -> -124.75
C29: DESA | D29: =SUMIFS(Tablo1[Adet],Tablo1[Hisse],C29,Tablo1[Durum],"Alış")-SUMIFS(Tablo1[Adet],Tablo1[Hisse],C29,Tablo1[Durum],"Satış") -> 325 | E29: =IFERROR(SUMIFS(Tablo1[Tutar],Tablo1[Hisse],C29)/D29,"") -> 0.24773954 | F29: =IFERROR(VLOOKUP(C29,Hisse!$A$2:$B$631,2,FALSE)/VLOOKUP(TODAY(),'İşlem Hisse'!$J$3:$K$460,2,FALSE),"") -> 0.24 | G29: =IFERROR(F29*D29,"") -> 78 | H29: =IFERROR((F29-E29)*D29,"") -> -2.5153515 | J29: IST | K29: =SUMIFS(Tablo13[Adet],Tablo13[Hisse],J29,Tablo13[Durum],"Alış")-SUMIFS(Tablo13[Adet],Tablo13[Hisse],J29,Tablo13[Durum],"Satış") -> 9641 | L29: =IFERROR(SUMIFS(Tablo13[Tutar],Tablo13[Hisse],J29)/K29,"") -> 0.0028802833 | M29: =IFERROR(VLOOKUP(J29,'İşlem Fon'!$J$3:$K$32,2,FALSE)/VLOOKUP(TODAY(),'İşlem Hisse'!$J$3:$K$460,2,FALSE),"") -> 0.0029016164 | N29: =IFERROR(M29*K29,"") -> 27.974484 | O29: =IFERROR((M29-L29)*K29,"") -> 0.20567322 | Q29: SAVA | R29: =SUMIFS(Tablo134[Adet],Tablo134[Hisse],Q29,Tablo134[Durum],"Alış")-SUMIFS(Tablo134[Adet],Tablo134[Hisse],Q29,Tablo134[Durum],"Satış") -> 5 | S29: =IFERROR(SUMIFS(Tablo134[Tutar],Tablo134[Hisse],Q29)/R29,"") -> 4.46 | T29: =IFERROR(VLOOKUP(Q29,'İşlem FonA'!$J$3:$K$16,2,FALSE),"") -> 2.4 | U29: =IFERROR(T29*R29,"") -> 12 | V29: =IFERROR((T29-S29)*R29,"") -> -10.3
C30: EDATA | D30: =SUMIFS(Tablo1[Adet],Tablo1[Hisse],C30,Tablo1[Durum],"Alış")-SUMIFS(Tablo1[Adet],Tablo1[Hisse],C30,Tablo1[Durum],"Satış") -> 250 | E30: =IFERROR(SUMIFS(Tablo1[Tutar],Tablo1[Hisse],C30)/D30,"") -> 0.10570184 | F30: =IFERROR(VLOOKUP(C30,Hisse!$A$2:$B$631,2,FALSE)/VLOOKUP(TODAY(),'İşlem Hisse'!$J$3:$K$460,2,FALSE),"") -> 0.11780822 | G30: =IFERROR(F30*D30,"") -> 29.452055 | H30: =IFERROR((F30-E30)*D30,"") -> 3.0265939 | J30: KSA | K30: =SUMIFS(Tablo13[Adet],Tablo13[Hisse],J30,Tablo13[Durum],"Alış")-SUMIFS(Tablo13[Adet],Tablo13[Hisse],J30,Tablo13[Durum],"Satış") -> 469 | L30: =IFERROR(SUMIFS(Tablo13[Tutar],Tablo13[Hisse],J30)/K30,"") -> 0.05915068 | M30: =IFERROR(VLOOKUP(J30,'İşlem Fon'!$J$3:$K$32,2,FALSE)/VLOOKUP(TODAY(),'İşlem Hisse'!$J$3:$K$460,2,FALSE),"") -> 0.059605342 | N30: =IFERROR(M30*K30,"") -> 27.954906 | O30: =IFERROR((M30-L30)*K30,"") -> 0.21323652 | R30: =SUMIFS(Tablo134[Adet],Tablo134[Hisse],Q30,Tablo134[Durum],"Alış")-SUMIFS(Tablo134[Adet],Tablo134[Hisse],Q30,Tablo134[Durum],"Satış") -> 0 | S30: =IFERROR(SUMIFS(Tablo134[Tutar],Tablo134[Hisse],Q30)/R30,"") | T30: =IFERROR(VLOOKUP(Q30,'İşlem FonA'!$J$3:$K$16,2,FALSE),"") | U30: =IFERROR(T30*R30,"") | V30: =IFERROR((T30-S30)*R30,"")
C31: KONTR | D31: =SUMIFS(Tablo1[Adet],Tablo1[Hisse],C31,Tablo1[Durum],"Alış")-SUMIFS(Tablo1[Adet],Tablo1[Hisse],C31,Tablo1[Durum],"Satış") -> 160 | E31: =IFERROR(SUMIFS(Tablo1[Tutar],Tablo1[Hisse],C31)/D31,"") -> 0.91983026 | F31: =IFERROR(VLOOKUP(C31,Hisse!$A$2:$B$631,2,FALSE)/VLOOKUP(TODAY(),'İşlem Hisse'!$J$3:$K$460,2,FALSE),"") -> 0.82191781 | G31: =IFERROR(F31*D31,"") -> 131.50685 | H31: =IFERROR((F31-E31)*D31,"") -> -15.665993 | J31: OJK | K31: =SUMIFS(Tablo13[Adet],Tablo13[Hisse],J31,Tablo13[Durum],"Alış")-SUMIFS(Tablo13[Adet],Tablo13[Hisse],J31,Tablo13[Durum],"Satış") -> 147 | L31: =IFERROR(SUMIFS(Tablo13[Tutar],Tablo13[Hisse],J31)/K31,"") -> 0.18797058 | M31: =IFERROR(VLOOKUP(J31,'İşlem Fon'!$J$3:$K$32,2,FALSE)/VLOOKUP(TODAY(),'İşlem Hisse'!$J$3:$K$460,2,FALSE),"") -> 0.18752532 | N31: =IFERROR(M31*K31,"") -> 27.566221 | O31: =IFERROR((M31-L31)*K31,"") -> -0.065454197 | R31: =SUMIFS(Tablo134[Adet],Tablo134[Hisse],Q31,Tablo134[Durum],"Alış")-SUMIFS(Tablo134[Adet],Tablo134[Hisse],Q31,Tablo134[Durum],"Satış") -> 0 | S31: =IFERROR(SUMIFS(Tablo134[Tutar],Tablo134[Hisse],Q31)/R31,"") | T31: =IFERROR(VLOOKUP(Q31,'İşlem FonA'!$J$3:$K$16,2,FALSE),"") | U31: =IFERROR(T31*R31,"") | V31: =IFERROR((T31-S31)*R31,"")
C32: MARKA | D32: =SUMIFS(Tablo1[Adet],Tablo1[Hisse],C32,Tablo1[Durum],"Alış")-SUMIFS(Tablo1[Adet],Tablo1[Hisse],C32,Tablo1[Durum],"Satış") -> 50 | E32: =IFERROR(SUMIFS(Tablo1[Tutar],Tablo1[Hisse],C32)/D32,"") -> 1.2042278 | F32: =IFERROR(VLOOKUP(C32,Hisse!$A$2:$B$631,2,FALSE)/VLOOKUP(TODAY(),'İşlem Hisse'!$J$3:$K$460,2,FALSE),"") -> 1.2838356 | G32: =IFERROR(F32*D32,"") -> 64.191781 | H32: =IFERROR((F32-E32)*D32,"") -> 3.9803903 | J32: PPN | K32: =SUMIFS(Tablo13[Adet],Tablo13[Hisse],J32,Tablo13[Durum],"Alış")-SUMIFS(Tablo13[Adet],Tablo13[Hisse],J32,Tablo13[Durum],"Satış") -> 326 | L32: =IFERROR(SUMIFS(Tablo13[Tutar],Tablo13[Hisse],J32)/K32,"") -> 0.085010247 | M32: =IFERROR(VLOOKUP(J32,'İşlem Fon'!$J$3:$K$32,2,FALSE)/VLOOKUP(TODAY(),'İşlem Hisse'!$J$3:$K$460,2,FALSE),"") -> 0.085556164 | N32: =IFERROR(M32*K32,"") -> 27.89131 | O32: =IFERROR((M32-L32)*K32,"") -> 0.17796902 | R32: =SUMIFS(Tablo134[Adet],Tablo134[Hisse],Q32,Tablo134[Durum],"Alış")-SUMIFS(Tablo134[Adet],Tablo134[Hisse],Q32,Tablo134[Durum],"Satış") -> 0 | S32: =IFERROR(SUMIFS(Tablo134[Tutar],Tablo134[Hisse],Q32)/R32,"") | T32: =IFERROR(VLOOKUP(Q32,'İşlem FonA'!$J$3:$K$16,2,FALSE),"") | U32: =IFERROR(T32*R32,"") | V32: =IFERROR((T32-S32)*R32,"")
C33: PRDGS | D33: =SUMIFS(Tablo1[Adet],Tablo1[Hisse],C33,Tablo1[Durum],"Alış")-SUMIFS(Tablo1[Adet],Tablo1[Hisse],C33,Tablo1[Durum],"Satış") -> 200 | E33: =IFERROR(SUMIFS(Tablo1[Tutar],Tablo1[Hisse],C33)/D33,"") -> 0.11615195 | F33: =IFERROR(VLOOKUP(C33,Hisse!$A$2:$B$631,2,FALSE)/VLOOKUP(TODAY(),'İşlem Hisse'!$J$3:$K$460,2,FALSE),"") -> 0.14082192 | G33: =IFERROR(F33*D33,"") -> 28.164384 | H33: =IFERROR((F33-E33)*D33,"") -> 4.933993 | J33: TAU | K33: =SUMIFS(Tablo13[Adet],Tablo13[Hisse],J33,Tablo13[Durum],"Alış")-SUMIFS(Tablo13[Adet],Tablo13[Hisse],J33,Tablo13[Durum],"Satış") -> 1831 | L33: =IFERROR(SUMIFS(Tablo13[Tutar],Tablo13[Hisse],J33)/K33,"") -> 0.015120665 | M33: =IFERROR(VLOOKUP(J33,'İşlem Fon'!$J$3:$K$32,2,FALSE)/VLOOKUP(TODAY(),'İşlem Hisse'!$J$3:$K$460,2,FALSE),"") -> 0.015674795 | N33: =IFERROR(M33*K33,"") -> 28.700549 | O33: =IFERROR((M33-L33)*K33,"") -> 1.0146115 | R33: =SUMIFS(Tablo134[Adet],Tablo134[Hisse],Q33,Tablo134[Durum],"Alış")-SUMIFS(Tablo134[Adet],Tablo134[Hisse],Q33,Tablo134[Durum],"Satış") -> 0 | S33: =IFERROR(SUMIFS(Tablo134[Tutar],Tablo134[Hisse],Q33)/R33,"") | T33: =IFERROR(VLOOKUP(Q33,'İşlem FonA'!$J$3:$K$16,2,FALSE),"") | U33: =IFERROR(T33*R33,"") | V33: =IFERROR((T33-S33)*R33,"")
C34: OBASE | D34: =SUMIFS(Tablo1[Adet],Tablo1[Hisse],C34,Tablo1[Durum],"Alış")-SUMIFS(Tablo1[Adet],Tablo1[Hisse],C34,Tablo1[Durum],"Satış") -> 70 | E34: =IFERROR(SUMIFS(Tablo1[Tutar],Tablo1[Hisse],C34)/D34,"") -> 0.83676269 | F34: =IFERROR(VLOOKUP(C34,Hisse!$A$2:$B$631,2,FALSE)/VLOOKUP(TODAY(),'İşlem Hisse'!$J$3:$K$460,2,FALSE),"") -> 0.79726027 | G34: =IFERROR(F34*D34,"") -> 55.808219 | H34: =IFERROR((F34-E34)*D34,"") -> -2.765169 | J34: TCA | K34: =SUMIFS(Tablo13[Adet],Tablo13[Hisse],J34,Tablo13[Durum],"Alış")-SUMIFS(Tablo13[Adet],Tablo13[Hisse],J34,Tablo13[Durum],"Satış") -> 2000 | L34: =IFERROR(SUMIFS(Tablo13[Tutar],Tablo13[Hisse],J34)/K34,"") -> 0.01223374 | M34: =IFERROR(VLOOKUP(J34,'İşlem Fon'!$J$3:$K$32,2,FALSE)/VLOOKUP(TODAY(),'İşlem Hisse'!$J$3:$K$460,2,FALSE),"") -> 0.012490849 | N34: =IFERROR(M34*K34,"") -> 24.981699 | O34: =IFERROR((M34-L34)*K34,"") -> 0.51421941 | R34: =SUMIFS(Tablo134[Adet],Tablo134[Hisse],Q34,Tablo134[Durum],"Alış")-SUMIFS(Tablo134[Adet],Tablo134[Hisse],Q34,Tablo134[Durum],"Satış") -> 0 | S34: =IFERROR(SUMIFS(Tablo134[Tutar],Tablo134[Hisse],Q34)/R34,"") | T34: =IFERROR(VLOOKUP(Q34,'İşlem FonA'!$J$3:$K$16,2,FALSE),"") | U34: =IFERROR(T34*R34,"") | V34: =IFERROR((T34-S34)*R34,"")
C35: ONCSM | D35: =SUMIFS(Tablo1[Adet],Tablo1[Hisse],C35,Tablo1[Durum],"Alış")-SUMIFS(Tablo1[Adet],Tablo1[Hisse],C35,Tablo1[Durum],"Satış") -> 22 | E35: =IFERROR(SUMIFS(Tablo1[Tutar],Tablo1[Hisse],C35)/D35,"") -> 2.617801 | F35: =IFERROR(VLOOKUP(C35,Hisse!$A$2:$B$631,2,FALSE)/VLOOKUP(TODAY(),'İşlem Hisse'!$J$3:$K$460,2,FALSE),"") -> 2.6479452 | G35: =IFERROR(F35*D35,"") -> 58.254795 | H35: =IFERROR((F35-E35)*D35,"") -> 0.66317148 | J35: TCB | K35: =SUMIFS(Tablo13[Adet],Tablo13[Hisse],J35,Tablo13[Durum],"Alış")-SUMIFS(Tablo13[Adet],Tablo13[Hisse],J35,Tablo13[Durum],"Satış") -> 7901 | L35: =IFERROR(SUMIFS(Tablo13[Tutar],Tablo13[Hisse],J35)/K35,"") -> 0.0035147459 | M35: =IFERROR(VLOOKUP(J35,'İşlem Fon'!$J$3:$K$32,2,FALSE)/VLOOKUP(TODAY(),'İşlem Hisse'!$J$3:$K$460,2,FALSE),"") -> 0.0035371233 | N35: =IFERROR(M35*K35,"") -> 27.946811 | O35: =IFERROR((M35-L35)*K35,"") -> 0.17680371 | R35: =SUMIFS(Tablo134[Adet],Tablo134[Hisse],Q35,Tablo134[Durum],"Alış")-SUMIFS(Tablo134[Adet],Tablo134[Hisse],Q35,Tablo134[Durum],"Satış") -> 0 | S35: =IFERROR(SUMIFS(Tablo134[Tutar],Tablo134[Hisse],Q35)/R35,"") | T35: =IFERROR(VLOOKUP(Q35,'İşlem FonA'!$J$3:$K$16,2,FALSE),"") | U35: =IFERROR(T35*R35,"") | V35: =IFERROR((T35-S35)*R35,"")
C36: SNICA | D36: =SUMIFS(Tablo1[Adet],Tablo1[Hisse],C36,Tablo1[Durum],"Alış")-SUMIFS(Tablo1[Adet],Tablo1[Hisse],C36,Tablo1[Durum],"Satış") -> 410 | E36: =IFERROR(SUMIFS(Tablo1[Tutar],Tablo1[Hisse],C36)/D36,"") -> 0.13607331 | F36: =IFERROR(VLOOKUP(C36,Hisse!$A$2:$B$631,2,FALSE)/VLOOKUP(TODAY(),'İşlem Hisse'!$J$3:$K$460,2,FALSE),"") -> 0.12986301 | G36: =IFERROR(F36*D36,"") -> 53.243836 | H36: =IFERROR((F36-E36)*D36,"") -> -2.5462227 | J36: TTA | K36: =SUMIFS(Tablo13[Adet],Tablo13[Hisse],J36,Tablo13[Durum],"Alış")-SUMIFS(Tablo13[Adet],Tablo13[Hisse],J36,Tablo13[Durum],"Satış") -> 2936 | L36: =IFERROR(SUMIFS(Tablo13[Tutar],Tablo13[Hisse],J36)/K36,"") -> 0.0094333795 | M36: =IFERROR(VLOOKUP(J36,'İşlem Fon'!$J$3:$K$32,2,FALSE)/VLOOKUP(TODAY(),'İşlem Hisse'!$J$3:$K$460,2,FALSE),"") -> 0.0097224932 | N36: =IFERROR(M36*K36,"") -> 28.54524 | O36: =IFERROR((M36-L36)*K36,"") -> 0.84883767 | R36: =SUMIFS(Tablo134[Adet],Tablo134[Hisse],Q36,Tablo134[Durum],"Alış")-SUMIFS(Tablo134[Adet],Tablo134[Hisse],Q36,Tablo134[Durum],"Satış") -> 0 | S36: =IFERROR(SUMIFS(Tablo134[Tutar],Tablo134[Hisse],Q36)/R36,"") | T36: =IFERROR(VLOOKUP(Q36,'İşlem FonA'!$J$3:$K$16,2,FALSE),"") | U36: =IFERROR(T36*R36,"") | V36: =IFERROR((T36-S36)*R36,"")
C37: TAVHL | D37: =SUMIFS(Tablo1[Adet],Tablo1[Hisse],C37,Tablo1[Durum],"Alış")-SUMIFS(Tablo1[Adet],Tablo1[Hisse],C37,Tablo1[Durum],"Satış") -> 25 | E37: =IFERROR(SUMIFS(Tablo1[Tutar],Tablo1[Hisse],C37)/D37,"") -> 7.1374035 | F37: =IFERROR(VLOOKUP(C37,Hisse!$A$2:$B$631,2,FALSE)/VLOOKUP(TODAY(),'İşlem Hisse'!$J$3:$K$460,2,FALSE),"") -> 6.8328767 | G37: =IFERROR(F37*D37,"") -> 170.82192 | H37: =IFERROR((F37-E37)*D37,"") -> -7.6131706 | J37: ZJB | K37: =SUMIFS(Tablo13[Adet],Tablo13[Hisse],J37,Tablo13[Durum],"Alış")-SUMIFS(Tablo13[Adet],Tablo13[Hisse],J37,Tablo13[Durum],"Satış") -> 118 | L37: =IFERROR(SUMIFS(Tablo13[Tutar],Tablo13[Hisse],J37)/K37,"") -> 0.2677918 | M37: =IFERROR(VLOOKUP(J37,'İşlem Fon'!$J$3:$K$32,2,FALSE)/VLOOKUP(TODAY(),'İşlem Hisse'!$J$3:$K$460,2,FALSE),"") -> 0.28755827 | N37: =IFERROR(M37*K37,"") -> 33.931876 | O37: =IFERROR((M37-L37)*K37,"") -> 2.3324439 | R37: =SUMIFS(Tablo134[Adet],Tablo134[Hisse],Q37,Tablo134[Durum],"Alış")-SUMIFS(Tablo134[Adet],Tablo134[Hisse],Q37,Tablo134[Durum],"Satış") -> 0 | S37: =IFERROR(SUMIFS(Tablo134[Tutar],Tablo134[Hisse],Q37)/R37,"") | T37: =IFERROR(VLOOKUP(Q37,'İşlem FonA'!$J$3:$K$16,2,FALSE),"") | U37: =IFERROR(T37*R37,"") | V37: =IFERROR((T37-S37)*R37,"")
C38: TNZTP | D38: =SUMIFS(Tablo1[Adet],Tablo1[Hisse],C38,Tablo1[Durum],"Alış")-SUMIFS(Tablo1[Adet],Tablo1[Hisse],C38,Tablo1[Durum],"Satış") -> 20 | E38: =IFERROR(SUMIFS(Tablo1[Tutar],Tablo1[Hisse],C38)/D38,"") -> 1.3137827 | F38: =IFERROR(VLOOKUP(C38,Hisse!$A$2:$B$631,2,FALSE)/VLOOKUP(TODAY(),'İşlem Hisse'!$J$3:$K$460,2,FALSE),"") -> 1.3578082 | G38: =IFERROR(F38*D38,"") -> 27.156164 | H38: =IFERROR((F38-E38)*D38,"") -> 0.88050961 | K38: =SUMIFS(Tablo13[Adet],Tablo13[Hisse],J38,Tablo13[Durum],"Alış")-SUMIFS(Tablo13[Adet],Tablo13[Hisse],J38,Tablo13[Durum],"Satış") -> 0 | L38: =IFERROR(SUMIFS(Tablo13[Tutar],Tablo13[Hisse],J38)/K38,"") | M38: =IFERROR(VLOOKUP(J38,'İşlem Fon'!$J$3:$K$32,2,FALSE)/VLOOKUP(TODAY(),'İşlem Hisse'!$J$3:$K$460,2,FALSE),"") | N38: =IFERROR(M38*K38,"") | O38: =IFERROR((M38-L38)*K38,"") | R38: =SUMIFS(Tablo134[Adet],Tablo134[Hisse],Q38,Tablo134[Durum],"Alış")-SUMIFS(Tablo134[Adet],Tablo134[Hisse],Q38,Tablo134[Durum],"Satış") -> 0 | S38: =IFERROR(SUMIFS(Tablo134[Tutar],Tablo134[Hisse],Q38)/R38,"") | T38: =IFERROR(VLOOKUP(Q38,'İşlem FonA'!$J$3:$K$16,2,FALSE),"") | U38: =IFERROR(T38*R38,"") | V38: =IFERROR((T38-S38)*R38,"")
C39: VBTYZ | D39: =SUMIFS(Tablo1[Adet],Tablo1[Hisse],C39,Tablo1[Durum],"Alış")-SUMIFS(Tablo1[Adet],Tablo1[Hisse],C39,Tablo1[Durum],"Satış") -> 140 | E39: =IFERROR(SUMIFS(Tablo1[Tutar],Tablo1[Hisse],C39)/D39,"") -> 0.64273982 | F39: =IFERROR(VLOOKUP(C39,Hisse!$A$2:$B$631,2,FALSE)/VLOOKUP(TODAY(),'İşlem Hisse'!$J$3:$K$460,2,FALSE),"") -> 0.5769863 | G39: =IFERROR(F39*D39,"") -> 80.778082 | H39: =IFERROR((F39-E39)*D39,"") -> -9.2054931 | K39: =SUMIFS(Tablo13[Adet],Tablo13[Hisse],J39,Tablo13[Durum],"Alış")-SUMIFS(Tablo13[Adet],Tablo13[Hisse],J39,Tablo13[Durum],"Satış") -> 0 | L39: =IFERROR(SUMIFS(Tablo13[Tutar],Tablo13[Hisse],J39)/K39,"") | M39: =IFERROR(VLOOKUP(J39,'İşlem Fon'!$J$3:$K$32,2,FALSE)/VLOOKUP(TODAY(),'İşlem Hisse'!$J$3:$K$460,2,FALSE),"") | N39: =IFERROR(M39*K39,"") | O39: =IFERROR((M39-L39)*K39,"") | R39: =SUMIFS(Tablo134[Adet],Tablo134[Hisse],Q39,Tablo134[Durum],"Alış")-SUMIFS(Tablo134[Adet],Tablo134[Hisse],Q39,Tablo134[Durum],"Satış") -> 0 | S39: =IFERROR(SUMIFS(Tablo134[Tutar],Tablo134[Hisse],Q39)/R39,"") | T39: =IFERROR(VLOOKUP(Q39,'İşlem FonA'!$J$3:$K$16,2,FALSE),"") | U39: =IFERROR(T39*R39,"") | V39: =IFERROR((T39-S39)*R39,"")
D40: =SUMIFS(Tablo1[Adet],Tablo1[Hisse],C40,Tablo1[Durum],"Alış")-SUMIFS(Tablo1[Adet],Tablo1[Hisse],C40,Tablo1[Durum],"Satış") -> 0 | E40: =IFERROR(SUMIFS(Tablo1[Tutar],Tablo1[Hisse],C40)/D40,"") | F40: =IFERROR(VLOOKUP(C40,Hisse!$A$2:$B$631,2,FALSE)/VLOOKUP(TODAY(),'İşlem Hisse'!$J$3:$K$460,2,FALSE),"") | G40: =IFERROR(F40*D40,"") | H40: =IFERROR((F40-E40)*D40,"") | K40: =SUMIFS(Tablo13[Adet],Tablo13[Hisse],J40,Tablo13[Durum],"Alış")-SUMIFS(Tablo13[Adet],Tablo13[Hisse],J40,Tablo13[Durum],"Satış") -> 0 | L40: =IFERROR(SUMIFS(Tablo13[Tutar],Tablo13[Hisse],J40)/K40,"") | M40: =IFERROR(VLOOKUP(J40,'İşlem Fon'!$J$3:$K$32,2,FALSE)/VLOOKUP(TODAY(),'İşlem Hisse'!$J$3:$K$460,2,FALSE),"") | N40: =IFERROR(M40*K40,"") | O40: =IFERROR((M40-L40)*K40,"") | R40: =SUMIFS(Tablo134[Adet],Tablo134[Hisse],Q40,Tablo134[Durum],"Alış")-SUMIFS(Tablo134[Adet],Tablo134[Hisse],Q40,Tablo134[Durum],"Satış") -> 0 | S40: =IFERROR(SUMIFS(Tablo134[Tutar],Tablo134[Hisse],Q40)/R40,"") | T40: =IFERROR(VLOOKUP(Q40,'İşlem FonA'!$J$3:$K$16,2,FALSE),"") | U40: =IFERROR(T40*R40,"") | V40: =IFERROR((T40-S40)*R40,"")
D41: =SUMIFS(Tablo1[Adet],Tablo1[Hisse],C41,Tablo1[Durum],"Alış")-SUMIFS(Tablo1[Adet],Tablo1[Hisse],C41,Tablo1[Durum],"Satış") -> 0 | E41: =IFERROR(SUMIFS(Tablo1[Tutar],Tablo1[Hisse],C41)/D41,"") | F41: =IFERROR(VLOOKUP(C41,Hisse!$A$2:$B$631,2,FALSE)/VLOOKUP(TODAY(),'İşlem Hisse'!$J$3:$K$460,2,FALSE),"") | G41: =IFERROR(F41*D41,"") | H41: =IFERROR((F41-E41)*D41,"") | K41: =SUMIFS(Tablo13[Adet],Tablo13[Hisse],J41,Tablo13[Durum],"Alış")-SUMIFS(Tablo13[Adet],Tablo13[Hisse],J41,Tablo13[Durum],"Satış") -> 0 | L41: =IFERROR(SUMIFS(Tablo13[Tutar],Tablo13[Hisse],J41)/K41,"") | M41: =IFERROR(VLOOKUP(J41,'İşlem Fon'!$J$3:$K$32,2,FALSE)/VLOOKUP(TODAY(),'İşlem Hisse'!$J$3:$K$460,2,FALSE),"") | N41: =IFERROR(M41*K41,"") | O41: =IFERROR((M41-L41)*K41,"") | R41: =SUMIFS(Tablo134[Adet],Tablo134[Hisse],Q41,Tablo134[Durum],"Alış")-SUMIFS(Tablo134[Adet],Tablo134[Hisse],Q41,Tablo134[Durum],"Satış") -> 0 | S41: =IFERROR(SUMIFS(Tablo134[Tutar],Tablo134[Hisse],Q41)/R41,"") | T41: =IFERROR(VLOOKUP(Q41,'İşlem FonA'!$J$3:$K$16,2,FALSE),"") | U41: =IFERROR(T41*R41,"") | V41: =IFERROR((T41-S41)*R41,"")
C42: TOPLAM | G42: =SUM(G24:G41) -> 1016.874 | H42: =SUM(H24:H41) -> -34.051406 | J42: TOPLAM | N42: =SUM(N24:N41) -> 390.8477 | O42: =SUM(O24:O41) -> 7.245531 | Q42: TOPLAM | U42: =SUM(U24:U41) -> 4465.7982 | V42: =SUM(V24:V41) -> -92.111757

Sheet İşlem Hisse
L1: Hisse | M1: Fon | N1: Hisse | O1: Kripto
B2: Tarih | C2: Hisse | D2: Durum | E2: Adet | F2: Fiyat | G2: Kur | H2: Tutar | L2: Kar Zarar | M2: Kar Zarar | N2: Yatırım | O2: Yatırım
B3: 45699 | C3: ARASE | D3: Alış | E3: 50 | F3: 46.64 | G3: =VLOOKUP(Tablo1[[#This Row],[Tarih]],$J$3:$K$460,2,FALSE) -> 36.01 | H3: =IF(Tablo1[[#This Row],[Durum]]="Alış",Tablo1[[#This Row],[Adet]]*Tablo1[[#This Row],[Fiyat]],(-Tablo1[[#This Row],[Adet]]*Tablo1[[#This Row],[Fiyat]]))/Tablo1[[#This Row],[Kur]] -> 64.759789 | J3: 45699 | K3: 36.01 | L3: 0 | M3: 0 | N3: 0 | O3: 0 | P3: =SUM(L3:O3) -> 0 | Q3: =P3 -> 0
B4: 45699 | C4: KONTR | D4: Alış | E4: 60 | F4: 34.3 | G4: =VLOOKUP(Tablo1[[#This Row],[Tarih]],$J$3:$K$460,2,FALSE) -> 36.01 | H4: =IF(Tablo1[[#This Row],[Durum]]="Alış",Tablo1[[#This Row],[Adet]]*Tablo1[[#This Row],[Fiyat]],(-Tablo1[[#This Row],[Adet]]*Tablo1[[#This Row],[Fiyat]]))/Tablo1[[#This Row],[Kur]] -> 57.150791 | I4: 1 | J4: 45700 | K4: 36.1 | L4: -5.3237128 | M4: 0.074363782 | N4: 15.37 | O4: 131 | P4: =SUM(L4:O4)-P3 -> 141.12065 | Q4: =+P4+Q3 -> 141.12065 | R4: =+Q4/I4 -> 141.12065
B5: 45699 | C5: TNZTP | D5: Alış | E5: 40 | F5: 50.95 | G5: =VLOOKUP(Tablo1[[#This Row],[Tarih]],$J$3:$K$460,2,FALSE) -> 36.01 | H5: =IF(Tablo1[[#This Row],[Durum]]="Alış",Tablo1[[#This Row],[Adet]]*Tablo1[[#This Row],[Fiyat]],(-Tablo1[[#This Row],[Adet]]*Tablo1[[#This Row],[Fiyat]]))/Tablo1[[#This Row],[Kur]] -> 56.59539 | I5: =+I4+1 -> 2 | J5: 45701 | K5: 36.1 | L5: 0.60010993 | M5: -0.20221802 | N5: 61.03 | O5: 219 | P5: =SUM(L5:O5)-P4 -> 139.30724 | Q5: =+P5+Q4 -> 280.42789 | R5: =+Q5/I5 -> 140.21395
B6: 45699 | C6: PRDGS | D6: Alış | E6: 410 | F6: 4.91 | G6: =VLOOKUP(Tablo1[[#This Row],[Tarih]],$J$3:$K$460,2,FALSE) -> 36.01 | H6: =IF(Tablo1[[#This Row],[Durum]]="Alış",Tablo1[[#This Row],[Adet]]*Tablo1[[#This Row],[Fiyat]],(-Tablo1[[#This Row],[Adet]]*Tablo1[[#This Row],[Fiyat]]))/Tablo1[[#This Row],[Kur]] -> 55.903916 | I6: =+I5+1 -> 3 | J6: 45702 | K6: 36.22 | L6: 3.177813 | M6: 1.5333618 | N6: 75.58 | O6: 227 | P6: =SUM(L6:O6)-Q5 -> 26.863283 | Q6: =+P6+Q5 -> 307.29117 | R6: =+Q6/I6 -> 102.43039
B7: 45699 | C7: VBTYZ | D7: Alış | E7: 90 | F7: 23.42 | G7: =VLOOKUP(Tablo1[[#This Row],[Tarih]],$J$3:$K$460,2,FALSE) -> 36.01 | H7: =IF(Tablo1[[#This Row],[Durum]]="Alış",Tablo1[[#This Row],[Adet]]*Tablo1[[#This Row],[Fiyat]],(-Tablo1[[#This Row],[Adet]]*Tablo1[[#This Row],[Fiyat]]))/Tablo1[[#This Row],[Kur]] -> 58.533741 | I7: =+I6+1 -> 4 | J7: 45703 | K7: 36.24 | L7: 3.177813 | M7: 1.5333618 | N7: 75.58 | O7: 250 | P7: =SUM(L7:O7)-Q6 -> 23 | Q7: =+P7+Q6 -> 330.29117 | R7: =+Q7/I7 -> 82.572794
B8: 45699 | C8: SNICA | D8: Alış | E8: 410 | F8: 4.9 | G8: =VLOOKUP(Tablo1[[#This Row],[Tarih]],$J$3:$K$460,2,FALSE) -> 36.01 | H8: =IF(Tablo1[[#This Row],[Durum]]="Alış",Tablo1[[#This Row],[Adet]]*Tablo1[[#This Row],[Fiyat]],(-Tablo1[[#This Row],[Adet]]*Tablo1[[#This Row],[Fiyat]]))/Tablo1[[#This Row],[Kur]] -> 55.790058 | I8: =+I7+1 -> 5 | J8: 45704 | K8: 36.24 | L8: 3.177813 | M8: 1.5333618 | N8: 85.06 | O8: 310 | P8: =SUM(L8:O8)-Q7 -> 69.48 | Q8: =+P8+Q7 -> 399.77117 | R8: =+Q8/I8 -> 79.954235
B9: 45700 | C9: EDATA | D9: Alış | E9: 500 | F9: 4.29 | G9: =VLOOKUP(Tablo1[[#This Row],[Tarih]],$J$3:$K$460,2,FALSE) -> 36.1 | H9: =IF(Tablo1[[#This Row],[Durum]]="Alış",Tablo1[[#This Row],[Adet]]*Tablo1[[#This Row],[Fiyat]],(-Tablo1[[#This Row],[Adet]]*Tablo1[[#This Row],[Fiyat]]))/Tablo1[[#This Row],[Kur]] -> 59.418283 | I9: =+I8+1 -> 6 | J9: 45705 | K9: 36.24 | L9: 0.6295017 | M9: 2.618109 | N9: 85.06 | O9: 385 | P9: =SUM(L9:O9)-Q8 -> 73.536436 | Q9: =+P9+Q8 -> 473.30761 | R9: =+Q9/I9 -> 78.884602
B10: 45700 | C10: ASTOR | D10: Alış | E10: 7 | F10: 111 | G10: =VLOOKUP(Tablo1[[#This Row],[Tarih]],$J$3:$K$460,2,FALSE) -> 36.1 | H10: =IF(Tablo1[[#This Row],[Durum]]="Alış",Tablo1[[#This Row],[Adet]]*Tablo1[[#This Row],[Fiyat]],(-Tablo1[[#This Row],[Adet]]*Tablo1[[#This Row],[Fiyat]]))/Tablo1[[#This Row],[Kur]] -> 21.523546 | I10: =+I9+1 -> 7 | J10: 45706 | K10: 36.28 | L10: 3.5026511 | M10: 2.1922873 | N10: 115.9 | O10: 425 | P10: =SUM(L10:O10)-Q9 -> 73.287328 | Q10: =+P10+Q9 -> 546.59494 | R10: =+Q10/I10 -> 78.084991
B11: 45700 | C11: MARKA | D11: Alış | E11: 50 | F11: 46 | G11: =VLOOKUP(Tablo1[[#This Row],[Tarih]],$J$3:$K$460,2,FALSE) -> 36.1 | H11: =IF(Tablo1[[#This Row],[Durum]]="Alış",Tablo1[[#This Row],[Adet]]*Tablo1[[#This Row],[Fiyat]],(-Tablo1[[#This Row],[Adet]]*Tablo1[[#This Row],[Fiyat]]))/Tablo1[[#This Row],[Kur]] -> 63.711911 | I11: =+I10+1 -> 8 | J11: 45707 | K11: 36.3 | L11: -7.7383958 | M11: 3.9006631 | N11: 144.74 | O11: 495 | P11: =SUM(L11:O11)-Q10 -> 89.307329 | Q11: =+P11+Q10 -> 635.90227 | R11: =+Q11/I11 -> 79.487783
B12: 45701 | C12: ASTOR | D12: Alış | E12: 7 | F12: 106.4 | G12: =VLOOKUP(Tablo1[[#This Row],[Tarih]],$J$3:$K$460,2,FALSE) -> 36.1 | H12: =IF(Tablo1[[#This Row],[Durum]]="Alış",Tablo1[[#This Row],[Adet]]*Tablo1[[#This Row],[Fiyat]],(-Tablo1[[#This Row],[Adet]]*Tablo1[[#This Row],[Fiyat]]))/Tablo1[[#This Row],[Kur]] -> 20.631579 | I12: =+I11+1 -> 9 | J12: 45708 | K12: 36.29 | L12: 4.0777057 | M12: 5.4592137 | N12: 143.75 | O12: 537 | P12: =SUM(L12:O12)-Q11 -> 54.384652 | Q12: =+P12+Q11 -> 690.28692 | R12: =+Q12/I12 -> 76.698547
B13: 45701 | C13: DESA | D13: Alış | E13: 225 | F13: 9 | G13: =VLOOKUP(Tablo1[[#This Row],[Tarih]],$J$3:$K$460,2,FALSE) -> 36.1 | H13: =IF(Tablo1[[#This Row],[Durum]]="Alış",Tablo1[[#This Row],[Adet]]*Tablo1[[#This Row],[Fiyat]],(-Tablo1[[#This Row],[Adet]]*Tablo1[[#This Row],[Fiyat]]))/Tablo1[[#This Row],[Kur]] -> 56.094183 | I13: =+I12+1 -> 10 | J13: 45709 | K13: 36.45 | L13: -20.614252 | M13: 5.279632 | N13: 48.04 | O13: 518 | P13: =SUM(L13:O13)-Q12 -> -139.58154 | Q13: =+P13+Q12 -> 550.70538 | R13: =+Q13/I13 -> 55.070538
B14: 45702 | C14: BURVA | D14: Alış | E14: 15 | F14: 102 | G14: =VLOOKUP(Tablo1[[#This Row],[Tarih]],$J$3:$K$460,2,FALSE) -> 36.22 | H14: =IF(Tablo1[[#This Row],[Durum]]="Alış",Tablo1[[#This Row],[Adet]]*Tablo1[[#This Row],[Fiyat]],(-Tablo1[[#This Row],[Adet]]*Tablo1[[#This Row],[Fiyat]]))/Tablo1[[#This Row],[Kur]] -> 42.241855 | I14: =+I13+1 -> 11 | J14: 45710 | K14: =K13 -> 36.45 | L14: -20.614252 | M14: 5.279632 | N14: 52.56 | O14: 585 | P14: =SUM(L14:O14)-Q13 -> 71.52 | Q14: =+P14+Q13 -> 622.22538 | R14: =+Q14/I14 -> 56.565944
B15: 45702 | C15: EDATA | D15: Satış | E15: 250 | F15: 4.78 | G15: =VLOOKUP(Tablo1[[#This Row],[Tarih]],$J$3:$K$460,2,FALSE) -> 36.22 | H15: =IF(Tablo1[[#This Row],[Durum]]="Alış",Tablo1[[#This Row],[Adet]]*Tablo1[[#This Row],[Fiyat]],(-Tablo1[[#This Row],[Adet]]*Tablo1[[#This Row],[Fiyat]]))/Tablo1[[#This Row],[Kur]] -> -32.992822 | I15: =+I14+1 -> 12 | J15: 45711 | K15: =K14 -> 36.45 | L15: -20.614252 | M15: 5.279632 | N15: 52.56 | O15: 543 | P15: =SUM(L15:O15)-Q14 -> -42 | Q15: =+P15+Q14 -> 580.22538 | R15: =+Q15/I15 -> 48.352115
B16: 45705 | C16: TAVHL | D16: Alış | E16: 5 | F16: 265 | G16: =VLOOKUP(Tablo1[[#This Row],[Tarih]],$J$3:$K$460,2,FALSE) -> 36.24 | H16: =IF(Tablo1[[#This Row],[Durum]]="Alış",Tablo1[[#This Row],[Adet]]*Tablo1[[#This Row],[Fiyat]],(-Tablo1[[#This Row],[Adet]]*Tablo1[[#This Row],[Fiyat]]))/Tablo1[[#This Row],[Kur]] -> 36.56181 | I16: =+I15+1 -> 13 | J16: 45712 | K16: 36.43 | L16: -14.637044 | M16: 5.4931273 | N16: 27.91 | O16: 511 | P16: =SUM(L16:O16)-Q15 -> -50.459297 | Q16: =+P16+Q15 -> 529.76608 | R16: =+Q16/I16 -> 40.751237
B17: 45706 | C17: DESA | D17: Alış | E17: 100 | F17: 8.86 | G17: =VLOOKUP(Tablo1[[#This Row],[Tarih]],$J$3:$K$460,2,FALSE) -> 36.28 | H17: =IF(Tablo1[[#This Row],[Durum]]="Alış",Tablo1[[#This Row],[Adet]]*Tablo1[[#This Row],[Fiyat]],(-Tablo1[[#This Row],[Adet]]*Tablo1[[#This Row],[Fiyat]]))/Tablo1[[#This Row],[Kur]] -> 24.421169 | I17: =+I16+1 -> 14 | J17: 45713 | K17: 36.45 | L17: -40.945955 | M17: 6.213946 | N17: -72.63 | O17: -303 | P17: =SUM(L17:O17)-Q16 -> -940.12809 | Q17: =+P17+Q16 -> -410.36201 | R17: =+Q17/I17 -> -29.311572
B18: 45706 | C18: VBTYZ | D18: Alış | E18: 50 | F18: 22.82 | G18: =VLOOKUP(Tablo1[[#This Row],[Tarih]],$J$3:$K$460,2,FALSE) -> 36.28 | H18: =IF(Tablo1[[#This Row],[Durum]]="Alış",Tablo1[[#This Row],[Adet]]*Tablo1[[#This Row],[Fiyat]],(-Tablo1[[#This Row],[Adet]]*Tablo1[[#This Row],[Fiyat]]))/Tablo1[[#This Row],[Kur]] -> 31.449835 | I18: =+I17+1 -> 15 | J18: 45714 | K18: 36.43 | L18: -38.191368 | M18: 7.8203551 | N18: -90.94 | O18: -738.7 | P18: =SUM(L18:O18)-Q17 -> -449.649 | Q18: =+P18+Q17 -> -860.01101 | R18: =+Q18/I18 -> -57.334068
B19: 45706 | C19: KONTR | D19: Alış | E19: 100 | F19: 32.66 | G19: =VLOOKUP(Tablo1[[#This Row],[Tarih]],$J$3:$K$460,2,FALSE) -> 36.28 | H19: =IF(Tablo1[[#This Row],[Durum]]="Alış",Tablo1[[#This Row],[Adet]]*Tablo1[[#This Row],[Fiyat]],(-Tablo1[[#This Row],[Adet]]*Tablo1[[#This Row],[Fiyat]]))/Tablo1[[#This Row],[Kur]] -> 90.022051 | I19: =+I18+1 -> 16 | J19: 45715 | K19: 36.43 | L19: -38.191368 | M19: 7.8203551 | N19: -90.94 | O19: -738.7 | P19: =SUM(L19:O19)-Q18 -> 0 | Q19: =+P19+Q18 -> -860.01101 | R19: =+Q19/I19 -> -53.750688
B20: 45706 | C20: TNZTP | D20: Satış | E20: 20 | F20: 55 | G20: =VLOOKUP(Tablo1[[#This Row],[Tarih]],$J$3:$K$460,2,FALSE) -> 36.28 | H20: =IF(Tablo1[[#This Row],[Durum]]="Alış",Tablo1[[#This Row],[Adet]]*Tablo1[[#This Row],[Fiyat]],(-Tablo1[[#This Row],[Adet]]*Tablo1[[#This Row],[Fiyat]]))/Tablo1[[#This Row],[Kur]] -> -30.319735 | I20: =+I19+1 -> 17 | J20: 45716 | K20: =K19 -> 36.43 | L20: -38.191368 | M20: 7.8203551 | N20: -90.94 | O20: -738.7 | P20: =SUM(L20:O20)-Q19 -> 0 | Q20: =+P20+Q19 -> -860.01101 | R20: =+Q20/I20 -> -50.588883
B21: 45707 | C21: TAVHL | D21: Alış | E21: 20 | F21: 257.5 | G21: =VLOOKUP(Tablo1[[#This Row],[Tarih]],$J$3:$K$460,2,FALSE) -> 36.3 | H21: =IF(Tablo1[[#This Row],[Durum]]="Alış",Tablo1[[#This Row],[Adet]]*Tablo1[[#This Row],[Fiyat]],(-Tablo1[[#This Row],[Adet]]*Tablo1[[#This Row],[Fiyat]]))/Tablo1[[#This Row],[Kur]] -> 141.87328 | I21: =+I20+1 -> 18 | J21: 45717 | K21: =K20 -> 36.43 | L21: -38.191368 | M21: 7.8203551 | N21: -90.94 | O21: -738.7 | P21: =SUM(L21:O21)-Q20 -> 0 | Q21: =+P21+Q20 -> -860.01101 | R21: =+Q21/I21 -> -47.77839
B22: 45708 | C22: MARKA | D22: Satış | E22: 30 | F22: 52.05 | G22: =VLOOKUP(Tablo1[[#This Row],[Tarih]],$J$3:$K$460,2,FALSE) -> 36.29 | H22: =IF(Tablo1[[#This Row],[Durum]]="Alış",Tablo1[[#This Row],[Adet]]*Tablo1[[#This Row],[Fiyat]],(-Tablo1[[#This Row],[Adet]]*Tablo1[[#This Row],[Fiyat]]))/Tablo1[[#This Row],[Kur]] -> -43.028382 | I22: =+I21+1 -> 19 | J22: 45718 | K22: 36.5 | L22: -38.191368 | M22: 7.245531 | N22: -92.111757 | O22: -1687 | P22: =SUM(L22:O22)-Q21 -> -950.04658 | Q22: =+P22+Q21 -> -1810.0576 | R22: =+Q22/I22 -> -95.266189
B23: 45708 | C23: ONCSM | D23: Alış | E23: 22 | F23: 95 | G23: =VLOOKUP(Tablo1[[#This Row],[Tarih]],$J$3:$K$460,2,FALSE) -> 36.29 | H23: =IF(Tablo1[[#This Row],[Durum]]="Alış",Tablo1[[#This Row],[Adet]]*Tablo1[[#This Row],[Fiyat]],(-Tablo1[[#This Row],[Adet]]*Tablo1[[#This Row],[Fiyat]]))/Tablo1[[#This Row],[Kur]] -> 57.591623 | I23: =+I22+1 -> 20 | J23: 45719 | K23: =K22 -> 36.5 | R23: =+Q23/I23 -> 0
B24: 45708 | C24: PRDGS | D24: Satış | E24: 210 | F24: 5.36 | G24: =VLOOKUP(Tablo1[[#This Row],[Tarih]],$J$3:$K$460,2,FALSE) -> 36.29 | H24: =IF(Tablo1[[#This Row],[Durum]]="Alış",Tablo1[[#This Row],[Adet]]*Tablo1[[#This Row],[Fiyat]],(-Tablo1[[#This Row],[Adet]]*Tablo1[[#This Row],[Fiyat]]))/Tablo1[[#This Row],[Kur]] -> -31.016809 | I24: =+I23+1 -> 21 | J24: 45720 | K24: =K23 -> 36.5 | R24: =+Q24/I24 -> 0
B25: 45708 | C25: PRDGS | D25: Alış | E25: 210 | F25: 5.09 | G25: =VLOOKUP(Tablo1[[#This Row],[Tarih]],$J$3:$K$460,2,FALSE) -> 36.29 | H25: =IF(Tablo1[[#This Row],[Durum]]="Alış",Tablo1[[#This Row],[Adet]]*Tablo1[[#This Row],[Fiyat]],(-Tablo1[[#This Row],[Adet]]*Tablo1[[#This Row],[Fiyat]]))/Tablo1[[#This Row],[Kur]] -> 29.454395 | I25: =+I24+1 -> 22 | J25: 45721 | K25: =K24 -> 36.5 | R25: =+Q25/I25 -> 0
B26: 45709 | C26: CEOEM | D26: Alış | E26: 50 | F26: 30 | G26: =VLOOKUP(Tablo1[[#This Row],[Tarih]],$J$3:$K$460,2,FALSE) -> 36.45 | H26: =IF(Tablo1[[#This Row],[Durum]]="Alış",Tablo1[[#This Row],[Adet]]*Tablo1[[#This Row],[Fiyat]],(-Tablo1[[#This Row],[Adet]]*Tablo1[[#This Row],[Fiyat]]))/Tablo1[[#This Row],[Kur]] -> 41.152263 | I26: =+I25+1 -> 23 | J26: 45722 | K26: =K25 -> 36.5 | R26: =+Q26/I26 -> 0
B27: 45709 | C27: OBASE | D27: Alış | E27: 70 | F27: 30.5 | G27: =VLOOKUP(Tablo1[[#This Row],[Tarih]],$J$3:$K$460,2,FALSE) -> 36.45 | H27: =IF(Tablo1[[#This Row],[Durum]]="Alış",Tablo1[[#This Row],[Adet]]*Tablo1[[#This Row],[Fiyat]],(-Tablo1[[#This Row],[Adet]]*Tablo1[[#This Row],[Fiyat]]))/Tablo1[[#This Row],[Kur]] -> 58.573388 | I27: =+I26+1 -> 24 | J27: 45723 | K27: =K26 -> 36.5 | R27: =+Q27/I27 -> 0
B28: 45709 | C28: ADEL | D28: Alış | E28: 35 | F28: 28.12 | G28: =VLOOKUP(Tablo1[[#This Row],[Tarih]],$J$3:$K$460,2,FALSE) -> 36.45 | H28: =IF(Tablo1[[#This Row],[Durum]]="Alış",Tablo1[[#This Row],[Adet]]*Tablo1[[#This Row],[Fiyat]],(-Tablo1[[#This Row],[Adet]]*Tablo1[[#This Row],[Fiyat]]))/Tablo1[[#This Row],[Kur]] -> 27.001372 | I28: =+I27+1 -> 25 | J28: 45724 | K28: =K27 -> 36.5 | R28: =+Q28/I28 -> 0
B29: 45712 | C29: MARKA | D29: Alış | E29: 30 | F29: 48 | G29: =VLOOKUP(Tablo1[[#This Row],[Tarih]],$J$3:$K$460,2,FALSE) -> 36.43 | H29: =IF(Tablo1[[#This Row],[Durum]]="Alış",Tablo1[[#This Row],[Adet]]*Tablo1[[#This Row],[Fiyat]],(-Tablo1[[#This Row],[Adet]]*Tablo1[[#This Row],[Fiyat]]))/Tablo1[[#This Row],[Kur]] -> 39.527862 | I29: =+I28+1 -> 26 | J29: 45725 | K29: =K28 -> 36.5 | R29: =+Q29/I29 -> 0
B30: 45713 | C30: PRDGS | D30: Satış | E30: 210 | F30: 5.4 | G30: =VLOOKUP(Tablo1[[#This Row],[Tarih]],$J$3:$K$460,2,FALSE) -> 36.45 | H30: =IF(Tablo1[[#This Row],[Durum]]="Alış",Tablo1[[#This Row],[Adet]]*Tablo1[[#This Row],[Fiyat]],(-Tablo1[[#This Row],[Adet]]*Tablo1[[#This Row],[Fiyat]]))/Tablo1[[#This Row],[Kur]] -> -31.111111 | I30: =+I29+1 -> 27 | J30: 45726 | K30: =K29 -> 36.5 | R30: =+Q30/I30 -> 0
B31: 45713 | C31: CEOEM | D31: Alış | E31: 40 | F31: 26.8 | G31: =VLOOKUP(Tablo1[[#This Row],[Tarih]],$J$3:$K$460,2,FALSE) -> 36.45 | H31: =IF(Tablo1[[#This Row],[Durum]]="Alış",Tablo1[[#This Row],[Adet]]*Tablo1[[#This Row],[Fiyat]],(-Tablo1[[#This Row],[Adet]]*Tablo1[[#This Row],[Fiyat]]))/Tablo1[[#This Row],[Kur]] -> 29.410151 | I31: =+I30+1 -> 28 | J31: 45727 | K31: =K30 -> 36.5 | R31: =+Q31/I31 -> 0
I32: =+I31+1 -> 29 | J32: 45728 | K32: =K31 -> 36.5 | R32: =+Q32/I32 -> 0
I33: =+I32+1 -> 30 | J33: 45729 | K33: =K32 -> 36.5
I34: =+I33+1 -> 31 | J34: 45730 | K34: =K33 -> 36.5
I35: =+I34+1 -> 32 | J35: 45731 | K35: =K34 -> 36.5
I36: =+I35+1 -> 33 | J36: 45732
I37: =+I36+1 -> 34 | J37: 45733
I38: =+I37+1 -> 35 | J38: 45734
I39: =+I38+1 -> 36 | J39: 45735
I40: =+I39+1 -> 37 | J40: 45736
...

Sheet İşlem Fon
B2: Tarih | C2: Hisse | D2: Durum | E2: Adet | F2: Fiyat | G2: Kur | H2: Tutar
B3: 45699 | C3: BGP | D3: Alış | E3: 237 | F3: 3.459343 | G3: =VLOOKUP(Tablo13[[#This Row],[Tarih]],'İşlem Hisse'!$J$3:$K$460,2,FALSE) -> 36.01 | H3: =IF(Tablo13[[#This Row],[Durum]]="Alış",Tablo13[[#This Row],[Adet]]*Tablo13[[#This Row],[Fiyat]],(-Tablo13[[#This Row],[Adet]]*Tablo13[[#This Row],[Fiyat]]))/Tablo13[[#This Row],[Kur]] -> 22.767684 | J3: BGP | K3: 3.581879
B4: 45699 | C4: IST | D4: Alış | E4: 9641 | F4: 0.103719 | G4: =VLOOKUP(Tablo13[[#This Row],[Tarih]],'İşlem Hisse'!$J$3:$K$460,2,FALSE) -> 36.01 | H4: =IF(Tablo13[[#This Row],[Durum]]="Alış",Tablo13[[#This Row],[Adet]]*Tablo13[[#This Row],[Fiyat]],(-Tablo13[[#This Row],[Adet]]*Tablo13[[#This Row],[Fiyat]]))/Tablo13[[#This Row],[Kur]] -> 27.768811 | J4: ADP | K4: 1.125153
B5: 45699 | C5: TCB | D5: Alış | E5: 7901 | F5: 0.126566 | G5: =VLOOKUP(Tablo13[[#This Row],[Tarih]],'İşlem Hisse'!$J$3:$K$460,2,FALSE) -> 36.01 | H5: =IF(Tablo13[[#This Row],[Durum]]="Alış",Tablo13[[#This Row],[Adet]]*Tablo13[[#This Row],[Fiyat]],(-Tablo13[[#This Row],[Adet]]*Tablo13[[#This Row],[Fiyat]]))/Tablo13[[#This Row],[Kur]] -> 27.770007 | J5: DLY | K5: 3.357893
B6: 45699 | C6: GO6 | D6: Alış | E6: 455 | F6: 2.193952 | G6: =VLOOKUP(Tablo13[[#This Row],[Tarih]],'İşlem Hisse'!$J$3:$K$460,2,FALSE) -> 36.01 | H6: =IF(Tablo13[[#This Row],[Durum]]="Alış",Tablo13[[#This Row],[Adet]]*Tablo13[[#This Row],[Fiyat]],(-Tablo13[[#This Row],[Adet]]*Tablo13[[#This Row],[Fiyat]]))/Tablo13[[#This Row],[Kur]] -> 27.721415 | J6: ZJB | K6: 10.495877
B7: 45699 | C7: KSA | D7: Alış | E7: 469 | F7: 2.130016 | G7: =VLOOKUP(Tablo13[[#This Row],[Tarih]],'İşlem Hisse'!$J$3:$K$460,2,FALSE) -> 36.01 | H7: =IF(Tablo13[[#This Row],[Durum]]="Alış",Tablo13[[#This Row],[Adet]]*Tablo13[[#This Row],[Fiyat]],(-Tablo13[[#This Row],[Adet]]*Tablo13[[#This Row],[Fiyat]]))/Tablo13[[#This Row],[Kur]] -> 27.741669 | J7: GGK | K7: 7.411764
B8: 45699 | C8: DLY | D8: Alış | E8: 303 | F8: 3.293279 | G8: =VLOOKUP(Tablo13[[#This Row],[Tarih]],'İşlem Hisse'!$J$3:$K$460,2,FALSE) -> 36.01 | H8: =IF(Tablo13[[#This Row],[Durum]]="Alış",Tablo13[[#This Row],[Adet]]*Tablo13[[#This Row],[Fiyat]],(-Tablo13[[#This Row],[Adet]]*Tablo13[[#This Row],[Fiyat]]))/Tablo13[[#This Row],[Kur]] -> 27.710734 | J8: GO6 | K8: 2.238635
B9: 45699 | C9: PPN | D9: Alış | E9: 326 | F9: 3.061219 | G9: =VLOOKUP(Tablo13[[#This Row],[Tarih]],'İşlem Hisse'!$J$3:$K$460,2,FALSE) -> 36.01 | H9: =IF(Tablo13[[#This Row],[Durum]]="Alış",Tablo13[[#This Row],[Adet]]*Tablo13[[#This Row],[Fiyat]],(-Tablo13[[#This Row],[Adet]]*Tablo13[[#This Row],[Fiyat]]))/Tablo13[[#This Row],[Kur]] -> 27.713341 | J9: IST | K9: 0.105909
B10: 45700 | C10: GGK | D10: Alış | E10: 136 | F10: 7.337439 | G10: =VLOOKUP(Tablo13[[#This Row],[Tarih]],'İşlem Hisse'!$J$3:$K$460,2,FALSE) -> 36.1 | H10: =IF(Tablo13[[#This Row],[Durum]]="Alış",Tablo13[[#This Row],[Adet]]*Tablo13[[#This Row],[Fiyat]],(-Tablo13[[#This Row],[Adet]]*Tablo13[[#This Row],[Fiyat]]))/Tablo13[[#This Row],[Kur]] -> 27.642429 | J10: KSA | K10: 2.175595
B11: 45700 | C11: OJK | D11: Alış | E11: 147 | F11: 6.785738 | G11: =VLOOKUP(Tablo13[[#This Row],[Tarih]],'İşlem Hisse'!$J$3:$K$460,2,FALSE) -> 36.1 | H11: =IF(Tablo13[[#This Row],[Durum]]="Alış",Tablo13[[#This Row],[Adet]]*Tablo13[[#This Row],[Fiyat]],(-Tablo13[[#This Row],[Adet]]*Tablo13[[#This Row],[Fiyat]]))/Tablo13[[#This Row],[Kur]] -> 27.631676 | J11: OJK | K11: 6.844674
B12: 45700 | C12: TCA | D12: Alış | E12: 2000 | F12: 0.441638 | G12: =VLOOKUP(Tablo13[[#This Row],[Tarih]],'İşlem Hisse'!$J$3:$K$460,2,FALSE) -> 36.1 | H12: =IF(Tablo13[[#This Row],[Durum]]="Alış",Tablo13[[#This Row],[Adet]]*Tablo13[[#This Row],[Fiyat]],(-Tablo13[[#This Row],[Adet]]*Tablo13[[#This Row],[Fiyat]]))/Tablo13[[#This Row],[Kur]] -> 24.467479 | J12: PPN | K12: 3.1228
B13: 45700 | C13: TAU | D13: Alış | E13: 1831 | F13: 0.545856 | G13: =VLOOKUP(Tablo13[[#This Row],[Tarih]],'İşlem Hisse'!$J$3:$K$460,2,FALSE) -> 36.1 | H13: =IF(Tablo13[[#This Row],[Durum]]="Alış",Tablo13[[#This Row],[Adet]]*Tablo13[[#This Row],[Fiyat]],(-Tablo13[[#This Row],[Adet]]*Tablo13[[#This Row],[Fiyat]]))/Tablo13[[#This Row],[Kur]] -> 27.685937 | J13: TAU | K13: 0.57213
B14: 45700 | C14: ADP | D14: Alış | E14: 931 | F14: 1.073506 | G14: =VLOOKUP(Tablo13[[#This Row],[Tarih]],'İşlem Hisse'!$J$3:$K$460,2,FALSE) -> 36.1 | H14: =IF(Tablo13[[#This Row],[Durum]]="Alış",Tablo13[[#This Row],[Adet]]*Tablo13[[#This Row],[Fiyat]],(-Tablo13[[#This Row],[Adet]]*Tablo13[[#This Row],[Fiyat]]))/Tablo13[[#This Row],[Kur]] -> 27.685155 | J14: TCA | K14: 0.455916
... B16: 45700 | C16: ZJB | D16: Alış | E16: 118 | F16: 9.667284 | G16: =VLOOKUP(Tablo13[[#This Row],[Tarih]],'İşlem Hisse'!$J$3:$K$460,2,FALSE) -> 36.1 | H16: =IF(Tablo13[[#This Row],[Durum]]="Alış",Tablo13[[#This Row],[Adet]]*Tablo13[[#This Row],[Fiyat]],(-Tablo13[[#This Row],[Adet]]*Tablo13[[#This Row],[Fiyat]]))/Tablo13[[#This Row],[Kur]] -> 31.599432 | J16: TTA | K16: 0.354871

Sheet İşlem FonA
B2: Tarih | C2: Hisse | D2: Durum | E2: Adet | F2: Fiyat | G2: Kur | H2: Tutar
B3: 45699 | C3: HEPS | D3: Alış | E3: 1 | F3: 1.06 | G3: 1 | H3: =IF(Tablo134[[#This Row],[Durum]]="Alış",Tablo134[[#This Row],[Adet]]*Tablo134[[#This Row],[Fiyat]],(-Tablo134[[#This Row],[Adet]]*Tablo134[[#This Row],[Fiyat]]))/Tablo134[[#This Row],[Kur]] -> 1.06 | J3: HEPS | K3: 3.32
B4: 45699 | C4: QLYD | D4: Alış | E4: 60 | F4: 17.88 | G4: 1 | H4: =IF(Tablo134[[#This Row],[Durum]]="Alış",Tablo134[[#This Row],[Adet]]*Tablo134[[#This Row],[Fiyat]],(-Tablo134[[#This Row],[Adet]]*Tablo134[[#This Row],[Fiyat]]))/Tablo134[[#This Row],[Kur]] -> 1072.8 | J4: QLYD | K4: 17.94
B5: 45699 | C5: KBWD | D5: Alış | E5: 59 | F5: 15.25 | G5: 1 | H5: =IF(Tablo134[[#This Row],[Durum]]="Alış",Tablo134[[#This Row],[Adet]]*Tablo134[[#This Row],[Fiyat]],(-Tablo134[[#This Row],[Adet]]*Tablo134[[#This Row],[Fiyat]]))/Tablo134[[#This Row],[Kur]] -> 899.75 | J5: KBWD | K5: 15.53
B6: 45699 | C6: PFFR | D6: Alış | E6: 100 | F6: 18.69 | G6: 1 | H6: =IF(Tablo134[[#This Row],[Durum]]="Alış",Tablo134[[#This Row],[Adet]]*Tablo134[[#This Row],[Fiyat]],(-Tablo134[[#This Row],[Adet]]*Tablo134[[#This Row],[Fiyat]]))/Tablo134[[#This Row],[Kur]] -> 1869 | J6: PFFR | K6: 18.73
B7: 45699 | C7: SOXL | D7: Alış | E7: 25 | F7: 27.72 | G7: 1 | H7: =IF(Tablo134[[#This Row],[Durum]]="Alış",Tablo134[[#This Row],[Adet]]*Tablo134[[#This Row],[Fiyat]],(-Tablo134[[#This Row],[Adet]]*Tablo134[[#This Row],[Fiyat]]))/Tablo134[[#This Row],[Kur]] -> 693 | J7: SOXL | K7: 22.73
B8: 45699 | C8: SAVA | D8: Alış | E8: 5 | F8: 4.46 | G8: 1 | H8: =IF(Tablo134[[#This Row],[Durum]]="Alış",Tablo134[[#This Row],[Adet]]*Tablo134[[#This Row],[Fiyat]],(-Tablo134[[#This Row],[Adet]]*Tablo134[[#This Row],[Fiyat]]))/Tablo134[[#This Row],[Kur]] -> 22.3 | J8: SAVA | K8: 2.4
B9: 45715 | C9: PFFR | D9: Alış | E9: 0.51364366 | F9: 0 | G9: 1 | H9: =IF(Tablo134[[#This Row],[Durum]]="Alış",Tablo134[[#This Row],[Adet]]*Tablo134[[#This Row],[Fiyat]],(-Tablo134[[#This Row],[Adet]]*Tablo134[[#This Row],[Fiyat]]))/Tablo134[[#This Row],[Kur]] -> 0
B10: 45716 | C10: KBWD | D10: Alış | E10: 0.44672873 | F10: 0 | G10: 1 | H10: =IF(Tablo134[[#This Row],[Durum]]="Alış",Tablo134[[#This Row],[Adet]]*Tablo134[[#This Row],[Fiyat]],(-Tablo134[[#This Row],[Adet]]*Tablo134[[#This Row],[Fiyat]]))/Tablo134[[#This Row],[Kur]] -> 0

Sheet Hisse
E1: =SUM(F1:M1) -> 142 | F1: 40 | G1: 30 | H1: 20 | I1: 10 | J1: 35 | K1: 5 | L1: 1 | M1: 1
A2: Şirket | B2: Son Fiyat | C2: Gün % | D2: Hacim | E2: Piyasa Değeri | F2: 1 Hafta % | G2: 1 Ay % | H2: 3 Ay % | I2: 6 Ay % | J2: 2025 % | K2: 1 Yıl % | L2: 3 Yıl % | M2: 5 Yıl %
A3: A1CAP | B3: 4.34 | C3: -0.46 | D3: 7757415.2 | E3: 2929500000 | F3: -0.91 | G3: -10.14 | H3: -9.58 | I3: -16.05 | J3: -22.5 | K3: -38.09
A4: ACSEL | B4: 105.3 | C4: 0.67 | D4: 5721753.8 | E4: 1128995010 | F4: -2.05 | G4: -11.74 | H4: -0.85 | I4: -1.87 | J4: -7.63 | K4: -37.36 | L4: 342.81 | M4: 1626.23
A5: ADEL | B5: 27.98 | C5: 0.14 | D5: 12204408 | E5: 7271302500 | F5: 0.5 | G5: -12.56 | H5: -20.42 | I5: -42.29 | J5: -16.43 | K5: -41.3 | L5: 1100.86 | M5: 2174.8 | O5: =F5*F$1/$E$1 -> 0.14084507 | P5: =G5*G$1/$E$1 -> -2.6535211 | Q5: =H5*H$1/$E$1 -> -2.8760563 | R5: =I5*I$1/$E$1 -> -2.978169 | S5: =J5*J$1/$E$1 -> -4.0496479 | T5: =K5*K$1/$E$1 -> -1.4542254 | U5: =L5*L$1/$E$1 -> 7.7525352 | V5: =M5*M$1/$E$1 -> 15.315493 | W5: =SUM(O5:V5) -> 9.1972535
A6: ADESE | B6: 1.92 | C6: -0.52 | D6: 31205229 | E6: 1935360000 | F6: -1.03 | G6: -6.8 | H6: -9.86 | I6: -3.52 | J6: -11.93 | K6: -33.79 | L6: 174.29 | M6: 60
A7: ADGYO | B7: 27.78 | C7: -0.43 | D7: 7226807.8 | E7: 8158986000 | F7: 0.22 | G7: -5.77 | H7: -11.64 | I7: -12.86 | J7: -16.93 | K7: -25.76
A8: AEFES | B8: 172.8 | C8: -0.35 | D8: 4.146936e+09 | E8: 1.0231579e+11 | F8: 5.05 | G8: 7.06 | H8: -13.43 | I8: -22.41 | J8: -9.81 | K8: 16.59 | L8: 715.86 | M8: 927.35
A9: AFYON | B9: 14.71 | C9: 0.07 | D9: 58866599 | E9: 5884000000 | F9: 3.37 | G9: -5.83 | H9: 5.68 | I9: -7.02 | J9: -0.68 | K9: 15.1 | L9: 431.05 | M9: 597.16
A10: AGESA | B10: 143 | C10: -0.07 | D10: 33102696 | E10: 25740000000 | F10: -0.28 | G10: 1.71 | H10: 2 | I10: 43.36 | J10: -12.11 | K10: 127.6 | L10: 631.46 | M10: 1056.96
A11: AGHOL | B11: 308.75 | C11: -2.14 | D11: 2.3348053e+08 | E11: 7.5191282e+10 | F11: -0.64 | G11: 2.66 | H11: -5.15 | I11: -6.51 | J11: -1.36 | K11: 21.88 | L11: 888.32 | M11: 1885.53
A12: AGROT | B12: 8.93 | C12: -1.11 | D12: 1.0284584e+08 | E12: 10716000000 | F12: -2.83 | G12: -10.97 | H12: -35.8 | I12: -44.64 | J12: -16.39 | K12: -75.14
A13: AGYO | B13: 6.88 | C13: 0.15 | D13: 4624160.2 | E13: 1811779200 | F13: -2.41 | G13: -6.01 | H13: -15.58 | I13: -1.01 | J13: -9.47 | K13: -30.29 | L13: 175.2 | M13: 327.33
A14: AHGAZ | B14: 19.54 | C14: -2.5 | D14: 1.0063089e+08 | E14: 50804000000 | F14: -1.66 | G14: 1.61 | H14: -3.27 | I14: 46.92 | J14: -5.79 | K14: 41.08
A15: AHSGY | B15: 24.3 | C15: 5.65 | D15: 53580083 | E15: 4738500000 | F15: 1.76 | G15: -4.03 | H15: 9.56 | I15: -4.93 | J15: 11.98
A16: AKBNK | B16: 67.3 | C16: -0.74 | D16: 5.1544478e+09 | E16: 349960000000 | F16: 3.86 | G16: 3.78 | H16: 10.6 | I16: 15.44 | J16: 3.78 | K16: 74.26 | L16: 1034.91 | M16: 1112.61
A17: AKCNS | B17: 172 | C17: -3.15 | D17: 61613503 | E17: 32928895696 | F17: -1.43 | G17: -17.39 | H17: 4.43 | I17: 8.86 | J17: -4.44 | K17: 15.03 | L17: 999.74 | M17: 2093.88
A18: AKENR | B18: 11.95 | C18: -0.25 | D18: 76253919 | E18: 8713509800 | F18: -5.16 | G18: -15.25 | H18: 4.37 | I18: -5.46 | J18: -9.33 | K18: 103.92 | L18: 696.67 | M18: 1038.1
A19: AKFGY | B19: 1.86 | C19: -0.53 | D19: 22237695 | E19: 7254000000 | F19: -1.06 | G19: -6.53 | H19: -16.96 | I19: -15.45 | J19: -10.14 | K19: -27.91 | L19: -7 | M19: 190.63
A20: AKFIS | B20: 21.64 | C20: -1.81 | D20: 2.588316e+08 | E20: 1.3775679e+10 | F20: 0.19 | G20: -18.03
A21: AKFYE | B21: 17.11 | C21: -0.7 | D21: 58112244 | E21: 2.0480027e+10 | F21: 3.38 | G21: -4.94 | H21: -7.61 | I21: -21.59 | J21: -12.75 | K21: -37.37
A22: AKGRT | B22: 6.42 | C22: -1.68 | D22: 76567352 | E22: 10349040000 | F22: -7.23 | G22: -20.15 | H22: -3.46 | I22: 15.88 | J22: -15.97 | K22: 5.07 | L22: 314.19 | M22: 401.56
A23: AKMGY | B23: 213.4 | C23: -0.28 | D23: 1632075 | E23: 7952137600 | F23: -4.94 | G23: 1.14 | H23: 2.89 | I23: -3.87 | J23: -4.99 | K23: -10.6 | L23: 496.92 | M23: 998.3
A24: AKSA | B24: 12.98 | C24: -0.31 | D24: 4.3475051e+08 | E24: 50427300000 | F24: -0.46 | G24: 12.48 | H24: 31.91 | I24: 45.35 | J24: 0.31 | K24: 53.25 | L24: 377.21 | M24: 2548.98
A25: AKSEN | B25: 35.34 | C25: -0.95 | D25: 1.2553429e+08 | E25: 4.3338793e+10 | F25: -2.75 | G25: -14.01 | H25: -0.62 | I25: -6.26 | J25: -9.85 | K25: -1.92 | L25: 198.48 | M25: 2054.88
A26: AKSGY | B26: 6.76 | C26: 0 | D26: 10612886 | E26: 16325400000 | F26: -1.46 | G26: -5.72 | H26: -4.52 | I26: 13.04 | J26: -9.87 | K26: 16.96 | L26: 1129.09 | M26: 777.92
A27: AKSUE | B27: 12.55 | C27: 0.8 | D27: 12580824 | E27: 828300000 | F27: 17.84 | G27: 14.82 | H27: 5.64 | I27: 11.95 | J27: 7.17 | K27: -15.15 | L27: -10.61 | M27: 359.71
A28: AKYHO | B28: 3.5 | C28: 5.11 | D28: 50641981 | E28: 868665000 | F28: 15.51 | G28: 37.25 | H28: 5.74 | I28: 0.29 | J28: 29.63 | K28: 12.9 | L28: 272.34 | M28: 614.29
A29: ALARK | B29: 76.2 | C29: -0.91 | D29: 4.9351212e+08 | E29: 33147000000 | F29: -1.87 | G29: -11.45 | H29: -20.91 | I29: -20.79 | J29: -17.17 | K29: -39.75 | L29: 325.46 | M29: 1356.98
A30: ALBRK | B30: 6.75 | C30: -0.74 | D30: 99756384 | E30: 16875000000 | F30: 3.53 | G30: -5.73 | H30: 8.7 | I30: 13.07 | J30: 4.98 | K30: 59.2 | L30: 423.26 | M30: 530.84
A31: ALCAR | B31: 922.5 | C31: 8.4 | D31: 98773552 | E31: 9963000000 | F31: 3.07 | G31: -3.71 | H31: -9.2 | I31: -4.8 | J31: -14.03 | K31: -43.61 | L31: 247.16 | M31: 1733.63
A32: ALCTL | B32: 147.8 | C32: 8.92 | D32: 1.1656002e+08 | E32: 5.7199741e+09 | F32: 9.24 | G32: 7.33 | H32: 23.37 | I32: 16.84 | J32: 23.27 | K32: 9.56 | L32: 518.93 | M32: 654.08 | O32: =F32*F$1/$E$1 -> 2.6028169 | P32: =G32*G$1/$E$1 -> 1.5485915 | Q32: =H32*H$1/$E$1 -> 3.2915493 | R32: =I32*I$1/$E$1 -> 1.1859155 | S32: =J32*J$1/$E$1 -> 5.7355634 | T32: =K32*K$1/$E$1 -> 0.33661972 | U32: =L32*L$1/$E$1 -> 3.6544366 | V32: =M32*M$1/$E$1 -> 4.6061972 | W32: =SUM(O32:V32) -> 22.96169
A33: ALFAS | B33: 56.15 | C33: 2.84 | D33: 168927749 | E33: 20663200000 | F33: -2.43 | G33: -23.45 | H33: 11.3 | I33: -2.01 | J33: -17.37 | K33: -45.32
A34: ALGYO | B34: 18.47 | C34: 0.05 | D34: 18781395 | E34: 5352606000 | F34: 1.32 | G34: -8.93 | H34: -6.81 | I34: -16.84 | J34: -11.8 | K34: -25.76 | L34: 186.8 | M34: 576.56
A35: ALKA | B35: 7.4 | C35: 0.95 | D35: 23610052 | E35: 5439000000 | F35: -4.27 | G35: -9.76 | H35: 12.8 | I35: 16.72 | J35: -19.04 | K35: -20.09 | L35: 478.13 | M35: 1847.37
A36: ALKIM | B36: 16.66 | C36: 0.6 | D36: 10228289 | E36: 4998000000 | F36: 2.84 | G36: -3.92 | H36: 0.12 | I36: 2.33 | J36: -12.5 | K36: -22.87 | L36: 92.38 | M36: 371.95
A37: ALKLC | B37: 31.8 | C37: 0.82 | D37: 2.8574847e+08 | E37: 3561600000 | F37: 5.16 | G37: 24.61 | H37: 4.13 | I37: 8.05 | J37: -11.42
A38: ALMAD | B38: 7.72 | C38: -1.91 | D38: 15859650 | E38: 2123000000 | F38: 1.85 | G38: 2.66 | H38: 8.12 | I38: 12.37 | J38: 2.52 | K38: -14.41 | L38: 343.68 | M38: 1444
A39: ALTNY | B39: 72.15 | C39: 0.91 | D39: 3.0882089e+08 | E39: 1.6976471e+10 | F39: 6.57 | G39: -5.38 | H39: -20.8 | I39: -24.65 | J39: -12.23
A40: ALVES | B40: 30.2 | C40: 0.33 | D40: 41442365 | E40: 4832000000 | F40: -2.52 | G40: -14.45 | H40: -7.48 | I40: -36.23 | J40: -21.07 | K40: 28.51
...
